2019-11-06 08:31:59.818 [error] <0.537.0> CRASH REPORT Process <0.537.0> with 0 neighbours exited with reason: {{#{'__exception__' => true,'__struct__' => 'Elixir.Phoenix.Router.NoRouteError',conn => #{'__struct__' => 'Elixir.Plug.Conn',adapter => {'Elixir.Plug.Cowboy.Conn',#{bindings => #{},body_length => 0,cert => undefined,has_body => false,headers => #{<<"accept">> => <<"*/*">>,<<"accept-encoding">> => <<"gzip, deflate, br">>,<<"accept-language">> => <<"en-US,en;q=0.9">>,<<"connection">> => <<"keep-alive">>,<<"host">> => <<"localhost:4000">>,<<"http_method">> => <<"POST">>,<<"purpose">> => <<"...">>,...},...}},...},...},...},...} in 'Elixir.Phoenix.Endpoint.Cowboy2Handler':init/4 line 59 in 'Elixir.Phoenix.Endpoint.Cowboy2Handler':init/4 line 59
2019-11-06 08:31:59.819 [error] <0.534.0> CRASH REPORT Process <0.534.0> with 0 neighbours exited with reason: {{#{'__exception__' => true,'__struct__' => 'Elixir.Phoenix.Router.NoRouteError',conn => #{'__struct__' => 'Elixir.Plug.Conn',adapter => {'Elixir.Plug.Cowboy.Conn',#{bindings => #{},body_length => 0,cert => undefined,has_body => false,headers => #{<<"accept">> => <<"text/css,*/*;q=0.1">>,<<"accept-encoding">> => <<"gzip, deflate, br">>,<<"accept-language">> => <<"en-US,en;q=0.9">>,<<"connection">> => <<"keep-alive">>,<<"host">> => <<"localhost:4000">>,<<"http_method">> => <<"POST">>,<<"...">> => ...,...},...}},...},...},...},...} in 'Elixir.Phoenix.Endpoint.Cowboy2Handler':init/4 line 59 in 'Elixir.Phoenix.Endpoint.Cowboy2Handler':init/4 line 59
2019-11-06 08:31:59.819 [error] <0.535.0> CRASH REPORT Process <0.535.0> with 0 neighbours exited with reason: {{#{'__exception__' => true,'__struct__' => 'Elixir.Phoenix.Router.NoRouteError',conn => #{'__struct__' => 'Elixir.Plug.Conn',adapter => {'Elixir.Plug.Cowboy.Conn',#{bindings => #{},body_length => 0,cert => undefined,has_body => false,headers => #{<<"accept">> => <<"image/webp,image/apng,image/*,*/*;q=0.8">>,<<"accept-encoding">> => <<"gzip, deflate, br">>,<<"accept-language">> => <<"en-US,en;q=0.9">>,<<"connection">> => <<"keep-alive">>,<<"host">> => <<"localhost:4000">>,<<"http_met...">> => ...,...},...}},...},...},...},...} in 'Elixir.Phoenix.Endpoint.Cowboy2Handler':init/4 line 59 in 'Elixir.Phoenix.Endpoint.Cowboy2Handler':init/4 line 59
2019-11-06 08:31:59.860 [error] <0.537.0> Cowboy stream 1 with ranch listener 'Elixir.RailwayUiWeb.Endpoint.HTTP' and connection process <0.536.0> had its request process exit with reason: {{#{'__exception__' => true,'__struct__' => 'Elixir.Phoenix.Router.NoRouteError',conn => #{'__struct__' => 'Elixir.Plug.Conn',adapter => {'Elixir.Plug.Cowboy.Conn',#{bindings => #{},body_length => 0,cert => undefined,has_body => false,headers => #{<<"accept">> => <<"*/*">>,<<"accept-encoding">> => <<"gzip, deflate, br">>,<<"accept-language">> => <<"en-US,en;q=0.9">>,<<"connection">> => <<"keep-alive">>,<<"host">> => <<"localhost:4000">>,<<"http_method">> => <<"POST">>,<<"purpose">> => <<"...">>,...},...}},...},...},...},...} in 'Elixir.Phoenix.Endpoint.Cowboy2Handler':init/4 line 59
2019-11-06 08:31:59.860 [error] <0.535.0> Cowboy stream 1 with ranch listener 'Elixir.RailwayUiWeb.Endpoint.HTTP' and connection process <0.499.0> had its request process exit with reason: {{#{'__exception__' => true,'__struct__' => 'Elixir.Phoenix.Router.NoRouteError',conn => #{'__struct__' => 'Elixir.Plug.Conn',adapter => {'Elixir.Plug.Cowboy.Conn',#{bindings => #{},body_length => 0,cert => undefined,has_body => false,headers => #{<<"accept">> => <<"image/webp,image/apng,image/*,*/*;q=0.8">>,<<"accept-encoding">> => <<"gzip, deflate, br">>,<<"accept-language">> => <<"en-US,en;q=0.9">>,<<"connection">> => <<"keep-alive">>,<<"host">> => <<"localhost:4000">>,<<"http_met...">> => ...,...},...}},...},...},...},...} in 'Elixir.Phoenix.Endpoint.Cowboy2Handler':init/4 line 59
2019-11-06 08:31:59.860 [error] <0.534.0> Cowboy stream 2 with ranch listener 'Elixir.RailwayUiWeb.Endpoint.HTTP' and connection process <0.498.0> had its request process exit with reason: {{#{'__exception__' => true,'__struct__' => 'Elixir.Phoenix.Router.NoRouteError',conn => #{'__struct__' => 'Elixir.Plug.Conn',adapter => {'Elixir.Plug.Cowboy.Conn',#{bindings => #{},body_length => 0,cert => undefined,has_body => false,headers => #{<<"accept">> => <<"text/css,*/*;q=0.1">>,<<"accept-encoding">> => <<"gzip, deflate, br">>,<<"accept-language">> => <<"en-US,en;q=0.9">>,<<"connection">> => <<"keep-alive">>,<<"host">> => <<"localhost:4000">>,<<"http_method">> => <<"POST">>,<<"...">> => ...,...},...}},...},...},...},...} in 'Elixir.Phoenix.Endpoint.Cowboy2Handler':init/4 line 59
2019-11-06 08:34:48.776 [error] <0.513.0> CRASH REPORT Process <0.513.0> with 0 neighbours exited with reason: {{#{'__exception__' => true,'__struct__' => 'Elixir.Phoenix.Router.NoRouteError',conn => #{'__struct__' => 'Elixir.Plug.Conn',adapter => {'Elixir.Plug.Cowboy.Conn',#{bindings => #{},body_length => 0,cert => undefined,has_body => false,headers => #{<<"accept">> => <<"text/css,*/*;q=0.1">>,<<"accept-encoding">> => <<"gzip, deflate, br">>,<<"accept-language">> => <<"en-US,en;q=0.9">>,<<"connection">> => <<"keep-alive">>,<<"host">> => <<"localhost:4000">>,<<"http_method">> => <<"POST">>,<<"...">> => ...,...},...}},...},...},...},...} in 'Elixir.Phoenix.Endpoint.Cowboy2Handler':init/4 line 59 in 'Elixir.Phoenix.Endpoint.Cowboy2Handler':init/4 line 59
2019-11-06 08:34:48.800 [error] <0.513.0> Cowboy stream 2 with ranch listener 'Elixir.RailwayUiWeb.Endpoint.HTTP' and connection process <0.509.0> had its request process exit with reason: {{#{'__exception__' => true,'__struct__' => 'Elixir.Phoenix.Router.NoRouteError',conn => #{'__struct__' => 'Elixir.Plug.Conn',adapter => {'Elixir.Plug.Cowboy.Conn',#{bindings => #{},body_length => 0,cert => undefined,has_body => false,headers => #{<<"accept">> => <<"text/css,*/*;q=0.1">>,<<"accept-encoding">> => <<"gzip, deflate, br">>,<<"accept-language">> => <<"en-US,en;q=0.9">>,<<"connection">> => <<"keep-alive">>,<<"host">> => <<"localhost:4000">>,<<"http_method">> => <<"POST">>,<<"...">> => ...,...},...}},...},...},...},...} in 'Elixir.Phoenix.Endpoint.Cowboy2Handler':init/4 line 59
2019-11-06 08:35:00.674 [error] <0.534.0> CRASH REPORT Process <0.534.0> with 0 neighbours exited with reason: {{#{'__exception__' => true,'__struct__' => 'Elixir.Phoenix.Router.NoRouteError',conn => #{'__struct__' => 'Elixir.Plug.Conn',adapter => {'Elixir.Plug.Cowboy.Conn',#{bindings => #{},body_length => 0,cert => undefined,has_body => false,headers => #{<<"accept">> => <<"text/css,*/*;q=0.1">>,<<"accept-encoding">> => <<"gzip, deflate, br">>,<<"accept-language">> => <<"en-US,en;q=0.9">>,<<"connection">> => <<"keep-alive">>,<<"host">> => <<"localhost:4000">>,<<"http_method">> => <<"POST">>,<<"...">> => ...,...},...}},...},...},...},...} in 'Elixir.Phoenix.Endpoint.Cowboy2Handler':init/4 line 59 in 'Elixir.Phoenix.Endpoint.Cowboy2Handler':init/4 line 59
2019-11-06 08:35:00.675 [error] <0.534.0> Cowboy stream 2 with ranch listener 'Elixir.RailwayUiWeb.Endpoint.HTTP' and connection process <0.522.0> had its request process exit with reason: {{#{'__exception__' => true,'__struct__' => 'Elixir.Phoenix.Router.NoRouteError',conn => #{'__struct__' => 'Elixir.Plug.Conn',adapter => {'Elixir.Plug.Cowboy.Conn',#{bindings => #{},body_length => 0,cert => undefined,has_body => false,headers => #{<<"accept">> => <<"text/css,*/*;q=0.1">>,<<"accept-encoding">> => <<"gzip, deflate, br">>,<<"accept-language">> => <<"en-US,en;q=0.9">>,<<"connection">> => <<"keep-alive">>,<<"host">> => <<"localhost:4000">>,<<"http_method">> => <<"POST">>,<<"...">> => ...,...},...}},...},...},...},...} in 'Elixir.Phoenix.Endpoint.Cowboy2Handler':init/4 line 59
2019-11-06 08:35:07.847 [error] <0.547.0> CRASH REPORT Process <0.547.0> with 0 neighbours exited with reason: {{#{'__exception__' => true,'__struct__' => 'Elixir.Phoenix.Router.NoRouteError',conn => #{'__struct__' => 'Elixir.Plug.Conn',adapter => {'Elixir.Plug.Cowboy.Conn',#{bindings => #{},body_length => 0,cert => undefined,has_body => false,headers => #{<<"accept">> => <<"text/css,*/*;q=0.1">>,<<"accept-encoding">> => <<"gzip, deflate, br">>,<<"accept-language">> => <<"en-US,en;q=0.9">>,<<"connection">> => <<"keep-alive">>,<<"host">> => <<"localhost:4000">>,<<"http_method">> => <<"POST">>,<<"...">> => ...,...},...}},...},...},...},...} in 'Elixir.Phoenix.Endpoint.Cowboy2Handler':init/4 line 59 in 'Elixir.Phoenix.Endpoint.Cowboy2Handler':init/4 line 59
2019-11-06 08:35:07.847 [error] <0.547.0> Cowboy stream 2 with ranch listener 'Elixir.RailwayUiWeb.Endpoint.HTTP' and connection process <0.543.0> had its request process exit with reason: {{#{'__exception__' => true,'__struct__' => 'Elixir.Phoenix.Router.NoRouteError',conn => #{'__struct__' => 'Elixir.Plug.Conn',adapter => {'Elixir.Plug.Cowboy.Conn',#{bindings => #{},body_length => 0,cert => undefined,has_body => false,headers => #{<<"accept">> => <<"text/css,*/*;q=0.1">>,<<"accept-encoding">> => <<"gzip, deflate, br">>,<<"accept-language">> => <<"en-US,en;q=0.9">>,<<"connection">> => <<"keep-alive">>,<<"host">> => <<"localhost:4000">>,<<"http_method">> => <<"POST">>,<<"...">> => ...,...},...}},...},...},...},...} in 'Elixir.Phoenix.Endpoint.Cowboy2Handler':init/4 line 59
2019-11-06 08:35:47.236 [error] <0.577.0> CRASH REPORT Process <0.577.0> with 0 neighbours exited with reason: {{#{'__exception__' => true,'__struct__' => 'Elixir.UndefinedFunctionError',arity => 1,function => init,message => nil,module => 'Elixir.RailwayUiWeb.ConsumedMessageController',reason => nil},[{'Elixir.RailwayUiWeb.ConsumedMessageController',init,[index],[]},{'Elixir.Phoenix.Router','__call__',2,[{file,"lib/phoenix/router.ex"},{line,288}]},{'Elixir.RailwayUiWeb.Endpoint',plug_builder_call,2,[{file,"lib/railway_ui_web/endpoint.ex"},{line,1}]},{'Elixir.RailwayUiWeb.Endpoint','call (overridable 3)',...},...]},...} in 'Elixir.Phoenix.Endpoint.Cowboy2Handler':init/4 line 59 in 'Elixir.Phoenix.Endpoint.Cowboy2Handler':init/4 line 59
2019-11-06 08:35:47.237 [error] <0.577.0> Cowboy stream 1 with ranch listener 'Elixir.RailwayUiWeb.Endpoint.HTTP' and connection process <0.575.0> had its request process exit with reason: {{#{'__exception__' => true,'__struct__' => 'Elixir.UndefinedFunctionError',arity => 1,function => init,message => nil,module => 'Elixir.RailwayUiWeb.ConsumedMessageController',reason => nil},[{'Elixir.RailwayUiWeb.ConsumedMessageController',init,[index],[]},{'Elixir.Phoenix.Router','__call__',2,[{file,"lib/phoenix/router.ex"},{line,288}]},{'Elixir.RailwayUiWeb.Endpoint',plug_builder_call,2,[{file,"lib/railway_ui_web/endpoint.ex"},{line,1}]},{'Elixir.RailwayUiWeb.Endpoint','call (overridable 3)',...},...]},...} in 'Elixir.Phoenix.Endpoint.Cowboy2Handler':init/4 line 59
2019-11-06 08:36:11.768 [error] <0.590.0> CRASH REPORT Process <0.590.0> with 0 neighbours exited with reason: {{#{'__exception__' => true,'__struct__' => 'Elixir.UndefinedFunctionError',arity => 1,function => all,message => nil,module => 'Elixir.Repo',reason => nil},[{'Elixir.Repo',all,['Elixir.RailwayIpc.Persistence.ConsumedMessage'],[]},{'Elixir.RailwayUiWeb.ConsumedMessageController',index,2,[{file,"lib/railway_ui_web/controllers/consumed_message_controller.ex"},{line,5}]},{'Elixir.RailwayUiWeb.ConsumedMessageController',action,2,[{file,"lib/railway_ui_web/controllers/consumed_message_controlle..."},...]},...]},...} in 'Elixir.Phoenix.Endpoint.Cowboy2Handler':init/4 line 59 in 'Elixir.Phoenix.Endpoint.Cowboy2Handler':init/4 line 59
2019-11-06 08:36:11.768 [error] <0.590.0> Cowboy stream 1 with ranch listener 'Elixir.RailwayUiWeb.Endpoint.HTTP' and connection process <0.589.0> had its request process exit with reason: {{#{'__exception__' => true,'__struct__' => 'Elixir.UndefinedFunctionError',arity => 1,function => all,message => nil,module => 'Elixir.Repo',reason => nil},[{'Elixir.Repo',all,['Elixir.RailwayIpc.Persistence.ConsumedMessage'],[]},{'Elixir.RailwayUiWeb.ConsumedMessageController',index,2,[{file,"lib/railway_ui_web/controllers/consumed_message_controller.ex"},{line,5}]},{'Elixir.RailwayUiWeb.ConsumedMessageController',action,2,[{file,"lib/railway_ui_web/controllers/consumed_message_controlle..."},...]},...]},...} in 'Elixir.Phoenix.Endpoint.Cowboy2Handler':init/4 line 59
2019-11-06 08:36:34.611 [error] <0.617.0> CRASH REPORT Process <0.617.0> with 0 neighbours exited with reason: {{#{'__exception__' => true,'__struct__' => 'Elixir.UndefinedFunctionError',arity => 1,function => all,message => nil,module => 'Elixir.Repo',reason => nil},[{'Elixir.Repo',all,['Elixir.RailwayIpc.Persistence.ConsumedMessage'],[]},{'Elixir.RailwayUiWeb.ConsumedMessageController',index,2,[{file,"lib/railway_ui_web/controllers/consumed_message_controller.ex"},{line,5}]},{'Elixir.RailwayUiWeb.ConsumedMessageController',action,2,[{file,"lib/railway_ui_web/controllers/consumed_message_controlle..."},...]},...]},...} in 'Elixir.Phoenix.Endpoint.Cowboy2Handler':init/4 line 59 in 'Elixir.Phoenix.Endpoint.Cowboy2Handler':init/4 line 59
2019-11-06 08:36:34.612 [error] <0.617.0> Cowboy stream 1 with ranch listener 'Elixir.RailwayUiWeb.Endpoint.HTTP' and connection process <0.616.0> had its request process exit with reason: {{#{'__exception__' => true,'__struct__' => 'Elixir.UndefinedFunctionError',arity => 1,function => all,message => nil,module => 'Elixir.Repo',reason => nil},[{'Elixir.Repo',all,['Elixir.RailwayIpc.Persistence.ConsumedMessage'],[]},{'Elixir.RailwayUiWeb.ConsumedMessageController',index,2,[{file,"lib/railway_ui_web/controllers/consumed_message_controller.ex"},{line,5}]},{'Elixir.RailwayUiWeb.ConsumedMessageController',action,2,[{file,"lib/railway_ui_web/controllers/consumed_message_controlle..."},...]},...]},...} in 'Elixir.Phoenix.Endpoint.Cowboy2Handler':init/4 line 59
2019-11-06 08:36:38.424 [error] <0.638.0> CRASH REPORT Process <0.638.0> with 0 neighbours exited with reason: {{#{'__exception__' => true,'__struct__' => 'Elixir.UndefinedFunctionError',arity => 1,function => all,message => nil,module => 'Elixir.Repo',reason => nil},[{'Elixir.Repo',all,['Elixir.RailwayIpc.Persistence.ConsumedMessage'],[]},{'Elixir.RailwayUiWeb.ConsumedMessageController',index,2,[{file,"lib/railway_ui_web/controllers/consumed_message_controller.ex"},{line,5}]},{'Elixir.RailwayUiWeb.ConsumedMessageController',action,2,[{file,"lib/railway_ui_web/controllers/consumed_message_controlle..."},...]},...]},...} in 'Elixir.Phoenix.Endpoint.Cowboy2Handler':init/4 line 59 in 'Elixir.Phoenix.Endpoint.Cowboy2Handler':init/4 line 59
2019-11-06 08:36:38.425 [error] <0.638.0> Cowboy stream 4 with ranch listener 'Elixir.RailwayUiWeb.Endpoint.HTTP' and connection process <0.616.0> had its request process exit with reason: {{#{'__exception__' => true,'__struct__' => 'Elixir.UndefinedFunctionError',arity => 1,function => all,message => nil,module => 'Elixir.Repo',reason => nil},[{'Elixir.Repo',all,['Elixir.RailwayIpc.Persistence.ConsumedMessage'],[]},{'Elixir.RailwayUiWeb.ConsumedMessageController',index,2,[{file,"lib/railway_ui_web/controllers/consumed_message_controller.ex"},{line,5}]},{'Elixir.RailwayUiWeb.ConsumedMessageController',action,2,[{file,"lib/railway_ui_web/controllers/consumed_message_controlle..."},...]},...]},...} in 'Elixir.Phoenix.Endpoint.Cowboy2Handler':init/4 line 59
2019-11-06 08:36:47.193 [error] <0.648.0> CRASH REPORT Process <0.648.0> with 0 neighbours exited with reason: {{#{'__exception__' => true,'__struct__' => 'Elixir.UndefinedFunctionError',arity => 1,function => all,message => nil,module => 'Elixir.Repo',reason => nil},[{'Elixir.Repo',all,['Elixir.RailwayIpc.Persistence.ConsumedMessage'],[]},{'Elixir.RailwayUiWeb.ConsumedMessageController',index,2,[{file,"lib/railway_ui_web/controllers/consumed_message_controller.ex"},{line,5}]},{'Elixir.RailwayUiWeb.ConsumedMessageController',action,2,[{file,"lib/railway_ui_web/controllers/consumed_message_controlle..."},...]},...]},...} in 'Elixir.Phoenix.Endpoint.Cowboy2Handler':init/4 line 59 in 'Elixir.Phoenix.Endpoint.Cowboy2Handler':init/4 line 59
2019-11-06 08:36:47.193 [error] <0.648.0> Cowboy stream 1 with ranch listener 'Elixir.RailwayUiWeb.Endpoint.HTTP' and connection process <0.646.0> had its request process exit with reason: {{#{'__exception__' => true,'__struct__' => 'Elixir.UndefinedFunctionError',arity => 1,function => all,message => nil,module => 'Elixir.Repo',reason => nil},[{'Elixir.Repo',all,['Elixir.RailwayIpc.Persistence.ConsumedMessage'],[]},{'Elixir.RailwayUiWeb.ConsumedMessageController',index,2,[{file,"lib/railway_ui_web/controllers/consumed_message_controller.ex"},{line,5}]},{'Elixir.RailwayUiWeb.ConsumedMessageController',action,2,[{file,"lib/railway_ui_web/controllers/consumed_message_controlle..."},...]},...]},...} in 'Elixir.Phoenix.Endpoint.Cowboy2Handler':init/4 line 59
2019-11-06 08:36:53.603 [error] <0.667.0> CRASH REPORT Process <0.667.0> with 0 neighbours exited with reason: {{#{'__exception__' => true,'__struct__' => 'Elixir.UndefinedFunctionError',arity => 1,function => all,message => nil,module => 'Elixir.Repo',reason => nil},[{'Elixir.Repo',all,['Elixir.RailwayIpc.Persistence.ConsumedMessage'],[]},{'Elixir.RailwayUiWeb.ConsumedMessageController',index,2,[{file,"lib/railway_ui_web/controllers/consumed_message_controller.ex"},{line,5}]},{'Elixir.RailwayUiWeb.ConsumedMessageController',action,2,[{file,"lib/railway_ui_web/controllers/consumed_message_controlle..."},...]},...]},...} in 'Elixir.Phoenix.Endpoint.Cowboy2Handler':init/4 line 59 in 'Elixir.Phoenix.Endpoint.Cowboy2Handler':init/4 line 59
2019-11-06 08:36:53.604 [error] <0.667.0> Cowboy stream 3 with ranch listener 'Elixir.RailwayUiWeb.Endpoint.HTTP' and connection process <0.660.0> had its request process exit with reason: {{#{'__exception__' => true,'__struct__' => 'Elixir.UndefinedFunctionError',arity => 1,function => all,message => nil,module => 'Elixir.Repo',reason => nil},[{'Elixir.Repo',all,['Elixir.RailwayIpc.Persistence.ConsumedMessage'],[]},{'Elixir.RailwayUiWeb.ConsumedMessageController',index,2,[{file,"lib/railway_ui_web/controllers/consumed_message_controller.ex"},{line,5}]},{'Elixir.RailwayUiWeb.ConsumedMessageController',action,2,[{file,"lib/railway_ui_web/controllers/consumed_message_controlle..."},...]},...]},...} in 'Elixir.Phoenix.Endpoint.Cowboy2Handler':init/4 line 59
2019-11-06 08:37:24.558 [error] <0.525.0> CRASH REPORT Process <0.525.0> with 0 neighbours exited with reason: {{#{'__exception__' => true,'__struct__' => 'Elixir.UndefinedFunctionError',arity => 1,function => all,message => nil,module => 'Elixir.Repo',reason => nil},[{'Elixir.Repo',all,['Elixir.RailwayIpc.Persistence.ConsumedMessage'],[]},{'Elixir.RailwayUiWeb.ConsumedMessageController',index,2,[{file,"lib/railway_ui_web/controllers/consumed_message_controller.ex"},{line,5}]},{'Elixir.RailwayUiWeb.ConsumedMessageController',action,2,[{file,"lib/railway_ui_web/controllers/consumed_message_controlle..."},...]},...]},...} in 'Elixir.Phoenix.Endpoint.Cowboy2Handler':init/4 line 59 in 'Elixir.Phoenix.Endpoint.Cowboy2Handler':init/4 line 59
2019-11-06 08:37:24.580 [error] <0.525.0> Cowboy stream 1 with ranch listener 'Elixir.RailwayUiWeb.Endpoint.HTTP' and connection process <0.523.0> had its request process exit with reason: {{#{'__exception__' => true,'__struct__' => 'Elixir.UndefinedFunctionError',arity => 1,function => all,message => nil,module => 'Elixir.Repo',reason => nil},[{'Elixir.Repo',all,['Elixir.RailwayIpc.Persistence.ConsumedMessage'],[]},{'Elixir.RailwayUiWeb.ConsumedMessageController',index,2,[{file,"lib/railway_ui_web/controllers/consumed_message_controller.ex"},{line,5}]},{'Elixir.RailwayUiWeb.ConsumedMessageController',action,2,[{file,"lib/railway_ui_web/controllers/consumed_message_controlle..."},...]},...]},...} in 'Elixir.Phoenix.Endpoint.Cowboy2Handler':init/4 line 59
2019-11-06 08:37:32.335 [error] <0.533.0> CRASH REPORT Process <0.533.0> with 0 neighbours exited with reason: {{#{'__exception__' => true,'__struct__' => 'Elixir.UndefinedFunctionError',arity => 1,function => all,message => nil,module => 'Elixir.Repo',reason => nil},[{'Elixir.Repo',all,['Elixir.RailwayIpc.Persistence.ConsumedMessage'],[]},{'Elixir.RailwayUiWeb.ConsumedMessageController',index,2,[{file,"lib/railway_ui_web/controllers/consumed_message_controller.ex"},{line,5}]},{'Elixir.RailwayUiWeb.ConsumedMessageController',action,2,[{file,"lib/railway_ui_web/controllers/consumed_message_controlle..."},...]},...]},...} in 'Elixir.Phoenix.Endpoint.Cowboy2Handler':init/4 line 59 in 'Elixir.Phoenix.Endpoint.Cowboy2Handler':init/4 line 59
2019-11-06 08:37:32.336 [error] <0.533.0> Cowboy stream 1 with ranch listener 'Elixir.RailwayUiWeb.Endpoint.HTTP' and connection process <0.532.0> had its request process exit with reason: {{#{'__exception__' => true,'__struct__' => 'Elixir.UndefinedFunctionError',arity => 1,function => all,message => nil,module => 'Elixir.Repo',reason => nil},[{'Elixir.Repo',all,['Elixir.RailwayIpc.Persistence.ConsumedMessage'],[]},{'Elixir.RailwayUiWeb.ConsumedMessageController',index,2,[{file,"lib/railway_ui_web/controllers/consumed_message_controller.ex"},{line,5}]},{'Elixir.RailwayUiWeb.ConsumedMessageController',action,2,[{file,"lib/railway_ui_web/controllers/consumed_message_controlle..."},...]},...]},...} in 'Elixir.Phoenix.Endpoint.Cowboy2Handler':init/4 line 59
2019-11-06 08:43:36.326 [error] <0.649.0> CRASH REPORT Process <0.649.0> with 0 neighbours exited with reason: {{#{'__exception__' => true,'__struct__' => 'Elixir.UndefinedFunctionError',arity => 0,function => all,message => nil,module => 'Elixir.RailwayUi.ConsumedMessage',reason => nil},[{'Elixir.RailwayUi.ConsumedMessage',all,[],[]},{'Elixir.RailwayUiWeb.ConsumedMessageController',index,2,[{file,"lib/railway_ui_web/controllers/consumed_message_controller.ex"},{line,7}]},{'Elixir.RailwayUiWeb.ConsumedMessageController',action,2,[{file,"lib/railway_ui_web/controllers/consumed_message_controller.ex"},...]},...]},...} in 'Elixir.Phoenix.Endpoint.Cowboy2Handler':init/4 line 59 in 'Elixir.Phoenix.Endpoint.Cowboy2Handler':init/4 line 59
2019-11-06 08:43:36.340 [error] <0.649.0> Cowboy stream 1 with ranch listener 'Elixir.RailwayUiWeb.Endpoint.HTTP' and connection process <0.648.0> had its request process exit with reason: {{#{'__exception__' => true,'__struct__' => 'Elixir.UndefinedFunctionError',arity => 0,function => all,message => nil,module => 'Elixir.RailwayUi.ConsumedMessage',reason => nil},[{'Elixir.RailwayUi.ConsumedMessage',all,[],[]},{'Elixir.RailwayUiWeb.ConsumedMessageController',index,2,[{file,"lib/railway_ui_web/controllers/consumed_message_controller.ex"},{line,7}]},{'Elixir.RailwayUiWeb.ConsumedMessageController',action,2,[{file,"lib/railway_ui_web/controllers/consumed_message_controller.ex"},...]},...]},...} in 'Elixir.Phoenix.Endpoint.Cowboy2Handler':init/4 line 59
2019-11-06 08:43:40.275 [error] <0.664.0> CRASH REPORT Process <0.664.0> with 0 neighbours exited with reason: {{#{'__exception__' => true,'__struct__' => 'Elixir.UndefinedFunctionError',arity => 0,function => all,message => nil,module => 'Elixir.RailwayUi.ConsumedMessage',reason => nil},[{'Elixir.RailwayUi.ConsumedMessage',all,[],[]},{'Elixir.RailwayUiWeb.ConsumedMessageController',index,2,[{file,"lib/railway_ui_web/controllers/consumed_message_controller.ex"},{line,7}]},{'Elixir.RailwayUiWeb.ConsumedMessageController',action,2,[{file,"lib/railway_ui_web/controllers/consumed_message_controller.ex"},...]},...]},...} in 'Elixir.Phoenix.Endpoint.Cowboy2Handler':init/4 line 59 in 'Elixir.Phoenix.Endpoint.Cowboy2Handler':init/4 line 59
2019-11-06 08:43:40.275 [error] <0.664.0> Cowboy stream 3 with ranch listener 'Elixir.RailwayUiWeb.Endpoint.HTTP' and connection process <0.648.0> had its request process exit with reason: {{#{'__exception__' => true,'__struct__' => 'Elixir.UndefinedFunctionError',arity => 0,function => all,message => nil,module => 'Elixir.RailwayUi.ConsumedMessage',reason => nil},[{'Elixir.RailwayUi.ConsumedMessage',all,[],[]},{'Elixir.RailwayUiWeb.ConsumedMessageController',index,2,[{file,"lib/railway_ui_web/controllers/consumed_message_controller.ex"},{line,7}]},{'Elixir.RailwayUiWeb.ConsumedMessageController',action,2,[{file,"lib/railway_ui_web/controllers/consumed_message_controller.ex"},...]},...]},...} in 'Elixir.Phoenix.Endpoint.Cowboy2Handler':init/4 line 59
2019-11-06 08:43:56.124 [error] <0.674.0> CRASH REPORT Process <0.674.0> with 0 neighbours exited with reason: {{#{'__exception__' => true,'__struct__' => 'Elixir.UndefinedFunctionError',arity => 0,function => get_consumed_messages,message => nil,module => nil,reason => nil},[{nil,get_consumed_messages,[],[]},{'Elixir.RailwayUiWeb.ConsumedMessageController',index,2,[{file,"lib/railway_ui_web/controllers/consumed_message_controller.ex"},{line,7}]},{'Elixir.RailwayUiWeb.ConsumedMessageController',action,2,[{file,"lib/railway_ui_web/controllers/consumed_message_controller.ex"},{line,1}]},{'Elixir.RailwayUiWeb.ConsumedMessageController',...},...]},...} in 'Elixir.Phoenix.Endpoint.Cowboy2Handler':init/4 line 59 in 'Elixir.Phoenix.Endpoint.Cowboy2Handler':init/4 line 59
2019-11-06 08:43:56.124 [error] <0.674.0> Cowboy stream 1 with ranch listener 'Elixir.RailwayUiWeb.Endpoint.HTTP' and connection process <0.673.0> had its request process exit with reason: {{#{'__exception__' => true,'__struct__' => 'Elixir.UndefinedFunctionError',arity => 0,function => get_consumed_messages,message => nil,module => nil,reason => nil},[{nil,get_consumed_messages,[],[]},{'Elixir.RailwayUiWeb.ConsumedMessageController',index,2,[{file,"lib/railway_ui_web/controllers/consumed_message_controller.ex"},{line,7}]},{'Elixir.RailwayUiWeb.ConsumedMessageController',action,2,[{file,"lib/railway_ui_web/controllers/consumed_message_controller.ex"},{line,1}]},{'Elixir.RailwayUiWeb.ConsumedMessageController',...},...]},...} in 'Elixir.Phoenix.Endpoint.Cowboy2Handler':init/4 line 59
2019-11-06 08:45:39.304 [error] <0.753.0> CRASH REPORT Process <0.753.0> with 0 neighbours exited with reason: {{#{'__exception__' => true,'__struct__' => 'Elixir.UndefinedFunctionError',arity => 2,function => published_messages_path,message => nil,module => 'Elixir.RailwayUiWeb.Router.Helpers',reason => nil},[{'Elixir.RailwayUiWeb.Router.Helpers',published_messages_path,[#{'__struct__' => 'Elixir.Plug.Conn',adapter => {'Elixir.Plug.Cowboy.Conn',#{bindings => #{},body_length => 0,cert => undefined,has_body => false,headers => #{<<"accept">> => <<"text/html,application/xhtml+xml,application/xml;q=...">>,...},...}},...},...],...},...]},...} in 'Elixir.Phoenix.Endpoint.Cowboy2Handler':init/4 line 59 in 'Elixir.Phoenix.Endpoint.Cowboy2Handler':init/4 line 59
2019-11-06 08:45:39.304 [error] <0.753.0> Cowboy stream 1 with ranch listener 'Elixir.RailwayUiWeb.Endpoint.HTTP' and connection process <0.751.0> had its request process exit with reason: {{#{'__exception__' => true,'__struct__' => 'Elixir.UndefinedFunctionError',arity => 2,function => published_messages_path,message => nil,module => 'Elixir.RailwayUiWeb.Router.Helpers',reason => nil},[{'Elixir.RailwayUiWeb.Router.Helpers',published_messages_path,[#{'__struct__' => 'Elixir.Plug.Conn',adapter => {'Elixir.Plug.Cowboy.Conn',#{bindings => #{},body_length => 0,cert => undefined,has_body => false,headers => #{<<"accept">> => <<"text/html,application/xhtml+xml,application/xml;q=...">>,...},...}},...},...],...},...]},...} in 'Elixir.Phoenix.Endpoint.Cowboy2Handler':init/4 line 59
2019-11-06 08:59:25.000 [error] <0.790.0> CRASH REPORT Process <0.790.0> with 0 neighbours exited with reason: {{#{'__exception__' => true,'__struct__' => 'Elixir.ArgumentError',message => <<"assign @messages not available in eex template.\n\nPlease make sure all proper assigns have been set. If this\nis a child template, ensure assigns are given explicitly by\nthe parent template as they are not automatically forwarded.\n\nAvailable assigns: [:conn, :view_module, :view_template]\n">>},[{'Elixir.Phoenix.HTML.Engine','fetch_assign!',2,[{file,"lib/phoenix_html/engine.ex"},{line,133}]},{'Elixir.RailwayUiWeb.PageView',...},...]},...} in 'Elixir.Phoenix.Endpoint.Cowboy2Handler':init/4 line 59 in 'Elixir.Phoenix.Endpoint.Cowboy2Handler':init/4 line 59
2019-11-06 08:59:25.010 [error] <0.790.0> Cowboy stream 1 with ranch listener 'Elixir.RailwayUiWeb.Endpoint.HTTP' and connection process <0.789.0> had its request process exit with reason: {{#{'__exception__' => true,'__struct__' => 'Elixir.ArgumentError',message => <<"assign @messages not available in eex template.\n\nPlease make sure all proper assigns have been set. If this\nis a child template, ensure assigns are given explicitly by\nthe parent template as they are not automatically forwarded.\n\nAvailable assigns: [:conn, :view_module, :view_template]\n">>},[{'Elixir.Phoenix.HTML.Engine','fetch_assign!',2,[{file,"lib/phoenix_html/engine.ex"},{line,133}]},{'Elixir.RailwayUiWeb.PageView',...},...]},...} in 'Elixir.Phoenix.Endpoint.Cowboy2Handler':init/4 line 59
2019-11-06 08:59:32.811 [error] <0.811.0> CRASH REPORT Process <0.811.0> with 0 neighbours exited with reason: {{#{'__exception__' => true,'__struct__' => 'Elixir.ArgumentError',message => <<"assign @messages not available in eex template.\n\nPlease make sure all proper assigns have been set. If this\nis a child template, ensure assigns are given explicitly by\nthe parent template as they are not automatically forwarded.\n\nAvailable assigns: [:conn, :view_module, :view_template]\n">>},[{'Elixir.Phoenix.HTML.Engine','fetch_assign!',2,[{file,"lib/phoenix_html/engine.ex"},{line,133}]},{'Elixir.RailwayUiWeb.PageView',...},...]},...} in 'Elixir.Phoenix.Endpoint.Cowboy2Handler':init/4 line 59 in 'Elixir.Phoenix.Endpoint.Cowboy2Handler':init/4 line 59
2019-11-06 08:59:32.812 [error] <0.811.0> Cowboy stream 1 with ranch listener 'Elixir.RailwayUiWeb.Endpoint.HTTP' and connection process <0.810.0> had its request process exit with reason: {{#{'__exception__' => true,'__struct__' => 'Elixir.ArgumentError',message => <<"assign @messages not available in eex template.\n\nPlease make sure all proper assigns have been set. If this\nis a child template, ensure assigns are given explicitly by\nthe parent template as they are not automatically forwarded.\n\nAvailable assigns: [:conn, :view_module, :view_template]\n">>},[{'Elixir.Phoenix.HTML.Engine','fetch_assign!',2,[{file,"lib/phoenix_html/engine.ex"},{line,133}]},{'Elixir.RailwayUiWeb.PageView',...},...]},...} in 'Elixir.Phoenix.Endpoint.Cowboy2Handler':init/4 line 59
2019-11-06 08:59:33.670 [error] <0.830.0> CRASH REPORT Process <0.830.0> with 0 neighbours exited with reason: {{#{'__exception__' => true,'__struct__' => 'Elixir.ArgumentError',message => <<"assign @messages not available in eex template.\n\nPlease make sure all proper assigns have been set. If this\nis a child template, ensure assigns are given explicitly by\nthe parent template as they are not automatically forwarded.\n\nAvailable assigns: [:conn, :view_module, :view_template]\n">>},[{'Elixir.Phoenix.HTML.Engine','fetch_assign!',2,[{file,"lib/phoenix_html/engine.ex"},{line,133}]},{'Elixir.RailwayUiWeb.PageView',...},...]},...} in 'Elixir.Phoenix.Endpoint.Cowboy2Handler':init/4 line 59 in 'Elixir.Phoenix.Endpoint.Cowboy2Handler':init/4 line 59
2019-11-06 08:59:33.672 [error] <0.830.0> Cowboy stream 3 with ranch listener 'Elixir.RailwayUiWeb.Endpoint.HTTP' and connection process <0.810.0> had its request process exit with reason: {{#{'__exception__' => true,'__struct__' => 'Elixir.ArgumentError',message => <<"assign @messages not available in eex template.\n\nPlease make sure all proper assigns have been set. If this\nis a child template, ensure assigns are given explicitly by\nthe parent template as they are not automatically forwarded.\n\nAvailable assigns: [:conn, :view_module, :view_template]\n">>},[{'Elixir.Phoenix.HTML.Engine','fetch_assign!',2,[{file,"lib/phoenix_html/engine.ex"},{line,133}]},{'Elixir.RailwayUiWeb.PageView',...},...]},...} in 'Elixir.Phoenix.Endpoint.Cowboy2Handler':init/4 line 59
2019-11-12 08:42:53.761 [error] <0.49.0> Loading of /Users/sophie.debenedetto/Dev/railway_hex/railway_ui/_build/test/lib/jason/ebin/Elixir.JASON.beam failed: badfile
2019-11-12 08:42:53.761 [error] emulator beam/beam_load.c(1433): Error loading module 'Elixir.JASON':
  BEAM file exists but it defines a module named Elixir.Jason

2019-11-29 10:01:59.544 [error] <0.2770.0> gen_server <0.2770.0> terminated with reason: #{'__exception__' => true,'__struct__' => 'Elixir.RuntimeError',message => <<"connect raised KeyError exception: key :database not found. The exception details are hidden, as they may contain sensitive data such as database credentials. You may set :show_sensitive_data_on_connection_error to true when starting your connection if you wish to see all of the details">>} in 'Elixir.Keyword':'fetch!'/2 line 393
2019-11-29 10:01:59.544 [error] <0.2772.0> gen_server <0.2772.0> terminated with reason: #{'__exception__' => true,'__struct__' => 'Elixir.RuntimeError',message => <<"connect raised KeyError exception: key :database not found. The exception details are hidden, as they may contain sensitive data such as database credentials. You may set :show_sensitive_data_on_connection_error to true when starting your connection if you wish to see all of the details">>} in 'Elixir.Keyword':'fetch!'/2 line 393
2019-11-29 10:01:59.545 [error] <0.2771.0> gen_server <0.2771.0> terminated with reason: #{'__exception__' => true,'__struct__' => 'Elixir.RuntimeError',message => <<"connect raised KeyError exception: key :database not found. The exception details are hidden, as they may contain sensitive data such as database credentials. You may set :show_sensitive_data_on_connection_error to true when starting your connection if you wish to see all of the details">>} in 'Elixir.Keyword':'fetch!'/2 line 393
2019-11-29 10:04:16.924 [error] <0.493.0> gen_server <0.493.0> terminated with reason: #{'__exception__' => true,'__struct__' => 'Elixir.RuntimeError',message => <<"connect raised KeyError exception: key :database not found. The exception details are hidden, as they may contain sensitive data such as database credentials. You may set :show_sensitive_data_on_connection_error to true when starting your connection if you wish to see all of the details">>} in 'Elixir.Keyword':'fetch!'/2 line 393
2019-11-29 10:04:16.924 [error] <0.496.0> gen_server <0.496.0> terminated with reason: #{'__exception__' => true,'__struct__' => 'Elixir.RuntimeError',message => <<"connect raised KeyError exception: key :database not found. The exception details are hidden, as they may contain sensitive data such as database credentials. You may set :show_sensitive_data_on_connection_error to true when starting your connection if you wish to see all of the details">>} in 'Elixir.Keyword':'fetch!'/2 line 393
2019-11-29 10:04:16.924 [error] <0.499.0> gen_server <0.499.0> terminated with reason: #{'__exception__' => true,'__struct__' => 'Elixir.RuntimeError',message => <<"connect raised KeyError exception: key :database not found. The exception details are hidden, as they may contain sensitive data such as database credentials. You may set :show_sensitive_data_on_connection_error to true when starting your connection if you wish to see all of the details">>} in 'Elixir.Keyword':'fetch!'/2 line 393
2019-11-29 10:04:16.924 [error] <0.495.0> gen_server <0.495.0> terminated with reason: #{'__exception__' => true,'__struct__' => 'Elixir.RuntimeError',message => <<"connect raised KeyError exception: key :database not found. The exception details are hidden, as they may contain sensitive data such as database credentials. You may set :show_sensitive_data_on_connection_error to true when starting your connection if you wish to see all of the details">>} in 'Elixir.Keyword':'fetch!'/2 line 393
2019-11-29 10:04:16.925 [error] <0.491.0> gen_server <0.491.0> terminated with reason: #{'__exception__' => true,'__struct__' => 'Elixir.RuntimeError',message => <<"connect raised KeyError exception: key :database not found. The exception details are hidden, as they may contain sensitive data such as database credentials. You may set :show_sensitive_data_on_connection_error to true when starting your connection if you wish to see all of the details">>} in 'Elixir.Keyword':'fetch!'/2 line 393
2019-11-29 10:04:16.925 [error] <0.492.0> gen_server <0.492.0> terminated with reason: #{'__exception__' => true,'__struct__' => 'Elixir.RuntimeError',message => <<"connect raised KeyError exception: key :database not found. The exception details are hidden, as they may contain sensitive data such as database credentials. You may set :show_sensitive_data_on_connection_error to true when starting your connection if you wish to see all of the details">>} in 'Elixir.Keyword':'fetch!'/2 line 393
2019-11-29 10:07:03.556 [error] <0.1994.0>@Elixir.RailwayIpc.Application:children:11 CRASH REPORT Process <0.1994.0> with 0 neighbours exited with reason: no function clause matching 'Elixir.RailwayIpc.Application':children(nil, dev) line 11 in application_master:init/4 line 138
2019-11-29 10:09:15.482 [error] <0.4388.0>@Elixir.RailwayIpc.Application:children:11 CRASH REPORT Process <0.4388.0> with 0 neighbours exited with reason: no function clause matching 'Elixir.RailwayIpc.Application':children(nil, dev) line 11 in application_master:init/4 line 138
2019-11-29 14:21:13.729 [error] <0.899.0> CRASH REPORT Process <0.899.0> with 0 neighbours exited with reason: {{#{'__exception__' => true,'__struct__' => 'Elixir.UndefinedFunctionError',arity => 0,function => '__live__',message => nil,module => 'Elixir.RailwayUiWeb.PublishedMessagesLive.Index',reason => nil},[{'Elixir.RailwayUiWeb.PublishedMessagesLive.Index','__live__',[],[]},{'Elixir.Phoenix.LiveView.Static','load_live!',2,[{file,"lib/phoenix_live_view/static.ex"},{line,219}]},{'Elixir.Phoenix.LiveView.Static',render,3,[{file,"lib/phoenix_live_view/static.ex"},{line,72}]},{'Elixir.Phoenix.LiveView.Controller',...},...]},...} in 'Elixir.Phoenix.Endpoint.Cowboy2Handler':init/4 line 59 in 'Elixir.Phoenix.Endpoint.Cowboy2Handler':init/4 line 59
2019-11-29 14:21:13.822 [error] <0.621.0> Lager event handler error_logger_lager_h exited with reason {'EXIT',{{case_clause,['Elixir.RailwayUiWeb.Endpoint.HTTP',<0.898.0>,1,<0.899.0>,{{#{'__exception__' => true,'__struct__' => 'Elixir.UndefinedFunctionError',arity => 0,function => '__live__',message => nil,module => 'Elixir.RailwayUiWeb.PublishedMessagesLive.Index',reason => nil},[{'Elixir.RailwayUiWeb.PublishedMessagesLive.Index','__live__',[],[]},{'Elixir.Phoenix.LiveView.Static','load_live!',2,[{file,"lib/phoenix_live_view/static.ex"},{line,219}]},{'Elixir.Phoenix.LiveView.Static',render,...},...]},...},...]},...}}
2019-11-29 14:21:31.234 [error] <0.936.0> CRASH REPORT Process <0.936.0> with 0 neighbours exited with reason: {{#{'__exception__' => true,'__struct__' => 'Elixir.UndefinedFunctionError',arity => 2,function => published_message_path,message => nil,module => 'Elixir.RailwayUiWeb.Router.Helpers',reason => nil},[{'Elixir.RailwayUiWeb.Router.Helpers',published_message_path,[#{'__struct__' => 'Elixir.Plug.Conn',adapter => {'Elixir.Plug.Cowboy.Conn',#{bindings => #{},body_length => 0,cert => undefined,has_body => false,headers => #{<<"accept">> => <<"text/html,application/xhtml+xml,application/xml;q=0....">>,...},...}},...},...],...},...]},...} in 'Elixir.Phoenix.Endpoint.Cowboy2Handler':init/4 line 59 in 'Elixir.Phoenix.Endpoint.Cowboy2Handler':init/4 line 59
2019-11-29 14:21:31.248 [error] <0.621.0> Lager event handler error_logger_lager_h exited with reason {'EXIT',{{case_clause,['Elixir.RailwayUiWeb.Endpoint.HTTP',<0.934.0>,1,<0.936.0>,{{#{'__exception__' => true,'__struct__' => 'Elixir.UndefinedFunctionError',arity => 2,function => published_message_path,message => nil,module => 'Elixir.RailwayUiWeb.Router.Helpers',reason => nil},[{'Elixir.RailwayUiWeb.Router.Helpers',published_message_path,[#{'__struct__' => 'Elixir.Plug.Conn',adapter => {'Elixir.Plug.Cowboy.Conn',#{bindings => #{},body_length => 0,cert => undefined,has_body => false,headers => ...,...}},...},...],...},...]},...},...]},...}}
2019-11-29 14:21:52.364 [error] <0.959.0> CRASH REPORT Process <0.959.0> with 0 neighbours exited with reason: {{#{'__exception__' => true,'__struct__' => 'Elixir.UndefinedFunctionError',arity => 2,function => live_published_message_path,message => nil,module => 'Elixir.RailwayUiWeb.Router.Helpers',reason => nil},[{'Elixir.RailwayUiWeb.Router.Helpers',live_published_message_path,[#{'__struct__' => 'Elixir.Plug.Conn',adapter => {'Elixir.Plug.Cowboy.Conn',#{bindings => #{},body_length => 0,cert => undefined,has_body => false,headers => #{<<"accept">> => <<"text/html,application/xhtml+xml,applicatio...">>,...},...}},...},...],...},...]},...} in 'Elixir.Phoenix.Endpoint.Cowboy2Handler':init/4 line 59 in 'Elixir.Phoenix.Endpoint.Cowboy2Handler':init/4 line 59
2019-11-29 14:21:52.443 [error] <0.621.0> Lager event handler error_logger_lager_h exited with reason {'EXIT',{{case_clause,['Elixir.RailwayUiWeb.Endpoint.HTTP',<0.958.0>,1,<0.959.0>,{{#{'__exception__' => true,'__struct__' => 'Elixir.UndefinedFunctionError',arity => 2,function => live_published_message_path,message => nil,module => 'Elixir.RailwayUiWeb.Router.Helpers',reason => nil},[{'Elixir.RailwayUiWeb.Router.Helpers',live_published_message_path,[#{'__struct__' => 'Elixir.Plug.Conn',adapter => {'Elixir.Plug.Cowboy.Conn',#{bindings => #{},body_length => 0,cert => undefined,has_body => false,...}},...},...],...},...]},...},...]},...}}
2019-11-29 14:22:23.738 [error] <0.982.0> CRASH REPORT Process <0.982.0> with 0 neighbours exited with reason: {{#{'__exception__' => true,'__struct__' => 'Elixir.ArgumentError',message => <<"no function clause for RailwayUiWeb.Router.Helpers.live_path/2 and action :index. The following actions/clauses are supported:\n\n    live_path(conn_or_endpoint, RailwayUiWeb.PublishedMessagesLive.Index, params \\\\ [])">>},[{'Elixir.Phoenix.Router.Helpers',raise_route_error,6,[{file,"lib/phoenix/router/helpers.ex"},{line,346}]},{'Elixir.RailwayUiWeb.LayoutView','app.html',1,[{file,"lib/railway_ui_web/templates/..."},...]},...]},...} in 'Elixir.Phoenix.Endpoint.Cowboy2Handler':init/4 line 59 in 'Elixir.Phoenix.Endpoint.Cowboy2Handler':init/4 line 59
2019-11-29 14:22:23.745 [error] <0.621.0> Lager event handler error_logger_lager_h exited with reason {'EXIT',{{case_clause,['Elixir.RailwayUiWeb.Endpoint.HTTP',<0.980.0>,1,<0.982.0>,{{#{'__exception__' => true,'__struct__' => 'Elixir.ArgumentError',message => <<"no function clause for RailwayUiWeb.Router.Helpers.live_path/2 and action :index. The following actions/clauses are supported:\n\n    live_path(conn_or_endpoint, RailwayUiWeb.PublishedMessagesLive.Index, params \\\\ [])">>},[{'Elixir.Phoenix.Router.Helpers',raise_route_error,6,[{file,"lib/phoenix/router/helpers.ex"},{line,346}]},{'Elixir.RailwayUiWeb.LayoutView',...},...]},...},...]},...}}
2019-11-29 14:28:57.589 [error] <0.1296.0>@Elixir.Phoenix.LiveView.Channel:handle_info:89 gen_server <0.1296.0> terminated with reason: call to undefined function 'Elixir.RailwayUiWeb.PublishedMessagesLive.Index':handle_event/3 from 'Elixir.Phoenix.LiveView.Channel':handle_info/2 line 89
2019-11-29 14:28:57.594 [error] <0.1296.0>@Elixir.RailwayUiWeb.PublishedMessagesLive.Index:handle_event CRASH REPORT Process <0.1296.0> with 0 neighbours crashed with reason: call to undefined function 'Elixir.RailwayUiWeb.PublishedMessagesLive.Index':handle_event(<<"republish">>, #{<<"altKey">> => false,<<"ctrlKey">> => false,<<"message_uuid">> => <<"#{message.uuid}">>,<<"...">> => ...,...}, #{'__struct__' => 'Elixir.Phoenix.LiveView.Socket',assigns => #{messages => []},changed => #{},'connected?' => ...,...})
2019-11-29 14:28:57.595 [error] <0.745.0>@Elixir.RailwayUiWeb.PublishedMessagesLive.Index:handle_event Supervisor {<0.745.0>,'Elixir.Phoenix.Socket.PoolSupervisor.WorkerSupervisor'} had child 'Elixir.Phoenix.Channel.Server' started with {'Elixir.Phoenix.Channel.Server',start_link,undefined} at <0.1296.0> exit with reason call to undefined function 'Elixir.RailwayUiWeb.PublishedMessagesLive.Index':handle_event(<<"republish">>, #{<<"altKey">> => false,<<"ctrlKey">> => false,<<"message_uuid">> => <<"#{message.uuid}">>,<<"...">> => ...,...}, #{'__struct__' => 'Elixir.Phoenix.LiveView.Socket',assigns => #{messages => []},changed => #{},'connected?' => ...,...}) in context child_terminated
2019-11-29 14:30:08.437 [error] <0.1364.0>@Elixir.Phoenix.LiveView.Channel:handle_info:89 gen_server <0.1364.0> terminated with reason: call to undefined function 'Elixir.RailwayUiWeb.PublishedMessagesLive.Index':handle_event/3 from 'Elixir.Phoenix.LiveView.Channel':handle_info/2 line 89
2019-11-29 14:30:08.439 [error] <0.1364.0>@Elixir.RailwayUiWeb.PublishedMessagesLive.Index:handle_event CRASH REPORT Process <0.1364.0> with 0 neighbours crashed with reason: call to undefined function 'Elixir.RailwayUiWeb.PublishedMessagesLive.Index':handle_event(<<"republish">>, #{<<"altKey">> => false,<<"ctrlKey">> => false,<<"message_uuid">> => <<"45ff7216-4cb6-4590-9bcf-a...">>,...}, #{'__struct__' => 'Elixir.Phoenix.LiveView.Socket',assigns => #{messages => []},changed => #{},'connected?' => ...,...})
2019-11-29 14:30:08.439 [error] <0.745.0>@Elixir.RailwayUiWeb.PublishedMessagesLive.Index:handle_event Supervisor {<0.745.0>,'Elixir.Phoenix.Socket.PoolSupervisor.WorkerSupervisor'} had child 'Elixir.Phoenix.Channel.Server' started with {'Elixir.Phoenix.Channel.Server',start_link,undefined} at <0.1364.0> exit with reason call to undefined function 'Elixir.RailwayUiWeb.PublishedMessagesLive.Index':handle_event(<<"republish">>, #{<<"altKey">> => false,<<"ctrlKey">> => false,<<"message_uuid">> => <<"45ff7216-4cb6-4590-9bcf-a...">>,...}, #{'__struct__' => 'Elixir.Phoenix.LiveView.Socket',assigns => #{messages => []},changed => #{},'connected?' => ...,...}) in context child_terminated
2019-11-29 14:30:25.740 [error] <0.1369.0>@Elixir.Phoenix.LiveView.Channel:handle_info:89 gen_server <0.1369.0> terminated with reason: call to undefined function 'Elixir.RailwayUiWeb.PublishedMessagesLive.Index':handle_event/3 from 'Elixir.Phoenix.LiveView.Channel':handle_info/2 line 89
2019-11-29 14:30:25.741 [error] <0.1369.0>@Elixir.RailwayUiWeb.PublishedMessagesLive.Index:handle_event CRASH REPORT Process <0.1369.0> with 0 neighbours crashed with reason: call to undefined function 'Elixir.RailwayUiWeb.PublishedMessagesLive.Index':handle_event(<<"republish">>, #{<<"altKey">> => false,<<"ctrlKey">> => false,<<"message_uuid">> => <<"45ff7216-4cb6-4590-9bcf-a...">>,...}, #{'__struct__' => 'Elixir.Phoenix.LiveView.Socket',assigns => #{messages => []},changed => #{},'connected?' => ...,...})
2019-11-29 14:30:25.742 [error] <0.746.0>@Elixir.RailwayUiWeb.PublishedMessagesLive.Index:handle_event Supervisor {<0.746.0>,'Elixir.Phoenix.Socket.PoolSupervisor.WorkerSupervisor'} had child 'Elixir.Phoenix.Channel.Server' started with {'Elixir.Phoenix.Channel.Server',start_link,undefined} at <0.1369.0> exit with reason call to undefined function 'Elixir.RailwayUiWeb.PublishedMessagesLive.Index':handle_event(<<"republish">>, #{<<"altKey">> => false,<<"ctrlKey">> => false,<<"message_uuid">> => <<"45ff7216-4cb6-4590-9bcf-a...">>,...}, #{'__struct__' => 'Elixir.Phoenix.LiveView.Socket',assigns => #{messages => []},changed => #{},'connected?' => ...,...}) in context child_terminated
2019-11-29 14:48:41.001 [error] <0.1537.0>@Elixir.RailwayUiWeb.PublishedMessagesLive.Index:request_data:23 gen_server <0.1537.0> terminated with reason: no function clause matching 'Elixir.RailwayUiWeb.PublishedMessagesLive.Index':request_data(#{'__struct__' => 'Elixir.Phoenix.LiveView.Socket',assigns => #{current_user => #{learn_uuid => <<...>>},...},...}) line 23
2019-11-29 14:48:41.029 [error] <0.1537.0>@Elixir.RailwayUiWeb.PublishedMessagesLive.Index:request_data:23 CRASH REPORT Process <0.1537.0> with 0 neighbours crashed with reason: no function clause matching 'Elixir.RailwayUiWeb.PublishedMessagesLive.Index':request_data(#{'__struct__' => 'Elixir.Phoenix.LiveView.Socket',assigns => #{current_user => #{learn_uuid => <<...>>},...},...}) line 23
2019-11-29 14:48:41.029 [error] <0.744.0>@Elixir.RailwayUiWeb.PublishedMessagesLive.Index:request_data:23 Supervisor {<0.744.0>,'Elixir.Phoenix.Socket.PoolSupervisor.WorkerSupervisor'} had child 'Elixir.Phoenix.Channel.Server' started with {'Elixir.Phoenix.Channel.Server',start_link,undefined} at <0.1537.0> exit with reason no function clause matching 'Elixir.RailwayUiWeb.PublishedMessagesLive.Index':request_data(#{'__struct__' => 'Elixir.Phoenix.LiveView.Socket',assigns => #{current_user => #{learn_uuid => <<...>>},...},...}) line 23 in context child_terminated
2019-11-29 14:52:54.358 [error] <0.1584.0> CRASH REPORT Process <0.1584.0> with 0 neighbours exited with reason: {{#{'__exception__' => true,'__struct__' => 'Elixir.ArgumentError',message => <<"assign @conn not available in eex template.\n\nPlease make sure all proper assigns have been set. If this\nis a child template, ensure assigns are given explicitly by\nthe parent template as they are not automatically forwarded.\n\nAvailable assigns: [:current_user_uuid, :messages, :socket, :view_module, :view_template]\n">>},[{'Elixir.Phoenix.LiveView.Engine','fetch_assign!',2,[{file,"lib/phoenix_live_view/engine.e..."},...]},...]},...} in 'Elixir.Phoenix.Endpoint.Cowboy2Handler':init/4 line 59 in 'Elixir.Phoenix.Endpoint.Cowboy2Handler':init/4 line 59
2019-11-29 14:52:54.365 [error] <0.621.0> Lager event handler error_logger_lager_h exited with reason {'EXIT',{{case_clause,['Elixir.RailwayUiWeb.Endpoint.HTTP',<0.1582.0>,1,<0.1584.0>,{{#{'__exception__' => true,'__struct__' => 'Elixir.ArgumentError',message => <<"assign @conn not available in eex template.\n\nPlease make sure all proper assigns have been set. If this\nis a child template, ensure assigns are given explicitly by\nthe parent template as they are not automatically forwarded.\n\nAvailable assigns: [:current_user_uuid, :messages, :socket, :view_module, :view_template]\n">>},[{'Elixir.Phoenix.LiveView.Engine',...},...]},...},...]},...}}
2019-11-29 14:57:32.337 [error] <0.1623.0> CRASH REPORT Process <0.1623.0> with 0 neighbours exited with reason: {{#{'__exception__' => true,'__struct__' => 'Elixir.ArgumentError',message => <<"assign @conn not available in eex template.\n\nPlease make sure all proper assigns have been set. If this\nis a child template, ensure assigns are given explicitly by\nthe parent template as they are not automatically forwarded.\n\nAvailable assigns: [:current_user_uuid, :flash, :messages, :socket, :view_module, :view_template]\n">>},[{'Elixir.Phoenix.LiveView.Engine','fetch_assign!',2,[{file,"lib/phoenix_live_view/..."},...]},...]},...} in 'Elixir.Phoenix.Endpoint.Cowboy2Handler':init/4 line 59 in 'Elixir.Phoenix.Endpoint.Cowboy2Handler':init/4 line 59
2019-11-29 14:57:32.344 [error] <0.621.0> Lager event handler error_logger_lager_h exited with reason {'EXIT',{{case_clause,['Elixir.RailwayUiWeb.Endpoint.HTTP',<0.1621.0>,1,<0.1623.0>,{{#{'__exception__' => true,'__struct__' => 'Elixir.ArgumentError',message => <<"assign @conn not available in eex template.\n\nPlease make sure all proper assigns have been set. If this\nis a child template, ensure assigns are given explicitly by\nthe parent template as they are not automatically forwarded.\n\nAvailable assigns: [:current_user_uuid, :flash, :messages, :socket, :view_module, :view_template]\n">>},[...]},...},...]},...}}
2019-11-29 15:06:09.585 [error] <0.4731.0> gen_server <0.4731.0> terminated with reason: #{'__exception__' => true,'__struct__' => 'Elixir.Protocol.UndefinedError',description => <<>>,protocol => 'Elixir.String.Chars',value => #{'__exception__' => true,'__struct__' => 'Elixir.Postgrex.Error',connection_id => 28062,message => nil,postgres => #{code => not_null_violation,column => <<"exchange">>,detail => <<"Failing row contains (2fa6084d-b525-4c0f-9064-e20eca56590f, LearnIpc::Commands::RepublishMessage, 1f4c4051-fe12-41cf-a39a-49f794f6b333, d233d296-5d52-4a58-bb69-7fc1af7a74e9, ...">>,...},...}} in 'Elixir.String.Chars':'impl_for!'/1 line 3
2019-11-29 15:06:09.585 [error] <0.4731.0> CRASH REPORT Process <0.4731.0> with 0 neighbours crashed with reason: #{'__exception__' => true,'__struct__' => 'Elixir.Protocol.UndefinedError',description => <<>>,protocol => 'Elixir.String.Chars',value => #{'__exception__' => true,'__struct__' => 'Elixir.Postgrex.Error',connection_id => 28062,message => nil,postgres => #{code => not_null_violation,column => <<"exchange">>,detail => <<"Failing row contains (2fa6084d-b525-4c0f-9064-e20eca56590f, LearnIpc::Commands::RepublishMessage, 1f4c4051-fe12-41cf-a39a-49f794f6b333, d233d296-5d52-4a58-bb69-7fc1af7a74e9, ...">>,...},...}} in 'Elixir.String.Chars':'impl_for!'/1 line 3
2019-11-29 15:06:09.586 [error] <0.4588.0> Supervisor {<0.4588.0>,'Elixir.Phoenix.Socket.PoolSupervisor.WorkerSupervisor'} had child 'Elixir.Phoenix.Channel.Server' started with {'Elixir.Phoenix.Channel.Server',start_link,undefined} at <0.4731.0> exit with reason #{'__exception__' => true,'__struct__' => 'Elixir.Protocol.UndefinedError',description => <<>>,protocol => 'Elixir.String.Chars',value => #{'__exception__' => true,'__struct__' => 'Elixir.Postgrex.Error',connection_id => 28062,message => nil,postgres => #{code => not_null_violation,column => <<"exchange">>,detail => <<"Failing row contains (2fa6084d-b525-4c0f-9064-e20eca56590f, LearnIpc::Commands::RepublishMessage, 1f4c4051-fe12-41cf-a39a-49f794f6b333, d233d296-5d52-4a58-bb69-7fc1af7a74e9, ...">>,...},...}} in 'Elixir.String.Chars':'impl_for!'/1 line 3 in context child_terminated
2019-11-29 15:10:29.725 [error] <0.4824.0> CRASH REPORT Process <0.4824.0> with 0 neighbours exited with reason: {{#{'__exception__' => true,'__struct__' => 'Elixir.UndefinedFunctionError',arity => 2,function => published_message_path,message => nil,module => 'Elixir.RailwayUiWeb.Router.Helpers',reason => nil},[{'Elixir.RailwayUiWeb.Router.Helpers',published_message_path,[#{'__struct__' => 'Elixir.Plug.Conn',adapter => {'Elixir.Plug.Cowboy.Conn',#{bindings => #{},body_length => 0,cert => undefined,has_body => false,headers => #{<<"accept">> => <<"text/html,application/xhtml+xml,application/xml;q=0....">>,...},...}},...},...],...},...]},...} in 'Elixir.Phoenix.Endpoint.Cowboy2Handler':init/4 line 59 in 'Elixir.Phoenix.Endpoint.Cowboy2Handler':init/4 line 59
2019-11-29 15:10:29.825 [error] <0.4476.0> Lager event handler error_logger_lager_h exited with reason {'EXIT',{{case_clause,['Elixir.RailwayUiWeb.Endpoint.HTTP',<0.4822.0>,1,<0.4824.0>,{{#{'__exception__' => true,'__struct__' => 'Elixir.UndefinedFunctionError',arity => 2,function => published_message_path,message => nil,module => 'Elixir.RailwayUiWeb.Router.Helpers',reason => nil},[{'Elixir.RailwayUiWeb.Router.Helpers',published_message_path,[#{'__struct__' => 'Elixir.Plug.Conn',adapter => {'Elixir.Plug.Cowboy.Conn',#{bindings => #{},body_length => 0,cert => undefined,has_body => false,...}},...},...],...},...]},...},...]},...}}
2019-11-29 16:36:19.227 [error] <0.388.0> Supervisor 'Elixir.RailwayIpc.Connection.Supervisor' had child 'Elixir.RailwayIpc.Connection' started with 'Elixir.RailwayIpc.Connection':start_link([{name,'Elixir.RailwayIpc.Connection'}]) at <0.389.0> exit with reason normal in context child_terminated
2019-11-29 16:36:39.548 [error] <0.388.0> Supervisor 'Elixir.RailwayIpc.Connection.Supervisor' had child 'Elixir.RailwayIpc.Connection' started with 'Elixir.RailwayIpc.Connection':start_link([{name,'Elixir.RailwayIpc.Connection'}]) at <0.608.0> exit with reason normal in context child_terminated
2019-11-30 07:53:54.052 [error] <0.548.0>@Elixir.RailwayUiWeb.PublishedMessagesLive.Index:handle_event:20 gen_server <0.548.0> terminated with reason: no function clause matching 'Elixir.RailwayUiWeb.PublishedMessagesLive.Index':handle_event(<<"republish">>, #{<<"published_message_uuid">> => <<"eb41f789-fde6-4152-b130-0cac11c7e034">>}, #{'__struct__' => 'Elixir.Phoenix.LiveView.Socket',assigns => #{current_user_uuid => <<"c07a9c36...">>,...},...}) line 20
2019-11-30 07:53:54.076 [error] <0.548.0>@Elixir.RailwayUiWeb.PublishedMessagesLive.Index:handle_event:20 CRASH REPORT Process <0.548.0> with 0 neighbours crashed with reason: no function clause matching 'Elixir.RailwayUiWeb.PublishedMessagesLive.Index':handle_event(<<"republish">>, #{<<"published_message_uuid">> => <<"eb41f789-fde6-4152-b130-0cac11c7e034">>}, #{'__struct__' => 'Elixir.Phoenix.LiveView.Socket',assigns => #{current_user_uuid => <<"c07a9c36...">>,...},...}) line 20
2019-11-30 07:53:54.076 [error] <0.434.0>@Elixir.RailwayUiWeb.PublishedMessagesLive.Index:handle_event:20 Supervisor 'Elixir.Phoenix.LiveView.DynamicSupervisor' had child undefined started with {'Elixir.Phoenix.LiveView.Channel',start_link,undefined} at <0.548.0> exit with reason no function clause matching 'Elixir.RailwayUiWeb.PublishedMessagesLive.Index':handle_event(<<"republish">>, #{<<"published_message_uuid">> => <<"eb41f789-fde6-4152-b130-0cac11c7e034">>}, #{'__struct__' => 'Elixir.Phoenix.LiveView.Socket',assigns => #{current_user_uuid => <<"c07a9c36...">>,...},...}) line 20 in context child_terminated
2019-11-30 08:10:52.109 [error] <0.562.0> gen_server <0.562.0> terminated with reason: {#{'__exception__' => true,'__struct__' => 'Elixir.UndefinedFunctionError',arity => 3,function => get_and_update,message => nil,module => 'Elixir.RailwayUiWeb.PublishedMessageLive.Index.Data',reason => <<"RailwayUiWeb.PublishedMessageLive.Index.Data does not implement the Access behaviour">>},[{'Elixir.RailwayUiWeb.PublishedMessageLive.Index.Data',get_and_update,[#{'__struct__' => 'Elixir.RailwayUiWeb.PublishedMessageLive.Index.Data',current_user_uuid => <<"395c620b-752b-4632-bff8-16972b5f3...">>,...},...],...},...]}
2019-11-30 08:10:52.133 [error] <0.562.0> CRASH REPORT Process <0.562.0> with 0 neighbours crashed with reason: {#{'__exception__' => true,'__struct__' => 'Elixir.UndefinedFunctionError',arity => 3,function => get_and_update,message => nil,module => 'Elixir.RailwayUiWeb.PublishedMessageLive.Index.Data',reason => <<"RailwayUiWeb.PublishedMessageLive.Index.Data does not implement the Access behaviour">>},[{'Elixir.RailwayUiWeb.PublishedMessageLive.Index.Data',get_and_update,[#{'__struct__' => 'Elixir.RailwayUiWeb.PublishedMessageLive.Index.Data',current_user_uuid => <<"395c620b-752b-4632-bff8-16972b5f3...">>,...},...],...},...]}
2019-11-30 08:10:52.133 [error] <0.448.0> Supervisor 'Elixir.Phoenix.LiveView.DynamicSupervisor' had child undefined started with {'Elixir.Phoenix.LiveView.Channel',start_link,undefined} at <0.562.0> exit with reason {#{'__exception__' => true,'__struct__' => 'Elixir.UndefinedFunctionError',arity => 3,function => get_and_update,message => nil,module => 'Elixir.RailwayUiWeb.PublishedMessageLive.Index.Data',reason => <<"RailwayUiWeb.PublishedMessageLive.Index.Data does not implement the Access behaviour">>},[{'Elixir.RailwayUiWeb.PublishedMessageLive.Index.Data',get_and_update,[#{'__struct__' => 'Elixir.RailwayUiWeb.PublishedMessageLive.Index.Data',current_user_uuid => <<"395c620b-752b-4632-bff8-16972b5f3...">>,...},...],...},...]} in context child_terminated
2019-11-30 08:14:03.144 [error] <0.553.0> gen_server <0.553.0> terminated with reason: {#{'__exception__' => true,'__struct__' => 'Elixir.UndefinedFunctionError',arity => 3,function => get_and_update,message => nil,module => 'Elixir.RailwayUiWeb.PublishedMessageLive.Index.Data',reason => <<"RailwayUiWeb.PublishedMessageLive.Index.Data does not implement the Access behaviour">>},[{'Elixir.RailwayUiWeb.PublishedMessageLive.Index.Data',get_and_update,[#{'__struct__' => 'Elixir.RailwayUiWeb.PublishedMessageLive.Index.Data',current_user_uuid => <<"23946573-bef2-447d-bb2e-f76e91e33...">>,...},...],...},...]}
2019-11-30 08:14:03.159 [error] <0.553.0> CRASH REPORT Process <0.553.0> with 0 neighbours crashed with reason: {#{'__exception__' => true,'__struct__' => 'Elixir.UndefinedFunctionError',arity => 3,function => get_and_update,message => nil,module => 'Elixir.RailwayUiWeb.PublishedMessageLive.Index.Data',reason => <<"RailwayUiWeb.PublishedMessageLive.Index.Data does not implement the Access behaviour">>},[{'Elixir.RailwayUiWeb.PublishedMessageLive.Index.Data',get_and_update,[#{'__struct__' => 'Elixir.RailwayUiWeb.PublishedMessageLive.Index.Data',current_user_uuid => <<"23946573-bef2-447d-bb2e-f76e91e33...">>,...},...],...},...]}
2019-11-30 08:14:03.159 [error] <0.443.0> Supervisor 'Elixir.Phoenix.LiveView.DynamicSupervisor' had child undefined started with {'Elixir.Phoenix.LiveView.Channel',start_link,undefined} at <0.553.0> exit with reason {#{'__exception__' => true,'__struct__' => 'Elixir.UndefinedFunctionError',arity => 3,function => get_and_update,message => nil,module => 'Elixir.RailwayUiWeb.PublishedMessageLive.Index.Data',reason => <<"RailwayUiWeb.PublishedMessageLive.Index.Data does not implement the Access behaviour">>},[{'Elixir.RailwayUiWeb.PublishedMessageLive.Index.Data',get_and_update,[#{'__struct__' => 'Elixir.RailwayUiWeb.PublishedMessageLive.Index.Data',current_user_uuid => <<"23946573-bef2-447d-bb2e-f76e91e33...">>,...},...],...},...]} in context child_terminated
2019-11-30 08:19:13.114 [error] <0.562.0> Supervisor 'Elixir.RailwayIpc.Connection.Supervisor' had child 'Elixir.RailwayIpc.Connection' started with 'Elixir.RailwayIpc.Connection':start_link([{name,'Elixir.RailwayIpc.Connection'}]) at <0.563.0> exit with reason normal in context child_terminated
2019-11-30 08:21:41.000 [error] <0.562.0> Supervisor 'Elixir.RailwayIpc.Connection.Supervisor' had child 'Elixir.RailwayIpc.Connection' started with 'Elixir.RailwayIpc.Connection':start_link([{name,'Elixir.RailwayIpc.Connection'}]) at <0.836.0> exit with reason normal in context child_terminated
2019-11-30 08:22:34.884 [error] <0.562.0> Supervisor 'Elixir.RailwayIpc.Connection.Supervisor' had child 'Elixir.RailwayIpc.Connection' started with 'Elixir.RailwayIpc.Connection':start_link([{name,'Elixir.RailwayIpc.Connection'}]) at <0.886.0> exit with reason normal in context child_terminated
2019-11-30 08:27:22.843 [error] <0.949.0> gen_server <0.949.0> terminated with reason: {socket_error,timeout}
2019-11-30 08:27:22.843 [error] <0.949.0> CRASH REPORT Process <0.949.0> with 0 neighbours exited with reason: {socket_error,timeout} in gen_server:handle_common_reply/8 line 751
2019-11-30 08:27:22.843 [error] <0.944.0> Supervisor {<0.944.0>,amqp_connection_type_sup} had child main_reader started with amqp_main_reader:start_link(#Port<0.1578>, <0.945.0>, <0.947.0>, {method,rabbit_framing_amqp_0_9_1}, <<"client 127.0.0.1:57786 -> 127.0.0.1:5672">>) at <0.949.0> exit with reason {socket_error,timeout} in context child_terminated
2019-11-30 08:27:22.844 [error] <0.944.0> Supervisor {<0.944.0>,amqp_connection_type_sup} had child main_reader started with amqp_main_reader:start_link(#Port<0.1578>, <0.945.0>, <0.947.0>, {method,rabbit_framing_amqp_0_9_1}, <<"client 127.0.0.1:57786 -> 127.0.0.1:5672">>) at <0.949.0> exit with reason reached_max_restart_intensity in context shutdown
2019-11-30 08:27:22.845 [error] <0.945.0> gen_server <0.945.0> terminated with reason: {socket_error,timeout}
2019-11-30 08:27:22.846 [error] <0.945.0> CRASH REPORT Process <0.945.0> with 0 neighbours exited with reason: {socket_error,timeout} in gen_server:handle_common_reply/8 line 751
2019-11-30 08:27:22.847 [error] <0.940.0>@gen_server:call gen_server 'Elixir.RailwayIpc.Connection' terminated with reason: no such process or port in call to gen_server:call(<0.945.0>, {command,{close,{'connection.close',200,<<"Goodbye">>,0,0},60000}}, 60000) in gen_server:call/3 line 223
2019-11-30 08:27:22.848 [error] <0.943.0> Supervisor {<0.943.0>,amqp_connection_sup} had child connection started with amqp_gen_connection:start_link(<0.944.0>, {amqp_params_network,<<"guest">>,<<"guest">>,<<"/">>,"localhost",5672,2047,0,10,60000,none,[#Fun<am..>,...],...}) at <0.945.0> exit with reason {socket_error,timeout} in context child_terminated
2019-11-30 08:27:22.848 [error] <0.943.0> Supervisor {<0.943.0>,amqp_connection_sup} had child connection started with amqp_gen_connection:start_link(<0.944.0>, {amqp_params_network,<<"guest">>,<<"guest">>,<<"/">>,"localhost",5672,2047,0,10,60000,none,[#Fun<am..>,...],...}) at <0.945.0> exit with reason reached_max_restart_intensity in context shutdown
2019-11-30 08:27:22.995 [error] <0.940.0>@gen_server:call CRASH REPORT Process 'Elixir.RailwayIpc.Connection' with 0 neighbours exited with reason: no such process or port in call to gen_server:call(<0.945.0>, {command,{close,{'connection.close',200,<<"Goodbye">>,0,0},60000}}, 60000) in gen_server:call/3 line 223
2019-11-30 08:27:22.997 [error] <0.562.0>@gen_server:call Supervisor 'Elixir.RailwayIpc.Connection.Supervisor' had child 'Elixir.RailwayIpc.Connection' started with 'Elixir.RailwayIpc.Connection':start_link([{name,'Elixir.RailwayIpc.Connection'}]) at <0.940.0> exit with reason no such process or port in call to gen_server:call(<0.945.0>, {command,{close,{'connection.close',200,<<"Goodbye">>,0,0},60000}}, 60000) in context child_terminated
2019-11-30 08:37:37.500 [error] <0.1340.0> CRASH REPORT Process <0.1340.0> with 0 neighbours exited with reason: {{#{'__exception__' => true,'__struct__' => 'Elixir.KeyError',key => page_nums,message => nil,term => #{'__struct__' => 'Elixir.RailwayUiWeb.PublishedMessageLive.Index.Data',current_user_uuid => <<"1f4c4051-fe12-41cf-a39a-49f794f6b333">>,flash => #{},page => 1}},[{'Elixir.RailwayUiWeb.PublishedMessageView','index.html',1,[{file,"lib/railway_ui_web/templates/published_message/index.html.leex"},{line,53}]},{'Elixir.Phoenix.LiveView.Utils',to_rendered,2,[{file,"lib/phoenix_live_view/utils.ex"},...]},...]},...} in 'Elixir.Phoenix.Endpoint.Cowboy2Handler':init/4 line 59 in 'Elixir.Phoenix.Endpoint.Cowboy2Handler':init/4 line 59
2019-11-30 08:37:37.590 [error] <0.527.0> Lager event handler error_logger_lager_h exited with reason {'EXIT',{{case_clause,['Elixir.RailwayUiWeb.Endpoint.HTTP',<0.1338.0>,1,<0.1340.0>,{{#{'__exception__' => true,'__struct__' => 'Elixir.KeyError',key => page_nums,message => nil,term => #{'__struct__' => 'Elixir.RailwayUiWeb.PublishedMessageLive.Index.Data',current_user_uuid => <<"1f4c4051-fe12-41cf-a39a-49f794f6b333">>,flash => #{},page => 1}},[{'Elixir.RailwayUiWeb.PublishedMessageView','index.html',1,[{file,"lib/railway_ui_web/templates/published_message/index.html.leex"},{line,53}]},{'Elixir.Phoenix.LiveView.Utils',...},...]},...},...]},...}}
2019-11-30 08:48:10.785 [error] <0.618.0> CRASH REPORT Process <0.618.0> with 0 neighbours exited with reason: {{#{'__exception__' => true,'__struct__' => 'Elixir.ArgumentError',message => <<"assign @page_num not available in eex template.\n\nPlease make sure all proper assigns have been set. If this\nis a child template, ensure assigns are given explicitly by\nthe parent template as they are not automatically forwarded.\n\nAvailable assigns: [:data, :messages, :socket, :view_module, :view_template]\n">>},[{'Elixir.Phoenix.LiveView.Engine','fetch_assign!',2,[{file,"lib/phoenix_live_view/engine.ex"},{line,...}]},...]},...} in 'Elixir.Phoenix.Endpoint.Cowboy2Handler':init/4 line 59 in 'Elixir.Phoenix.Endpoint.Cowboy2Handler':init/4 line 59
2019-11-30 08:48:10.905 [error] <0.378.0> Lager event handler error_logger_lager_h exited with reason {'EXIT',{{case_clause,['Elixir.RailwayUiWeb.Endpoint.HTTP',<0.616.0>,1,<0.618.0>,{{#{'__exception__' => true,'__struct__' => 'Elixir.ArgumentError',message => <<"assign @page_num not available in eex template.\n\nPlease make sure all proper assigns have been set. If this\nis a child template, ensure assigns are given explicitly by\nthe parent template as they are not automatically forwarded.\n\nAvailable assigns: [:data, :messages, :socket, :view_module, :view_template]\n">>},[{'Elixir.Phoenix.LiveView.Engine',...},...]},...},...]},...}}
2019-11-30 08:48:16.705 [error] <0.630.0> CRASH REPORT Process <0.630.0> with 0 neighbours exited with reason: {{#{'__exception__' => true,'__struct__' => 'Elixir.ArgumentError',message => <<"assign @page_num not available in eex template.\n\nPlease make sure all proper assigns have been set. If this\nis a child template, ensure assigns are given explicitly by\nthe parent template as they are not automatically forwarded.\n\nAvailable assigns: [:data, :messages, :socket, :view_module, :view_template]\n">>},[{'Elixir.Phoenix.LiveView.Engine','fetch_assign!',2,[{file,"lib/phoenix_live_view/engine.ex"},{line,...}]},...]},...} in 'Elixir.Phoenix.Endpoint.Cowboy2Handler':init/4 line 59 in 'Elixir.Phoenix.Endpoint.Cowboy2Handler':init/4 line 59
2019-11-30 08:48:16.710 [error] <0.378.0> Lager event handler error_logger_lager_h exited with reason {'EXIT',{{case_clause,['Elixir.RailwayUiWeb.Endpoint.HTTP',<0.628.0>,1,<0.630.0>,{{#{'__exception__' => true,'__struct__' => 'Elixir.ArgumentError',message => <<"assign @page_num not available in eex template.\n\nPlease make sure all proper assigns have been set. If this\nis a child template, ensure assigns are given explicitly by\nthe parent template as they are not automatically forwarded.\n\nAvailable assigns: [:data, :messages, :socket, :view_module, :view_template]\n">>},[{'Elixir.Phoenix.LiveView.Engine',...},...]},...},...]},...}}
2019-11-30 08:50:08.853 [error] <0.695.0> gen_server <0.695.0> terminated with reason: #{'__exception__' => true,'__struct__' => 'Elixir.ArgumentError',message => <<"no function clause for RailwayUiWeb.Router.Helpers.live_path/3 and action PublishedMessageLive.Index. The following actions/clauses are supported:\n\n    live_path(conn_or_endpoint, RailwayUiWeb.PublishedMessageLive.Index, params \\\\ [])">>} in 'Elixir.Phoenix.Router.Helpers':raise_route_error/6 line 346
2019-11-30 08:50:08.854 [error] <0.695.0> CRASH REPORT Process <0.695.0> with 0 neighbours crashed with reason: #{'__exception__' => true,'__struct__' => 'Elixir.ArgumentError',message => <<"no function clause for RailwayUiWeb.Router.Helpers.live_path/3 and action PublishedMessageLive.Index. The following actions/clauses are supported:\n\n    live_path(conn_or_endpoint, RailwayUiWeb.PublishedMessageLive.Index, params \\\\ [])">>} in 'Elixir.Phoenix.Router.Helpers':raise_route_error/6 line 346
2019-11-30 08:50:08.855 [error] <0.502.0> Supervisor {<0.502.0>,'Elixir.Phoenix.Socket.PoolSupervisor.WorkerSupervisor'} had child 'Elixir.Phoenix.Channel.Server' started with {'Elixir.Phoenix.Channel.Server',start_link,undefined} at <0.695.0> exit with reason #{'__exception__' => true,'__struct__' => 'Elixir.ArgumentError',message => <<"no function clause for RailwayUiWeb.Router.Helpers.live_path/3 and action PublishedMessageLive.Index. The following actions/clauses are supported:\n\n    live_path(conn_or_endpoint, RailwayUiWeb.PublishedMessageLive.Index, params \\\\ [])">>} in 'Elixir.Phoenix.Router.Helpers':raise_route_error/6 line 346 in context child_terminated
2019-11-30 08:50:08.884 [error] <0.682.0> CRASH REPORT Process <0.682.0> with 0 neighbours exited with reason: {{#{'__exception__' => true,'__struct__' => 'Elixir.ArgumentError',message => <<"no function clause for RailwayUiWeb.Router.Helpers.live_path/3 and action PublishedMessageLive.Index. The following actions/clauses are supported:\n\n    live_path(conn_or_endpoint, RailwayUiWeb.PublishedMessageLive.Index, params \\\\ [])">>},[{'Elixir.Phoenix.Router.Helpers',raise_route_error,6,[{file,"lib/phoenix/router/helpers.ex"},{line,346}]},{'Elixir.RailwayUiWeb.PublishedMessageView','-index.html/1-fun-2-',...},...]},...} in 'Elixir.Phoenix.Endpoint.Cowboy2Handler':init/4 line 59 in 'Elixir.Phoenix.Endpoint.Cowboy2Handler':init/4 line 59
2019-11-30 08:50:08.889 [error] <0.378.0> Lager event handler error_logger_lager_h exited with reason {'EXIT',{{case_clause,['Elixir.RailwayUiWeb.Endpoint.HTTP',<0.680.0>,1,<0.682.0>,{{#{'__exception__' => true,'__struct__' => 'Elixir.ArgumentError',message => <<"no function clause for RailwayUiWeb.Router.Helpers.live_path/3 and action PublishedMessageLive.Index. The following actions/clauses are supported:\n\n    live_path(conn_or_endpoint, RailwayUiWeb.PublishedMessageLive.Index, params \\\\ [])">>},[{'Elixir.Phoenix.Router.Helpers',raise_route_error,6,[{file,"lib/phoenix/router/helpers...."},...]},...]},...},...]},...}}
2019-11-30 08:50:35.901 [error] <0.752.0>@Elixir.Phoenix.LiveView.Channel:handle_info:62 gen_server <0.752.0> terminated with reason: call to undefined function 'Elixir.RailwayUiWeb.PublishedMessageLive.Index':handle_params/3 from 'Elixir.Phoenix.LiveView.Channel':handle_info/2 line 62
2019-11-30 08:50:35.921 [error] <0.752.0>@Elixir.RailwayUiWeb.PublishedMessageLive.Index:handle_params CRASH REPORT Process <0.752.0> with 0 neighbours crashed with reason: call to undefined function 'Elixir.RailwayUiWeb.PublishedMessageLive.Index':handle_params(#{<<"page">> => <<"3">>}, <<"http://localhost:4000/published_messages?page=3">>, #{'__struct__' => 'Elixir.Phoenix.LiveView.Socket',assigns => #{data => #{'__struct__' => 'Elixir.RailwayUiWeb.PublishedMessageLive.Index.Data',...},...},...})
2019-11-30 08:50:35.921 [error] <0.500.0>@Elixir.RailwayUiWeb.PublishedMessageLive.Index:handle_params Supervisor {<0.500.0>,'Elixir.Phoenix.Socket.PoolSupervisor.WorkerSupervisor'} had child 'Elixir.Phoenix.Channel.Server' started with {'Elixir.Phoenix.Channel.Server',start_link,undefined} at <0.752.0> exit with reason call to undefined function 'Elixir.RailwayUiWeb.PublishedMessageLive.Index':handle_params(#{<<"page">> => <<"3">>}, <<"http://localhost:4000/published_messages?page=3">>, #{'__struct__' => 'Elixir.Phoenix.LiveView.Socket',assigns => #{data => #{'__struct__' => 'Elixir.RailwayUiWeb.PublishedMessageLive.Index.Data',...},...},...}) in context child_terminated
2019-11-30 08:53:19.228 [error] <0.786.0> CRASH REPORT Process <0.786.0> with 0 neighbours exited with reason: {{#{'__exception__' => true,'__struct__' => 'Elixir.FunctionClauseError',args => nil,arity => 3,clauses => nil,function => handle_params,kind => nil,module => 'Elixir.RailwayUiWeb.PublishedMessageLive.Index'},[{'Elixir.RailwayUiWeb.PublishedMessageLive.Index',handle_params,[#{},<<"http://localhost:4000/published_messages">>,#{'__struct__' => 'Elixir.Phoenix.LiveView.Socket',assigns => #{data => #{'__struct__' => 'Elixir.RailwayUiWeb.PublishedMessageLive.Index.Data',current_user_uuid => <<"...">>,...},...},...}],...},...]},...} in 'Elixir.Phoenix.Endpoint.Cowboy2Handler':init/4 line 59 in 'Elixir.Phoenix.Endpoint.Cowboy2Handler':init/4 line 59
2019-11-30 08:53:19.235 [error] <0.378.0> Lager event handler error_logger_lager_h exited with reason {'EXIT',{{case_clause,['Elixir.RailwayUiWeb.Endpoint.HTTP',<0.785.0>,1,<0.786.0>,{{#{'__exception__' => true,'__struct__' => 'Elixir.FunctionClauseError',args => nil,arity => 3,clauses => nil,function => handle_params,kind => nil,module => 'Elixir.RailwayUiWeb.PublishedMessageLive.Index'},[{'Elixir.RailwayUiWeb.PublishedMessageLive.Index',handle_params,[#{},<<"http://localhost:4000/published_messages">>,#{'__struct__' => 'Elixir.Phoenix.LiveView.Socket',assigns => #{data => #{'__struct__' => ...,...},...},...}],...},...]},...},...]},...}}
2019-11-30 08:53:23.838 [error] <0.813.0> CRASH REPORT Process <0.813.0> with 0 neighbours exited with reason: {{#{'__exception__' => true,'__struct__' => 'Elixir.FunctionClauseError',args => nil,arity => 3,clauses => nil,function => handle_params,kind => nil,module => 'Elixir.RailwayUiWeb.PublishedMessageLive.Index'},[{'Elixir.RailwayUiWeb.PublishedMessageLive.Index',handle_params,[#{},<<"http://localhost:4000/published_messages">>,#{'__struct__' => 'Elixir.Phoenix.LiveView.Socket',assigns => #{data => #{'__struct__' => 'Elixir.RailwayUiWeb.PublishedMessageLive.Index.Data',current_user_uuid => <<"...">>,...},...},...}],...},...]},...} in 'Elixir.Phoenix.Endpoint.Cowboy2Handler':init/4 line 59 in 'Elixir.Phoenix.Endpoint.Cowboy2Handler':init/4 line 59
2019-11-30 08:53:23.843 [error] <0.378.0> Lager event handler error_logger_lager_h exited with reason {'EXIT',{{case_clause,['Elixir.RailwayUiWeb.Endpoint.HTTP',<0.785.0>,4,<0.813.0>,{{#{'__exception__' => true,'__struct__' => 'Elixir.FunctionClauseError',args => nil,arity => 3,clauses => nil,function => handle_params,kind => nil,module => 'Elixir.RailwayUiWeb.PublishedMessageLive.Index'},[{'Elixir.RailwayUiWeb.PublishedMessageLive.Index',handle_params,[#{},<<"http://localhost:4000/published_messages">>,#{'__struct__' => 'Elixir.Phoenix.LiveView.Socket',assigns => #{data => #{'__struct__' => ...,...},...},...}],...},...]},...},...]},...}}
2019-11-30 08:55:06.810 [error] <0.863.0> CRASH REPORT Process <0.863.0> with 0 neighbours exited with reason: {{#{'__exception__' => true,'__struct__' => 'Elixir.UndefinedFunctionError',arity => 1,function => messages_page,message => nil,module => 'Elixir.RailwayUiWeb.PublishedMessageLive.Index.Data',reason => nil},[{'Elixir.RailwayUiWeb.PublishedMessageLive.Index.Data',messages_page,[<<"6">>],[]},{'Elixir.RailwayUiWeb.PublishedMessageLive.Index',handle_params,3,[{file,"lib/railway_ui_web/live/published_message_live/index.ex"},{line,25}]},{'Elixir.Phoenix.LiveView.Static','call_mount_and_handle_params!',...},...]},...} in 'Elixir.Phoenix.Endpoint.Cowboy2Handler':init/4 line 59 in 'Elixir.Phoenix.Endpoint.Cowboy2Handler':init/4 line 59
2019-11-30 08:55:06.834 [error] <0.378.0> Lager event handler error_logger_lager_h exited with reason {'EXIT',{{case_clause,['Elixir.RailwayUiWeb.Endpoint.HTTP',<0.862.0>,1,<0.863.0>,{{#{'__exception__' => true,'__struct__' => 'Elixir.UndefinedFunctionError',arity => 1,function => messages_page,message => nil,module => 'Elixir.RailwayUiWeb.PublishedMessageLive.Index.Data',reason => nil},[{'Elixir.RailwayUiWeb.PublishedMessageLive.Index.Data',messages_page,[<<"6">>],[]},{'Elixir.RailwayUiWeb.PublishedMessageLive.Index',handle_params,3,[{file,"lib/railway_ui_web/live/published_message_live/..."},...]},...]},...},...]},...}}
2019-11-30 08:55:26.463 [error] <0.892.0> CRASH REPORT Process <0.892.0> with 0 neighbours exited with reason: {{#{'__exception__' => true,'__struct__' => 'Elixir.UndefinedFunctionError',arity => 1,function => all,message => nil,module => 'Elixir.RailwayUi.PublishedMessage',reason => nil},[{'Elixir.RailwayUi.PublishedMessage',all,[<<"6">>],[]},{'Elixir.RailwayUiWeb.PublishedMessageLive.Index.Data',messages_page,2,[{file,"lib/railway_ui_web/live/published_message_live/index/data.ex"},{line,24}]},{'Elixir.RailwayUiWeb.PublishedMessageLive.Index',handle_params,3,[{file,"lib/railway_ui_web/live/publish..."},...]},...]},...} in 'Elixir.Phoenix.Endpoint.Cowboy2Handler':init/4 line 59 in 'Elixir.Phoenix.Endpoint.Cowboy2Handler':init/4 line 59
2019-11-30 08:55:26.470 [error] <0.378.0> Lager event handler error_logger_lager_h exited with reason {'EXIT',{{case_clause,['Elixir.RailwayUiWeb.Endpoint.HTTP',<0.890.0>,1,<0.892.0>,{{#{'__exception__' => true,'__struct__' => 'Elixir.UndefinedFunctionError',arity => 1,function => all,message => nil,module => 'Elixir.RailwayUi.PublishedMessage',reason => nil},[{'Elixir.RailwayUi.PublishedMessage',all,[<<"6">>],[]},{'Elixir.RailwayUiWeb.PublishedMessageLive.Index.Data',messages_page,2,[{file,"lib/railway_ui_web/live/published_message_live/index/data.ex"},{line,24}]},{'Elixir.RailwayUiWeb.PublishedMessageLive.Index',...},...]},...},...]},...}}
2019-11-30 08:55:40.193 [error] <0.914.0> CRASH REPORT Process <0.914.0> with 0 neighbours exited with reason: {{#{'__exception__' => true,'__struct__' => 'Elixir.UndefinedFunctionError',arity => 2,function => update,message => nil,module => 'Elixir.Map',reason => nil},[{'Elixir.Map',update,[#{'__struct__' => 'Elixir.RailwayUiWeb.PublishedMessageLive.Index.Data',current_user_uuid => <<"1f4c4051-fe12-41cf-a39a-49f794f6b333">>,flash => #{},page => 1,page_nums => 15},#{messages => [#{'__meta__' => #{'__struct__' => 'Elixir.Ecto.Schema.Metadata',context => nil,prefix => nil,schema => 'Elixir.RailwayIpc.Persistence.PublishedMessage',...},...},...]}],...},...]},...} in 'Elixir.Phoenix.Endpoint.Cowboy2Handler':init/4 line 59 in 'Elixir.Phoenix.Endpoint.Cowboy2Handler':init/4 line 59
2019-11-30 08:55:40.205 [error] <0.378.0> Lager event handler error_logger_lager_h exited with reason {'EXIT',{{case_clause,['Elixir.RailwayUiWeb.Endpoint.HTTP',<0.912.0>,1,<0.914.0>,{{#{'__exception__' => true,'__struct__' => 'Elixir.UndefinedFunctionError',arity => 2,function => update,message => nil,module => 'Elixir.Map',reason => nil},[{'Elixir.Map',update,[#{'__struct__' => 'Elixir.RailwayUiWeb.PublishedMessageLive.Index.Data',current_user_uuid => <<"1f4c4051-fe12-41cf-a39a-49f794f6b333">>,flash => #{},page => 1,page_nums => 15},#{messages => [#{'__meta__' => #{'__struct__' => 'Elixir.Ecto.Schema.Metadata',...},...},...]}],...},...]},...},...]},...}}
2019-11-30 08:58:14.952 [error] <0.1079.0> gen_server <0.1079.0> terminated with reason: {#{'__exception__' => true,'__struct__' => 'Elixir.UndefinedFunctionError',arity => 1,function => messages_page,message => nil,module => 'Elixir.RailwayUiWeb.PublishedMessageLive.Index.Data',reason => nil},[{'Elixir.RailwayUiWeb.PublishedMessageLive.Index.Data',messages_page,[<<"9">>],[]},{'Elixir.RailwayUiWeb.PublishedMessageLive.Index',handle_params,3,[{file,"lib/railway_ui_web/live/published_message_live/index.ex"},{line,25}]},{'Elixir.Phoenix.LiveView.Channel',maybe_call_mount_handle_params,...},...]}
2019-11-30 08:58:14.952 [error] <0.1079.0> CRASH REPORT Process <0.1079.0> with 0 neighbours crashed with reason: {#{'__exception__' => true,'__struct__' => 'Elixir.UndefinedFunctionError',arity => 1,function => messages_page,message => nil,module => 'Elixir.RailwayUiWeb.PublishedMessageLive.Index.Data',reason => nil},[{'Elixir.RailwayUiWeb.PublishedMessageLive.Index.Data',messages_page,[<<"9">>],[]},{'Elixir.RailwayUiWeb.PublishedMessageLive.Index',handle_params,3,[{file,"lib/railway_ui_web/live/published_message_live/index.ex"},{line,25}]},{'Elixir.Phoenix.LiveView.Channel',maybe_call_mount_handle_params,...},...]}
2019-11-30 08:58:14.953 [error] <0.501.0> Supervisor {<0.501.0>,'Elixir.Phoenix.Socket.PoolSupervisor.WorkerSupervisor'} had child 'Elixir.Phoenix.Channel.Server' started with {'Elixir.Phoenix.Channel.Server',start_link,undefined} at <0.1079.0> exit with reason {#{'__exception__' => true,'__struct__' => 'Elixir.UndefinedFunctionError',arity => 1,function => messages_page,message => nil,module => 'Elixir.RailwayUiWeb.PublishedMessageLive.Index.Data',reason => nil},[{'Elixir.RailwayUiWeb.PublishedMessageLive.Index.Data',messages_page,[<<"9">>],[]},{'Elixir.RailwayUiWeb.PublishedMessageLive.Index',handle_params,3,[{file,"lib/railway_ui_web/live/published_message_live/index.ex"},{line,25}]},{'Elixir.Phoenix.LiveView.Channel',maybe_call_mount_handle_params,...},...]} in context child_terminated
2019-11-30 08:58:14.988 [error] <0.1061.0> CRASH REPORT Process <0.1061.0> with 0 neighbours exited with reason: {{#{'__exception__' => true,'__struct__' => 'Elixir.UndefinedFunctionError',arity => 1,function => messages_page,message => nil,module => 'Elixir.RailwayUiWeb.PublishedMessageLive.Index.Data',reason => nil},[{'Elixir.RailwayUiWeb.PublishedMessageLive.Index.Data',messages_page,[<<"9">>],[]},{'Elixir.RailwayUiWeb.PublishedMessageLive.Index',handle_params,3,[{file,"lib/railway_ui_web/live/published_message_live/index.ex"},{line,25}]},{'Elixir.Phoenix.LiveView.Static','call_mount_and_handle_params!',...},...]},...} in 'Elixir.Phoenix.Endpoint.Cowboy2Handler':init/4 line 59 in 'Elixir.Phoenix.Endpoint.Cowboy2Handler':init/4 line 59
2019-11-30 08:58:15.006 [error] <0.378.0> Lager event handler error_logger_lager_h exited with reason {'EXIT',{{case_clause,['Elixir.RailwayUiWeb.Endpoint.HTTP',<0.1059.0>,1,<0.1061.0>,{{#{'__exception__' => true,'__struct__' => 'Elixir.UndefinedFunctionError',arity => 1,function => messages_page,message => nil,module => 'Elixir.RailwayUiWeb.PublishedMessageLive.Index.Data',reason => nil},[{'Elixir.RailwayUiWeb.PublishedMessageLive.Index.Data',messages_page,[<<"9">>],[]},{'Elixir.RailwayUiWeb.PublishedMessageLive.Index',handle_params,3,[{file,"lib/railway_ui_web/live/published_message_liv..."},...]},...]},...},...]},...}}
2019-11-30 09:06:02.209 [error] <0.1298.0> CRASH REPORT Process <0.1298.0> with 0 neighbours exited with reason: {{#{'__exception__' => true,'__struct__' => 'Elixir.Postgrex.Error',connection_id => 16494,message => nil,postgres => #{code => ambiguous_function,file => <<"parse_oper.c">>,hint => <<"Could not choose a best candidate operator. You might need to add explicit type casts.">>,line => <<"720">>,message => <<"operator is not unique: unknown * unknown">>,pg_code => <<"42725">>,position => <<"234">>,routine => <<"op_error">>,severity => <<"ERROR">>,unknown => <<"ERROR">>},query => <<"SELECT r0.\"u...">>},...},...} in 'Elixir.Phoenix.Endpoint.Cowboy2Handler':init/4 line 59 in 'Elixir.Phoenix.Endpoint.Cowboy2Handler':init/4 line 59
2019-11-30 09:06:02.217 [error] <0.378.0> Lager event handler error_logger_lager_h exited with reason {'EXIT',{{case_clause,['Elixir.RailwayUiWeb.Endpoint.HTTP',<0.1296.0>,1,<0.1298.0>,{{#{'__exception__' => true,'__struct__' => 'Elixir.Postgrex.Error',connection_id => 16494,message => nil,postgres => #{code => ambiguous_function,file => <<"parse_oper.c">>,hint => <<"Could not choose a best candidate operator. You might need to add explicit type casts.">>,line => <<"720">>,message => <<"operator is not unique: unknown * unknown">>,pg_code => <<"42725">>,position => <<"234">>,routine => <<"...">>,...},...},...},...},...]},...}}
2019-11-30 09:06:08.647 [error] <0.1342.0> CRASH REPORT Process <0.1342.0> with 0 neighbours exited with reason: {{#{'__exception__' => true,'__struct__' => 'Elixir.Postgrex.Error',connection_id => 16491,message => nil,postgres => #{code => ambiguous_function,file => <<"parse_oper.c">>,hint => <<"Could not choose a best candidate operator. You might need to add explicit type casts.">>,line => <<"720">>,message => <<"operator is not unique: unknown * unknown">>,pg_code => <<"42725">>,position => <<"234">>,routine => <<"op_error">>,severity => <<"ERROR">>,unknown => <<"ERROR">>},query => <<"SELECT r0.\"u...">>},...},...} in 'Elixir.Phoenix.Endpoint.Cowboy2Handler':init/4 line 59 in 'Elixir.Phoenix.Endpoint.Cowboy2Handler':init/4 line 59
2019-11-30 09:06:08.660 [error] <0.378.0> Lager event handler error_logger_lager_h exited with reason {'EXIT',{{case_clause,['Elixir.RailwayUiWeb.Endpoint.HTTP',<0.1340.0>,1,<0.1342.0>,{{#{'__exception__' => true,'__struct__' => 'Elixir.Postgrex.Error',connection_id => 16491,message => nil,postgres => #{code => ambiguous_function,file => <<"parse_oper.c">>,hint => <<"Could not choose a best candidate operator. You might need to add explicit type casts.">>,line => <<"720">>,message => <<"operator is not unique: unknown * unknown">>,pg_code => <<"42725">>,position => <<"234">>,routine => <<"...">>,...},...},...},...},...]},...}}
2019-11-30 09:06:19.733 [error] <0.1404.0> CRASH REPORT Process <0.1404.0> with 0 neighbours exited with reason: {{#{'__exception__' => true,'__struct__' => 'Elixir.Postgrex.Error',connection_id => 16494,message => nil,postgres => #{code => ambiguous_function,file => <<"parse_oper.c">>,hint => <<"Could not choose a best candidate operator. You might need to add explicit type casts.">>,line => <<"720">>,message => <<"operator is not unique: unknown * unknown">>,pg_code => <<"42725">>,position => <<"234">>,routine => <<"op_error">>,severity => <<"ERROR">>,unknown => <<"ERROR">>},query => <<"SELECT r0.\"u...">>},...},...} in 'Elixir.Phoenix.Endpoint.Cowboy2Handler':init/4 line 59 in 'Elixir.Phoenix.Endpoint.Cowboy2Handler':init/4 line 59
2019-11-30 09:06:19.748 [error] <0.378.0> Lager event handler error_logger_lager_h exited with reason {'EXIT',{{case_clause,['Elixir.RailwayUiWeb.Endpoint.HTTP',<0.1402.0>,1,<0.1404.0>,{{#{'__exception__' => true,'__struct__' => 'Elixir.Postgrex.Error',connection_id => 16494,message => nil,postgres => #{code => ambiguous_function,file => <<"parse_oper.c">>,hint => <<"Could not choose a best candidate operator. You might need to add explicit type casts.">>,line => <<"720">>,message => <<"operator is not unique: unknown * unknown">>,pg_code => <<"42725">>,position => <<"234">>,routine => <<"...">>,...},...},...},...},...]},...}}
2019-11-30 09:06:41.547 [error] <0.1436.0> CRASH REPORT Process <0.1436.0> with 0 neighbours exited with reason: {{#{'__exception__' => true,'__struct__' => 'Elixir.Postgrex.Error',connection_id => 16500,message => nil,postgres => #{code => ambiguous_function,file => <<"parse_oper.c">>,hint => <<"Could not choose a best candidate operator. You might need to add explicit type casts.">>,line => <<"720">>,message => <<"operator is not unique: unknown * unknown">>,pg_code => <<"42725">>,position => <<"234">>,routine => <<"op_error">>,severity => <<"ERROR">>,unknown => <<"ERROR">>},query => <<"SELECT r0.\"u...">>},...},...} in 'Elixir.Phoenix.Endpoint.Cowboy2Handler':init/4 line 59 in 'Elixir.Phoenix.Endpoint.Cowboy2Handler':init/4 line 59
2019-11-30 09:06:41.555 [error] <0.378.0> Lager event handler error_logger_lager_h exited with reason {'EXIT',{{case_clause,['Elixir.RailwayUiWeb.Endpoint.HTTP',<0.1434.0>,1,<0.1436.0>,{{#{'__exception__' => true,'__struct__' => 'Elixir.Postgrex.Error',connection_id => 16500,message => nil,postgres => #{code => ambiguous_function,file => <<"parse_oper.c">>,hint => <<"Could not choose a best candidate operator. You might need to add explicit type casts.">>,line => <<"720">>,message => <<"operator is not unique: unknown * unknown">>,pg_code => <<"42725">>,position => <<"234">>,routine => <<"...">>,...},...},...},...},...]},...}}
2019-11-30 09:07:32.374 [error] <0.1474.0> CRASH REPORT Process <0.1474.0> with 0 neighbours exited with reason: {{#{'__exception__' => true,'__struct__' => 'Elixir.ArgumentError',message => <<"ranges (first..last) expect both sides to be integers, got: 0..7.5">>},[{'Elixir.Range',new,2,[{file,"lib/range.ex"},{line,59}]},{'Elixir.RailwayUiWeb.PublishedMessageView','index.html',1,[{file,"lib/railway_ui_web/templates/published_message/index.html.leex"},{line,53}]},{'Elixir.Phoenix.LiveView.Utils',to_rendered,2,[{file,"lib/phoenix_live_view/utils.ex"},{line,70}]},{'Elixir.Phoenix.LiveView.Static',to_rendered_content_tag,...},...]},...} in 'Elixir.Phoenix.Endpoint.Cowboy2Handler':init/4 line 59 in 'Elixir.Phoenix.Endpoint.Cowboy2Handler':init/4 line 59
2019-11-30 09:07:32.384 [error] <0.378.0> Lager event handler error_logger_lager_h exited with reason {'EXIT',{{case_clause,['Elixir.RailwayUiWeb.Endpoint.HTTP',<0.1472.0>,1,<0.1474.0>,{{#{'__exception__' => true,'__struct__' => 'Elixir.ArgumentError',message => <<"ranges (first..last) expect both sides to be integers, got: 0..7.5">>},[{'Elixir.Range',new,2,[{file,"lib/range.ex"},{line,59}]},{'Elixir.RailwayUiWeb.PublishedMessageView','index.html',1,[{file,"lib/railway_ui_web/templates/published_message/index.html.leex"},{line,53}]},{'Elixir.Phoenix.LiveView.Utils',to_rendered,2,[{file,"l..."},...]},...]},...},...]},...}}
2019-11-30 09:07:43.019 [error] <0.1506.0> CRASH REPORT Process <0.1506.0> with 0 neighbours exited with reason: {{#{'__exception__' => true,'__struct__' => 'Elixir.ArgumentError',message => <<"ranges (first..last) expect both sides to be integers, got: 0..8.0">>},[{'Elixir.Range',new,2,[{file,"lib/range.ex"},{line,59}]},{'Elixir.RailwayUiWeb.PublishedMessageView','index.html',1,[{file,"lib/railway_ui_web/templates/published_message/index.html.leex"},{line,53}]},{'Elixir.Phoenix.LiveView.Utils',to_rendered,2,[{file,"lib/phoenix_live_view/utils.ex"},{line,70}]},{'Elixir.Phoenix.LiveView.Static',to_rendered_content_tag,...},...]},...} in 'Elixir.Phoenix.Endpoint.Cowboy2Handler':init/4 line 59 in 'Elixir.Phoenix.Endpoint.Cowboy2Handler':init/4 line 59
2019-11-30 09:07:43.025 [error] <0.378.0> Lager event handler error_logger_lager_h exited with reason {'EXIT',{{case_clause,['Elixir.RailwayUiWeb.Endpoint.HTTP',<0.1505.0>,1,<0.1506.0>,{{#{'__exception__' => true,'__struct__' => 'Elixir.ArgumentError',message => <<"ranges (first..last) expect both sides to be integers, got: 0..8.0">>},[{'Elixir.Range',new,2,[{file,"lib/range.ex"},{line,59}]},{'Elixir.RailwayUiWeb.PublishedMessageView','index.html',1,[{file,"lib/railway_ui_web/templates/published_message/index.html.leex"},{line,53}]},{'Elixir.Phoenix.LiveView.Utils',to_rendered,2,[{file,"l..."},...]},...]},...},...]},...}}
2019-11-30 09:11:05.266 [error] <0.1543.0> CRASH REPORT Process <0.1543.0> with 0 neighbours exited with reason: {{#{'__exception__' => true,'__struct__' => 'Elixir.ArgumentError',message => <<"ranges (first..last) expect both sides to be integers, got: 0..8.0">>},[{'Elixir.Range',new,2,[{file,"lib/range.ex"},{line,59}]},{'Elixir.RailwayUiWeb.PublishedMessageView','index.html',1,[{file,"lib/railway_ui_web/templates/published_message/index.html.leex"},{line,53}]},{'Elixir.Phoenix.LiveView.Utils',to_rendered,2,[{file,"lib/phoenix_live_view/utils.ex"},{line,70}]},{'Elixir.Phoenix.LiveView.Static',to_rendered_content_tag,...},...]},...} in 'Elixir.Phoenix.Endpoint.Cowboy2Handler':init/4 line 59 in 'Elixir.Phoenix.Endpoint.Cowboy2Handler':init/4 line 59
2019-11-30 09:11:05.271 [error] <0.378.0> Lager event handler error_logger_lager_h exited with reason {'EXIT',{{case_clause,['Elixir.RailwayUiWeb.Endpoint.HTTP',<0.1541.0>,1,<0.1543.0>,{{#{'__exception__' => true,'__struct__' => 'Elixir.ArgumentError',message => <<"ranges (first..last) expect both sides to be integers, got: 0..8.0">>},[{'Elixir.Range',new,2,[{file,"lib/range.ex"},{line,59}]},{'Elixir.RailwayUiWeb.PublishedMessageView','index.html',1,[{file,"lib/railway_ui_web/templates/published_message/index.html.leex"},{line,53}]},{'Elixir.Phoenix.LiveView.Utils',to_rendered,2,[{file,"l..."},...]},...]},...},...]},...}}
2019-11-30 09:12:36.117 [error] <0.1574.0> CRASH REPORT Process <0.1574.0> with 0 neighbours exited with reason: {{#{'__exception__' => true,'__struct__' => 'Elixir.ArgumentError',message => <<"ranges (first..last) expect both sides to be integers, got: 0..8.0">>},[{'Elixir.Range',new,2,[{file,"lib/range.ex"},{line,59}]},{'Elixir.RailwayUiWeb.PublishedMessageView','index.html',1,[{file,"lib/railway_ui_web/templates/published_message/index.html.leex"},{line,53}]},{'Elixir.Phoenix.LiveView.Utils',to_rendered,2,[{file,"lib/phoenix_live_view/utils.ex"},{line,70}]},{'Elixir.Phoenix.LiveView.Static',to_rendered_content_tag,...},...]},...} in 'Elixir.Phoenix.Endpoint.Cowboy2Handler':init/4 line 59 in 'Elixir.Phoenix.Endpoint.Cowboy2Handler':init/4 line 59
2019-11-30 09:12:36.134 [error] <0.378.0> Lager event handler error_logger_lager_h exited with reason {'EXIT',{{case_clause,['Elixir.RailwayUiWeb.Endpoint.HTTP',<0.1572.0>,1,<0.1574.0>,{{#{'__exception__' => true,'__struct__' => 'Elixir.ArgumentError',message => <<"ranges (first..last) expect both sides to be integers, got: 0..8.0">>},[{'Elixir.Range',new,2,[{file,"lib/range.ex"},{line,59}]},{'Elixir.RailwayUiWeb.PublishedMessageView','index.html',1,[{file,"lib/railway_ui_web/templates/published_message/index.html.leex"},{line,53}]},{'Elixir.Phoenix.LiveView.Utils',to_rendered,2,[{file,"l..."},...]},...]},...},...]},...}}
2019-11-30 09:13:15.388 [error] <0.1596.0> CRASH REPORT Process <0.1596.0> with 0 neighbours exited with reason: {{#{'__exception__' => true,'__struct__' => 'Elixir.Postgrex.Error',connection_id => 16494,message => nil,postgres => #{code => ambiguous_function,file => <<"parse_oper.c">>,hint => <<"Could not choose a best candidate operator. You might need to add explicit type casts.">>,line => <<"720">>,message => <<"operator is not unique: unknown * unknown">>,pg_code => <<"42725">>,position => <<"234">>,routine => <<"op_error">>,severity => <<"ERROR">>,unknown => <<"ERROR">>},query => <<"SELECT r0.\"u...">>},...},...} in 'Elixir.Phoenix.Endpoint.Cowboy2Handler':init/4 line 59 in 'Elixir.Phoenix.Endpoint.Cowboy2Handler':init/4 line 59
2019-11-30 09:13:15.395 [error] <0.378.0> Lager event handler error_logger_lager_h exited with reason {'EXIT',{{case_clause,['Elixir.RailwayUiWeb.Endpoint.HTTP',<0.1594.0>,1,<0.1596.0>,{{#{'__exception__' => true,'__struct__' => 'Elixir.Postgrex.Error',connection_id => 16494,message => nil,postgres => #{code => ambiguous_function,file => <<"parse_oper.c">>,hint => <<"Could not choose a best candidate operator. You might need to add explicit type casts.">>,line => <<"720">>,message => <<"operator is not unique: unknown * unknown">>,pg_code => <<"42725">>,position => <<"234">>,routine => <<"...">>,...},...},...},...},...]},...}}
2019-11-30 09:13:29.128 [error] <0.1629.0> CRASH REPORT Process <0.1629.0> with 0 neighbours exited with reason: {{#{'__exception__' => true,'__struct__' => 'Elixir.FunctionClauseError',args => nil,arity => 1,clauses => nil,function => get_published_messages,kind => nil,module => 'Elixir.RailwayUi.Persistence'},[{'Elixir.RailwayUi.Persistence',get_published_messages,[<<"4">>],[{file,"lib/railway_ui/persistence.ex"},{line,19}]},{'Elixir.RailwayUiWeb.PublishedMessageLive.Index',handle_params,3,[{file,"lib/railway_ui_web/live/published_message_live/index.ex"},{line,26}]},{'Elixir.Phoenix.LiveView.Static',...},...]},...} in 'Elixir.Phoenix.Endpoint.Cowboy2Handler':init/4 line 59 in 'Elixir.Phoenix.Endpoint.Cowboy2Handler':init/4 line 59
2019-11-30 09:13:29.136 [error] <0.378.0> Lager event handler error_logger_lager_h exited with reason {'EXIT',{{case_clause,['Elixir.RailwayUiWeb.Endpoint.HTTP',<0.1627.0>,1,<0.1629.0>,{{#{'__exception__' => true,'__struct__' => 'Elixir.FunctionClauseError',args => nil,arity => 1,clauses => nil,function => get_published_messages,kind => nil,module => 'Elixir.RailwayUi.Persistence'},[{'Elixir.RailwayUi.Persistence',get_published_messages,[<<"4">>],[{file,"lib/railway_ui/persistence.ex"},{line,19}]},{'Elixir.RailwayUiWeb.PublishedMessageLive.Index',handle_params,3,[{file,"lib/railway_ui_web..."},...]},...]},...},...]},...}}
2019-11-30 09:14:34.496 [error] <0.1684.0> CRASH REPORT Process <0.1684.0> with 0 neighbours exited with reason: {{#{'__exception__' => true,'__struct__' => 'Elixir.FunctionClauseError',args => nil,arity => 1,clauses => nil,function => get_published_messages,kind => nil,module => 'Elixir.RailwayUi.Persistence'},[{'Elixir.RailwayUi.Persistence',get_published_messages,[<<"4">>],[{file,"lib/railway_ui/persistence.ex"},{line,19}]},{'Elixir.RailwayUiWeb.PublishedMessageLive.Index',handle_params,3,[{file,"lib/railway_ui_web/live/published_message_live/index.ex"},{line,26}]},{'Elixir.Phoenix.LiveView.Static',...},...]},...} in 'Elixir.Phoenix.Endpoint.Cowboy2Handler':init/4 line 59 in 'Elixir.Phoenix.Endpoint.Cowboy2Handler':init/4 line 59
2019-11-30 09:14:34.505 [error] <0.378.0> Lager event handler error_logger_lager_h exited with reason {'EXIT',{{case_clause,['Elixir.RailwayUiWeb.Endpoint.HTTP',<0.1683.0>,1,<0.1684.0>,{{#{'__exception__' => true,'__struct__' => 'Elixir.FunctionClauseError',args => nil,arity => 1,clauses => nil,function => get_published_messages,kind => nil,module => 'Elixir.RailwayUi.Persistence'},[{'Elixir.RailwayUi.Persistence',get_published_messages,[<<"4">>],[{file,"lib/railway_ui/persistence.ex"},{line,19}]},{'Elixir.RailwayUiWeb.PublishedMessageLive.Index',handle_params,3,[{file,"lib/railway_ui_web..."},...]},...]},...},...]},...}}
2019-11-30 09:15:07.300 [error] <0.1718.0> CRASH REPORT Process <0.1718.0> with 0 neighbours exited with reason: {{#{'__exception__' => true,'__struct__' => 'Elixir.ArithmeticError',message => <<"bad argument in arithmetic expression">>},[{erlang,'*',[2,<<"4">>],[]},{'Elixir.RailwayUi.Persistence',get_published_messages,1,[{file,"lib/railway_ui/persistence.ex"},{line,20}]},{'Elixir.RailwayUiWeb.PublishedMessageLive.Index',handle_params,3,[{file,"lib/railway_ui_web/live/published_message_live/index.ex"},{line,26}]},{'Elixir.Phoenix.LiveView.Static','call_mount_and_handle_params!',6,[{file,"lib/phoenix..."},...]},...]},...} in 'Elixir.Phoenix.Endpoint.Cowboy2Handler':init/4 line 59 in 'Elixir.Phoenix.Endpoint.Cowboy2Handler':init/4 line 59
2019-11-30 09:15:07.323 [error] <0.378.0> Lager event handler error_logger_lager_h exited with reason {'EXIT',{{case_clause,['Elixir.RailwayUiWeb.Endpoint.HTTP',<0.1716.0>,1,<0.1718.0>,{{#{'__exception__' => true,'__struct__' => 'Elixir.ArithmeticError',message => <<"bad argument in arithmetic expression">>},[{erlang,'*',[2,<<"4">>],[]},{'Elixir.RailwayUi.Persistence',get_published_messages,1,[{file,"lib/railway_ui/persistence.ex"},{line,20}]},{'Elixir.RailwayUiWeb.PublishedMessageLive.Index',handle_params,3,[{file,"lib/railway_ui_web/live/published_message_live/index.ex"},{line,26}]},{'Elixir.Phoenix.LiveView.Static',...},...]},...},...]},...}}
2019-11-30 09:15:28.347 [error] <0.1751.0> CRASH REPORT Process <0.1751.0> with 0 neighbours exited with reason: {{#{'__exception__' => true,'__struct__' => 'Elixir.ArgumentError',message => <<"argument error">>},[{erlang,binary_to_integer,[1],[]},{'Elixir.RailwayUi.Persistence',get_published_messages,1,[{file,"lib/railway_ui/persistence.ex"},{line,20}]},{'Elixir.RailwayUiWeb.PublishedMessageLive.Index',mount,2,[{file,"lib/railway_ui_web/live/published_message_live/index.ex"},{line,14}]},{'Elixir.Phoenix.LiveView.Utils','maybe_call_mount!',3,[{file,"lib/phoenix_live_view/utils.ex"},{line,170}]},{'Elixir.Phoenix.LiveView.Static',...},...]},...} in 'Elixir.Phoenix.Endpoint.Cowboy2Handler':init/4 line 59 in 'Elixir.Phoenix.Endpoint.Cowboy2Handler':init/4 line 59
2019-11-30 09:15:28.353 [error] <0.378.0> Lager event handler error_logger_lager_h exited with reason {'EXIT',{{case_clause,['Elixir.RailwayUiWeb.Endpoint.HTTP',<0.1750.0>,1,<0.1751.0>,{{#{'__exception__' => true,'__struct__' => 'Elixir.ArgumentError',message => <<"argument error">>},[{erlang,binary_to_integer,[1],[]},{'Elixir.RailwayUi.Persistence',get_published_messages,1,[{file,"lib/railway_ui/persistence.ex"},{line,20}]},{'Elixir.RailwayUiWeb.PublishedMessageLive.Index',mount,2,[{file,"lib/railway_ui_web/live/published_message_live/index.ex"},{line,14}]},{'Elixir.Phoenix.LiveView.Utils',...},...]},...},...]},...}}
2019-11-30 09:15:46.988 [error] <0.1784.0> CRASH REPORT Process <0.1784.0> with 0 neighbours exited with reason: {{#{'__exception__' => true,'__struct__' => 'Elixir.ArgumentError',message => <<"argument error">>},[{erlang,binary_to_integer,[1],[]},{'Elixir.RailwayUi.Persistence',get_published_messages,1,[{file,"lib/railway_ui/persistence.ex"},{line,22}]},{'Elixir.RailwayUiWeb.PublishedMessageLive.Index',mount,2,[{file,"lib/railway_ui_web/live/published_message_live/index.ex"},{line,14}]},{'Elixir.Phoenix.LiveView.Utils','maybe_call_mount!',3,[{file,"lib/phoenix_live_view/utils.ex"},{line,170}]},{'Elixir.Phoenix.LiveView.Static',...},...]},...} in 'Elixir.Phoenix.Endpoint.Cowboy2Handler':init/4 line 59 in 'Elixir.Phoenix.Endpoint.Cowboy2Handler':init/4 line 59
2019-11-30 09:15:46.994 [error] <0.378.0> Lager event handler error_logger_lager_h exited with reason {'EXIT',{{case_clause,['Elixir.RailwayUiWeb.Endpoint.HTTP',<0.1782.0>,1,<0.1784.0>,{{#{'__exception__' => true,'__struct__' => 'Elixir.ArgumentError',message => <<"argument error">>},[{erlang,binary_to_integer,[1],[]},{'Elixir.RailwayUi.Persistence',get_published_messages,1,[{file,"lib/railway_ui/persistence.ex"},{line,22}]},{'Elixir.RailwayUiWeb.PublishedMessageLive.Index',mount,2,[{file,"lib/railway_ui_web/live/published_message_live/index.ex"},{line,14}]},{'Elixir.Phoenix.LiveView.Utils',...},...]},...},...]},...}}
2019-11-30 09:15:54.319 [error] <0.1822.0> CRASH REPORT Process <0.1822.0> with 0 neighbours exited with reason: {{#{'__exception__' => true,'__struct__' => 'Elixir.ArgumentError',message => <<"ranges (first..last) expect both sides to be integers, got: 0..8.0">>},[{'Elixir.Range',new,2,[{file,"lib/range.ex"},{line,59}]},{'Elixir.RailwayUiWeb.PublishedMessageView','index.html',1,[{file,"lib/railway_ui_web/templates/published_message/index.html.leex"},{line,53}]},{'Elixir.Phoenix.LiveView.Utils',to_rendered,2,[{file,"lib/phoenix_live_view/utils.ex"},{line,70}]},{'Elixir.Phoenix.LiveView.Static',to_rendered_content_tag,...},...]},...} in 'Elixir.Phoenix.Endpoint.Cowboy2Handler':init/4 line 59 in 'Elixir.Phoenix.Endpoint.Cowboy2Handler':init/4 line 59
2019-11-30 09:15:54.324 [error] <0.378.0> Lager event handler error_logger_lager_h exited with reason {'EXIT',{{case_clause,['Elixir.RailwayUiWeb.Endpoint.HTTP',<0.1820.0>,1,<0.1822.0>,{{#{'__exception__' => true,'__struct__' => 'Elixir.ArgumentError',message => <<"ranges (first..last) expect both sides to be integers, got: 0..8.0">>},[{'Elixir.Range',new,2,[{file,"lib/range.ex"},{line,59}]},{'Elixir.RailwayUiWeb.PublishedMessageView','index.html',1,[{file,"lib/railway_ui_web/templates/published_message/index.html.leex"},{line,53}]},{'Elixir.Phoenix.LiveView.Utils',to_rendered,2,[{file,"l..."},...]},...]},...},...]},...}}
2019-11-30 09:23:10.760 [error] <0.500.0> Supervisor {<0.500.0>,'Elixir.Phoenix.Socket.PoolSupervisor.WorkerSupervisor'} had child 'Elixir.Phoenix.Channel.Server' started with {'Elixir.Phoenix.Channel.Server',start_link,undefined} at <0.2101.0> exit with reason killed in context child_terminated
2019-11-30 09:23:35.193 [error] <0.2312.0> CRASH REPORT Process <0.2312.0> with 0 neighbours exited with reason: {{#{'__exception__' => true,'__struct__' => 'Elixir.ArithmeticError',message => <<"bad argument in arithmetic expression">>},[{'Elixir.RailwayUiWeb.PublishedMessageView','index.html',1,[{file,"lib/railway_ui_web/templates/published_message/index.html.leex"},{line,51}]},{'Elixir.Phoenix.LiveView.Utils',to_rendered,2,[{file,"lib/phoenix_live_view/utils.ex"},{line,70}]},{'Elixir.Phoenix.LiveView.Static',to_rendered_content_tag,4,[{file,"lib/phoenix_live_view/static.ex"},{line,213}]},{'Elixir.Phoenix.LiveView.Static',...},...]},...} in 'Elixir.Phoenix.Endpoint.Cowboy2Handler':init/4 line 59 in 'Elixir.Phoenix.Endpoint.Cowboy2Handler':init/4 line 59
2019-11-30 09:23:35.197 [error] <0.378.0> Lager event handler error_logger_lager_h exited with reason {'EXIT',{{case_clause,['Elixir.RailwayUiWeb.Endpoint.HTTP',<0.2310.0>,1,<0.2312.0>,{{#{'__exception__' => true,'__struct__' => 'Elixir.ArithmeticError',message => <<"bad argument in arithmetic expression">>},[{'Elixir.RailwayUiWeb.PublishedMessageView','index.html',1,[{file,"lib/railway_ui_web/templates/published_message/index.html.leex"},{line,51}]},{'Elixir.Phoenix.LiveView.Utils',to_rendered,2,[{file,"lib/phoenix_live_view/utils.ex"},{line,70}]},{'Elixir.Phoenix.LiveView.Static',to_rendered_content_tag,...},...]},...},...]},...}}
2019-11-30 09:38:27.719 [error] <0.3115.0> gen_server <0.3115.0> terminated with reason: {#{'__exception__' => true,'__struct__' => 'Elixir.FunctionClauseError',args => nil,arity => 1,clauses => nil,function => get_published_messages,kind => nil,module => 'Elixir.RailwayUi.Persistence'},[{'Elixir.RailwayUi.Persistence',get_published_messages,[2],[{file,"lib/railway_ui/persistence.ex"},{line,12}]},{'Elixir.RailwayUiWeb.PublishedMessageLive.Index',mount,2,[{file,"lib/railway_ui_web/live/published_message_live/index.ex"},{line,14}]},{'Elixir.Phoenix.LiveView.Utils','maybe_call_mount!',...},...]}
2019-11-30 09:38:27.720 [error] <0.3115.0> CRASH REPORT Process <0.3115.0> with 0 neighbours crashed with reason: {#{'__exception__' => true,'__struct__' => 'Elixir.FunctionClauseError',args => nil,arity => 1,clauses => nil,function => get_published_messages,kind => nil,module => 'Elixir.RailwayUi.Persistence'},[{'Elixir.RailwayUi.Persistence',get_published_messages,[2],[{file,"lib/railway_ui/persistence.ex"},{line,12}]},{'Elixir.RailwayUiWeb.PublishedMessageLive.Index',mount,2,[{file,"lib/railway_ui_web/live/published_message_live/index.ex"},{line,14}]},{'Elixir.Phoenix.LiveView.Utils','maybe_call_mount!',...},...]}
2019-11-30 09:38:27.720 [error] <0.502.0> Supervisor {<0.502.0>,'Elixir.Phoenix.Socket.PoolSupervisor.WorkerSupervisor'} had child 'Elixir.Phoenix.Channel.Server' started with {'Elixir.Phoenix.Channel.Server',start_link,undefined} at <0.3115.0> exit with reason {#{'__exception__' => true,'__struct__' => 'Elixir.FunctionClauseError',args => nil,arity => 1,clauses => nil,function => get_published_messages,kind => nil,module => 'Elixir.RailwayUi.Persistence'},[{'Elixir.RailwayUi.Persistence',get_published_messages,[2],[{file,"lib/railway_ui/persistence.ex"},{line,12}]},{'Elixir.RailwayUiWeb.PublishedMessageLive.Index',mount,2,[{file,"lib/railway_ui_web/live/published_message_live/index.ex"},{line,14}]},{'Elixir.Phoenix.LiveView.Utils','maybe_call_mount!',...},...]} in context child_terminated
2019-11-30 09:38:27.816 [error] <0.3092.0> CRASH REPORT Process <0.3092.0> with 0 neighbours exited with reason: {{#{'__exception__' => true,'__struct__' => 'Elixir.FunctionClauseError',args => nil,arity => 1,clauses => nil,function => get_published_messages,kind => nil,module => 'Elixir.RailwayUi.Persistence'},[{'Elixir.RailwayUi.Persistence',get_published_messages,[2],[{file,"lib/railway_ui/persistence.ex"},{line,12}]},{'Elixir.RailwayUiWeb.PublishedMessageLive.Index',mount,2,[{file,"lib/railway_ui_web/live/published_message_live/index.ex"},{line,14}]},{'Elixir.Phoenix.LiveView.Utils','maybe_call_mount!',...},...]},...} in 'Elixir.Phoenix.Endpoint.Cowboy2Handler':init/4 line 59 in 'Elixir.Phoenix.Endpoint.Cowboy2Handler':init/4 line 59
2019-11-30 09:38:27.828 [error] <0.378.0> Lager event handler error_logger_lager_h exited with reason {'EXIT',{{case_clause,['Elixir.RailwayUiWeb.Endpoint.HTTP',<0.3090.0>,1,<0.3092.0>,{{#{'__exception__' => true,'__struct__' => 'Elixir.FunctionClauseError',args => nil,arity => 1,clauses => nil,function => get_published_messages,kind => nil,module => 'Elixir.RailwayUi.Persistence'},[{'Elixir.RailwayUi.Persistence',get_published_messages,[2],[{file,"lib/railway_ui/persistence.ex"},{line,12}]},{'Elixir.RailwayUiWeb.PublishedMessageLive.Index',mount,2,[{file,"lib/railway_ui_web/live/publishe..."},...]},...]},...},...]},...}}
2019-11-30 09:39:13.536 [error] <0.3178.0> gen_server <0.3178.0> terminated with reason: {#{'__exception__' => true,'__struct__' => 'Elixir.ArgumentError',message => <<"argument error">>},[{erlang,apply,[15,count,[]],[]},{'Elixir.RailwayUi.PublishedMessage',page_nums,0,[{file,"lib/railway_ui/published_message.ex"},{line,12}]},{'Elixir.RailwayUiWeb.PublishedMessageLive.Index.Data',new,1,[{file,"lib/railway_ui_web/live/published_message_live/index/data.ex"},{line,10}]},{'Elixir.RailwayUiWeb.PublishedMessageLive.Index',mount,2,[{file,"lib/railway_ui_web/live/published_message_live..."},...]},...]}
2019-11-30 09:39:13.537 [error] <0.3178.0> CRASH REPORT Process <0.3178.0> with 0 neighbours crashed with reason: {#{'__exception__' => true,'__struct__' => 'Elixir.ArgumentError',message => <<"argument error">>},[{erlang,apply,[15,count,[]],[]},{'Elixir.RailwayUi.PublishedMessage',page_nums,0,[{file,"lib/railway_ui/published_message.ex"},{line,12}]},{'Elixir.RailwayUiWeb.PublishedMessageLive.Index.Data',new,1,[{file,"lib/railway_ui_web/live/published_message_live/index/data.ex"},{line,10}]},{'Elixir.RailwayUiWeb.PublishedMessageLive.Index',mount,2,[{file,"lib/railway_ui_web/live/published_message_live..."},...]},...]}
2019-11-30 09:39:13.538 [error] <0.500.0> Supervisor {<0.500.0>,'Elixir.Phoenix.Socket.PoolSupervisor.WorkerSupervisor'} had child 'Elixir.Phoenix.Channel.Server' started with {'Elixir.Phoenix.Channel.Server',start_link,undefined} at <0.3178.0> exit with reason {#{'__exception__' => true,'__struct__' => 'Elixir.ArgumentError',message => <<"argument error">>},[{erlang,apply,[15,count,[]],[]},{'Elixir.RailwayUi.PublishedMessage',page_nums,0,[{file,"lib/railway_ui/published_message.ex"},{line,12}]},{'Elixir.RailwayUiWeb.PublishedMessageLive.Index.Data',new,1,[{file,"lib/railway_ui_web/live/published_message_live/index/data.ex"},{line,10}]},{'Elixir.RailwayUiWeb.PublishedMessageLive.Index',mount,2,[{file,"lib/railway_ui_web/live/published_message_live..."},...]},...]} in context child_terminated
2019-11-30 09:39:13.605 [error] <0.3165.0> CRASH REPORT Process <0.3165.0> with 0 neighbours exited with reason: {{#{'__exception__' => true,'__struct__' => 'Elixir.ArgumentError',message => <<"argument error">>},[{erlang,apply,[15,count,[]],[]},{'Elixir.RailwayUi.PublishedMessage',page_nums,0,[{file,"lib/railway_ui/published_message.ex"},{line,12}]},{'Elixir.RailwayUiWeb.PublishedMessageLive.Index.Data',new,1,[{file,"lib/railway_ui_web/live/published_message_live/index/data.ex"},{line,10}]},{'Elixir.RailwayUiWeb.PublishedMessageLive.Index',mount,2,[{file,"lib/railway_ui_web/live/published_message_li..."},...]},...]},...} in 'Elixir.Phoenix.Endpoint.Cowboy2Handler':init/4 line 59 in 'Elixir.Phoenix.Endpoint.Cowboy2Handler':init/4 line 59
2019-11-30 09:39:13.613 [error] <0.378.0> Lager event handler error_logger_lager_h exited with reason {'EXIT',{{case_clause,['Elixir.RailwayUiWeb.Endpoint.HTTP',<0.3163.0>,1,<0.3165.0>,{{#{'__exception__' => true,'__struct__' => 'Elixir.ArgumentError',message => <<"argument error">>},[{erlang,apply,[15,count,[]],[]},{'Elixir.RailwayUi.PublishedMessage',page_nums,0,[{file,"lib/railway_ui/published_message.ex"},{line,12}]},{'Elixir.RailwayUiWeb.PublishedMessageLive.Index.Data',new,1,[{file,"lib/railway_ui_web/live/published_message_live/index/data.ex"},{line,10}]},{'Elixir.RailwayUiWeb.PublishedMessageLive.Index',...},...]},...},...]},...}}
2019-11-30 09:54:40.854 [error] <0.628.0> gen_server <0.628.0> terminated with reason: #{'__exception__' => true,'__struct__' => 'Elixir.ArgumentError',message => <<"assign @uuid not available in eex template.\n\nPlease make sure all proper assigns have been set. If this\nis a child template, ensure assigns are given explicitly by\nthe parent template as they are not automatically forwarded.\n\nAvailable assigns: [:data, :messages, :socket, :view_module, :view_template]\n">>} in 'Elixir.Phoenix.LiveView.Engine':'fetch_assign!'/2 line 769
2019-11-30 09:54:40.877 [error] <0.628.0> CRASH REPORT Process <0.628.0> with 0 neighbours crashed with reason: #{'__exception__' => true,'__struct__' => 'Elixir.ArgumentError',message => <<"assign @uuid not available in eex template.\n\nPlease make sure all proper assigns have been set. If this\nis a child template, ensure assigns are given explicitly by\nthe parent template as they are not automatically forwarded.\n\nAvailable assigns: [:data, :messages, :socket, :view_module, :view_template]\n">>} in 'Elixir.Phoenix.LiveView.Engine':'fetch_assign!'/2 line 769
2019-11-30 09:54:40.878 [error] <0.510.0> Supervisor {<0.510.0>,'Elixir.Phoenix.Socket.PoolSupervisor.WorkerSupervisor'} had child 'Elixir.Phoenix.Channel.Server' started with {'Elixir.Phoenix.Channel.Server',start_link,undefined} at <0.628.0> exit with reason #{'__exception__' => true,'__struct__' => 'Elixir.ArgumentError',message => <<"assign @uuid not available in eex template.\n\nPlease make sure all proper assigns have been set. If this\nis a child template, ensure assigns are given explicitly by\nthe parent template as they are not automatically forwarded.\n\nAvailable assigns: [:data, :messages, :socket, :view_module, :view_template]\n">>} in 'Elixir.Phoenix.LiveView.Engine':'fetch_assign!'/2 line 769 in context child_terminated
2019-11-30 09:54:42.950 [error] <0.633.0> gen_server <0.633.0> terminated with reason: #{'__exception__' => true,'__struct__' => 'Elixir.ArgumentError',message => <<"assign @uuid not available in eex template.\n\nPlease make sure all proper assigns have been set. If this\nis a child template, ensure assigns are given explicitly by\nthe parent template as they are not automatically forwarded.\n\nAvailable assigns: [:data, :messages, :socket, :view_module, :view_template]\n">>} in 'Elixir.Phoenix.LiveView.Engine':'fetch_assign!'/2 line 769
2019-11-30 09:54:42.951 [error] <0.633.0> CRASH REPORT Process <0.633.0> with 0 neighbours crashed with reason: #{'__exception__' => true,'__struct__' => 'Elixir.ArgumentError',message => <<"assign @uuid not available in eex template.\n\nPlease make sure all proper assigns have been set. If this\nis a child template, ensure assigns are given explicitly by\nthe parent template as they are not automatically forwarded.\n\nAvailable assigns: [:data, :messages, :socket, :view_module, :view_template]\n">>} in 'Elixir.Phoenix.LiveView.Engine':'fetch_assign!'/2 line 769
2019-11-30 09:54:42.951 [error] <0.511.0> Supervisor {<0.511.0>,'Elixir.Phoenix.Socket.PoolSupervisor.WorkerSupervisor'} had child 'Elixir.Phoenix.Channel.Server' started with {'Elixir.Phoenix.Channel.Server',start_link,undefined} at <0.633.0> exit with reason #{'__exception__' => true,'__struct__' => 'Elixir.ArgumentError',message => <<"assign @uuid not available in eex template.\n\nPlease make sure all proper assigns have been set. If this\nis a child template, ensure assigns are given explicitly by\nthe parent template as they are not automatically forwarded.\n\nAvailable assigns: [:data, :messages, :socket, :view_module, :view_template]\n">>} in 'Elixir.Phoenix.LiveView.Engine':'fetch_assign!'/2 line 769 in context child_terminated
2019-11-30 09:54:45.505 [error] <0.634.0> gen_server <0.634.0> terminated with reason: #{'__exception__' => true,'__struct__' => 'Elixir.ArgumentError',message => <<"assign @uuid not available in eex template.\n\nPlease make sure all proper assigns have been set. If this\nis a child template, ensure assigns are given explicitly by\nthe parent template as they are not automatically forwarded.\n\nAvailable assigns: [:data, :messages, :socket, :view_module, :view_template]\n">>} in 'Elixir.Phoenix.LiveView.Engine':'fetch_assign!'/2 line 769
2019-11-30 09:54:45.506 [error] <0.634.0> CRASH REPORT Process <0.634.0> with 0 neighbours crashed with reason: #{'__exception__' => true,'__struct__' => 'Elixir.ArgumentError',message => <<"assign @uuid not available in eex template.\n\nPlease make sure all proper assigns have been set. If this\nis a child template, ensure assigns are given explicitly by\nthe parent template as they are not automatically forwarded.\n\nAvailable assigns: [:data, :messages, :socket, :view_module, :view_template]\n">>} in 'Elixir.Phoenix.LiveView.Engine':'fetch_assign!'/2 line 769
2019-11-30 09:54:45.506 [error] <0.512.0> Supervisor {<0.512.0>,'Elixir.Phoenix.Socket.PoolSupervisor.WorkerSupervisor'} had child 'Elixir.Phoenix.Channel.Server' started with {'Elixir.Phoenix.Channel.Server',start_link,undefined} at <0.634.0> exit with reason #{'__exception__' => true,'__struct__' => 'Elixir.ArgumentError',message => <<"assign @uuid not available in eex template.\n\nPlease make sure all proper assigns have been set. If this\nis a child template, ensure assigns are given explicitly by\nthe parent template as they are not automatically forwarded.\n\nAvailable assigns: [:data, :messages, :socket, :view_module, :view_template]\n">>} in 'Elixir.Phoenix.LiveView.Engine':'fetch_assign!'/2 line 769 in context child_terminated
2019-11-30 09:54:47.087 [error] <0.638.0> CRASH REPORT Process <0.638.0> with 0 neighbours exited with reason: {{#{'__exception__' => true,'__struct__' => 'Elixir.ArgumentError',message => <<"assign @uuid not available in eex template.\n\nPlease make sure all proper assigns have been set. If this\nis a child template, ensure assigns are given explicitly by\nthe parent template as they are not automatically forwarded.\n\nAvailable assigns: [:data, :messages, :socket, :view_module, :view_template]\n">>},[{'Elixir.Phoenix.LiveView.Engine','fetch_assign!',2,[{file,"lib/phoenix_live_view/engine.ex"},{line,769}]},...]},...} in 'Elixir.Phoenix.Endpoint.Cowboy2Handler':init/4 line 59 in 'Elixir.Phoenix.Endpoint.Cowboy2Handler':init/4 line 59
2019-11-30 09:54:47.209 [error] <0.388.0> Lager event handler error_logger_lager_h exited with reason {'EXIT',{{case_clause,['Elixir.RailwayUiWeb.Endpoint.HTTP',<0.637.0>,1,<0.638.0>,{{#{'__exception__' => true,'__struct__' => 'Elixir.ArgumentError',message => <<"assign @uuid not available in eex template.\n\nPlease make sure all proper assigns have been set. If this\nis a child template, ensure assigns are given explicitly by\nthe parent template as they are not automatically forwarded.\n\nAvailable assigns: [:data, :messages, :socket, :view_module, :view_template]\n">>},[{'Elixir.Phoenix.LiveView.Engine',...},...]},...},...]},...}}
2019-11-30 10:07:26.869 [error] <0.480.0> gen_server <0.480.0> terminated with reason: {socket_error,timeout}
2019-11-30 10:07:26.869 [error] <0.480.0> CRASH REPORT Process <0.480.0> with 0 neighbours exited with reason: {socket_error,timeout} in gen_server:handle_common_reply/8 line 751
2019-11-30 10:07:26.869 [error] <0.446.0> gen_server <0.446.0> terminated with reason: {socket_error,timeout}
2019-11-30 10:07:26.870 [error] <0.446.0> CRASH REPORT Process <0.446.0> with 0 neighbours exited with reason: {socket_error,timeout} in gen_server:handle_common_reply/8 line 751
2019-11-30 10:07:26.870 [error] <0.434.0> Supervisor {<0.434.0>,amqp_connection_type_sup} had child main_reader started with amqp_main_reader:start_link(#Port<0.64>, <0.446.0>, <0.467.0>, {method,rabbit_framing_amqp_0_9_1}, <<"client 127.0.0.1:64476 -> 127.0.0.1:5672">>) at <0.480.0> exit with reason {socket_error,timeout} in context child_terminated
2019-11-30 10:07:26.870 [error] <0.434.0> Supervisor {<0.434.0>,amqp_connection_type_sup} had child main_reader started with amqp_main_reader:start_link(#Port<0.64>, <0.446.0>, <0.467.0>, {method,rabbit_framing_amqp_0_9_1}, <<"client 127.0.0.1:64476 -> 127.0.0.1:5672">>) at <0.480.0> exit with reason reached_max_restart_intensity in context shutdown
2019-11-30 10:07:26.871 [error] <0.432.0> Supervisor {<0.432.0>,amqp_connection_sup} had child connection started with amqp_gen_connection:start_link(<0.434.0>, {amqp_params_network,<<"guest">>,<<"guest">>,<<"/">>,"localhost",5672,2047,0,10,60000,none,[#Fun<am..>,...],...}) at <0.446.0> exit with reason {socket_error,timeout} in context child_terminated
2019-11-30 10:07:26.871 [error] <0.432.0> Supervisor {<0.432.0>,amqp_connection_sup} had child connection started with amqp_gen_connection:start_link(<0.434.0>, {amqp_params_network,<<"guest">>,<<"guest">>,<<"/">>,"localhost",5672,2047,0,10,60000,none,[#Fun<am..>,...],...}) at <0.446.0> exit with reason reached_max_restart_intensity in context shutdown
2019-11-30 10:07:26.872 [error] <0.424.0>@gen_server:call gen_server 'Elixir.RailwayIpc.Connection' terminated with reason: no such process or port in call to gen_server:call(<0.446.0>, {command,{close,{'connection.close',200,<<"Goodbye">>,0,0},60000}}, 60000) in gen_server:call/3 line 223
2019-11-30 10:07:26.872 [error] <0.424.0>@gen_server:call CRASH REPORT Process 'Elixir.RailwayIpc.Connection' with 0 neighbours exited with reason: no such process or port in call to gen_server:call(<0.446.0>, {command,{close,{'connection.close',200,<<"Goodbye">>,0,0},60000}}, 60000) in gen_server:call/3 line 223
2019-11-30 10:07:26.873 [error] <0.423.0>@gen_server:call Supervisor 'Elixir.RailwayIpc.Connection.Supervisor' had child 'Elixir.RailwayIpc.Connection' started with 'Elixir.RailwayIpc.Connection':start_link([{name,'Elixir.RailwayIpc.Connection'}]) at <0.424.0> exit with reason no such process or port in call to gen_server:call(<0.446.0>, {command,{close,{'connection.close',200,<<"Goodbye">>,0,0},60000}}, 60000) in context child_terminated
2019-11-30 11:29:19.860 [error] <0.759.0> gen_server <0.759.0> terminated with reason: {socket_error,timeout}
2019-11-30 11:29:19.860 [error] <0.759.0> CRASH REPORT Process <0.759.0> with 0 neighbours exited with reason: {socket_error,timeout} in gen_server:handle_common_reply/8 line 751
2019-11-30 11:29:19.860 [error] <0.755.0> gen_server <0.755.0> terminated with reason: {socket_error,timeout}
2019-11-30 11:29:19.861 [error] <0.754.0> Supervisor {<0.754.0>,amqp_connection_type_sup} had child main_reader started with amqp_main_reader:start_link(#Port<0.101>, <0.755.0>, <0.757.0>, {method,rabbit_framing_amqp_0_9_1}, <<"client 127.0.0.1:64601 -> 127.0.0.1:5672">>) at <0.759.0> exit with reason {socket_error,timeout} in context child_terminated
2019-11-30 11:29:19.861 [error] <0.754.0> Supervisor {<0.754.0>,amqp_connection_type_sup} had child main_reader started with amqp_main_reader:start_link(#Port<0.101>, <0.755.0>, <0.757.0>, {method,rabbit_framing_amqp_0_9_1}, <<"client 127.0.0.1:64601 -> 127.0.0.1:5672">>) at <0.759.0> exit with reason reached_max_restart_intensity in context shutdown
2019-11-30 11:29:19.861 [error] <0.755.0> CRASH REPORT Process <0.755.0> with 0 neighbours exited with reason: {socket_error,timeout} in gen_server:handle_common_reply/8 line 751
2019-11-30 11:29:19.862 [error] <0.750.0>@gen_server:call gen_server 'Elixir.RailwayIpc.Connection' terminated with reason: no such process or port in call to gen_server:call(<0.755.0>, {command,{close,{'connection.close',200,<<"Goodbye">>,0,0},60000}}, 60000) in gen_server:call/3 line 223
2019-11-30 11:29:19.863 [error] <0.750.0>@gen_server:call CRASH REPORT Process 'Elixir.RailwayIpc.Connection' with 0 neighbours exited with reason: no such process or port in call to gen_server:call(<0.755.0>, {command,{close,{'connection.close',200,<<"Goodbye">>,0,0},60000}}, 60000) in gen_server:call/3 line 223
2019-11-30 11:29:19.873 [error] <0.753.0> Supervisor {<0.753.0>,amqp_connection_sup} had child connection started with amqp_gen_connection:start_link(<0.754.0>, {amqp_params_network,<<"guest">>,<<"guest">>,<<"/">>,"localhost",5672,2047,0,10,60000,none,[#Fun<am..>,...],...}) at <0.755.0> exit with reason {socket_error,timeout} in context child_terminated
2019-11-30 11:29:19.873 [error] <0.753.0> Supervisor {<0.753.0>,amqp_connection_sup} had child connection started with amqp_gen_connection:start_link(<0.754.0>, {amqp_params_network,<<"guest">>,<<"guest">>,<<"/">>,"localhost",5672,2047,0,10,60000,none,[#Fun<am..>,...],...}) at <0.755.0> exit with reason reached_max_restart_intensity in context shutdown
2019-11-30 11:29:19.873 [error] <0.423.0>@gen_server:call Supervisor 'Elixir.RailwayIpc.Connection.Supervisor' had child 'Elixir.RailwayIpc.Connection' started with 'Elixir.RailwayIpc.Connection':start_link([{name,'Elixir.RailwayIpc.Connection'}]) at <0.750.0> exit with reason no such process or port in call to gen_server:call(<0.755.0>, {command,{close,{'connection.close',200,<<"Goodbye">>,0,0},60000}}, 60000) in context child_terminated
2019-11-30 11:35:14.574 [error] <0.1201.0> CRASH REPORT Process <0.1201.0> with 0 neighbours exited with reason: {{#{'__exception__' => true,'__struct__' => 'Elixir.KeyError',key => search_by,message => nil,term => #{'__struct__' => 'Elixir.RailwayUiWeb.PublishedMessageLive.Index.Data',current_user_uuid => <<"1f4c4051-fe12-41cf-a39a-49f794f6b333">>,flash => #{},page => 8,page_nums => 8}},[{'Elixir.RailwayUiWeb.PublishedMessageView','index.html',1,[{file,"lib/railway_ui_web/templates/published_message/index.html.leex"},{line,36}]},{'Elixir.Phoenix.LiveView.Utils',to_rendered,2,[{file,"lib/phoenix_live..."},...]},...]},...} in 'Elixir.Phoenix.Endpoint.Cowboy2Handler':init/4 line 59 in 'Elixir.Phoenix.Endpoint.Cowboy2Handler':init/4 line 59
2019-11-30 11:35:14.583 [error] <0.388.0> Lager event handler error_logger_lager_h exited with reason {'EXIT',{{case_clause,['Elixir.RailwayUiWeb.Endpoint.HTTP',<0.1199.0>,1,<0.1201.0>,{{#{'__exception__' => true,'__struct__' => 'Elixir.KeyError',key => search_by,message => nil,term => #{'__struct__' => 'Elixir.RailwayUiWeb.PublishedMessageLive.Index.Data',current_user_uuid => <<"1f4c4051-fe12-41cf-a39a-49f794f6b333">>,flash => #{},page => 8,page_nums => 8}},[{'Elixir.RailwayUiWeb.PublishedMessageView','index.html',1,[{file,"lib/railway_ui_web/templates/published_message/index.html.leex"},...]},...]},...},...]},...}}
2019-11-30 11:35:26.383 [error] <0.1220.0> CRASH REPORT Process <0.1220.0> with 0 neighbours exited with reason: {{#{'__exception__' => true,'__struct__' => 'Elixir.KeyError',key => search_by,message => nil,term => #{'__struct__' => 'Elixir.RailwayUiWeb.PublishedMessageLive.Index.Data',current_user_uuid => <<"1f4c4051-fe12-41cf-a39a-49f794f6b333">>,flash => #{},page => 8,page_nums => 8}},[{'Elixir.RailwayUiWeb.PublishedMessageView','index.html',1,[{file,"lib/railway_ui_web/templates/published_message/index.html.leex"},{line,36}]},{'Elixir.Phoenix.LiveView.Utils',to_rendered,2,[{file,"lib/phoenix_live..."},...]},...]},...} in 'Elixir.Phoenix.Endpoint.Cowboy2Handler':init/4 line 59 in 'Elixir.Phoenix.Endpoint.Cowboy2Handler':init/4 line 59
2019-11-30 11:35:26.387 [error] <0.388.0> Lager event handler error_logger_lager_h exited with reason {'EXIT',{{case_clause,['Elixir.RailwayUiWeb.Endpoint.HTTP',<0.1218.0>,1,<0.1220.0>,{{#{'__exception__' => true,'__struct__' => 'Elixir.KeyError',key => search_by,message => nil,term => #{'__struct__' => 'Elixir.RailwayUiWeb.PublishedMessageLive.Index.Data',current_user_uuid => <<"1f4c4051-fe12-41cf-a39a-49f794f6b333">>,flash => #{},page => 8,page_nums => 8}},[{'Elixir.RailwayUiWeb.PublishedMessageView','index.html',1,[{file,"lib/railway_ui_web/templates/published_message/index.html.leex"},...]},...]},...},...]},...}}
2019-11-30 11:50:41.068 [error] <0.1935.0> CRASH REPORT Process <0.1935.0> with 0 neighbours exited with reason: {{#{'__exception__' => true,'__struct__' => 'Elixir.KeyError',key => search_by,message => nil,term => #{'__struct__' => 'Elixir.RailwayUiWeb.PublishedMessageLive.Index.Data',current_user_uuid => <<"1f4c4051-fe12-41cf-a39a-49f794f6b333">>,flash => #{},page => 4,page_nums => 8,query_filter => nil}},[{'Elixir.RailwayUiWeb.PublishedMessageView','index.html',1,[{file,"lib/railway_ui_web/templates/published_message/index.html.leex"},{line,54}]},{'Elixir.Phoenix.LiveView.Utils',to_rendered,2,[{file,...},...]},...]},...} in 'Elixir.Phoenix.Endpoint.Cowboy2Handler':init/4 line 59 in 'Elixir.Phoenix.Endpoint.Cowboy2Handler':init/4 line 59
2019-11-30 11:50:41.076 [error] <0.388.0> Lager event handler error_logger_lager_h exited with reason {'EXIT',{{case_clause,['Elixir.RailwayUiWeb.Endpoint.HTTP',<0.1934.0>,1,<0.1935.0>,{{#{'__exception__' => true,'__struct__' => 'Elixir.KeyError',key => search_by,message => nil,term => #{'__struct__' => 'Elixir.RailwayUiWeb.PublishedMessageLive.Index.Data',current_user_uuid => <<"1f4c4051-fe12-41cf-a39a-49f794f6b333">>,flash => #{},page => 4,page_nums => 8,query_filter => nil}},[{'Elixir.RailwayUiWeb.PublishedMessageView','index.html',1,[{file,"lib/railway_ui_web/templates/published_mess..."},...]},...]},...},...]},...}}
2019-11-30 11:52:07.755 [error] <0.2057.0> gen_server <0.2057.0> terminated with reason: #{'__exception__' => true,'__struct__' => 'Elixir.ArgumentError',message => <<"invalid noreply from RailwayUiWeb.PublishedMessageLive.Index.handle_event/3 callback.\n\nExpected one of:\n\n    {:noreply, %Socket{}}\n    {:stop, %Socket{}}\n\nGot: %{__struct__: RailwayUiWeb.PublishedMessageLive.Index.Data, current_user_uuid: \"1f4c4051-fe12-41cf-a39a-49f794f6b333\", flash: %{}, page: 4, page_nums: 8, query_filter: nil, search_by: \"message_uuid\"}\n">>} in 'Elixir.Phoenix.LiveView.Channel':handle_result/3 line 263
2019-11-30 11:52:07.765 [error] <0.2057.0> CRASH REPORT Process <0.2057.0> with 0 neighbours crashed with reason: #{'__exception__' => true,'__struct__' => 'Elixir.ArgumentError',message => <<"invalid noreply from RailwayUiWeb.PublishedMessageLive.Index.handle_event/3 callback.\n\nExpected one of:\n\n    {:noreply, %Socket{}}\n    {:stop, %Socket{}}\n\nGot: %{__struct__: RailwayUiWeb.PublishedMessageLive.Index.Data, current_user_uuid: \"1f4c4051-fe12-41cf-a39a-49f794f6b333\", flash: %{}, page: 4, page_nums: 8, query_filter: nil, search_by: \"message_uuid\"}\n">>} in 'Elixir.Phoenix.LiveView.Channel':handle_result/3 line 263
2019-11-30 11:52:07.765 [error] <0.511.0> Supervisor {<0.511.0>,'Elixir.Phoenix.Socket.PoolSupervisor.WorkerSupervisor'} had child 'Elixir.Phoenix.Channel.Server' started with {'Elixir.Phoenix.Channel.Server',start_link,undefined} at <0.2057.0> exit with reason #{'__exception__' => true,'__struct__' => 'Elixir.ArgumentError',message => <<"invalid noreply from RailwayUiWeb.PublishedMessageLive.Index.handle_event/3 callback.\n\nExpected one of:\n\n    {:noreply, %Socket{}}\n    {:stop, %Socket{}}\n\nGot: %{__struct__: RailwayUiWeb.PublishedMessageLive.Index.Data, current_user_uuid: \"1f4c4051-fe12-41cf-a39a-49f794f6b333\", flash: %{}, page: 4, page_nums: 8, query_filter: nil, search_by: \"message_uuid\"}\n">>} in 'Elixir.Phoenix.LiveView.Channel':handle_result/3 line 263 in context child_terminated
2019-11-30 12:06:24.147 [error] <0.2458.0> gen_server <0.2458.0> terminated with reason: #{'__exception__' => true,'__struct__' => 'Elixir.Ecto.QueryError',message => <<"lib/railway_ui/persistence.ex:29: field `message_uuid` in `where` does not exist in schema RailwayIpc.Persistence.PublishedMessage in query:\n\nfrom p0 in RailwayIpc.Persistence.PublishedMessage,\n  where: p0.message_uuid == ^\"454d45b0-7cf9-44df-aa94-fa1153835e2a\",\n  select: p0\n">>} in 'Elixir.Enum':'-reduce/3-lists^foldl/2-0-'/3 line 1948
2019-11-30 12:06:24.148 [error] <0.2458.0> CRASH REPORT Process <0.2458.0> with 0 neighbours crashed with reason: #{'__exception__' => true,'__struct__' => 'Elixir.Ecto.QueryError',message => <<"lib/railway_ui/persistence.ex:29: field `message_uuid` in `where` does not exist in schema RailwayIpc.Persistence.PublishedMessage in query:\n\nfrom p0 in RailwayIpc.Persistence.PublishedMessage,\n  where: p0.message_uuid == ^\"454d45b0-7cf9-44df-aa94-fa1153835e2a\",\n  select: p0\n">>} in 'Elixir.Enum':'-reduce/3-lists^foldl/2-0-'/3 line 1948
2019-11-30 12:06:24.148 [error] <0.510.0> Supervisor {<0.510.0>,'Elixir.Phoenix.Socket.PoolSupervisor.WorkerSupervisor'} had child 'Elixir.Phoenix.Channel.Server' started with {'Elixir.Phoenix.Channel.Server',start_link,undefined} at <0.2458.0> exit with reason #{'__exception__' => true,'__struct__' => 'Elixir.Ecto.QueryError',message => <<"lib/railway_ui/persistence.ex:29: field `message_uuid` in `where` does not exist in schema RailwayIpc.Persistence.PublishedMessage in query:\n\nfrom p0 in RailwayIpc.Persistence.PublishedMessage,\n  where: p0.message_uuid == ^\"454d45b0-7cf9-44df-aa94-fa1153835e2a\",\n  select: p0\n">>} in 'Elixir.Enum':'-reduce/3-lists^foldl/2-0-'/3 line 1948 in context child_terminated
2019-11-30 12:13:02.137 [error] <0.2611.0> gen_server <0.2611.0> terminated with reason: {'module could not be loaded',[{'Elixir.Routes',live_path,[#{'__struct__' => 'Elixir.Phoenix.LiveView.Socket',assigns => #{data => #{'__struct__' => 'Elixir.RailwayUiWeb.PublishedMessageLive.Index.Data',current_user_uuid => <<"1f4c4051-fe12-41cf-a39a-49f794f6b333">>,flash => #{},page => 4,page_nums => 8,query_filter => <<"uuid">>},messages => []},changed => #{},'connected?' => true,endpoint => 'Elixir.RailwayUiWeb.Endpoint',fingerprints => {142093936675103812280353160439262684400,#{5 => 137073136173526650860537822598359375899,...}},...},...],...},...]}
2019-11-30 12:13:02.138 [error] <0.2611.0>@Elixir.Routes:live_path CRASH REPORT Process <0.2611.0> with 0 neighbours crashed with reason: call to undefined function 'Elixir.Routes':live_path(#{'__struct__' => 'Elixir.Phoenix.LiveView.Socket',assigns => #{data => #{'__struct__' => 'Elixir.RailwayUiWeb.PublishedMessageLive.Index.Data',...},...},...}, 'Elixir.RailwayUiWeb.PublishedMessageLive.Index', #{<<"uuid">> => <<"454d45b0-7cf9-44df-aa94-fa1153835e2a">>})
2019-11-30 12:13:02.138 [error] <0.510.0>@Elixir.Routes:live_path Supervisor {<0.510.0>,'Elixir.Phoenix.Socket.PoolSupervisor.WorkerSupervisor'} had child 'Elixir.Phoenix.Channel.Server' started with {'Elixir.Phoenix.Channel.Server',start_link,undefined} at <0.2611.0> exit with reason call to undefined function 'Elixir.Routes':live_path(#{'__struct__' => 'Elixir.Phoenix.LiveView.Socket',assigns => #{data => #{'__struct__' => 'Elixir.RailwayUiWeb.PublishedMessageLive.Index.Data',...},...},...}, 'Elixir.RailwayUiWeb.PublishedMessageLive.Index', #{<<"uuid">> => <<"454d45b0-7cf9-44df-aa94-fa1153835e2a">>}) in context child_terminated
2019-11-30 12:27:15.873 [error] <0.789.0> gen_server <0.789.0> terminated with reason: {socket_error,timeout}
2019-11-30 12:27:15.873 [error] <0.789.0> CRASH REPORT Process <0.789.0> with 0 neighbours exited with reason: {socket_error,timeout} in gen_server:handle_common_reply/8 line 751
2019-11-30 12:27:15.873 [error] <0.785.0> gen_server <0.785.0> terminated with reason: {socket_error,timeout}
2019-11-30 12:27:15.873 [error] <0.785.0> CRASH REPORT Process <0.785.0> with 0 neighbours exited with reason: {socket_error,timeout} in gen_server:handle_common_reply/8 line 751
2019-11-30 12:27:15.874 [error] <0.783.0> Supervisor {<0.783.0>,amqp_connection_sup} had child connection started with amqp_gen_connection:start_link(<0.784.0>, {amqp_params_network,<<"guest">>,<<"guest">>,<<"/">>,"localhost",5672,2047,0,10,60000,none,[#Fun<am..>,...],...}) at <0.785.0> exit with reason {socket_error,timeout} in context child_terminated
2019-11-30 12:27:15.874 [error] <0.783.0> Supervisor {<0.783.0>,amqp_connection_sup} had child connection started with amqp_gen_connection:start_link(<0.784.0>, {amqp_params_network,<<"guest">>,<<"guest">>,<<"/">>,"localhost",5672,2047,0,10,60000,none,[#Fun<am..>,...],...}) at <0.785.0> exit with reason reached_max_restart_intensity in context shutdown
2019-11-30 12:27:15.875 [error] <0.780.0>@gen_server:call gen_server 'Elixir.RailwayIpc.Connection' terminated with reason: no such process or port in call to gen_server:call(<0.785.0>, {command,{close,{'connection.close',200,<<"Goodbye">>,0,0},60000}}, 60000) in gen_server:call/3 line 223
2019-11-30 12:27:15.875 [error] <0.780.0>@gen_server:call CRASH REPORT Process 'Elixir.RailwayIpc.Connection' with 0 neighbours exited with reason: no such process or port in call to gen_server:call(<0.785.0>, {command,{close,{'connection.close',200,<<"Goodbye">>,0,0},60000}}, 60000) in gen_server:call/3 line 223
2019-11-30 12:27:15.875 [error] <0.423.0>@gen_server:call Supervisor 'Elixir.RailwayIpc.Connection.Supervisor' had child 'Elixir.RailwayIpc.Connection' started with 'Elixir.RailwayIpc.Connection':start_link([{name,'Elixir.RailwayIpc.Connection'}]) at <0.780.0> exit with reason no such process or port in call to gen_server:call(<0.785.0>, {command,{close,{'connection.close',200,<<"Goodbye">>,0,0},60000}}, 60000) in context child_terminated
2019-11-30 12:27:15.875 [error] <0.784.0> Supervisor {<0.784.0>,amqp_connection_type_sup} had child main_reader started with amqp_main_reader:start_link(#Port<0.104>, <0.785.0>, <0.787.0>, {method,rabbit_framing_amqp_0_9_1}, <<"client 127.0.0.1:64644 -> 127.0.0.1:5672">>) at <0.789.0> exit with reason {socket_error,timeout} in context child_terminated
2019-11-30 12:27:15.875 [error] <0.784.0> Supervisor {<0.784.0>,amqp_connection_type_sup} had child main_reader started with amqp_main_reader:start_link(#Port<0.104>, <0.785.0>, <0.787.0>, {method,rabbit_framing_amqp_0_9_1}, <<"client 127.0.0.1:64644 -> 127.0.0.1:5672">>) at <0.789.0> exit with reason reached_max_restart_intensity in context shutdown
2019-11-30 12:30:28.369 [error] <0.2867.0> gen_server <0.2867.0> terminated with reason: #{'__exception__' => true,'__struct__' => 'Elixir.KeyError',key => query_filter,message => nil,term => #{'__struct__' => 'Elixir.RailwayUiWeb.PublishedMessageLive.Index.Data',current_user_uuid => <<"1f4c4051-fe12-41cf-a39a-49f794f6b333">>,flash => #{},page => 1,page_nums => 8}} in 'Elixir.RailwayUiWeb.PublishedMessageView':'index.html'/1 line 24
2019-11-30 12:30:28.370 [error] <0.2867.0> CRASH REPORT Process <0.2867.0> with 0 neighbours crashed with reason: #{'__exception__' => true,'__struct__' => 'Elixir.KeyError',key => query_filter,message => nil,term => #{'__struct__' => 'Elixir.RailwayUiWeb.PublishedMessageLive.Index.Data',current_user_uuid => <<"1f4c4051-fe12-41cf-a39a-49f794f6b333">>,flash => #{},page => 1,page_nums => 8}} in 'Elixir.RailwayUiWeb.PublishedMessageView':'index.html'/1 line 24
2019-11-30 12:30:28.370 [error] <0.512.0> Supervisor {<0.512.0>,'Elixir.Phoenix.Socket.PoolSupervisor.WorkerSupervisor'} had child 'Elixir.Phoenix.Channel.Server' started with {'Elixir.Phoenix.Channel.Server',start_link,undefined} at <0.2867.0> exit with reason #{'__exception__' => true,'__struct__' => 'Elixir.KeyError',key => query_filter,message => nil,term => #{'__struct__' => 'Elixir.RailwayUiWeb.PublishedMessageLive.Index.Data',current_user_uuid => <<"1f4c4051-fe12-41cf-a39a-49f794f6b333">>,flash => #{},page => 1,page_nums => 8}} in 'Elixir.RailwayUiWeb.PublishedMessageView':'index.html'/1 line 24 in context child_terminated
2019-11-30 12:30:28.440 [error] <0.2849.0> CRASH REPORT Process <0.2849.0> with 0 neighbours exited with reason: {{#{'__exception__' => true,'__struct__' => 'Elixir.KeyError',key => query_filter,message => nil,term => #{'__struct__' => 'Elixir.RailwayUiWeb.PublishedMessageLive.Index.Data',current_user_uuid => <<"1f4c4051-fe12-41cf-a39a-49f794f6b333">>,flash => #{},page => 1,page_nums => 8}},[{'Elixir.RailwayUiWeb.PublishedMessageView','index.html',1,[{file,"lib/railway_ui_web/templates/published_message/index.html.leex"},{line,24}]},{'Elixir.Phoenix.LiveView.Utils',to_rendered,2,[{file,"lib/phoenix_l..."},...]},...]},...} in 'Elixir.Phoenix.Endpoint.Cowboy2Handler':init/4 line 59 in 'Elixir.Phoenix.Endpoint.Cowboy2Handler':init/4 line 59
2019-11-30 12:30:28.446 [error] <0.388.0> Lager event handler error_logger_lager_h exited with reason {'EXIT',{{case_clause,['Elixir.RailwayUiWeb.Endpoint.HTTP',<0.2848.0>,1,<0.2849.0>,{{#{'__exception__' => true,'__struct__' => 'Elixir.KeyError',key => query_filter,message => nil,term => #{'__struct__' => 'Elixir.RailwayUiWeb.PublishedMessageLive.Index.Data',current_user_uuid => <<"1f4c4051-fe12-41cf-a39a-49f794f6b333">>,flash => #{},page => 1,page_nums => 8}},[{'Elixir.RailwayUiWeb.PublishedMessageView','index.html',1,[{file,"lib/railway_ui_web/templates/published_message/index.html.le..."},...]},...]},...},...]},...}}
2019-11-30 12:30:59.014 [error] <0.2881.0> CRASH REPORT Process <0.2881.0> with 0 neighbours exited with reason: {{#{'__exception__' => true,'__struct__' => 'Elixir.KeyError',key => query_filter,message => nil,term => #{'__struct__' => 'Elixir.RailwayUiWeb.PublishedMessageLive.Index.Data',current_user_uuid => <<"1f4c4051-fe12-41cf-a39a-49f794f6b333">>,flash => #{},page => 1,page_nums => 8}},[{'Elixir.RailwayUiWeb.PublishedMessageView','index.html',1,[{file,"lib/railway_ui_web/templates/published_message/index.html.leex"},{line,24}]},{'Elixir.Phoenix.LiveView.Utils',to_rendered,2,[{file,"lib/phoenix_l..."},...]},...]},...} in 'Elixir.Phoenix.Endpoint.Cowboy2Handler':init/4 line 59 in 'Elixir.Phoenix.Endpoint.Cowboy2Handler':init/4 line 59
2019-11-30 12:30:59.020 [error] <0.388.0> Lager event handler error_logger_lager_h exited with reason {'EXIT',{{case_clause,['Elixir.RailwayUiWeb.Endpoint.HTTP',<0.2879.0>,1,<0.2881.0>,{{#{'__exception__' => true,'__struct__' => 'Elixir.KeyError',key => query_filter,message => nil,term => #{'__struct__' => 'Elixir.RailwayUiWeb.PublishedMessageLive.Index.Data',current_user_uuid => <<"1f4c4051-fe12-41cf-a39a-49f794f6b333">>,flash => #{},page => 1,page_nums => 8}},[{'Elixir.RailwayUiWeb.PublishedMessageView','index.html',1,[{file,"lib/railway_ui_web/templates/published_message/index.html.le..."},...]},...]},...},...]},...}}
2019-11-30 12:30:59.342 [error] <0.2897.0> CRASH REPORT Process <0.2897.0> with 0 neighbours exited with reason: {{#{'__exception__' => true,'__struct__' => 'Elixir.KeyError',key => query_filter,message => nil,term => #{'__struct__' => 'Elixir.RailwayUiWeb.PublishedMessageLive.Index.Data',current_user_uuid => <<"1f4c4051-fe12-41cf-a39a-49f794f6b333">>,flash => #{},page => 1,page_nums => 8}},[{'Elixir.RailwayUiWeb.PublishedMessageView','index.html',1,[{file,"lib/railway_ui_web/templates/published_message/index.html.leex"},{line,24}]},{'Elixir.Phoenix.LiveView.Utils',to_rendered,2,[{file,"lib/phoenix_l..."},...]},...]},...} in 'Elixir.Phoenix.Endpoint.Cowboy2Handler':init/4 line 59 in 'Elixir.Phoenix.Endpoint.Cowboy2Handler':init/4 line 59
2019-11-30 12:30:59.348 [error] <0.388.0> Lager event handler error_logger_lager_h exited with reason {'EXIT',{{case_clause,['Elixir.RailwayUiWeb.Endpoint.HTTP',<0.2879.0>,3,<0.2897.0>,{{#{'__exception__' => true,'__struct__' => 'Elixir.KeyError',key => query_filter,message => nil,term => #{'__struct__' => 'Elixir.RailwayUiWeb.PublishedMessageLive.Index.Data',current_user_uuid => <<"1f4c4051-fe12-41cf-a39a-49f794f6b333">>,flash => #{},page => 1,page_nums => 8}},[{'Elixir.RailwayUiWeb.PublishedMessageView','index.html',1,[{file,"lib/railway_ui_web/templates/published_message/index.html.le..."},...]},...]},...},...]},...}}
2019-11-30 12:31:20.139 [error] <0.2909.0> CRASH REPORT Process <0.2909.0> with 0 neighbours exited with reason: {{#{'__exception__' => true,'__struct__' => 'Elixir.KeyError',key => query_filter,message => nil,term => #{'__struct__' => 'Elixir.RailwayUiWeb.PublishedMessageLive.Index.Data',current_user_uuid => <<"1f4c4051-fe12-41cf-a39a-49f794f6b333">>,flash => #{},page => 1,page_nums => 8}},[{'Elixir.RailwayUiWeb.PublishedMessageView','index.html',1,[{file,"lib/railway_ui_web/templates/published_message/index.html.leex"},{line,24}]},{'Elixir.Phoenix.LiveView.Utils',to_rendered,2,[{file,"lib/phoenix_l..."},...]},...]},...} in 'Elixir.Phoenix.Endpoint.Cowboy2Handler':init/4 line 59 in 'Elixir.Phoenix.Endpoint.Cowboy2Handler':init/4 line 59
2019-11-30 12:31:20.146 [error] <0.388.0> Lager event handler error_logger_lager_h exited with reason {'EXIT',{{case_clause,['Elixir.RailwayUiWeb.Endpoint.HTTP',<0.2907.0>,1,<0.2909.0>,{{#{'__exception__' => true,'__struct__' => 'Elixir.KeyError',key => query_filter,message => nil,term => #{'__struct__' => 'Elixir.RailwayUiWeb.PublishedMessageLive.Index.Data',current_user_uuid => <<"1f4c4051-fe12-41cf-a39a-49f794f6b333">>,flash => #{},page => 1,page_nums => 8}},[{'Elixir.RailwayUiWeb.PublishedMessageView','index.html',1,[{file,"lib/railway_ui_web/templates/published_message/index.html.le..."},...]},...]},...},...]},...}}
2019-11-30 12:31:30.402 [error] <0.2926.0> CRASH REPORT Process <0.2926.0> with 0 neighbours exited with reason: {{#{'__exception__' => true,'__struct__' => 'Elixir.KeyError',key => query_filter,message => nil,term => #{'__struct__' => 'Elixir.RailwayUiWeb.PublishedMessageLive.Index.Data',current_user_uuid => <<"1f4c4051-fe12-41cf-a39a-49f794f6b333">>,flash => #{},page => 1,page_nums => 8}},[{'Elixir.RailwayUiWeb.PublishedMessageView','index.html',1,[{file,"lib/railway_ui_web/templates/published_message/index.html.leex"},{line,24}]},{'Elixir.Phoenix.LiveView.Utils',to_rendered,2,[{file,"lib/phoenix_l..."},...]},...]},...} in 'Elixir.Phoenix.Endpoint.Cowboy2Handler':init/4 line 59 in 'Elixir.Phoenix.Endpoint.Cowboy2Handler':init/4 line 59
2019-11-30 12:31:30.407 [error] <0.388.0> Lager event handler error_logger_lager_h exited with reason {'EXIT',{{case_clause,['Elixir.RailwayUiWeb.Endpoint.HTTP',<0.2925.0>,1,<0.2926.0>,{{#{'__exception__' => true,'__struct__' => 'Elixir.KeyError',key => query_filter,message => nil,term => #{'__struct__' => 'Elixir.RailwayUiWeb.PublishedMessageLive.Index.Data',current_user_uuid => <<"1f4c4051-fe12-41cf-a39a-49f794f6b333">>,flash => #{},page => 1,page_nums => 8}},[{'Elixir.RailwayUiWeb.PublishedMessageView','index.html',1,[{file,"lib/railway_ui_web/templates/published_message/index.html.le..."},...]},...]},...},...]},...}}
2019-11-30 12:31:30.735 [error] <0.2943.0> CRASH REPORT Process <0.2943.0> with 0 neighbours exited with reason: {{#{'__exception__' => true,'__struct__' => 'Elixir.KeyError',key => query_filter,message => nil,term => #{'__struct__' => 'Elixir.RailwayUiWeb.PublishedMessageLive.Index.Data',current_user_uuid => <<"1f4c4051-fe12-41cf-a39a-49f794f6b333">>,flash => #{},page => 1,page_nums => 8}},[{'Elixir.RailwayUiWeb.PublishedMessageView','index.html',1,[{file,"lib/railway_ui_web/templates/published_message/index.html.leex"},{line,24}]},{'Elixir.Phoenix.LiveView.Utils',to_rendered,2,[{file,"lib/phoenix_l..."},...]},...]},...} in 'Elixir.Phoenix.Endpoint.Cowboy2Handler':init/4 line 59 in 'Elixir.Phoenix.Endpoint.Cowboy2Handler':init/4 line 59
2019-11-30 12:31:30.739 [error] <0.388.0> Lager event handler error_logger_lager_h exited with reason {'EXIT',{{case_clause,['Elixir.RailwayUiWeb.Endpoint.HTTP',<0.2925.0>,3,<0.2943.0>,{{#{'__exception__' => true,'__struct__' => 'Elixir.KeyError',key => query_filter,message => nil,term => #{'__struct__' => 'Elixir.RailwayUiWeb.PublishedMessageLive.Index.Data',current_user_uuid => <<"1f4c4051-fe12-41cf-a39a-49f794f6b333">>,flash => #{},page => 1,page_nums => 8}},[{'Elixir.RailwayUiWeb.PublishedMessageView','index.html',1,[{file,"lib/railway_ui_web/templates/published_message/index.html.le..."},...]},...]},...},...]},...}}
2019-11-30 12:31:43.340 [error] <0.2953.0> CRASH REPORT Process <0.2953.0> with 0 neighbours exited with reason: {{#{'__exception__' => true,'__struct__' => 'Elixir.KeyError',key => query_filter,message => nil,term => #{'__struct__' => 'Elixir.RailwayUiWeb.PublishedMessageLive.Index.Data',current_user_uuid => <<"1f4c4051-fe12-41cf-a39a-49f794f6b333">>,flash => #{},page => 1,page_nums => 8}},[{'Elixir.RailwayUiWeb.PublishedMessageView','index.html',1,[{file,"lib/railway_ui_web/templates/published_message/index.html.leex"},{line,24}]},{'Elixir.Phoenix.LiveView.Utils',to_rendered,2,[{file,"lib/phoenix_l..."},...]},...]},...} in 'Elixir.Phoenix.Endpoint.Cowboy2Handler':init/4 line 59 in 'Elixir.Phoenix.Endpoint.Cowboy2Handler':init/4 line 59
2019-11-30 12:31:43.346 [error] <0.388.0> Lager event handler error_logger_lager_h exited with reason {'EXIT',{{case_clause,['Elixir.RailwayUiWeb.Endpoint.HTTP',<0.2952.0>,1,<0.2953.0>,{{#{'__exception__' => true,'__struct__' => 'Elixir.KeyError',key => query_filter,message => nil,term => #{'__struct__' => 'Elixir.RailwayUiWeb.PublishedMessageLive.Index.Data',current_user_uuid => <<"1f4c4051-fe12-41cf-a39a-49f794f6b333">>,flash => #{},page => 1,page_nums => 8}},[{'Elixir.RailwayUiWeb.PublishedMessageView','index.html',1,[{file,"lib/railway_ui_web/templates/published_message/index.html.le..."},...]},...]},...},...]},...}}
2019-11-30 12:31:46.302 [error] <0.2970.0> CRASH REPORT Process <0.2970.0> with 0 neighbours exited with reason: {{#{'__exception__' => true,'__struct__' => 'Elixir.KeyError',key => query_filter,message => nil,term => #{'__struct__' => 'Elixir.RailwayUiWeb.PublishedMessageLive.Index.Data',current_user_uuid => <<"1f4c4051-fe12-41cf-a39a-49f794f6b333">>,flash => #{},page => 1,page_nums => 8}},[{'Elixir.RailwayUiWeb.PublishedMessageView','index.html',1,[{file,"lib/railway_ui_web/templates/published_message/index.html.leex"},{line,24}]},{'Elixir.Phoenix.LiveView.Utils',to_rendered,2,[{file,"lib/phoenix_l..."},...]},...]},...} in 'Elixir.Phoenix.Endpoint.Cowboy2Handler':init/4 line 59 in 'Elixir.Phoenix.Endpoint.Cowboy2Handler':init/4 line 59
2019-11-30 12:31:46.311 [error] <0.388.0> Lager event handler error_logger_lager_h exited with reason {'EXIT',{{case_clause,['Elixir.RailwayUiWeb.Endpoint.HTTP',<0.2952.0>,3,<0.2970.0>,{{#{'__exception__' => true,'__struct__' => 'Elixir.KeyError',key => query_filter,message => nil,term => #{'__struct__' => 'Elixir.RailwayUiWeb.PublishedMessageLive.Index.Data',current_user_uuid => <<"1f4c4051-fe12-41cf-a39a-49f794f6b333">>,flash => #{},page => 1,page_nums => 8}},[{'Elixir.RailwayUiWeb.PublishedMessageView','index.html',1,[{file,"lib/railway_ui_web/templates/published_message/index.html.le..."},...]},...]},...},...]},...}}
2019-11-30 12:31:49.075 [error] <0.2987.0> CRASH REPORT Process <0.2987.0> with 0 neighbours exited with reason: {{#{'__exception__' => true,'__struct__' => 'Elixir.KeyError',key => query_filter,message => nil,term => #{'__struct__' => 'Elixir.RailwayUiWeb.PublishedMessageLive.Index.Data',current_user_uuid => <<"1f4c4051-fe12-41cf-a39a-49f794f6b333">>,flash => #{},page => 1,page_nums => 8}},[{'Elixir.RailwayUiWeb.PublishedMessageView','index.html',1,[{file,"lib/railway_ui_web/templates/published_message/index.html.leex"},{line,28}]},{'Elixir.Phoenix.LiveView.Utils',to_rendered,2,[{file,"lib/phoenix_l..."},...]},...]},...} in 'Elixir.Phoenix.Endpoint.Cowboy2Handler':init/4 line 59 in 'Elixir.Phoenix.Endpoint.Cowboy2Handler':init/4 line 59
2019-11-30 12:31:49.081 [error] <0.388.0> Lager event handler error_logger_lager_h exited with reason {'EXIT',{{case_clause,['Elixir.RailwayUiWeb.Endpoint.HTTP',<0.2952.0>,5,<0.2987.0>,{{#{'__exception__' => true,'__struct__' => 'Elixir.KeyError',key => query_filter,message => nil,term => #{'__struct__' => 'Elixir.RailwayUiWeb.PublishedMessageLive.Index.Data',current_user_uuid => <<"1f4c4051-fe12-41cf-a39a-49f794f6b333">>,flash => #{},page => 1,page_nums => 8}},[{'Elixir.RailwayUiWeb.PublishedMessageView','index.html',1,[{file,"lib/railway_ui_web/templates/published_message/index.html.le..."},...]},...]},...},...]},...}}
2019-11-30 12:34:19.011 [error] <0.3076.0> gen_server <0.3076.0> terminated with reason: #{'__exception__' => true,'__struct__' => 'Elixir.Ecto.Query.CastError',message => <<"lib/railway_ui/persistence.ex:30: value `\"1234\"` cannot be dumped to type :binary_id in query:\n\nfrom p0 in RailwayIpc.Persistence.PublishedMessage,\n  where: p0.uuid == ^\"1234\",\n  select: p0\n">>,type => binary_id,value => <<"1234">>} in 'Elixir.Enum':'-reduce/3-lists^foldl/2-0-'/3 line 1948
2019-11-30 12:34:19.012 [error] <0.3076.0> CRASH REPORT Process <0.3076.0> with 0 neighbours crashed with reason: #{'__exception__' => true,'__struct__' => 'Elixir.Ecto.Query.CastError',message => <<"lib/railway_ui/persistence.ex:30: value `\"1234\"` cannot be dumped to type :binary_id in query:\n\nfrom p0 in RailwayIpc.Persistence.PublishedMessage,\n  where: p0.uuid == ^\"1234\",\n  select: p0\n">>,type => binary_id,value => <<"1234">>} in 'Elixir.Enum':'-reduce/3-lists^foldl/2-0-'/3 line 1948
2019-11-30 12:34:19.012 [error] <0.512.0> Supervisor {<0.512.0>,'Elixir.Phoenix.Socket.PoolSupervisor.WorkerSupervisor'} had child 'Elixir.Phoenix.Channel.Server' started with {'Elixir.Phoenix.Channel.Server',start_link,undefined} at <0.3076.0> exit with reason #{'__exception__' => true,'__struct__' => 'Elixir.Ecto.Query.CastError',message => <<"lib/railway_ui/persistence.ex:30: value `\"1234\"` cannot be dumped to type :binary_id in query:\n\nfrom p0 in RailwayIpc.Persistence.PublishedMessage,\n  where: p0.uuid == ^\"1234\",\n  select: p0\n">>,type => binary_id,value => <<"1234">>} in 'Elixir.Enum':'-reduce/3-lists^foldl/2-0-'/3 line 1948 in context child_terminated
2019-11-30 12:34:19.073 [error] <0.3063.0> CRASH REPORT Process <0.3063.0> with 0 neighbours exited with reason: {{#{'__exception__' => true,'__struct__' => 'Elixir.Ecto.Query.CastError',message => <<"lib/railway_ui/persistence.ex:30: value `\"1234\"` cannot be dumped to type :binary_id in query:\n\nfrom p0 in RailwayIpc.Persistence.PublishedMessage,\n  where: p0.uuid == ^\"1234\",\n  select: p0\n">>,type => binary_id,value => <<"1234">>},[{'Elixir.Enum','-reduce/3-lists^foldl/2-0-',3,[{file,"lib/enum.ex"},{line,1948}]},{'Elixir.Enum','-map_reduce/3-lists^mapfoldl/2-0-',3,[{file,"lib/enum.ex"},{line,1440}]},...]},...} in 'Elixir.Phoenix.Endpoint.Cowboy2Handler':init/4 line 59 in 'Elixir.Phoenix.Endpoint.Cowboy2Handler':init/4 line 59
2019-11-30 12:34:19.081 [error] <0.388.0> Lager event handler error_logger_lager_h exited with reason {'EXIT',{{case_clause,['Elixir.RailwayUiWeb.Endpoint.HTTP',<0.3061.0>,1,<0.3063.0>,{{#{'__exception__' => true,'__struct__' => 'Elixir.Ecto.Query.CastError',message => <<"lib/railway_ui/persistence.ex:30: value `\"1234\"` cannot be dumped to type :binary_id in query:\n\nfrom p0 in RailwayIpc.Persistence.PublishedMessage,\n  where: p0.uuid == ^\"1234\",\n  select: p0\n">>,type => binary_id,value => <<"1234">>},[{'Elixir.Enum','-reduce/3-lists^foldl/2-0-',3,[{file,"lib/enum.ex"},{line,1948}]},{'Elixir.Enum',...},...]},...},...]},...}}
2019-11-30 12:39:21.328 [error] <0.3238.0> gen_server <0.3238.0> terminated with reason: {'module could not be loaded',[{'Elixir.RailwayUiWeb.PublishedMessageLive.Index.Data.Data',set_query_filter,[#{'__struct__' => 'Elixir.RailwayUiWeb.PublishedMessageLive.Index.Data',current_user_uuid => <<"1f4c4051-fe12-41cf-a39a-49f794f6b333">>,flash => #{},page => 1,page_nums => 8,query_filter => nil},<<"message_uuid">>],[]},{'Elixir.RailwayUiWeb.PublishedMessageLive.Index',handle_event,3,[{file,"lib/railway_ui_web/live/published_message_live/index.ex"},{line,60}]},{'Elixir.Phoenix.LiveView.Channel',...},...]}
2019-11-30 12:39:21.329 [error] <0.3238.0>@Elixir.RailwayUiWeb.PublishedMessageLive.Index.Data.Data:set_query_filter CRASH REPORT Process <0.3238.0> with 0 neighbours crashed with reason: call to undefined function 'Elixir.RailwayUiWeb.PublishedMessageLive.Index.Data.Data':set_query_filter(#{'__struct__' => 'Elixir.RailwayUiWeb.PublishedMessageLive.Index.Data',current_user_uuid => <<"1...">>,...}, <<"message_uuid">>)
2019-11-30 12:39:21.329 [error] <0.511.0>@Elixir.RailwayUiWeb.PublishedMessageLive.Index.Data.Data:set_query_filter Supervisor {<0.511.0>,'Elixir.Phoenix.Socket.PoolSupervisor.WorkerSupervisor'} had child 'Elixir.Phoenix.Channel.Server' started with {'Elixir.Phoenix.Channel.Server',start_link,undefined} at <0.3238.0> exit with reason call to undefined function 'Elixir.RailwayUiWeb.PublishedMessageLive.Index.Data.Data':set_query_filter(#{'__struct__' => 'Elixir.RailwayUiWeb.PublishedMessageLive.Index.Data',current_user_uuid => <<"1...">>,...}, <<"message_uuid">>) in context child_terminated
2019-11-30 12:40:10.970 [error] <0.3263.0> gen_server <0.3263.0> terminated with reason: #{'__exception__' => true,'__struct__' => 'Elixir.Ecto.QueryError',message => <<"lib/railway_ui/persistence.ex:30: field `messate_type` in `where` does not exist in schema RailwayIpc.Persistence.PublishedMessage in query:\n\nfrom p0 in RailwayIpc.Persistence.PublishedMessage,\n  where: p0.messate_type == ^\"CreateBatch\",\n  select: p0\n">>} in 'Elixir.Enum':'-reduce/3-lists^foldl/2-0-'/3 line 1948
2019-11-30 12:40:10.971 [error] <0.3263.0> CRASH REPORT Process <0.3263.0> with 0 neighbours crashed with reason: #{'__exception__' => true,'__struct__' => 'Elixir.Ecto.QueryError',message => <<"lib/railway_ui/persistence.ex:30: field `messate_type` in `where` does not exist in schema RailwayIpc.Persistence.PublishedMessage in query:\n\nfrom p0 in RailwayIpc.Persistence.PublishedMessage,\n  where: p0.messate_type == ^\"CreateBatch\",\n  select: p0\n">>} in 'Elixir.Enum':'-reduce/3-lists^foldl/2-0-'/3 line 1948
2019-11-30 12:40:10.971 [error] <0.513.0> Supervisor {<0.513.0>,'Elixir.Phoenix.Socket.PoolSupervisor.WorkerSupervisor'} had child 'Elixir.Phoenix.Channel.Server' started with {'Elixir.Phoenix.Channel.Server',start_link,undefined} at <0.3263.0> exit with reason #{'__exception__' => true,'__struct__' => 'Elixir.Ecto.QueryError',message => <<"lib/railway_ui/persistence.ex:30: field `messate_type` in `where` does not exist in schema RailwayIpc.Persistence.PublishedMessage in query:\n\nfrom p0 in RailwayIpc.Persistence.PublishedMessage,\n  where: p0.messate_type == ^\"CreateBatch\",\n  select: p0\n">>} in 'Elixir.Enum':'-reduce/3-lists^foldl/2-0-'/3 line 1948 in context child_terminated
2019-11-30 12:55:09.468 [error] <0.3764.0> gen_server <0.3764.0> terminated with reason: #{'__exception__' => true,'__struct__' => 'Elixir.Ecto.Query.CastError',message => <<"lib/railway_ui/persistence.ex:30: value `\"CreateBatch\"` cannot be dumped to type :binary_id in query:\n\nfrom p0 in RailwayIpc.Persistence.PublishedMessage,\n  where: p0.correlation_id == ^\"CreateBatch\",\n  select: p0\n">>,type => binary_id,value => <<"CreateBatch">>} in 'Elixir.Enum':'-reduce/3-lists^foldl/2-0-'/3 line 1948
2019-11-30 12:55:09.468 [error] <0.3764.0> CRASH REPORT Process <0.3764.0> with 0 neighbours crashed with reason: #{'__exception__' => true,'__struct__' => 'Elixir.Ecto.Query.CastError',message => <<"lib/railway_ui/persistence.ex:30: value `\"CreateBatch\"` cannot be dumped to type :binary_id in query:\n\nfrom p0 in RailwayIpc.Persistence.PublishedMessage,\n  where: p0.correlation_id == ^\"CreateBatch\",\n  select: p0\n">>,type => binary_id,value => <<"CreateBatch">>} in 'Elixir.Enum':'-reduce/3-lists^foldl/2-0-'/3 line 1948
2019-11-30 12:55:09.468 [error] <0.512.0> Supervisor {<0.512.0>,'Elixir.Phoenix.Socket.PoolSupervisor.WorkerSupervisor'} had child 'Elixir.Phoenix.Channel.Server' started with {'Elixir.Phoenix.Channel.Server',start_link,undefined} at <0.3764.0> exit with reason #{'__exception__' => true,'__struct__' => 'Elixir.Ecto.Query.CastError',message => <<"lib/railway_ui/persistence.ex:30: value `\"CreateBatch\"` cannot be dumped to type :binary_id in query:\n\nfrom p0 in RailwayIpc.Persistence.PublishedMessage,\n  where: p0.correlation_id == ^\"CreateBatch\",\n  select: p0\n">>,type => binary_id,value => <<"CreateBatch">>} in 'Elixir.Enum':'-reduce/3-lists^foldl/2-0-'/3 line 1948 in context child_terminated
