2019-12-01 00:43:33.949 [error] <0.3567.0> gen_server <0.3567.0> terminated with reason: {socket_error,timeout}
2019-12-01 00:43:33.950 [error] <0.3567.0> CRASH REPORT Process <0.3567.0> with 0 neighbours exited with reason: {socket_error,timeout} in gen_server:handle_common_reply/8 line 751
2019-12-01 00:43:33.950 [error] <0.3563.0> gen_server <0.3563.0> terminated with reason: {socket_error,timeout}
2019-12-01 00:43:33.950 [error] <0.3562.0> Supervisor {<0.3562.0>,amqp_connection_type_sup} had child main_reader started with amqp_main_reader:start_link(#Port<0.530>, <0.3563.0>, <0.3565.0>, {method,rabbit_framing_amqp_0_9_1}, <<"client 127.0.0.1:63481 -> 127.0.0.1:5672">>) at <0.3567.0> exit with reason {socket_error,timeout} in context child_terminated
2019-12-01 00:43:33.950 [error] <0.3562.0> Supervisor {<0.3562.0>,amqp_connection_type_sup} had child main_reader started with amqp_main_reader:start_link(#Port<0.530>, <0.3563.0>, <0.3565.0>, {method,rabbit_framing_amqp_0_9_1}, <<"client 127.0.0.1:63481 -> 127.0.0.1:5672">>) at <0.3567.0> exit with reason reached_max_restart_intensity in context shutdown
2019-12-01 00:43:33.951 [error] <0.3563.0> CRASH REPORT Process <0.3563.0> with 0 neighbours exited with reason: {socket_error,timeout} in gen_server:handle_common_reply/8 line 751
2019-12-01 00:43:33.952 [error] <0.3561.0> Supervisor {<0.3561.0>,amqp_connection_sup} had child connection started with amqp_gen_connection:start_link(<0.3562.0>, {amqp_params_network,<<"guest">>,<<"guest">>,<<"/">>,"localhost",5672,2047,0,10,60000,none,[#Fun<am..>,...],...}) at <0.3563.0> exit with reason {socket_error,timeout} in context child_terminated
2019-12-01 00:43:33.953 [error] <0.3561.0> Supervisor {<0.3561.0>,amqp_connection_sup} had child connection started with amqp_gen_connection:start_link(<0.3562.0>, {amqp_params_network,<<"guest">>,<<"guest">>,<<"/">>,"localhost",5672,2047,0,10,60000,none,[#Fun<am..>,...],...}) at <0.3563.0> exit with reason reached_max_restart_intensity in context shutdown
2019-12-01 00:43:33.953 [error] <0.3558.0>@gen_server:call gen_server 'Elixir.RailwayIpc.Connection' terminated with reason: no such process or port in call to gen_server:call(<0.3563.0>, {command,{close,{'connection.close',200,<<"Goodbye">>,0,0},60000}}, 60000) in gen_server:call/3 line 223
2019-12-01 00:43:33.953 [error] <0.3558.0>@gen_server:call CRASH REPORT Process 'Elixir.RailwayIpc.Connection' with 0 neighbours exited with reason: no such process or port in call to gen_server:call(<0.3563.0>, {command,{close,{'connection.close',200,<<"Goodbye">>,0,0},60000}}, 60000) in gen_server:call/3 line 223
2019-12-01 00:43:33.953 [error] <0.433.0>@gen_server:call Supervisor 'Elixir.RailwayIpc.Connection.Supervisor' had child 'Elixir.RailwayIpc.Connection' started with 'Elixir.RailwayIpc.Connection':start_link([{name,'Elixir.RailwayIpc.Connection'}]) at <0.3558.0> exit with reason no such process or port in call to gen_server:call(<0.3563.0>, {command,{close,{'connection.close',200,<<"Goodbye">>,0,0},60000}}, 60000) in context child_terminated
2019-12-01 01:37:45.618 [error] <0.3597.0> gen_server <0.3597.0> terminated with reason: {socket_error,timeout}
2019-12-01 01:37:45.619 [error] <0.3593.0> gen_server <0.3593.0> terminated with reason: {socket_error,timeout}
2019-12-01 01:37:45.619 [error] <0.3597.0> CRASH REPORT Process <0.3597.0> with 0 neighbours exited with reason: {socket_error,timeout} in gen_server:handle_common_reply/8 line 751
2019-12-01 01:37:45.619 [error] <0.3592.0> Supervisor {<0.3592.0>,amqp_connection_type_sup} had child main_reader started with amqp_main_reader:start_link(#Port<0.533>, <0.3593.0>, <0.3595.0>, {method,rabbit_framing_amqp_0_9_1}, <<"client 127.0.0.1:63749 -> 127.0.0.1:5672">>) at <0.3597.0> exit with reason {socket_error,timeout} in context child_terminated
2019-12-01 01:37:45.620 [error] <0.3592.0> Supervisor {<0.3592.0>,amqp_connection_type_sup} had child main_reader started with amqp_main_reader:start_link(#Port<0.533>, <0.3593.0>, <0.3595.0>, {method,rabbit_framing_amqp_0_9_1}, <<"client 127.0.0.1:63749 -> 127.0.0.1:5672">>) at <0.3597.0> exit with reason reached_max_restart_intensity in context shutdown
2019-12-01 01:37:45.620 [error] <0.3593.0> CRASH REPORT Process <0.3593.0> with 0 neighbours exited with reason: {socket_error,timeout} in gen_server:handle_common_reply/8 line 751
2019-12-01 01:37:45.620 [error] <0.3591.0> Supervisor {<0.3591.0>,amqp_connection_sup} had child connection started with amqp_gen_connection:start_link(<0.3592.0>, {amqp_params_network,<<"guest">>,<<"guest">>,<<"/">>,"localhost",5672,2047,0,10,60000,none,[#Fun<am..>,...],...}) at <0.3593.0> exit with reason {socket_error,timeout} in context child_terminated
2019-12-01 01:37:45.620 [error] <0.3588.0>@gen_server:call gen_server 'Elixir.RailwayIpc.Connection' terminated with reason: no such process or port in call to gen_server:call(<0.3593.0>, {command,{close,{'connection.close',200,<<"Goodbye">>,0,0},60000}}, 60000) in gen_server:call/3 line 223
2019-12-01 01:37:45.620 [error] <0.3591.0> Supervisor {<0.3591.0>,amqp_connection_sup} had child connection started with amqp_gen_connection:start_link(<0.3592.0>, {amqp_params_network,<<"guest">>,<<"guest">>,<<"/">>,"localhost",5672,2047,0,10,60000,none,[#Fun<am..>,...],...}) at <0.3593.0> exit with reason reached_max_restart_intensity in context shutdown
2019-12-01 01:37:45.621 [error] <0.3588.0>@gen_server:call CRASH REPORT Process 'Elixir.RailwayIpc.Connection' with 0 neighbours exited with reason: no such process or port in call to gen_server:call(<0.3593.0>, {command,{close,{'connection.close',200,<<"Goodbye">>,0,0},60000}}, 60000) in gen_server:call/3 line 223
2019-12-01 01:37:45.621 [error] <0.433.0>@gen_server:call Supervisor 'Elixir.RailwayIpc.Connection.Supervisor' had child 'Elixir.RailwayIpc.Connection' started with 'Elixir.RailwayIpc.Connection':start_link([{name,'Elixir.RailwayIpc.Connection'}]) at <0.3588.0> exit with reason no such process or port in call to gen_server:call(<0.3593.0>, {command,{close,{'connection.close',200,<<"Goodbye">>,0,0},60000}}, 60000) in context child_terminated
2019-12-01 02:31:45.903 [error] <0.3632.0> gen_server <0.3632.0> terminated with reason: {socket_error,timeout}
2019-12-01 02:31:45.903 [error] <0.3632.0> CRASH REPORT Process <0.3632.0> with 0 neighbours exited with reason: {socket_error,timeout} in gen_server:handle_common_reply/8 line 751
2019-12-01 02:31:45.903 [error] <0.3628.0> gen_server <0.3628.0> terminated with reason: {socket_error,timeout}
2019-12-01 02:31:45.904 [error] <0.3627.0> Supervisor {<0.3627.0>,amqp_connection_type_sup} had child main_reader started with amqp_main_reader:start_link(#Port<0.536>, <0.3628.0>, <0.3630.0>, {method,rabbit_framing_amqp_0_9_1}, <<"client 127.0.0.1:64001 -> 127.0.0.1:5672">>) at <0.3632.0> exit with reason {socket_error,timeout} in context child_terminated
2019-12-01 02:31:45.904 [error] <0.3627.0> Supervisor {<0.3627.0>,amqp_connection_type_sup} had child main_reader started with amqp_main_reader:start_link(#Port<0.536>, <0.3628.0>, <0.3630.0>, {method,rabbit_framing_amqp_0_9_1}, <<"client 127.0.0.1:64001 -> 127.0.0.1:5672">>) at <0.3632.0> exit with reason reached_max_restart_intensity in context shutdown
2019-12-01 02:31:45.904 [error] <0.3628.0> CRASH REPORT Process <0.3628.0> with 0 neighbours exited with reason: {socket_error,timeout} in gen_server:handle_common_reply/8 line 751
2019-12-01 02:31:45.905 [error] <0.3623.0>@gen_server:call gen_server 'Elixir.RailwayIpc.Connection' terminated with reason: no such process or port in call to gen_server:call(<0.3628.0>, {command,{close,{'connection.close',200,<<"Goodbye">>,0,0},60000}}, 60000) in gen_server:call/3 line 223
2019-12-01 02:31:45.907 [error] <0.3623.0>@gen_server:call CRASH REPORT Process 'Elixir.RailwayIpc.Connection' with 0 neighbours exited with reason: no such process or port in call to gen_server:call(<0.3628.0>, {command,{close,{'connection.close',200,<<"Goodbye">>,0,0},60000}}, 60000) in gen_server:call/3 line 223
2019-12-01 02:31:45.924 [error] <0.3626.0> Supervisor {<0.3626.0>,amqp_connection_sup} had child connection started with amqp_gen_connection:start_link(<0.3627.0>, {amqp_params_network,<<"guest">>,<<"guest">>,<<"/">>,"localhost",5672,2047,0,10,60000,none,[#Fun<am..>,...],...}) at <0.3628.0> exit with reason {socket_error,timeout} in context child_terminated
2019-12-01 02:31:45.925 [error] <0.3626.0> Supervisor {<0.3626.0>,amqp_connection_sup} had child connection started with amqp_gen_connection:start_link(<0.3627.0>, {amqp_params_network,<<"guest">>,<<"guest">>,<<"/">>,"localhost",5672,2047,0,10,60000,none,[#Fun<am..>,...],...}) at <0.3628.0> exit with reason reached_max_restart_intensity in context shutdown
2019-12-01 02:31:45.925 [error] <0.433.0>@gen_server:call Supervisor 'Elixir.RailwayIpc.Connection.Supervisor' had child 'Elixir.RailwayIpc.Connection' started with 'Elixir.RailwayIpc.Connection':start_link([{name,'Elixir.RailwayIpc.Connection'}]) at <0.3623.0> exit with reason no such process or port in call to gen_server:call(<0.3628.0>, {command,{close,{'connection.close',200,<<"Goodbye">>,0,0},60000}}, 60000) in context child_terminated
2019-12-01 03:25:51.941 [error] <0.3654.0> gen_server <0.3654.0> terminated with reason: {socket_error,timeout}
2019-12-01 03:25:51.941 [error] <0.3654.0> CRASH REPORT Process <0.3654.0> with 0 neighbours exited with reason: {socket_error,timeout} in gen_server:handle_common_reply/8 line 751
2019-12-01 03:25:51.941 [error] <0.3650.0> gen_server <0.3650.0> terminated with reason: {socket_error,timeout}
2019-12-01 03:25:51.942 [error] <0.3649.0> Supervisor {<0.3649.0>,amqp_connection_type_sup} had child main_reader started with amqp_main_reader:start_link(#Port<0.537>, <0.3650.0>, <0.3652.0>, {method,rabbit_framing_amqp_0_9_1}, <<"client 127.0.0.1:64020 -> 127.0.0.1:5672">>) at <0.3654.0> exit with reason {socket_error,timeout} in context child_terminated
2019-12-01 03:25:51.942 [error] <0.3649.0> Supervisor {<0.3649.0>,amqp_connection_type_sup} had child main_reader started with amqp_main_reader:start_link(#Port<0.537>, <0.3650.0>, <0.3652.0>, {method,rabbit_framing_amqp_0_9_1}, <<"client 127.0.0.1:64020 -> 127.0.0.1:5672">>) at <0.3654.0> exit with reason reached_max_restart_intensity in context shutdown
2019-12-01 03:25:51.942 [error] <0.3650.0> CRASH REPORT Process <0.3650.0> with 0 neighbours exited with reason: {socket_error,timeout} in gen_server:handle_common_reply/8 line 751
2019-12-01 03:25:51.942 [error] <0.3648.0> Supervisor {<0.3648.0>,amqp_connection_sup} had child connection started with amqp_gen_connection:start_link(<0.3649.0>, {amqp_params_network,<<"guest">>,<<"guest">>,<<"/">>,"localhost",5672,2047,0,10,60000,none,[#Fun<am..>,...],...}) at <0.3650.0> exit with reason {socket_error,timeout} in context child_terminated
2019-12-01 03:25:51.942 [error] <0.3648.0> Supervisor {<0.3648.0>,amqp_connection_sup} had child connection started with amqp_gen_connection:start_link(<0.3649.0>, {amqp_params_network,<<"guest">>,<<"guest">>,<<"/">>,"localhost",5672,2047,0,10,60000,none,[#Fun<am..>,...],...}) at <0.3650.0> exit with reason reached_max_restart_intensity in context shutdown
2019-12-01 03:25:51.943 [error] <0.3645.0>@gen_server:call gen_server 'Elixir.RailwayIpc.Connection' terminated with reason: no such process or port in call to gen_server:call(<0.3650.0>, {command,{close,{'connection.close',200,<<"Goodbye">>,0,0},60000}}, 60000) in gen_server:call/3 line 223
2019-12-01 03:25:51.944 [error] <0.3645.0>@gen_server:call CRASH REPORT Process 'Elixir.RailwayIpc.Connection' with 0 neighbours exited with reason: no such process or port in call to gen_server:call(<0.3650.0>, {command,{close,{'connection.close',200,<<"Goodbye">>,0,0},60000}}, 60000) in gen_server:call/3 line 223
2019-12-01 03:25:51.944 [error] <0.433.0>@gen_server:call Supervisor 'Elixir.RailwayIpc.Connection.Supervisor' had child 'Elixir.RailwayIpc.Connection' started with 'Elixir.RailwayIpc.Connection':start_link([{name,'Elixir.RailwayIpc.Connection'}]) at <0.3645.0> exit with reason no such process or port in call to gen_server:call(<0.3650.0>, {command,{close,{'connection.close',200,<<"Goodbye">>,0,0},60000}}, 60000) in context child_terminated
2019-12-01 04:19:57.900 [error] <0.3676.0> gen_server <0.3676.0> terminated with reason: {socket_error,timeout}
2019-12-01 04:19:57.900 [error] <0.3676.0> CRASH REPORT Process <0.3676.0> with 0 neighbours exited with reason: {socket_error,timeout} in gen_server:handle_common_reply/8 line 751
2019-12-01 04:19:57.902 [error] <0.3672.0> gen_server <0.3672.0> terminated with reason: {socket_error,timeout}
2019-12-01 04:19:57.903 [error] <0.3671.0> Supervisor {<0.3671.0>,amqp_connection_type_sup} had child main_reader started with amqp_main_reader:start_link(#Port<0.538>, <0.3672.0>, <0.3674.0>, {method,rabbit_framing_amqp_0_9_1}, <<"client 127.0.0.1:64057 -> 127.0.0.1:5672">>) at <0.3676.0> exit with reason {socket_error,timeout} in context child_terminated
2019-12-01 04:19:57.903 [error] <0.3671.0> Supervisor {<0.3671.0>,amqp_connection_type_sup} had child main_reader started with amqp_main_reader:start_link(#Port<0.538>, <0.3672.0>, <0.3674.0>, {method,rabbit_framing_amqp_0_9_1}, <<"client 127.0.0.1:64057 -> 127.0.0.1:5672">>) at <0.3676.0> exit with reason reached_max_restart_intensity in context shutdown
2019-12-01 04:19:57.903 [error] <0.3672.0> CRASH REPORT Process <0.3672.0> with 0 neighbours exited with reason: {socket_error,timeout} in gen_server:handle_common_reply/8 line 751
2019-12-01 04:19:57.904 [error] <0.3670.0> Supervisor {<0.3670.0>,amqp_connection_sup} had child connection started with amqp_gen_connection:start_link(<0.3671.0>, {amqp_params_network,<<"guest">>,<<"guest">>,<<"/">>,"localhost",5672,2047,0,10,60000,none,[#Fun<am..>,...],...}) at <0.3672.0> exit with reason {socket_error,timeout} in context child_terminated
2019-12-01 04:19:57.904 [error] <0.3670.0> Supervisor {<0.3670.0>,amqp_connection_sup} had child connection started with amqp_gen_connection:start_link(<0.3671.0>, {amqp_params_network,<<"guest">>,<<"guest">>,<<"/">>,"localhost",5672,2047,0,10,60000,none,[#Fun<am..>,...],...}) at <0.3672.0> exit with reason reached_max_restart_intensity in context shutdown
2019-12-01 04:19:57.904 [error] <0.3667.0>@gen_server:call gen_server 'Elixir.RailwayIpc.Connection' terminated with reason: no such process or port in call to gen_server:call(<0.3672.0>, {command,{close,{'connection.close',200,<<"Goodbye">>,0,0},60000}}, 60000) in gen_server:call/3 line 223
2019-12-01 04:19:57.905 [error] <0.3667.0>@gen_server:call CRASH REPORT Process 'Elixir.RailwayIpc.Connection' with 0 neighbours exited with reason: no such process or port in call to gen_server:call(<0.3672.0>, {command,{close,{'connection.close',200,<<"Goodbye">>,0,0},60000}}, 60000) in gen_server:call/3 line 223
2019-12-01 04:19:57.905 [error] <0.433.0>@gen_server:call Supervisor 'Elixir.RailwayIpc.Connection.Supervisor' had child 'Elixir.RailwayIpc.Connection' started with 'Elixir.RailwayIpc.Connection':start_link([{name,'Elixir.RailwayIpc.Connection'}]) at <0.3667.0> exit with reason no such process or port in call to gen_server:call(<0.3672.0>, {command,{close,{'connection.close',200,<<"Goodbye">>,0,0},60000}}, 60000) in context child_terminated
2019-12-01 04:46:03.903 [error] <0.3698.0> gen_server <0.3698.0> terminated with reason: {socket_error,timeout}
2019-12-01 04:46:03.903 [error] <0.3698.0> CRASH REPORT Process <0.3698.0> with 0 neighbours exited with reason: {socket_error,timeout} in gen_server:handle_common_reply/8 line 751
2019-12-01 04:46:03.903 [error] <0.3694.0> gen_server <0.3694.0> terminated with reason: {socket_error,timeout}
2019-12-01 04:46:03.904 [error] <0.3694.0> CRASH REPORT Process <0.3694.0> with 0 neighbours exited with reason: {socket_error,timeout} in gen_server:handle_common_reply/8 line 751
2019-12-01 04:46:03.905 [error] <0.3692.0> Supervisor {<0.3692.0>,amqp_connection_sup} had child connection started with amqp_gen_connection:start_link(<0.3693.0>, {amqp_params_network,<<"guest">>,<<"guest">>,<<"/">>,"localhost",5672,2047,0,10,60000,none,[#Fun<am..>,...],...}) at <0.3694.0> exit with reason {socket_error,timeout} in context child_terminated
2019-12-01 04:46:03.905 [error] <0.3692.0> Supervisor {<0.3692.0>,amqp_connection_sup} had child connection started with amqp_gen_connection:start_link(<0.3693.0>, {amqp_params_network,<<"guest">>,<<"guest">>,<<"/">>,"localhost",5672,2047,0,10,60000,none,[#Fun<am..>,...],...}) at <0.3694.0> exit with reason reached_max_restart_intensity in context shutdown
2019-12-01 04:46:03.906 [error] <0.3689.0>@gen_server:call gen_server 'Elixir.RailwayIpc.Connection' terminated with reason: no such process or port in call to gen_server:call(<0.3694.0>, {command,{close,{'connection.close',200,<<"Goodbye">>,0,0},60000}}, 60000) in gen_server:call/3 line 223
2019-12-01 04:46:03.906 [error] <0.3689.0>@gen_server:call CRASH REPORT Process 'Elixir.RailwayIpc.Connection' with 0 neighbours exited with reason: no such process or port in call to gen_server:call(<0.3694.0>, {command,{close,{'connection.close',200,<<"Goodbye">>,0,0},60000}}, 60000) in gen_server:call/3 line 223
2019-12-01 04:46:03.906 [error] <0.433.0>@gen_server:call Supervisor 'Elixir.RailwayIpc.Connection.Supervisor' had child 'Elixir.RailwayIpc.Connection' started with 'Elixir.RailwayIpc.Connection':start_link([{name,'Elixir.RailwayIpc.Connection'}]) at <0.3689.0> exit with reason no such process or port in call to gen_server:call(<0.3694.0>, {command,{close,{'connection.close',200,<<"Goodbye">>,0,0},60000}}, 60000) in context child_terminated
2019-12-01 04:46:03.916 [error] <0.3693.0> Supervisor {<0.3693.0>,amqp_connection_type_sup} had child main_reader started with amqp_main_reader:start_link(#Port<0.539>, <0.3694.0>, <0.3696.0>, {method,rabbit_framing_amqp_0_9_1}, <<"client 127.0.0.1:64093 -> 127.0.0.1:5672">>) at <0.3698.0> exit with reason {socket_error,timeout} in context child_terminated
2019-12-01 04:46:03.916 [error] <0.3693.0> Supervisor {<0.3693.0>,amqp_connection_type_sup} had child main_reader started with amqp_main_reader:start_link(#Port<0.539>, <0.3694.0>, <0.3696.0>, {method,rabbit_framing_amqp_0_9_1}, <<"client 127.0.0.1:64093 -> 127.0.0.1:5672">>) at <0.3698.0> exit with reason reached_max_restart_intensity in context shutdown
2019-12-01 05:16:40.915 [error] <0.3720.0> gen_server <0.3720.0> terminated with reason: {socket_error,timeout}
2019-12-01 05:16:40.915 [error] <0.3720.0> CRASH REPORT Process <0.3720.0> with 0 neighbours exited with reason: {socket_error,timeout} in gen_server:handle_common_reply/8 line 751
2019-12-01 05:16:40.916 [error] <0.3715.0> Supervisor {<0.3715.0>,amqp_connection_type_sup} had child main_reader started with amqp_main_reader:start_link(#Port<0.540>, <0.3716.0>, <0.3718.0>, {method,rabbit_framing_amqp_0_9_1}, <<"client 127.0.0.1:64134 -> 127.0.0.1:5672">>) at <0.3720.0> exit with reason {socket_error,timeout} in context child_terminated
2019-12-01 05:16:40.916 [error] <0.3715.0> Supervisor {<0.3715.0>,amqp_connection_type_sup} had child main_reader started with amqp_main_reader:start_link(#Port<0.540>, <0.3716.0>, <0.3718.0>, {method,rabbit_framing_amqp_0_9_1}, <<"client 127.0.0.1:64134 -> 127.0.0.1:5672">>) at <0.3720.0> exit with reason reached_max_restart_intensity in context shutdown
2019-12-01 05:16:40.916 [error] <0.3716.0> gen_server <0.3716.0> terminated with reason: {socket_error,timeout}
2019-12-01 05:16:40.916 [error] <0.3716.0> CRASH REPORT Process <0.3716.0> with 0 neighbours exited with reason: {socket_error,timeout} in gen_server:handle_common_reply/8 line 751
2019-12-01 05:16:40.916 [error] <0.3711.0>@gen_server:call gen_server 'Elixir.RailwayIpc.Connection' terminated with reason: no such process or port in call to gen_server:call(<0.3716.0>, {command,{close,{'connection.close',200,<<"Goodbye">>,0,0},60000}}, 60000) in gen_server:call/3 line 223
2019-12-01 05:16:40.918 [error] <0.3711.0>@gen_server:call CRASH REPORT Process 'Elixir.RailwayIpc.Connection' with 0 neighbours exited with reason: no such process or port in call to gen_server:call(<0.3716.0>, {command,{close,{'connection.close',200,<<"Goodbye">>,0,0},60000}}, 60000) in gen_server:call/3 line 223
2019-12-01 05:16:40.919 [error] <0.3714.0> Supervisor {<0.3714.0>,amqp_connection_sup} had child connection started with amqp_gen_connection:start_link(<0.3715.0>, {amqp_params_network,<<"guest">>,<<"guest">>,<<"/">>,"localhost",5672,2047,0,10,60000,none,[#Fun<am..>,...],...}) at <0.3716.0> exit with reason {socket_error,timeout} in context child_terminated
2019-12-01 05:16:40.919 [error] <0.3714.0> Supervisor {<0.3714.0>,amqp_connection_sup} had child connection started with amqp_gen_connection:start_link(<0.3715.0>, {amqp_params_network,<<"guest">>,<<"guest">>,<<"/">>,"localhost",5672,2047,0,10,60000,none,[#Fun<am..>,...],...}) at <0.3716.0> exit with reason reached_max_restart_intensity in context shutdown
2019-12-01 05:16:40.919 [error] <0.433.0>@gen_server:call Supervisor 'Elixir.RailwayIpc.Connection.Supervisor' had child 'Elixir.RailwayIpc.Connection' started with 'Elixir.RailwayIpc.Connection':start_link([{name,'Elixir.RailwayIpc.Connection'}]) at <0.3711.0> exit with reason no such process or port in call to gen_server:call(<0.3716.0>, {command,{close,{'connection.close',200,<<"Goodbye">>,0,0},60000}}, 60000) in context child_terminated
2019-12-01 06:10:47.915 [error] <0.3742.0> gen_server <0.3742.0> terminated with reason: {socket_error,timeout}
2019-12-01 06:10:47.915 [error] <0.3742.0> CRASH REPORT Process <0.3742.0> with 0 neighbours exited with reason: {socket_error,timeout} in gen_server:handle_common_reply/8 line 751
2019-12-01 06:10:47.915 [error] <0.3738.0> gen_server <0.3738.0> terminated with reason: {socket_error,timeout}
2019-12-01 06:10:47.915 [error] <0.3737.0> Supervisor {<0.3737.0>,amqp_connection_type_sup} had child main_reader started with amqp_main_reader:start_link(#Port<0.541>, <0.3738.0>, <0.3740.0>, {method,rabbit_framing_amqp_0_9_1}, <<"client 127.0.0.1:64180 -> 127.0.0.1:5672">>) at <0.3742.0> exit with reason {socket_error,timeout} in context child_terminated
2019-12-01 06:10:47.915 [error] <0.3737.0> Supervisor {<0.3737.0>,amqp_connection_type_sup} had child main_reader started with amqp_main_reader:start_link(#Port<0.541>, <0.3738.0>, <0.3740.0>, {method,rabbit_framing_amqp_0_9_1}, <<"client 127.0.0.1:64180 -> 127.0.0.1:5672">>) at <0.3742.0> exit with reason reached_max_restart_intensity in context shutdown
2019-12-01 06:10:47.915 [error] <0.3738.0> CRASH REPORT Process <0.3738.0> with 0 neighbours exited with reason: {socket_error,timeout} in gen_server:handle_common_reply/8 line 751
2019-12-01 06:10:47.915 [error] <0.3732.0>@gen_server:call gen_server 'Elixir.RailwayIpc.Connection' terminated with reason: no such process or port in call to gen_server:call(<0.3738.0>, {command,{close,{'connection.close',200,<<"Goodbye">>,0,0},60000}}, 60000) in gen_server:call/3 line 223
2019-12-01 06:10:47.915 [error] <0.3732.0>@gen_server:call CRASH REPORT Process 'Elixir.RailwayIpc.Connection' with 0 neighbours exited with reason: no such process or port in call to gen_server:call(<0.3738.0>, {command,{close,{'connection.close',200,<<"Goodbye">>,0,0},60000}}, 60000) in gen_server:call/3 line 223
2019-12-01 06:10:47.916 [error] <0.3736.0> Supervisor {<0.3736.0>,amqp_connection_sup} had child connection started with amqp_gen_connection:start_link(<0.3737.0>, {amqp_params_network,<<"guest">>,<<"guest">>,<<"/">>,"localhost",5672,2047,0,10,60000,none,[#Fun<am..>,...],...}) at <0.3738.0> exit with reason {socket_error,timeout} in context child_terminated
2019-12-01 06:10:47.916 [error] <0.3736.0> Supervisor {<0.3736.0>,amqp_connection_sup} had child connection started with amqp_gen_connection:start_link(<0.3737.0>, {amqp_params_network,<<"guest">>,<<"guest">>,<<"/">>,"localhost",5672,2047,0,10,60000,none,[#Fun<am..>,...],...}) at <0.3738.0> exit with reason reached_max_restart_intensity in context shutdown
2019-12-01 06:10:47.916 [error] <0.3736.0> Supervisor {<0.3736.0>,amqp_connection_sup} had child connection_type_sup started with amqp_connection_type_sup:start_link() at <0.3737.0> exit with reason shutdown in context shutdown_error
2019-12-01 06:10:47.916 [error] <0.433.0>@gen_server:call Supervisor 'Elixir.RailwayIpc.Connection.Supervisor' had child 'Elixir.RailwayIpc.Connection' started with 'Elixir.RailwayIpc.Connection':start_link([{name,'Elixir.RailwayIpc.Connection'}]) at <0.3732.0> exit with reason no such process or port in call to gen_server:call(<0.3738.0>, {command,{close,{'connection.close',200,<<"Goodbye">>,0,0},60000}}, 60000) in context child_terminated
2019-12-01 07:04:53.906 [error] <0.3764.0> gen_server <0.3764.0> terminated with reason: {socket_error,timeout}
2019-12-01 07:04:53.906 [error] <0.3764.0> CRASH REPORT Process <0.3764.0> with 0 neighbours exited with reason: {socket_error,timeout} in gen_server:handle_common_reply/8 line 751
2019-12-01 07:04:53.906 [error] <0.3759.0> gen_server <0.3759.0> terminated with reason: {socket_error,timeout}
2019-12-01 07:04:53.907 [error] <0.3758.0> Supervisor {<0.3758.0>,amqp_connection_type_sup} had child main_reader started with amqp_main_reader:start_link(#Port<0.542>, <0.3759.0>, <0.3762.0>, {method,rabbit_framing_amqp_0_9_1}, <<"client 127.0.0.1:64207 -> 127.0.0.1:5672">>) at <0.3764.0> exit with reason {socket_error,timeout} in context child_terminated
2019-12-01 07:04:53.907 [error] <0.3758.0> Supervisor {<0.3758.0>,amqp_connection_type_sup} had child main_reader started with amqp_main_reader:start_link(#Port<0.542>, <0.3759.0>, <0.3762.0>, {method,rabbit_framing_amqp_0_9_1}, <<"client 127.0.0.1:64207 -> 127.0.0.1:5672">>) at <0.3764.0> exit with reason reached_max_restart_intensity in context shutdown
2019-12-01 07:04:53.907 [error] <0.3759.0> CRASH REPORT Process <0.3759.0> with 0 neighbours exited with reason: {socket_error,timeout} in gen_server:handle_common_reply/8 line 751
2019-12-01 07:04:53.908 [error] <0.3754.0>@gen_server:call gen_server 'Elixir.RailwayIpc.Connection' terminated with reason: no such process or port in call to gen_server:call(<0.3759.0>, {command,{close,{'connection.close',200,<<"Goodbye">>,0,0},60000}}, 60000) in gen_server:call/3 line 223
2019-12-01 07:04:53.909 [error] <0.3754.0>@gen_server:call CRASH REPORT Process 'Elixir.RailwayIpc.Connection' with 0 neighbours exited with reason: no such process or port in call to gen_server:call(<0.3759.0>, {command,{close,{'connection.close',200,<<"Goodbye">>,0,0},60000}}, 60000) in gen_server:call/3 line 223
2019-12-01 07:04:53.917 [error] <0.3757.0> Supervisor {<0.3757.0>,amqp_connection_sup} had child connection started with amqp_gen_connection:start_link(<0.3758.0>, {amqp_params_network,<<"guest">>,<<"guest">>,<<"/">>,"localhost",5672,2047,0,10,60000,none,[#Fun<am..>,...],...}) at <0.3759.0> exit with reason {socket_error,timeout} in context child_terminated
2019-12-01 07:04:53.917 [error] <0.3757.0> Supervisor {<0.3757.0>,amqp_connection_sup} had child connection started with amqp_gen_connection:start_link(<0.3758.0>, {amqp_params_network,<<"guest">>,<<"guest">>,<<"/">>,"localhost",5672,2047,0,10,60000,none,[#Fun<am..>,...],...}) at <0.3759.0> exit with reason reached_max_restart_intensity in context shutdown
2019-12-01 07:04:53.917 [error] <0.3757.0> Supervisor {<0.3757.0>,amqp_connection_sup} had child connection_type_sup started with amqp_connection_type_sup:start_link() at <0.3758.0> exit with reason shutdown in context shutdown_error
2019-12-01 07:04:53.918 [error] <0.433.0>@gen_server:call Supervisor 'Elixir.RailwayIpc.Connection.Supervisor' had child 'Elixir.RailwayIpc.Connection' started with 'Elixir.RailwayIpc.Connection':start_link([{name,'Elixir.RailwayIpc.Connection'}]) at <0.3754.0> exit with reason no such process or port in call to gen_server:call(<0.3759.0>, {command,{close,{'connection.close',200,<<"Goodbye">>,0,0},60000}}, 60000) in context child_terminated
2019-12-01 07:15:28.899 [error] <0.3786.0> gen_server <0.3786.0> terminated with reason: {socket_error,timeout}
2019-12-01 07:15:28.899 [error] <0.3786.0> CRASH REPORT Process <0.3786.0> with 0 neighbours exited with reason: {socket_error,timeout} in gen_server:handle_common_reply/8 line 751
2019-12-01 07:15:28.900 [error] <0.3782.0> gen_server <0.3782.0> terminated with reason: {socket_error,timeout}
2019-12-01 07:15:28.902 [error] <0.3781.0> Supervisor {<0.3781.0>,amqp_connection_type_sup} had child main_reader started with amqp_main_reader:start_link(#Port<0.543>, <0.3782.0>, <0.3784.0>, {method,rabbit_framing_amqp_0_9_1}, <<"client 127.0.0.1:64244 -> 127.0.0.1:5672">>) at <0.3786.0> exit with reason {socket_error,timeout} in context child_terminated
2019-12-01 07:15:28.902 [error] <0.3781.0> Supervisor {<0.3781.0>,amqp_connection_type_sup} had child main_reader started with amqp_main_reader:start_link(#Port<0.543>, <0.3782.0>, <0.3784.0>, {method,rabbit_framing_amqp_0_9_1}, <<"client 127.0.0.1:64244 -> 127.0.0.1:5672">>) at <0.3786.0> exit with reason reached_max_restart_intensity in context shutdown
2019-12-01 07:15:28.902 [error] <0.3782.0> CRASH REPORT Process <0.3782.0> with 0 neighbours exited with reason: {socket_error,timeout} in gen_server:handle_common_reply/8 line 751
2019-12-01 07:15:28.903 [error] <0.3777.0>@gen_server:call gen_server 'Elixir.RailwayIpc.Connection' terminated with reason: no such process or port in call to gen_server:call(<0.3782.0>, {command,{close,{'connection.close',200,<<"Goodbye">>,0,0},60000}}, 60000) in gen_server:call/3 line 223
2019-12-01 07:15:28.904 [error] <0.3777.0>@gen_server:call CRASH REPORT Process 'Elixir.RailwayIpc.Connection' with 0 neighbours exited with reason: no such process or port in call to gen_server:call(<0.3782.0>, {command,{close,{'connection.close',200,<<"Goodbye">>,0,0},60000}}, 60000) in gen_server:call/3 line 223
2019-12-01 07:15:28.907 [error] <0.3780.0> Supervisor {<0.3780.0>,amqp_connection_sup} had child connection started with amqp_gen_connection:start_link(<0.3781.0>, {amqp_params_network,<<"guest">>,<<"guest">>,<<"/">>,"localhost",5672,2047,0,10,60000,none,[#Fun<am..>,...],...}) at <0.3782.0> exit with reason {socket_error,timeout} in context child_terminated
2019-12-01 07:15:28.907 [error] <0.3780.0> Supervisor {<0.3780.0>,amqp_connection_sup} had child connection started with amqp_gen_connection:start_link(<0.3781.0>, {amqp_params_network,<<"guest">>,<<"guest">>,<<"/">>,"localhost",5672,2047,0,10,60000,none,[#Fun<am..>,...],...}) at <0.3782.0> exit with reason reached_max_restart_intensity in context shutdown
2019-12-01 07:15:28.907 [error] <0.3780.0> Supervisor {<0.3780.0>,amqp_connection_sup} had child connection_type_sup started with amqp_connection_type_sup:start_link() at <0.3781.0> exit with reason shutdown in context shutdown_error
2019-12-01 07:15:28.907 [error] <0.433.0>@gen_server:call Supervisor 'Elixir.RailwayIpc.Connection.Supervisor' had child 'Elixir.RailwayIpc.Connection' started with 'Elixir.RailwayIpc.Connection':start_link([{name,'Elixir.RailwayIpc.Connection'}]) at <0.3777.0> exit with reason no such process or port in call to gen_server:call(<0.3782.0>, {command,{close,{'connection.close',200,<<"Goodbye">>,0,0},60000}}, 60000) in context child_terminated
2019-12-01 07:21:48.383 [error] <0.3884.0> CRASH REPORT Process <0.3884.0> with 0 neighbours exited with reason: {{#{'__exception__' => true,'__struct__' => 'Elixir.Phoenix.Template.UndefinedError',assigns => #{'__phx_template_not_found__' => 'Elixir.RailwayUiWeb.PublishedMessageView',data => #{'__struct__' => 'Elixir.RailwayUiWeb.PublishedMessageLive.Index.State',current_user_uuid => <<"1f4c4051-fe12-41cf-a39a-49f794f6b333">>,flash => #{},page => 4,page_nums => 8,query_filter => nil,query_value => nil,search => #{'__struct__' => 'Elixir.RailwayUiWeb.PublishedMessageLive.Index.Search',query => nil,...}},...},...},...},...} in 'Elixir.Phoenix.Endpoint.Cowboy2Handler':init/4 line 59 in 'Elixir.Phoenix.Endpoint.Cowboy2Handler':init/4 line 59
2019-12-01 07:21:48.389 [error] <0.398.0> Lager event handler error_logger_lager_h exited with reason {'EXIT',{{case_clause,['Elixir.RailwayUiWeb.Endpoint.HTTP',<0.3882.0>,1,<0.3884.0>,{{#{'__exception__' => true,'__struct__' => 'Elixir.Phoenix.Template.UndefinedError',assigns => #{'__phx_template_not_found__' => 'Elixir.RailwayUiWeb.PublishedMessageView',data => #{'__struct__' => 'Elixir.RailwayUiWeb.PublishedMessageLive.Index.State',current_user_uuid => <<"1f4c4051-fe12-41cf-a39a-49f794f6b333">>,flash => #{},page => 4,page_nums => 8,query_filter => nil,query_value => nil,search => #{...}},...},...},...},...},...]},...}}
2019-12-01 07:21:54.561 [error] <0.3902.0> CRASH REPORT Process <0.3902.0> with 0 neighbours exited with reason: {{#{'__exception__' => true,'__struct__' => 'Elixir.Phoenix.Template.UndefinedError',assigns => #{'__phx_template_not_found__' => 'Elixir.RailwayUiWeb.PublishedMessageView',data => #{'__struct__' => 'Elixir.RailwayUiWeb.PublishedMessageLive.Index.State',current_user_uuid => <<"1f4c4051-fe12-41cf-a39a-49f794f6b333">>,flash => #{},page => 4,page_nums => 8,query_filter => nil,query_value => nil,search => #{'__struct__' => 'Elixir.RailwayUiWeb.PublishedMessageLive.Index.Search',query => nil,...}},...},...},...},...} in 'Elixir.Phoenix.Endpoint.Cowboy2Handler':init/4 line 59 in 'Elixir.Phoenix.Endpoint.Cowboy2Handler':init/4 line 59
2019-12-01 07:21:54.574 [error] <0.398.0> Lager event handler error_logger_lager_h exited with reason {'EXIT',{{case_clause,['Elixir.RailwayUiWeb.Endpoint.HTTP',<0.3901.0>,1,<0.3902.0>,{{#{'__exception__' => true,'__struct__' => 'Elixir.Phoenix.Template.UndefinedError',assigns => #{'__phx_template_not_found__' => 'Elixir.RailwayUiWeb.PublishedMessageView',data => #{'__struct__' => 'Elixir.RailwayUiWeb.PublishedMessageLive.Index.State',current_user_uuid => <<"1f4c4051-fe12-41cf-a39a-49f794f6b333">>,flash => #{},page => 4,page_nums => 8,query_filter => nil,query_value => nil,search => #{...}},...},...},...},...},...]},...}}
2019-12-01 07:22:07.558 [error] <0.3913.0> CRASH REPORT Process <0.3913.0> with 0 neighbours exited with reason: {{#{'__exception__' => true,'__struct__' => 'Elixir.Phoenix.Template.UndefinedError',assigns => #{'__phx_template_not_found__' => 'Elixir.RailwayUiWeb.PublishedMessageView',data => #{'__struct__' => 'Elixir.RailwayUiWeb.PublishedMessageLive.Index.State',current_user_uuid => <<"1f4c4051-fe12-41cf-a39a-49f794f6b333">>,flash => #{},page => 4,page_nums => 8,query_filter => nil,query_value => nil,search => #{'__struct__' => 'Elixir.RailwayUiWeb.PublishedMessageLive.Index.Search',query => nil,...}},...},...},...},...} in 'Elixir.Phoenix.Endpoint.Cowboy2Handler':init/4 line 59 in 'Elixir.Phoenix.Endpoint.Cowboy2Handler':init/4 line 59
2019-12-01 07:22:07.565 [error] <0.398.0> Lager event handler error_logger_lager_h exited with reason {'EXIT',{{case_clause,['Elixir.RailwayUiWeb.Endpoint.HTTP',<0.3911.0>,1,<0.3913.0>,{{#{'__exception__' => true,'__struct__' => 'Elixir.Phoenix.Template.UndefinedError',assigns => #{'__phx_template_not_found__' => 'Elixir.RailwayUiWeb.PublishedMessageView',data => #{'__struct__' => 'Elixir.RailwayUiWeb.PublishedMessageLive.Index.State',current_user_uuid => <<"1f4c4051-fe12-41cf-a39a-49f794f6b333">>,flash => #{},page => 4,page_nums => 8,query_filter => nil,query_value => nil,search => #{...}},...},...},...},...},...]},...}}
2019-12-01 07:22:07.851 [error] <0.3928.0> CRASH REPORT Process <0.3928.0> with 0 neighbours exited with reason: {{#{'__exception__' => true,'__struct__' => 'Elixir.Phoenix.Template.UndefinedError',assigns => #{'__phx_template_not_found__' => 'Elixir.RailwayUiWeb.PublishedMessageView',data => #{'__struct__' => 'Elixir.RailwayUiWeb.PublishedMessageLive.Index.State',current_user_uuid => <<"1f4c4051-fe12-41cf-a39a-49f794f6b333">>,flash => #{},page => 4,page_nums => 8,query_filter => nil,query_value => nil,search => #{'__struct__' => 'Elixir.RailwayUiWeb.PublishedMessageLive.Index.Search',query => nil,...}},...},...},...},...} in 'Elixir.Phoenix.Endpoint.Cowboy2Handler':init/4 line 59 in 'Elixir.Phoenix.Endpoint.Cowboy2Handler':init/4 line 59
2019-12-01 07:22:07.856 [error] <0.398.0> Lager event handler error_logger_lager_h exited with reason {'EXIT',{{case_clause,['Elixir.RailwayUiWeb.Endpoint.HTTP',<0.3911.0>,2,<0.3928.0>,{{#{'__exception__' => true,'__struct__' => 'Elixir.Phoenix.Template.UndefinedError',assigns => #{'__phx_template_not_found__' => 'Elixir.RailwayUiWeb.PublishedMessageView',data => #{'__struct__' => 'Elixir.RailwayUiWeb.PublishedMessageLive.Index.State',current_user_uuid => <<"1f4c4051-fe12-41cf-a39a-49f794f6b333">>,flash => #{},page => 4,page_nums => 8,query_filter => nil,query_value => nil,search => #{...}},...},...},...},...},...]},...}}
2019-12-01 07:22:16.320 [error] <0.3939.0> CRASH REPORT Process <0.3939.0> with 0 neighbours exited with reason: {{#{'__exception__' => true,'__struct__' => 'Elixir.Phoenix.Template.UndefinedError',assigns => #{'__phx_template_not_found__' => 'Elixir.RailwayUiWeb.PublishedMessageView',data => #{'__struct__' => 'Elixir.RailwayUiWeb.PublishedMessageLive.Index.State',current_user_uuid => <<"1f4c4051-fe12-41cf-a39a-49f794f6b333">>,flash => #{},page => 4,page_nums => 8,query_filter => nil,query_value => nil,search => #{'__struct__' => 'Elixir.RailwayUiWeb.PublishedMessageLive.Index.Search',query => nil,...}},...},...},...},...} in 'Elixir.Phoenix.Endpoint.Cowboy2Handler':init/4 line 59 in 'Elixir.Phoenix.Endpoint.Cowboy2Handler':init/4 line 59
2019-12-01 07:22:16.325 [error] <0.398.0> Lager event handler error_logger_lager_h exited with reason {'EXIT',{{case_clause,['Elixir.RailwayUiWeb.Endpoint.HTTP',<0.3938.0>,1,<0.3939.0>,{{#{'__exception__' => true,'__struct__' => 'Elixir.Phoenix.Template.UndefinedError',assigns => #{'__phx_template_not_found__' => 'Elixir.RailwayUiWeb.PublishedMessageView',data => #{'__struct__' => 'Elixir.RailwayUiWeb.PublishedMessageLive.Index.State',current_user_uuid => <<"1f4c4051-fe12-41cf-a39a-49f794f6b333">>,flash => #{},page => 4,page_nums => 8,query_filter => nil,query_value => nil,search => #{...}},...},...},...},...},...]},...}}
2019-12-01 07:22:17.866 [error] <0.3956.0> CRASH REPORT Process <0.3956.0> with 0 neighbours exited with reason: {{#{'__exception__' => true,'__struct__' => 'Elixir.Phoenix.Template.UndefinedError',assigns => #{'__phx_template_not_found__' => 'Elixir.RailwayUiWeb.PublishedMessageView',data => #{'__struct__' => 'Elixir.RailwayUiWeb.PublishedMessageLive.Index.State',current_user_uuid => <<"1f4c4051-fe12-41cf-a39a-49f794f6b333">>,flash => #{},page => 4,page_nums => 8,query_filter => nil,query_value => nil,search => #{'__struct__' => 'Elixir.RailwayUiWeb.PublishedMessageLive.Index.Search',query => nil,...}},...},...},...},...} in 'Elixir.Phoenix.Endpoint.Cowboy2Handler':init/4 line 59 in 'Elixir.Phoenix.Endpoint.Cowboy2Handler':init/4 line 59
2019-12-01 07:22:17.873 [error] <0.398.0> Lager event handler error_logger_lager_h exited with reason {'EXIT',{{case_clause,['Elixir.RailwayUiWeb.Endpoint.HTTP',<0.3938.0>,3,<0.3956.0>,{{#{'__exception__' => true,'__struct__' => 'Elixir.Phoenix.Template.UndefinedError',assigns => #{'__phx_template_not_found__' => 'Elixir.RailwayUiWeb.PublishedMessageView',data => #{'__struct__' => 'Elixir.RailwayUiWeb.PublishedMessageLive.Index.State',current_user_uuid => <<"1f4c4051-fe12-41cf-a39a-49f794f6b333">>,flash => #{},page => 4,page_nums => 8,query_filter => nil,query_value => nil,search => #{...}},...},...},...},...},...]},...}}
2019-12-01 07:23:15.140 [error] <0.3967.0> CRASH REPORT Process <0.3967.0> with 0 neighbours exited with reason: {{#{'__exception__' => true,'__struct__' => 'Elixir.Phoenix.Template.UndefinedError',assigns => #{'__phx_template_not_found__' => 'Elixir.RailwayUiWeb.PublishedMessageView',data => #{'__struct__' => 'Elixir.RailwayUiWeb.PublishedMessageLive.Index.State',current_user_uuid => <<"1f4c4051-fe12-41cf-a39a-49f794f6b333">>,flash => #{},page => 4,page_nums => 8,query_filter => nil,query_value => nil,search => #{'__struct__' => 'Elixir.RailwayUiWeb.PublishedMessageLive.Index.Search',query => nil,...}},...},...},...},...} in 'Elixir.Phoenix.Endpoint.Cowboy2Handler':init/4 line 59 in 'Elixir.Phoenix.Endpoint.Cowboy2Handler':init/4 line 59
2019-12-01 07:23:15.152 [error] <0.398.0> Lager event handler error_logger_lager_h exited with reason {'EXIT',{{case_clause,['Elixir.RailwayUiWeb.Endpoint.HTTP',<0.3966.0>,1,<0.3967.0>,{{#{'__exception__' => true,'__struct__' => 'Elixir.Phoenix.Template.UndefinedError',assigns => #{'__phx_template_not_found__' => 'Elixir.RailwayUiWeb.PublishedMessageView',data => #{'__struct__' => 'Elixir.RailwayUiWeb.PublishedMessageLive.Index.State',current_user_uuid => <<"1f4c4051-fe12-41cf-a39a-49f794f6b333">>,flash => #{},page => 4,page_nums => 8,query_filter => nil,query_value => nil,search => #{...}},...},...},...},...},...]},...}}
2019-12-01 07:23:39.270 [error] <0.3983.0> CRASH REPORT Process <0.3983.0> with 0 neighbours exited with reason: {{#{'__exception__' => true,'__struct__' => 'Elixir.Phoenix.Template.UndefinedError',assigns => #{'__phx_template_not_found__' => 'Elixir.RailwayUiWeb.PublishedMessageView',data => #{'__struct__' => 'Elixir.RailwayUiWeb.PublishedMessageLive.Index.State',current_user_uuid => <<"1f4c4051-fe12-41cf-a39a-49f794f6b333">>,flash => #{},page => 4,page_nums => 8,query_filter => nil,query_value => nil,search => #{'__struct__' => 'Elixir.RailwayUiWeb.PublishedMessageLive.Index.Search',query => nil,...}},...},...},...},...} in 'Elixir.Phoenix.Endpoint.Cowboy2Handler':init/4 line 59 in 'Elixir.Phoenix.Endpoint.Cowboy2Handler':init/4 line 59
2019-12-01 07:23:39.279 [error] <0.398.0> Lager event handler error_logger_lager_h exited with reason {'EXIT',{{case_clause,['Elixir.RailwayUiWeb.Endpoint.HTTP',<0.3981.0>,1,<0.3983.0>,{{#{'__exception__' => true,'__struct__' => 'Elixir.Phoenix.Template.UndefinedError',assigns => #{'__phx_template_not_found__' => 'Elixir.RailwayUiWeb.PublishedMessageView',data => #{'__struct__' => 'Elixir.RailwayUiWeb.PublishedMessageLive.Index.State',current_user_uuid => <<"1f4c4051-fe12-41cf-a39a-49f794f6b333">>,flash => #{},page => 4,page_nums => 8,query_filter => nil,query_value => nil,search => #{...}},...},...},...},...},...]},...}}
2019-12-01 07:23:49.186 [error] <0.4001.0> CRASH REPORT Process <0.4001.0> with 0 neighbours exited with reason: {{#{'__exception__' => true,'__struct__' => 'Elixir.Phoenix.Template.UndefinedError',assigns => #{'__phx_template_not_found__' => 'Elixir.RailwayUiWeb.PublishedMessageView',data => #{'__struct__' => 'Elixir.RailwayUiWeb.PublishedMessageLive.Index.State',current_user_uuid => <<"1f4c4051-fe12-41cf-a39a-49f794f6b333">>,flash => #{},page => 4,page_nums => 8,query_filter => nil,query_value => nil,search => #{'__struct__' => 'Elixir.RailwayUiWeb.PublishedMessageLive.Index.Search',query => nil,...}},...},...},...},...} in 'Elixir.Phoenix.Endpoint.Cowboy2Handler':init/4 line 59 in 'Elixir.Phoenix.Endpoint.Cowboy2Handler':init/4 line 59
2019-12-01 07:23:49.253 [error] <0.398.0> Lager event handler error_logger_lager_h exited with reason {'EXIT',{{case_clause,['Elixir.RailwayUiWeb.Endpoint.HTTP',<0.3999.0>,1,<0.4001.0>,{{#{'__exception__' => true,'__struct__' => 'Elixir.Phoenix.Template.UndefinedError',assigns => #{'__phx_template_not_found__' => 'Elixir.RailwayUiWeb.PublishedMessageView',data => #{'__struct__' => 'Elixir.RailwayUiWeb.PublishedMessageLive.Index.State',current_user_uuid => <<"1f4c4051-fe12-41cf-a39a-49f794f6b333">>,flash => #{},page => 4,page_nums => 8,query_filter => nil,query_value => nil,search => #{...}},...},...},...},...},...]},...}}
2019-12-01 07:24:09.120 [error] <0.433.0> Supervisor 'Elixir.RailwayIpc.Connection.Supervisor' had child 'Elixir.RailwayIpc.Connection' started with 'Elixir.RailwayIpc.Connection':start_link([{name,'Elixir.RailwayIpc.Connection'}]) at <0.3798.0> exit with reason normal in context child_terminated
2019-12-01 07:25:41.270 [error] <0.4087.0> CRASH REPORT Process <0.4087.0> with 0 neighbours exited with reason: {{#{'__exception__' => true,'__struct__' => 'Elixir.Phoenix.Template.UndefinedError',assigns => #{'__phx_template_not_found__' => 'Elixir.RailwayUiWeb.MessageView',data => #{'__struct__' => 'Elixir.RailwayUiWeb.PublishedMessageLive.Index.State',current_user_uuid => <<"1f4c4051-fe12-41cf-a39a-49f794f6b333">>,flash => #{},page => 4,page_nums => 8,query_filter => nil,query_value => nil,search => #{'__struct__' => 'Elixir.RailwayUiWeb.PublishedMessageLive.Index.Search',query => nil,value => nil}},...},...},...},...} in 'Elixir.Phoenix.Endpoint.Cowboy2Handler':init/4 line 59 in 'Elixir.Phoenix.Endpoint.Cowboy2Handler':init/4 line 59
2019-12-01 07:25:41.277 [error] <0.398.0> Lager event handler error_logger_lager_h exited with reason {'EXIT',{{case_clause,['Elixir.RailwayUiWeb.Endpoint.HTTP',<0.4085.0>,1,<0.4087.0>,{{#{'__exception__' => true,'__struct__' => 'Elixir.Phoenix.Template.UndefinedError',assigns => #{'__phx_template_not_found__' => 'Elixir.RailwayUiWeb.MessageView',data => #{'__struct__' => 'Elixir.RailwayUiWeb.PublishedMessageLive.Index.State',current_user_uuid => <<"1f4c4051-fe12-41cf-a39a-49f794f6b333">>,flash => #{},page => 4,page_nums => 8,query_filter => nil,query_value => nil,search => #{'__struct__' => ...,...}},...},...},...},...},...]},...}}
2019-12-01 07:26:55.286 [error] <0.4198.0> CRASH REPORT Process <0.4198.0> with 0 neighbours exited with reason: {{#{'__exception__' => true,'__struct__' => 'Elixir.Phoenix.Template.UndefinedError',assigns => #{'__phx_template_not_found__' => 'Elixir.RailwayUiWeb.MessageView',data => #{'__struct__' => 'Elixir.RailwayUiWeb.PublishedMessageLive.Index.State',current_user_uuid => <<"1f4c4051-fe12-41cf-a39a-49f794f6b333">>,flash => #{},page => 1,page_nums => 5,query_filter => nil,query_value => nil,search => #{'__struct__' => 'Elixir.RailwayUiWeb.PublishedMessageLive.Index.Search',query => <<"message_ty...">>,...}},...},...},...},...} in 'Elixir.Phoenix.Endpoint.Cowboy2Handler':init/4 line 59 in 'Elixir.Phoenix.Endpoint.Cowboy2Handler':init/4 line 59
2019-12-01 07:26:55.346 [error] <0.398.0> Lager event handler error_logger_lager_h exited with reason {'EXIT',{{case_clause,['Elixir.RailwayUiWeb.Endpoint.HTTP',<0.4196.0>,1,<0.4198.0>,{{#{'__exception__' => true,'__struct__' => 'Elixir.Phoenix.Template.UndefinedError',assigns => #{'__phx_template_not_found__' => 'Elixir.RailwayUiWeb.MessageView',data => #{'__struct__' => 'Elixir.RailwayUiWeb.PublishedMessageLive.Index.State',current_user_uuid => <<"1f4c4051-fe12-41cf-a39a-49f794f6b333">>,flash => #{},page => 1,page_nums => 5,query_filter => nil,query_value => nil,search => #{'__struct__' => ...,...}},...},...},...},...},...]},...}}
2019-12-01 07:27:39.272 [error] <0.4283.0> CRASH REPORT Process <0.4283.0> with 0 neighbours exited with reason: {{#{'__exception__' => true,'__struct__' => 'Elixir.Phoenix.Template.UndefinedError',assigns => #{'__phx_template_not_found__' => 'Elixir.RailwayUiWeb.MessageView',data => #{'__struct__' => 'Elixir.RailwayUiWeb.PublishedMessageLive.Index.State',current_user_uuid => <<"1f4c4051-fe12-41cf-a39a-49f794f6b333">>,flash => #{},page => 1,page_nums => 5,query_filter => nil,query_value => nil,search => #{'__struct__' => 'Elixir.RailwayUiWeb.PublishedMessageLive.Index.Search',query => <<"message_ty...">>,...}},...},...},...},...} in 'Elixir.Phoenix.Endpoint.Cowboy2Handler':init/4 line 59 in 'Elixir.Phoenix.Endpoint.Cowboy2Handler':init/4 line 59
2019-12-01 07:27:39.278 [error] <0.398.0> Lager event handler error_logger_lager_h exited with reason {'EXIT',{{case_clause,['Elixir.RailwayUiWeb.Endpoint.HTTP',<0.4280.0>,1,<0.4283.0>,{{#{'__exception__' => true,'__struct__' => 'Elixir.Phoenix.Template.UndefinedError',assigns => #{'__phx_template_not_found__' => 'Elixir.RailwayUiWeb.MessageView',data => #{'__struct__' => 'Elixir.RailwayUiWeb.PublishedMessageLive.Index.State',current_user_uuid => <<"1f4c4051-fe12-41cf-a39a-49f794f6b333">>,flash => #{},page => 1,page_nums => 5,query_filter => nil,query_value => nil,search => #{'__struct__' => ...,...}},...},...},...},...},...]},...}}
2019-12-01 07:31:45.055 [error] <0.4369.0> gen_server <0.4369.0> terminated with reason: {#{'__exception__' => true,'__struct__' => 'Elixir.UndefinedFunctionError',arity => 1,function => render,message => nil,module => 'Elixir.RailwayUiWeb.PublishedMessageLive.Index',reason => nil},[{'Elixir.RailwayUiWeb.PublishedMessageLive.Index',render,[#{socket => #{'__struct__' => 'Elixir.Phoenix.LiveView.Socket',assigns => #{},changed => #{},'connected?' => true,endpoint => 'Elixir.RailwayUiWeb.Endpoint',fingerprints => {nil,#{}},id => <<"phx-lmcGKu2q">>,parent_pid => nil,private => #{...},...}}],...},...]}
2019-12-01 07:31:45.056 [error] <0.4369.0> CRASH REPORT Process <0.4369.0> with 0 neighbours crashed with reason: {#{'__exception__' => true,'__struct__' => 'Elixir.UndefinedFunctionError',arity => 1,function => render,message => nil,module => 'Elixir.RailwayUiWeb.PublishedMessageLive.Index',reason => nil},[{'Elixir.RailwayUiWeb.PublishedMessageLive.Index',render,[#{socket => #{'__struct__' => 'Elixir.Phoenix.LiveView.Socket',assigns => #{},changed => #{},'connected?' => true,endpoint => 'Elixir.RailwayUiWeb.Endpoint',fingerprints => {nil,#{}},id => <<"phx-lmcGKu2q">>,parent_pid => nil,private => #{...},...}}],...},...]}
2019-12-01 07:31:45.057 [error] <0.520.0> Supervisor {<0.520.0>,'Elixir.Phoenix.Socket.PoolSupervisor.WorkerSupervisor'} had child 'Elixir.Phoenix.Channel.Server' started with {'Elixir.Phoenix.Channel.Server',start_link,undefined} at <0.4369.0> exit with reason {#{'__exception__' => true,'__struct__' => 'Elixir.UndefinedFunctionError',arity => 1,function => render,message => nil,module => 'Elixir.RailwayUiWeb.PublishedMessageLive.Index',reason => nil},[{'Elixir.RailwayUiWeb.PublishedMessageLive.Index',render,[#{socket => #{'__struct__' => 'Elixir.Phoenix.LiveView.Socket',assigns => #{},changed => #{},'connected?' => true,endpoint => 'Elixir.RailwayUiWeb.Endpoint',fingerprints => {nil,#{}},id => <<"phx-lmcGKu2q">>,parent_pid => nil,private => #{...},...}}],...},...]} in context child_terminated
2019-12-01 07:31:45.096 [error] <0.4351.0> CRASH REPORT Process <0.4351.0> with 0 neighbours exited with reason: {{#{'__exception__' => true,'__struct__' => 'Elixir.UndefinedFunctionError',arity => 1,function => render,message => nil,module => 'Elixir.RailwayUiWeb.PublishedMessageLive.Index',reason => nil},[{'Elixir.RailwayUiWeb.PublishedMessageLive.Index',render,[#{socket => #{'__struct__' => 'Elixir.Phoenix.LiveView.Socket',assigns => #{},changed => #{},'connected?' => false,endpoint => 'Elixir.RailwayUiWeb.Endpoint',fingerprints => {nil,#{}},id => <<"phx-LB8kZ73p">>,parent_pid => nil,private => #{...},...}}],...},...]},...} in 'Elixir.Phoenix.Endpoint.Cowboy2Handler':init/4 line 59 in 'Elixir.Phoenix.Endpoint.Cowboy2Handler':init/4 line 59
2019-12-01 07:31:45.105 [error] <0.398.0> Lager event handler error_logger_lager_h exited with reason {'EXIT',{{case_clause,['Elixir.RailwayUiWeb.Endpoint.HTTP',<0.4349.0>,1,<0.4351.0>,{{#{'__exception__' => true,'__struct__' => 'Elixir.UndefinedFunctionError',arity => 1,function => render,message => nil,module => 'Elixir.RailwayUiWeb.PublishedMessageLive.Index',reason => nil},[{'Elixir.RailwayUiWeb.PublishedMessageLive.Index',render,[#{socket => #{'__struct__' => 'Elixir.Phoenix.LiveView.Socket',assigns => #{},changed => #{},'connected?' => false,endpoint => 'Elixir.RailwayUiWeb.Endpoint',...}}],...},...]},...},...]},...}}
2019-12-01 07:32:40.767 [error] <0.4382.0> CRASH REPORT Process <0.4382.0> with 0 neighbours exited with reason: {{#{'__exception__' => true,'__struct__' => 'Elixir.UndefinedFunctionError',arity => 1,function => render,message => nil,module => 'Elixir.RailwayUiWeb.PublishedMessageLive.Index',reason => nil},[{'Elixir.RailwayUiWeb.PublishedMessageLive.Index',render,[#{socket => #{'__struct__' => 'Elixir.Phoenix.LiveView.Socket',assigns => #{},changed => #{},'connected?' => false,endpoint => 'Elixir.RailwayUiWeb.Endpoint',fingerprints => {nil,#{}},id => <<"phx-y0Grmm6h">>,parent_pid => nil,private => #{...},...}}],...},...]},...} in 'Elixir.Phoenix.Endpoint.Cowboy2Handler':init/4 line 59 in 'Elixir.Phoenix.Endpoint.Cowboy2Handler':init/4 line 59
2019-12-01 07:32:40.772 [error] <0.398.0> Lager event handler error_logger_lager_h exited with reason {'EXIT',{{case_clause,['Elixir.RailwayUiWeb.Endpoint.HTTP',<0.4380.0>,1,<0.4382.0>,{{#{'__exception__' => true,'__struct__' => 'Elixir.UndefinedFunctionError',arity => 1,function => render,message => nil,module => 'Elixir.RailwayUiWeb.PublishedMessageLive.Index',reason => nil},[{'Elixir.RailwayUiWeb.PublishedMessageLive.Index',render,[#{socket => #{'__struct__' => 'Elixir.Phoenix.LiveView.Socket',assigns => #{},changed => #{},'connected?' => false,endpoint => 'Elixir.RailwayUiWeb.Endpoint',...}}],...},...]},...},...]},...}}
2019-12-01 07:40:46.832 [error] <0.4688.0> gen_server <0.4688.0> terminated with reason: {#{'__exception__' => true,'__struct__' => 'Elixir.UndefinedFunctionError',arity => 1,function => load_messages,message => nil,module => 'Elixir.RailwayUiWeb.PublishedMessageLive.Index.State',reason => nil},[{'Elixir.RailwayUiWeb.PublishedMessageLive.Index.State',load_messages,['Elixir.RailwayUi.PublishedMessage'],[]},{'Elixir.RailwayUiWeb.PublishedMessageLive.Index',mount,2,[{file,"lib/railway_ui_web/live/published_message_live/index.ex"},{line,2}]},{'Elixir.Phoenix.LiveView.Utils','maybe_call_mount!',...},...]}
2019-12-01 07:40:46.833 [error] <0.4688.0> CRASH REPORT Process <0.4688.0> with 0 neighbours crashed with reason: {#{'__exception__' => true,'__struct__' => 'Elixir.UndefinedFunctionError',arity => 1,function => load_messages,message => nil,module => 'Elixir.RailwayUiWeb.PublishedMessageLive.Index.State',reason => nil},[{'Elixir.RailwayUiWeb.PublishedMessageLive.Index.State',load_messages,['Elixir.RailwayUi.PublishedMessage'],[]},{'Elixir.RailwayUiWeb.PublishedMessageLive.Index',mount,2,[{file,"lib/railway_ui_web/live/published_message_live/index.ex"},{line,2}]},{'Elixir.Phoenix.LiveView.Utils','maybe_call_mount!',...},...]}
2019-12-01 07:40:46.833 [error] <0.521.0> Supervisor {<0.521.0>,'Elixir.Phoenix.Socket.PoolSupervisor.WorkerSupervisor'} had child 'Elixir.Phoenix.Channel.Server' started with {'Elixir.Phoenix.Channel.Server',start_link,undefined} at <0.4688.0> exit with reason {#{'__exception__' => true,'__struct__' => 'Elixir.UndefinedFunctionError',arity => 1,function => load_messages,message => nil,module => 'Elixir.RailwayUiWeb.PublishedMessageLive.Index.State',reason => nil},[{'Elixir.RailwayUiWeb.PublishedMessageLive.Index.State',load_messages,['Elixir.RailwayUi.PublishedMessage'],[]},{'Elixir.RailwayUiWeb.PublishedMessageLive.Index',mount,2,[{file,"lib/railway_ui_web/live/published_message_live/index.ex"},{line,2}]},{'Elixir.Phoenix.LiveView.Utils','maybe_call_mount!',...},...]} in context child_terminated
2019-12-01 07:40:46.881 [error] <0.4670.0> CRASH REPORT Process <0.4670.0> with 0 neighbours exited with reason: {{#{'__exception__' => true,'__struct__' => 'Elixir.UndefinedFunctionError',arity => 1,function => load_messages,message => nil,module => 'Elixir.RailwayUiWeb.PublishedMessageLive.Index.State',reason => nil},[{'Elixir.RailwayUiWeb.PublishedMessageLive.Index.State',load_messages,['Elixir.RailwayUi.PublishedMessage'],[]},{'Elixir.RailwayUiWeb.PublishedMessageLive.Index',mount,2,[{file,"lib/railway_ui_web/live/published_message_live/index.ex"},{line,2}]},{'Elixir.Phoenix.LiveView.Utils','maybe_call_mount!',...},...]},...} in 'Elixir.Phoenix.Endpoint.Cowboy2Handler':init/4 line 59 in 'Elixir.Phoenix.Endpoint.Cowboy2Handler':init/4 line 59
2019-12-01 07:40:46.929 [error] <0.398.0> Lager event handler error_logger_lager_h exited with reason {'EXIT',{{case_clause,['Elixir.RailwayUiWeb.Endpoint.HTTP',<0.4668.0>,1,<0.4670.0>,{{#{'__exception__' => true,'__struct__' => 'Elixir.UndefinedFunctionError',arity => 1,function => load_messages,message => nil,module => 'Elixir.RailwayUiWeb.PublishedMessageLive.Index.State',reason => nil},[{'Elixir.RailwayUiWeb.PublishedMessageLive.Index.State',load_messages,['Elixir.RailwayUi.PublishedMessage'],[]},{'Elixir.RailwayUiWeb.PublishedMessageLive.Index',mount,2,[{file,"lib/railway_ui_web/live..."},...]},...]},...},...]},...}}
2019-12-01 07:41:42.388 [error] <0.4727.0>@Elixir.RailwayUiWeb.PublishedMessageLive.Index:handle_params:2 gen_server <0.4727.0> terminated with reason: call to undefined function 'Elixir.RailwayUiWeb.PublishedMessageLive.Index.State':load_messages/0 from 'Elixir.RailwayUiWeb.PublishedMessageLive.Index':handle_params/3 line 2
2019-12-01 07:41:42.389 [error] <0.4727.0>@Elixir.RailwayUiWeb.PublishedMessageLive.Index.State:load_messages CRASH REPORT Process <0.4727.0> with 0 neighbours crashed with reason: call to undefined function 'Elixir.RailwayUiWeb.PublishedMessageLive.Index.State':load_messages()
2019-12-01 07:41:42.389 [error] <0.522.0>@Elixir.RailwayUiWeb.PublishedMessageLive.Index.State:load_messages Supervisor {<0.522.0>,'Elixir.Phoenix.Socket.PoolSupervisor.WorkerSupervisor'} had child 'Elixir.Phoenix.Channel.Server' started with {'Elixir.Phoenix.Channel.Server',start_link,undefined} at <0.4727.0> exit with reason call to undefined function 'Elixir.RailwayUiWeb.PublishedMessageLive.Index.State':load_messages() in context child_terminated
2019-12-01 07:44:17.276 [error] <0.4798.0>@Elixir.RailwayUiWeb.PublishedMessageLive.Index:handle_params:2 gen_server <0.4798.0> terminated with reason: call to undefined function 'Elixir.RailwayUiWeb.PublishedMessageLive.Index.State':for_search/3 from 'Elixir.RailwayUiWeb.PublishedMessageLive.Index':handle_params/3 line 2
2019-12-01 07:44:17.276 [error] <0.4798.0>@Elixir.RailwayUiWeb.PublishedMessageLive.Index.State:for_search CRASH REPORT Process <0.4798.0> with 0 neighbours crashed with reason: call to undefined function 'Elixir.RailwayUiWeb.PublishedMessageLive.Index.State':for_search(#{'__struct__' => 'Elixir.RailwayUiWeb.PublishedMessageLive.Index.State',current_user_uuid => <<"...">>,...}, <<"message_type">>, <<"CreateBatch">>)
2019-12-01 07:44:17.277 [error] <0.520.0>@Elixir.RailwayUiWeb.PublishedMessageLive.Index.State:for_search Supervisor {<0.520.0>,'Elixir.Phoenix.Socket.PoolSupervisor.WorkerSupervisor'} had child 'Elixir.Phoenix.Channel.Server' started with {'Elixir.Phoenix.Channel.Server',start_link,undefined} at <0.4798.0> exit with reason call to undefined function 'Elixir.RailwayUiWeb.PublishedMessageLive.Index.State':for_search(#{'__struct__' => 'Elixir.RailwayUiWeb.PublishedMessageLive.Index.State',current_user_uuid => <<"...">>,...}, <<"message_type">>, <<"CreateBatch">>) in context child_terminated
2019-12-01 07:56:24.460 [error] <0.4844.0> CRASH REPORT Process <0.4844.0> with 0 neighbours exited with reason: {{#{'__exception__' => true,'__struct__' => 'Elixir.UndefinedFunctionError',arity => 2,function => consumed_message_path,message => nil,module => 'Elixir.RailwayUiWeb.Router.Helpers',reason => nil},[{'Elixir.RailwayUiWeb.Router.Helpers',consumed_message_path,[#{'__struct__' => 'Elixir.Plug.Conn',adapter => {'Elixir.Plug.Cowboy.Conn',#{bindings => #{},body_length => 0,cert => undefined,has_body => false,headers => #{<<"accept">> => <<"text/html,application/xhtml+xml,application/xml;q=0.9,...">>,...},...}},...},...],...},...]},...} in 'Elixir.Phoenix.Endpoint.Cowboy2Handler':init/4 line 59 in 'Elixir.Phoenix.Endpoint.Cowboy2Handler':init/4 line 59
2019-12-01 07:56:24.518 [error] <0.398.0> Lager event handler error_logger_lager_h exited with reason {'EXIT',{{case_clause,['Elixir.RailwayUiWeb.Endpoint.HTTP',<0.4843.0>,1,<0.4844.0>,{{#{'__exception__' => true,'__struct__' => 'Elixir.UndefinedFunctionError',arity => 2,function => consumed_message_path,message => nil,module => 'Elixir.RailwayUiWeb.Router.Helpers',reason => nil},[{'Elixir.RailwayUiWeb.Router.Helpers',consumed_message_path,[#{'__struct__' => 'Elixir.Plug.Conn',adapter => {'Elixir.Plug.Cowboy.Conn',#{bindings => #{},body_length => 0,cert => undefined,has_body => false,headers => ...,...}},...},...],...},...]},...},...]},...}}
2019-12-01 07:56:44.539 [error] <0.4896.0> CRASH REPORT Process <0.4896.0> with 0 neighbours exited with reason: {{#{'__exception__' => true,'__struct__' => 'Elixir.UndefinedFunctionError',arity => 2,function => consumed_message_path,message => nil,module => 'Elixir.RailwayUiWeb.Router.Helpers',reason => nil},[{'Elixir.RailwayUiWeb.Router.Helpers',consumed_message_path,[#{'__struct__' => 'Elixir.Plug.Conn',adapter => {'Elixir.Plug.Cowboy.Conn',#{bindings => #{},body_length => 0,cert => undefined,has_body => false,headers => #{<<"accept">> => <<"text/html,application/xhtml+xml,application/xml;q=0.9,...">>,...},...}},...},...],...},...]},...} in 'Elixir.Phoenix.Endpoint.Cowboy2Handler':init/4 line 59 in 'Elixir.Phoenix.Endpoint.Cowboy2Handler':init/4 line 59
2019-12-01 07:56:44.615 [error] <0.398.0> Lager event handler error_logger_lager_h exited with reason {'EXIT',{{case_clause,['Elixir.RailwayUiWeb.Endpoint.HTTP',<0.4894.0>,1,<0.4896.0>,{{#{'__exception__' => true,'__struct__' => 'Elixir.UndefinedFunctionError',arity => 2,function => consumed_message_path,message => nil,module => 'Elixir.RailwayUiWeb.Router.Helpers',reason => nil},[{'Elixir.RailwayUiWeb.Router.Helpers',consumed_message_path,[#{'__struct__' => 'Elixir.Plug.Conn',adapter => {'Elixir.Plug.Cowboy.Conn',#{bindings => #{},body_length => 0,cert => undefined,has_body => false,headers => ...,...}},...},...],...},...]},...},...]},...}}
2019-12-01 07:58:26.280 [error] <0.4920.0> CRASH REPORT Process <0.4920.0> with 0 neighbours exited with reason: {{#{'__exception__' => true,'__struct__' => 'Elixir.UndefinedFunctionError',arity => 2,function => consumed_message_path,message => nil,module => 'Elixir.RailwayUiWeb.Router.Helpers',reason => nil},[{'Elixir.RailwayUiWeb.Router.Helpers',consumed_message_path,[#{'__struct__' => 'Elixir.Plug.Conn',adapter => {'Elixir.Plug.Cowboy.Conn',#{bindings => #{},body_length => 0,cert => undefined,has_body => false,headers => #{<<"accept">> => <<"text/html,application/xhtml+xml,application/xml;q=0.9,...">>,...},...}},...},...],...},...]},...} in 'Elixir.Phoenix.Endpoint.Cowboy2Handler':init/4 line 59 in 'Elixir.Phoenix.Endpoint.Cowboy2Handler':init/4 line 59
2019-12-01 07:58:26.290 [error] <0.398.0> Lager event handler error_logger_lager_h exited with reason {'EXIT',{{case_clause,['Elixir.RailwayUiWeb.Endpoint.HTTP',<0.4918.0>,1,<0.4920.0>,{{#{'__exception__' => true,'__struct__' => 'Elixir.UndefinedFunctionError',arity => 2,function => consumed_message_path,message => nil,module => 'Elixir.RailwayUiWeb.Router.Helpers',reason => nil},[{'Elixir.RailwayUiWeb.Router.Helpers',consumed_message_path,[#{'__struct__' => 'Elixir.Plug.Conn',adapter => {'Elixir.Plug.Cowboy.Conn',#{bindings => #{},body_length => 0,cert => undefined,has_body => false,headers => ...,...}},...},...],...},...]},...},...]},...}}
2019-12-01 08:00:51.322 [error] <0.5072.0> gen_server <0.5072.0> terminated with reason: #{'__exception__' => true,'__struct__' => 'Elixir.ArgumentError',message => <<"assign @view not available in eex template.\n\nPlease make sure all proper assigns have been set. If this\nis a child template, ensure assigns are given explicitly by\nthe parent template as they are not automatically forwarded.\n\nAvailable assigns: [:data, :messages, :socket, :view_module, :view_template]\n">>} in 'Elixir.Phoenix.LiveView.Engine':'fetch_assign!'/2 line 769
2019-12-01 08:00:51.324 [error] <0.5072.0> CRASH REPORT Process <0.5072.0> with 0 neighbours crashed with reason: #{'__exception__' => true,'__struct__' => 'Elixir.ArgumentError',message => <<"assign @view not available in eex template.\n\nPlease make sure all proper assigns have been set. If this\nis a child template, ensure assigns are given explicitly by\nthe parent template as they are not automatically forwarded.\n\nAvailable assigns: [:data, :messages, :socket, :view_module, :view_template]\n">>} in 'Elixir.Phoenix.LiveView.Engine':'fetch_assign!'/2 line 769
2019-12-01 08:00:51.325 [error] <0.522.0> Supervisor {<0.522.0>,'Elixir.Phoenix.Socket.PoolSupervisor.WorkerSupervisor'} had child 'Elixir.Phoenix.Channel.Server' started with {'Elixir.Phoenix.Channel.Server',start_link,undefined} at <0.5072.0> exit with reason #{'__exception__' => true,'__struct__' => 'Elixir.ArgumentError',message => <<"assign @view not available in eex template.\n\nPlease make sure all proper assigns have been set. If this\nis a child template, ensure assigns are given explicitly by\nthe parent template as they are not automatically forwarded.\n\nAvailable assigns: [:data, :messages, :socket, :view_module, :view_template]\n">>} in 'Elixir.Phoenix.LiveView.Engine':'fetch_assign!'/2 line 769 in context child_terminated
2019-12-01 08:00:51.363 [error] <0.5049.0> CRASH REPORT Process <0.5049.0> with 0 neighbours exited with reason: {{#{'__exception__' => true,'__struct__' => 'Elixir.ArgumentError',message => <<"assign @view not available in eex template.\n\nPlease make sure all proper assigns have been set. If this\nis a child template, ensure assigns are given explicitly by\nthe parent template as they are not automatically forwarded.\n\nAvailable assigns: [:data, :messages, :socket, :view_module, :view_template]\n">>},[{'Elixir.Phoenix.LiveView.Engine','fetch_assign!',2,[{file,"lib/phoenix_live_view/engine.ex"},{line,769}]},...]},...} in 'Elixir.Phoenix.Endpoint.Cowboy2Handler':init/4 line 59 in 'Elixir.Phoenix.Endpoint.Cowboy2Handler':init/4 line 59
2019-12-01 08:00:51.372 [error] <0.398.0> Lager event handler error_logger_lager_h exited with reason {'EXIT',{{case_clause,['Elixir.RailwayUiWeb.Endpoint.HTTP',<0.5048.0>,1,<0.5049.0>,{{#{'__exception__' => true,'__struct__' => 'Elixir.ArgumentError',message => <<"assign @view not available in eex template.\n\nPlease make sure all proper assigns have been set. If this\nis a child template, ensure assigns are given explicitly by\nthe parent template as they are not automatically forwarded.\n\nAvailable assigns: [:data, :messages, :socket, :view_module, :view_template]\n">>},[{'Elixir.Phoenix.LiveView.Engine',...},...]},...},...]},...}}
2019-12-01 08:01:15.035 [error] <0.5084.0> CRASH REPORT Process <0.5084.0> with 0 neighbours exited with reason: {{#{'__exception__' => true,'__struct__' => 'Elixir.ArgumentError',message => <<"no function clause for RailwayUiWeb.Router.Helpers.live_path/3 and action RailwayUiWeb.PublishedMessageView. The following actions/clauses are supported:\n\n    live_path(conn_or_endpoint, RailwayUiWeb.ConsumedMessageLive.Index, params \\\\ [])\n    live_path(conn_or_endpoint, RailwayUiWeb.PublishedMessageLive.Index, params \\\\ [])">>},[{'Elixir.Phoenix.Router.Helpers',raise_route_error,6,[{file,"lib/phoenix/ro..."},...]},...]},...} in 'Elixir.Phoenix.Endpoint.Cowboy2Handler':init/4 line 59 in 'Elixir.Phoenix.Endpoint.Cowboy2Handler':init/4 line 59
2019-12-01 08:01:15.047 [error] <0.398.0> Lager event handler error_logger_lager_h exited with reason {'EXIT',{{case_clause,['Elixir.RailwayUiWeb.Endpoint.HTTP',<0.5083.0>,1,<0.5084.0>,{{#{'__exception__' => true,'__struct__' => 'Elixir.ArgumentError',message => <<"no function clause for RailwayUiWeb.Router.Helpers.live_path/3 and action RailwayUiWeb.PublishedMessageView. The following actions/clauses are supported:\n\n    live_path(conn_or_endpoint, RailwayUiWeb.ConsumedMessageLive.Index, params \\\\ [])\n    live_path(conn_or_endpoint, RailwayUiWeb.PublishedMessageLive.Index, params \\\\ [])">>},...},...},...]},...}}
2019-12-01 08:01:47.467 [error] <0.5117.0> CRASH REPORT Process <0.5117.0> with 0 neighbours exited with reason: {{#{'__exception__' => true,'__struct__' => 'Elixir.ArgumentError',message => <<"no function clause for RailwayUiWeb.Router.Helpers.live_path/3 and action RailwayUiWeb.PublishedMessageView. The following actions/clauses are supported:\n\n    live_path(conn_or_endpoint, RailwayUiWeb.ConsumedMessageLive.Index, params \\\\ [])\n    live_path(conn_or_endpoint, RailwayUiWeb.PublishedMessageLive.Index, params \\\\ [])">>},[{'Elixir.Phoenix.Router.Helpers',raise_route_error,6,[{file,"lib/phoenix/ro..."},...]},...]},...} in 'Elixir.Phoenix.Endpoint.Cowboy2Handler':init/4 line 59 in 'Elixir.Phoenix.Endpoint.Cowboy2Handler':init/4 line 59
2019-12-01 08:01:47.473 [error] <0.398.0> Lager event handler error_logger_lager_h exited with reason {'EXIT',{{case_clause,['Elixir.RailwayUiWeb.Endpoint.HTTP',<0.5116.0>,1,<0.5117.0>,{{#{'__exception__' => true,'__struct__' => 'Elixir.ArgumentError',message => <<"no function clause for RailwayUiWeb.Router.Helpers.live_path/3 and action RailwayUiWeb.PublishedMessageView. The following actions/clauses are supported:\n\n    live_path(conn_or_endpoint, RailwayUiWeb.ConsumedMessageLive.Index, params \\\\ [])\n    live_path(conn_or_endpoint, RailwayUiWeb.PublishedMessageLive.Index, params \\\\ [])">>},...},...},...]},...}}
2019-12-01 08:24:56.477 [error] <0.5396.0> CRASH REPORT Process <0.5396.0> with 0 neighbours exited with reason: {{#{'__exception__' => true,'__struct__' => 'Elixir.ArgumentError',message => <<"assign @data not available in eex template.\n\nPlease make sure all proper assigns have been set. If this\nis a child template, ensure assigns are given explicitly by\nthe parent template as they are not automatically forwarded.\n\nAvailable assigns: [:messages, :socket, :state, :view, :view_module, :view_template]\n">>},[{'Elixir.Phoenix.LiveView.Engine','fetch_assign!',2,[{file,"lib/phoenix_live_view/engine.ex"},{line,...}]},...]},...} in 'Elixir.Phoenix.Endpoint.Cowboy2Handler':init/4 line 59 in 'Elixir.Phoenix.Endpoint.Cowboy2Handler':init/4 line 59
2019-12-01 08:24:56.482 [error] <0.398.0> Lager event handler error_logger_lager_h exited with reason {'EXIT',{{case_clause,['Elixir.RailwayUiWeb.Endpoint.HTTP',<0.5395.0>,1,<0.5396.0>,{{#{'__exception__' => true,'__struct__' => 'Elixir.ArgumentError',message => <<"assign @data not available in eex template.\n\nPlease make sure all proper assigns have been set. If this\nis a child template, ensure assigns are given explicitly by\nthe parent template as they are not automatically forwarded.\n\nAvailable assigns: [:messages, :socket, :state, :view, :view_module, :view_template]\n">>},[{'Elixir.Phoenix.LiveView.Engine',...},...]},...},...]},...}}
2019-12-01 08:25:03.380 [error] <0.5434.0> CRASH REPORT Process <0.5434.0> with 0 neighbours exited with reason: {{#{'__exception__' => true,'__struct__' => 'Elixir.ArgumentError',message => <<"assign @data not available in eex template.\n\nPlease make sure all proper assigns have been set. If this\nis a child template, ensure assigns are given explicitly by\nthe parent template as they are not automatically forwarded.\n\nAvailable assigns: [:messages, :socket, :state, :view, :view_module, :view_template]\n">>},[{'Elixir.Phoenix.LiveView.Engine','fetch_assign!',2,[{file,"lib/phoenix_live_view/engine.ex"},{line,...}]},...]},...} in 'Elixir.Phoenix.Endpoint.Cowboy2Handler':init/4 line 59 in 'Elixir.Phoenix.Endpoint.Cowboy2Handler':init/4 line 59
2019-12-01 08:25:03.385 [error] <0.398.0> Lager event handler error_logger_lager_h exited with reason {'EXIT',{{case_clause,['Elixir.RailwayUiWeb.Endpoint.HTTP',<0.5432.0>,1,<0.5434.0>,{{#{'__exception__' => true,'__struct__' => 'Elixir.ArgumentError',message => <<"assign @data not available in eex template.\n\nPlease make sure all proper assigns have been set. If this\nis a child template, ensure assigns are given explicitly by\nthe parent template as they are not automatically forwarded.\n\nAvailable assigns: [:messages, :socket, :state, :view, :view_module, :view_template]\n">>},[{'Elixir.Phoenix.LiveView.Engine',...},...]},...},...]},...}}
2019-12-01 08:45:12.914 [error] <0.4049.0> gen_server <0.4049.0> terminated with reason: {socket_error,timeout}
2019-12-01 08:45:12.914 [error] <0.4049.0> CRASH REPORT Process <0.4049.0> with 0 neighbours exited with reason: {socket_error,timeout} in gen_server:handle_common_reply/8 line 751
2019-12-01 08:45:12.919 [error] <0.4045.0> gen_server <0.4045.0> terminated with reason: {socket_error,timeout}
2019-12-01 08:45:12.920 [error] <0.4045.0> CRASH REPORT Process <0.4045.0> with 0 neighbours exited with reason: {socket_error,timeout} in gen_server:handle_common_reply/8 line 751
2019-12-01 08:45:12.921 [error] <0.4044.0> Supervisor {<0.4044.0>,amqp_connection_type_sup} had child main_reader started with amqp_main_reader:start_link(#Port<0.584>, <0.4045.0>, <0.4047.0>, {method,rabbit_framing_amqp_0_9_1}, <<"client 127.0.0.1:50163 -> 127.0.0.1:5672">>) at <0.4049.0> exit with reason {socket_error,timeout} in context child_terminated
2019-12-01 08:45:12.921 [error] <0.4044.0> Supervisor {<0.4044.0>,amqp_connection_type_sup} had child main_reader started with amqp_main_reader:start_link(#Port<0.584>, <0.4045.0>, <0.4047.0>, {method,rabbit_framing_amqp_0_9_1}, <<"client 127.0.0.1:50163 -> 127.0.0.1:5672">>) at <0.4049.0> exit with reason reached_max_restart_intensity in context shutdown
2019-12-01 08:45:12.921 [error] <0.4043.0> Supervisor {<0.4043.0>,amqp_connection_sup} had child connection started with amqp_gen_connection:start_link(<0.4044.0>, {amqp_params_network,<<"guest">>,<<"guest">>,<<"/">>,"localhost",5672,2047,0,10,60000,none,[#Fun<am..>,...],...}) at <0.4045.0> exit with reason {socket_error,timeout} in context child_terminated
2019-12-01 08:45:12.921 [error] <0.4043.0> Supervisor {<0.4043.0>,amqp_connection_sup} had child connection started with amqp_gen_connection:start_link(<0.4044.0>, {amqp_params_network,<<"guest">>,<<"guest">>,<<"/">>,"localhost",5672,2047,0,10,60000,none,[#Fun<am..>,...],...}) at <0.4045.0> exit with reason reached_max_restart_intensity in context shutdown
2019-12-01 08:45:12.923 [error] <0.4040.0>@gen_server:call gen_server 'Elixir.RailwayIpc.Connection' terminated with reason: no such process or port in call to gen_server:call(<0.4045.0>, {command,{close,{'connection.close',200,<<"Goodbye">>,0,0},60000}}, 60000) in gen_server:call/3 line 223
2019-12-01 08:45:12.923 [error] <0.4040.0>@gen_server:call CRASH REPORT Process 'Elixir.RailwayIpc.Connection' with 0 neighbours exited with reason: no such process or port in call to gen_server:call(<0.4045.0>, {command,{close,{'connection.close',200,<<"Goodbye">>,0,0},60000}}, 60000) in gen_server:call/3 line 223
2019-12-01 08:45:12.924 [error] <0.433.0>@gen_server:call Supervisor 'Elixir.RailwayIpc.Connection.Supervisor' had child 'Elixir.RailwayIpc.Connection' started with 'Elixir.RailwayIpc.Connection':start_link([{name,'Elixir.RailwayIpc.Connection'}]) at <0.4040.0> exit with reason no such process or port in call to gen_server:call(<0.4045.0>, {command,{close,{'connection.close',200,<<"Goodbye">>,0,0},60000}}, 60000) in context child_terminated
2019-12-01 09:30:19.064 [error] <0.5505.0> gen_server <0.5505.0> terminated with reason: {socket_error,timeout}
2019-12-01 09:30:19.064 [error] <0.5505.0> CRASH REPORT Process <0.5505.0> with 0 neighbours exited with reason: {socket_error,timeout} in gen_server:handle_common_reply/8 line 751
2019-12-01 09:30:19.064 [error] <0.5501.0> gen_server <0.5501.0> terminated with reason: {socket_error,timeout}
2019-12-01 09:30:19.065 [error] <0.5500.0> Supervisor {<0.5500.0>,amqp_connection_type_sup} had child main_reader started with amqp_main_reader:start_link(#Port<0.791>, <0.5501.0>, <0.5503.0>, {method,rabbit_framing_amqp_0_9_1}, <<"client 127.0.0.1:57721 -> 127.0.0.1:5672">>) at <0.5505.0> exit with reason {socket_error,timeout} in context child_terminated
2019-12-01 09:30:19.065 [error] <0.5500.0> Supervisor {<0.5500.0>,amqp_connection_type_sup} had child main_reader started with amqp_main_reader:start_link(#Port<0.791>, <0.5501.0>, <0.5503.0>, {method,rabbit_framing_amqp_0_9_1}, <<"client 127.0.0.1:57721 -> 127.0.0.1:5672">>) at <0.5505.0> exit with reason reached_max_restart_intensity in context shutdown
2019-12-01 09:30:19.065 [error] <0.5501.0> CRASH REPORT Process <0.5501.0> with 0 neighbours exited with reason: {socket_error,timeout} in gen_server:handle_common_reply/8 line 751
2019-12-01 09:30:19.066 [error] <0.5499.0> Supervisor {<0.5499.0>,amqp_connection_sup} had child connection started with amqp_gen_connection:start_link(<0.5500.0>, {amqp_params_network,<<"guest">>,<<"guest">>,<<"/">>,"localhost",5672,2047,0,10,60000,none,[#Fun<am..>,...],...}) at <0.5501.0> exit with reason {socket_error,timeout} in context child_terminated
2019-12-01 09:30:19.066 [error] <0.5499.0> Supervisor {<0.5499.0>,amqp_connection_sup} had child connection started with amqp_gen_connection:start_link(<0.5500.0>, {amqp_params_network,<<"guest">>,<<"guest">>,<<"/">>,"localhost",5672,2047,0,10,60000,none,[#Fun<am..>,...],...}) at <0.5501.0> exit with reason reached_max_restart_intensity in context shutdown
2019-12-01 09:30:19.067 [error] <0.5496.0>@gen_server:call gen_server 'Elixir.RailwayIpc.Connection' terminated with reason: no such process or port in call to gen_server:call(<0.5501.0>, {command,{close,{'connection.close',200,<<"Goodbye">>,0,0},60000}}, 60000) in gen_server:call/3 line 223
2019-12-01 09:30:19.068 [error] <0.5496.0>@gen_server:call CRASH REPORT Process 'Elixir.RailwayIpc.Connection' with 0 neighbours exited with reason: no such process or port in call to gen_server:call(<0.5501.0>, {command,{close,{'connection.close',200,<<"Goodbye">>,0,0},60000}}, 60000) in gen_server:call/3 line 223
2019-12-01 09:30:19.068 [error] <0.433.0>@gen_server:call Supervisor 'Elixir.RailwayIpc.Connection.Supervisor' had child 'Elixir.RailwayIpc.Connection' started with 'Elixir.RailwayIpc.Connection':start_link([{name,'Elixir.RailwayIpc.Connection'}]) at <0.5496.0> exit with reason no such process or port in call to gen_server:call(<0.5501.0>, {command,{close,{'connection.close',200,<<"Goodbye">>,0,0},60000}}, 60000) in context child_terminated
2019-12-01 10:24:26.055 [error] <0.5544.0> gen_server <0.5544.0> terminated with reason: {socket_error,timeout}
2019-12-01 10:24:26.056 [error] <0.5544.0> CRASH REPORT Process <0.5544.0> with 0 neighbours exited with reason: {socket_error,timeout} in gen_server:handle_common_reply/8 line 751
2019-12-01 10:24:26.056 [error] <0.5539.0> Supervisor {<0.5539.0>,amqp_connection_type_sup} had child main_reader started with amqp_main_reader:start_link(#Port<0.794>, <0.5540.0>, <0.5542.0>, {method,rabbit_framing_amqp_0_9_1}, <<"client 127.0.0.1:57828 -> 127.0.0.1:5672">>) at <0.5544.0> exit with reason {socket_error,timeout} in context child_terminated
2019-12-01 10:24:26.057 [error] <0.5539.0> Supervisor {<0.5539.0>,amqp_connection_type_sup} had child main_reader started with amqp_main_reader:start_link(#Port<0.794>, <0.5540.0>, <0.5542.0>, {method,rabbit_framing_amqp_0_9_1}, <<"client 127.0.0.1:57828 -> 127.0.0.1:5672">>) at <0.5544.0> exit with reason reached_max_restart_intensity in context shutdown
2019-12-01 10:24:26.075 [error] <0.5540.0> gen_server <0.5540.0> terminated with reason: {socket_error,timeout}
2019-12-01 10:24:26.075 [error] <0.5540.0> CRASH REPORT Process <0.5540.0> with 0 neighbours exited with reason: {socket_error,timeout} in gen_server:handle_common_reply/8 line 751
2019-12-01 10:24:26.075 [error] <0.5538.0> Supervisor {<0.5538.0>,amqp_connection_sup} had child connection started with amqp_gen_connection:start_link(<0.5539.0>, {amqp_params_network,<<"guest">>,<<"guest">>,<<"/">>,"localhost",5672,2047,0,10,60000,none,[#Fun<am..>,...],...}) at <0.5540.0> exit with reason {socket_error,timeout} in context child_terminated
2019-12-01 10:24:26.075 [error] <0.5538.0> Supervisor {<0.5538.0>,amqp_connection_sup} had child connection started with amqp_gen_connection:start_link(<0.5539.0>, {amqp_params_network,<<"guest">>,<<"guest">>,<<"/">>,"localhost",5672,2047,0,10,60000,none,[#Fun<am..>,...],...}) at <0.5540.0> exit with reason reached_max_restart_intensity in context shutdown
2019-12-01 10:24:26.076 [error] <0.5535.0>@gen_server:call gen_server 'Elixir.RailwayIpc.Connection' terminated with reason: no such process or port in call to gen_server:call(<0.5540.0>, {command,{close,{'connection.close',200,<<"Goodbye">>,0,0},60000}}, 60000) in gen_server:call/3 line 223
2019-12-01 10:24:26.076 [error] <0.5535.0>@gen_server:call CRASH REPORT Process 'Elixir.RailwayIpc.Connection' with 0 neighbours exited with reason: no such process or port in call to gen_server:call(<0.5540.0>, {command,{close,{'connection.close',200,<<"Goodbye">>,0,0},60000}}, 60000) in gen_server:call/3 line 223
2019-12-01 10:24:26.076 [error] <0.433.0>@gen_server:call Supervisor 'Elixir.RailwayIpc.Connection.Supervisor' had child 'Elixir.RailwayIpc.Connection' started with 'Elixir.RailwayIpc.Connection':start_link([{name,'Elixir.RailwayIpc.Connection'}]) at <0.5535.0> exit with reason no such process or port in call to gen_server:call(<0.5540.0>, {command,{close,{'connection.close',200,<<"Goodbye">>,0,0},60000}}, 60000) in context child_terminated
2019-12-01 11:18:28.066 [error] <0.5574.0> gen_server <0.5574.0> terminated with reason: {socket_error,timeout}
2019-12-01 11:18:28.066 [error] <0.5574.0> CRASH REPORT Process <0.5574.0> with 0 neighbours exited with reason: {socket_error,timeout} in gen_server:handle_common_reply/8 line 751
2019-12-01 11:18:28.066 [error] <0.5570.0> gen_server <0.5570.0> terminated with reason: {socket_error,timeout}
2019-12-01 11:18:28.076 [error] <0.5570.0> CRASH REPORT Process <0.5570.0> with 0 neighbours exited with reason: {socket_error,timeout} in gen_server:handle_common_reply/8 line 751
2019-12-01 11:18:28.076 [error] <0.5569.0> Supervisor {<0.5569.0>,amqp_connection_type_sup} had child main_reader started with amqp_main_reader:start_link(#Port<0.797>, <0.5570.0>, <0.5572.0>, {method,rabbit_framing_amqp_0_9_1}, <<"client 127.0.0.1:57919 -> 127.0.0.1:5672">>) at <0.5574.0> exit with reason {socket_error,timeout} in context child_terminated
2019-12-01 11:18:28.076 [error] <0.5569.0> Supervisor {<0.5569.0>,amqp_connection_type_sup} had child main_reader started with amqp_main_reader:start_link(#Port<0.797>, <0.5570.0>, <0.5572.0>, {method,rabbit_framing_amqp_0_9_1}, <<"client 127.0.0.1:57919 -> 127.0.0.1:5672">>) at <0.5574.0> exit with reason reached_max_restart_intensity in context shutdown
2019-12-01 11:18:28.076 [error] <0.5568.0> Supervisor {<0.5568.0>,amqp_connection_sup} had child connection started with amqp_gen_connection:start_link(<0.5569.0>, {amqp_params_network,<<"guest">>,<<"guest">>,<<"/">>,"localhost",5672,2047,0,10,60000,none,[#Fun<am..>,...],...}) at <0.5570.0> exit with reason {socket_error,timeout} in context child_terminated
2019-12-01 11:18:28.076 [error] <0.5568.0> Supervisor {<0.5568.0>,amqp_connection_sup} had child connection started with amqp_gen_connection:start_link(<0.5569.0>, {amqp_params_network,<<"guest">>,<<"guest">>,<<"/">>,"localhost",5672,2047,0,10,60000,none,[#Fun<am..>,...],...}) at <0.5570.0> exit with reason reached_max_restart_intensity in context shutdown
2019-12-01 11:18:28.076 [error] <0.5565.0>@gen_server:call gen_server 'Elixir.RailwayIpc.Connection' terminated with reason: no such process or port in call to gen_server:call(<0.5570.0>, {command,{close,{'connection.close',200,<<"Goodbye">>,0,0},60000}}, 60000) in gen_server:call/3 line 223
2019-12-01 11:18:28.076 [error] <0.5565.0>@gen_server:call CRASH REPORT Process 'Elixir.RailwayIpc.Connection' with 0 neighbours exited with reason: no such process or port in call to gen_server:call(<0.5570.0>, {command,{close,{'connection.close',200,<<"Goodbye">>,0,0},60000}}, 60000) in gen_server:call/3 line 223
2019-12-01 11:18:28.077 [error] <0.433.0>@gen_server:call Supervisor 'Elixir.RailwayIpc.Connection.Supervisor' had child 'Elixir.RailwayIpc.Connection' started with 'Elixir.RailwayIpc.Connection':start_link([{name,'Elixir.RailwayIpc.Connection'}]) at <0.5565.0> exit with reason no such process or port in call to gen_server:call(<0.5570.0>, {command,{close,{'connection.close',200,<<"Goodbye">>,0,0},60000}}, 60000) in context child_terminated
2019-12-01 12:12:30.059 [error] <0.5604.0> gen_server <0.5604.0> terminated with reason: {socket_error,timeout}
2019-12-01 12:12:30.059 [error] <0.5604.0> CRASH REPORT Process <0.5604.0> with 0 neighbours exited with reason: {socket_error,timeout} in gen_server:handle_common_reply/8 line 751
2019-12-01 12:12:30.060 [error] <0.5599.0> gen_server <0.5599.0> terminated with reason: {socket_error,timeout}
2019-12-01 12:12:30.060 [error] <0.5598.0> Supervisor {<0.5598.0>,amqp_connection_type_sup} had child main_reader started with amqp_main_reader:start_link(#Port<0.800>, <0.5599.0>, <0.5602.0>, {method,rabbit_framing_amqp_0_9_1}, <<"client 127.0.0.1:57958 -> 127.0.0.1:5672">>) at <0.5604.0> exit with reason {socket_error,timeout} in context child_terminated
2019-12-01 12:12:30.061 [error] <0.5598.0> Supervisor {<0.5598.0>,amqp_connection_type_sup} had child main_reader started with amqp_main_reader:start_link(#Port<0.800>, <0.5599.0>, <0.5602.0>, {method,rabbit_framing_amqp_0_9_1}, <<"client 127.0.0.1:57958 -> 127.0.0.1:5672">>) at <0.5604.0> exit with reason reached_max_restart_intensity in context shutdown
2019-12-01 12:12:30.061 [error] <0.5599.0> CRASH REPORT Process <0.5599.0> with 0 neighbours exited with reason: {socket_error,timeout} in gen_server:handle_common_reply/8 line 751
2019-12-01 12:12:30.077 [error] <0.5597.0> Supervisor {<0.5597.0>,amqp_connection_sup} had child connection started with amqp_gen_connection:start_link(<0.5598.0>, {amqp_params_network,<<"guest">>,<<"guest">>,<<"/">>,"localhost",5672,2047,0,10,60000,none,[#Fun<am..>,...],...}) at <0.5599.0> exit with reason {socket_error,timeout} in context child_terminated
2019-12-01 12:12:30.080 [error] <0.5597.0> Supervisor {<0.5597.0>,amqp_connection_sup} had child connection started with amqp_gen_connection:start_link(<0.5598.0>, {amqp_params_network,<<"guest">>,<<"guest">>,<<"/">>,"localhost",5672,2047,0,10,60000,none,[#Fun<am..>,...],...}) at <0.5599.0> exit with reason reached_max_restart_intensity in context shutdown
2019-12-01 12:12:30.080 [error] <0.5594.0>@gen_server:call gen_server 'Elixir.RailwayIpc.Connection' terminated with reason: no such process or port in call to gen_server:call(<0.5599.0>, {command,{close,{'connection.close',200,<<"Goodbye">>,0,0},60000}}, 60000) in gen_server:call/3 line 223
2019-12-01 12:12:30.080 [error] <0.5594.0>@gen_server:call CRASH REPORT Process 'Elixir.RailwayIpc.Connection' with 0 neighbours exited with reason: no such process or port in call to gen_server:call(<0.5599.0>, {command,{close,{'connection.close',200,<<"Goodbye">>,0,0},60000}}, 60000) in gen_server:call/3 line 223
2019-12-01 12:12:30.080 [error] <0.433.0>@gen_server:call Supervisor 'Elixir.RailwayIpc.Connection.Supervisor' had child 'Elixir.RailwayIpc.Connection' started with 'Elixir.RailwayIpc.Connection':start_link([{name,'Elixir.RailwayIpc.Connection'}]) at <0.5594.0> exit with reason no such process or port in call to gen_server:call(<0.5599.0>, {command,{close,{'connection.close',200,<<"Goodbye">>,0,0},60000}}, 60000) in context child_terminated
2019-12-01 12:34:49.060 [error] <0.5634.0> gen_server <0.5634.0> terminated with reason: {socket_error,timeout}
2019-12-01 12:34:49.060 [error] <0.5634.0> CRASH REPORT Process <0.5634.0> with 0 neighbours exited with reason: {socket_error,timeout} in gen_server:handle_common_reply/8 line 751
2019-12-01 12:34:49.060 [error] <0.5630.0> gen_server <0.5630.0> terminated with reason: {socket_error,timeout}
2019-12-01 12:34:49.061 [error] <0.5630.0> CRASH REPORT Process <0.5630.0> with 0 neighbours exited with reason: {socket_error,timeout} in gen_server:handle_common_reply/8 line 751
2019-12-01 12:34:49.062 [error] <0.5628.0> Supervisor {<0.5628.0>,amqp_connection_sup} had child connection started with amqp_gen_connection:start_link(<0.5629.0>, {amqp_params_network,<<"guest">>,<<"guest">>,<<"/">>,"localhost",5672,2047,0,10,60000,none,[#Fun<am..>,...],...}) at <0.5630.0> exit with reason {socket_error,timeout} in context child_terminated
2019-12-01 12:34:49.063 [error] <0.5628.0> Supervisor {<0.5628.0>,amqp_connection_sup} had child connection started with amqp_gen_connection:start_link(<0.5629.0>, {amqp_params_network,<<"guest">>,<<"guest">>,<<"/">>,"localhost",5672,2047,0,10,60000,none,[#Fun<am..>,...],...}) at <0.5630.0> exit with reason reached_max_restart_intensity in context shutdown
2019-12-01 12:34:49.063 [error] <0.5625.0>@gen_server:call gen_server 'Elixir.RailwayIpc.Connection' terminated with reason: no such process or port in call to gen_server:call(<0.5630.0>, {command,{close,{'connection.close',200,<<"Goodbye">>,0,0},60000}}, 60000) in gen_server:call/3 line 223
2019-12-01 12:34:49.063 [error] <0.5625.0>@gen_server:call CRASH REPORT Process 'Elixir.RailwayIpc.Connection' with 0 neighbours exited with reason: no such process or port in call to gen_server:call(<0.5630.0>, {command,{close,{'connection.close',200,<<"Goodbye">>,0,0},60000}}, 60000) in gen_server:call/3 line 223
2019-12-01 12:34:49.063 [error] <0.433.0>@gen_server:call Supervisor 'Elixir.RailwayIpc.Connection.Supervisor' had child 'Elixir.RailwayIpc.Connection' started with 'Elixir.RailwayIpc.Connection':start_link([{name,'Elixir.RailwayIpc.Connection'}]) at <0.5625.0> exit with reason no such process or port in call to gen_server:call(<0.5630.0>, {command,{close,{'connection.close',200,<<"Goodbye">>,0,0},60000}}, 60000) in context child_terminated
2019-12-01 12:34:49.070 [error] <0.5629.0> Supervisor {<0.5629.0>,amqp_connection_type_sup} had child main_reader started with amqp_main_reader:start_link(#Port<0.803>, <0.5630.0>, <0.5632.0>, {method,rabbit_framing_amqp_0_9_1}, <<"client 127.0.0.1:57998 -> 127.0.0.1:5672">>) at <0.5634.0> exit with reason {socket_error,timeout} in context child_terminated
2019-12-01 12:34:49.070 [error] <0.5629.0> Supervisor {<0.5629.0>,amqp_connection_type_sup} had child main_reader started with amqp_main_reader:start_link(#Port<0.803>, <0.5630.0>, <0.5632.0>, {method,rabbit_framing_amqp_0_9_1}, <<"client 127.0.0.1:57998 -> 127.0.0.1:5672">>) at <0.5634.0> exit with reason reached_max_restart_intensity in context shutdown
2019-12-01 13:28:56.044 [error] <0.5664.0> gen_server <0.5664.0> terminated with reason: {socket_error,timeout}
2019-12-01 13:28:56.044 [error] <0.5664.0> CRASH REPORT Process <0.5664.0> with 0 neighbours exited with reason: {socket_error,timeout} in gen_server:handle_common_reply/8 line 751
2019-12-01 13:28:56.044 [error] <0.5660.0> gen_server <0.5660.0> terminated with reason: {socket_error,timeout}
2019-12-01 13:28:56.045 [error] <0.5660.0> CRASH REPORT Process <0.5660.0> with 0 neighbours exited with reason: {socket_error,timeout} in gen_server:handle_common_reply/8 line 751
2019-12-01 13:28:56.046 [error] <0.5655.0>@gen_server:call gen_server 'Elixir.RailwayIpc.Connection' terminated with reason: no such process or port in call to gen_server:call(<0.5660.0>, {command,{close,{'connection.close',200,<<"Goodbye">>,0,0},60000}}, 60000) in gen_server:call/3 line 223
2019-12-01 13:28:56.046 [error] <0.5655.0>@gen_server:call CRASH REPORT Process 'Elixir.RailwayIpc.Connection' with 0 neighbours exited with reason: no such process or port in call to gen_server:call(<0.5660.0>, {command,{close,{'connection.close',200,<<"Goodbye">>,0,0},60000}}, 60000) in gen_server:call/3 line 223
2019-12-01 13:28:56.046 [error] <0.5658.0> Supervisor {<0.5658.0>,amqp_connection_sup} had child connection started with amqp_gen_connection:start_link(<0.5659.0>, {amqp_params_network,<<"guest">>,<<"guest">>,<<"/">>,"localhost",5672,2047,0,10,60000,none,[#Fun<am..>,...],...}) at <0.5660.0> exit with reason {socket_error,timeout} in context child_terminated
2019-12-01 13:28:56.047 [error] <0.5658.0> Supervisor {<0.5658.0>,amqp_connection_sup} had child connection started with amqp_gen_connection:start_link(<0.5659.0>, {amqp_params_network,<<"guest">>,<<"guest">>,<<"/">>,"localhost",5672,2047,0,10,60000,none,[#Fun<am..>,...],...}) at <0.5660.0> exit with reason reached_max_restart_intensity in context shutdown
2019-12-01 13:28:56.047 [error] <0.433.0>@gen_server:call Supervisor 'Elixir.RailwayIpc.Connection.Supervisor' had child 'Elixir.RailwayIpc.Connection' started with 'Elixir.RailwayIpc.Connection':start_link([{name,'Elixir.RailwayIpc.Connection'}]) at <0.5655.0> exit with reason no such process or port in call to gen_server:call(<0.5660.0>, {command,{close,{'connection.close',200,<<"Goodbye">>,0,0},60000}}, 60000) in context child_terminated
2019-12-01 13:28:56.050 [error] <0.5659.0> Supervisor {<0.5659.0>,amqp_connection_type_sup} had child main_reader started with amqp_main_reader:start_link(#Port<0.806>, <0.5660.0>, <0.5662.0>, {method,rabbit_framing_amqp_0_9_1}, <<"client 127.0.0.1:58026 -> 127.0.0.1:5672">>) at <0.5664.0> exit with reason {socket_error,timeout} in context child_terminated
2019-12-01 13:28:56.051 [error] <0.5659.0> Supervisor {<0.5659.0>,amqp_connection_type_sup} had child main_reader started with amqp_main_reader:start_link(#Port<0.806>, <0.5660.0>, <0.5662.0>, {method,rabbit_framing_amqp_0_9_1}, <<"client 127.0.0.1:58026 -> 127.0.0.1:5672">>) at <0.5664.0> exit with reason reached_max_restart_intensity in context shutdown
2019-12-01 14:22:58.035 [error] <0.5694.0> gen_server <0.5694.0> terminated with reason: {socket_error,timeout}
2019-12-01 14:22:58.035 [error] <0.5694.0> CRASH REPORT Process <0.5694.0> with 0 neighbours exited with reason: {socket_error,timeout} in gen_server:handle_common_reply/8 line 751
2019-12-01 14:22:58.035 [error] <0.5690.0> gen_server <0.5690.0> terminated with reason: {socket_error,timeout}
2019-12-01 14:22:58.036 [error] <0.5689.0> Supervisor {<0.5689.0>,amqp_connection_type_sup} had child main_reader started with amqp_main_reader:start_link(#Port<0.809>, <0.5690.0>, <0.5692.0>, {method,rabbit_framing_amqp_0_9_1}, <<"client 127.0.0.1:58157 -> 127.0.0.1:5672">>) at <0.5694.0> exit with reason {socket_error,timeout} in context child_terminated
2019-12-01 14:22:58.037 [error] <0.5689.0> Supervisor {<0.5689.0>,amqp_connection_type_sup} had child main_reader started with amqp_main_reader:start_link(#Port<0.809>, <0.5690.0>, <0.5692.0>, {method,rabbit_framing_amqp_0_9_1}, <<"client 127.0.0.1:58157 -> 127.0.0.1:5672">>) at <0.5694.0> exit with reason reached_max_restart_intensity in context shutdown
2019-12-01 14:22:58.037 [error] <0.5690.0> CRASH REPORT Process <0.5690.0> with 0 neighbours exited with reason: {socket_error,timeout} in gen_server:handle_common_reply/8 line 751
2019-12-01 14:22:58.038 [error] <0.5688.0> Supervisor {<0.5688.0>,amqp_connection_sup} had child connection started with amqp_gen_connection:start_link(<0.5689.0>, {amqp_params_network,<<"guest">>,<<"guest">>,<<"/">>,"localhost",5672,2047,0,10,60000,none,[#Fun<am..>,...],...}) at <0.5690.0> exit with reason {socket_error,timeout} in context child_terminated
2019-12-01 14:22:58.038 [error] <0.5688.0> Supervisor {<0.5688.0>,amqp_connection_sup} had child connection started with amqp_gen_connection:start_link(<0.5689.0>, {amqp_params_network,<<"guest">>,<<"guest">>,<<"/">>,"localhost",5672,2047,0,10,60000,none,[#Fun<am..>,...],...}) at <0.5690.0> exit with reason reached_max_restart_intensity in context shutdown
2019-12-01 14:22:58.039 [error] <0.5685.0>@gen_server:call gen_server 'Elixir.RailwayIpc.Connection' terminated with reason: no such process or port in call to gen_server:call(<0.5690.0>, {command,{close,{'connection.close',200,<<"Goodbye">>,0,0},60000}}, 60000) in gen_server:call/3 line 223
2019-12-01 14:22:58.039 [error] <0.5685.0>@gen_server:call CRASH REPORT Process 'Elixir.RailwayIpc.Connection' with 0 neighbours exited with reason: no such process or port in call to gen_server:call(<0.5690.0>, {command,{close,{'connection.close',200,<<"Goodbye">>,0,0},60000}}, 60000) in gen_server:call/3 line 223
2019-12-01 14:22:58.039 [error] <0.433.0>@gen_server:call Supervisor 'Elixir.RailwayIpc.Connection.Supervisor' had child 'Elixir.RailwayIpc.Connection' started with 'Elixir.RailwayIpc.Connection':start_link([{name,'Elixir.RailwayIpc.Connection'}]) at <0.5685.0> exit with reason no such process or port in call to gen_server:call(<0.5690.0>, {command,{close,{'connection.close',200,<<"Goodbye">>,0,0},60000}}, 60000) in context child_terminated
2019-12-01 15:17:00.065 [error] <0.5724.0> gen_server <0.5724.0> terminated with reason: {socket_error,timeout}
2019-12-01 15:17:00.065 [error] <0.5724.0> CRASH REPORT Process <0.5724.0> with 0 neighbours exited with reason: {socket_error,timeout} in gen_server:handle_common_reply/8 line 751
2019-12-01 15:17:00.065 [error] <0.5720.0> gen_server <0.5720.0> terminated with reason: {socket_error,timeout}
2019-12-01 15:17:00.065 [error] <0.5719.0> Supervisor {<0.5719.0>,amqp_connection_type_sup} had child main_reader started with amqp_main_reader:start_link(#Port<0.812>, <0.5720.0>, <0.5722.0>, {method,rabbit_framing_amqp_0_9_1}, <<"client 127.0.0.1:58195 -> 127.0.0.1:5672">>) at <0.5724.0> exit with reason {socket_error,timeout} in context child_terminated
2019-12-01 15:17:00.065 [error] <0.5719.0> Supervisor {<0.5719.0>,amqp_connection_type_sup} had child main_reader started with amqp_main_reader:start_link(#Port<0.812>, <0.5720.0>, <0.5722.0>, {method,rabbit_framing_amqp_0_9_1}, <<"client 127.0.0.1:58195 -> 127.0.0.1:5672">>) at <0.5724.0> exit with reason reached_max_restart_intensity in context shutdown
2019-12-01 15:17:00.065 [error] <0.5720.0> CRASH REPORT Process <0.5720.0> with 0 neighbours exited with reason: {socket_error,timeout} in gen_server:handle_common_reply/8 line 751
2019-12-01 15:17:00.066 [error] <0.5715.0>@gen_server:call gen_server 'Elixir.RailwayIpc.Connection' terminated with reason: no such process or port in call to gen_server:call(<0.5720.0>, {command,{close,{'connection.close',200,<<"Goodbye">>,0,0},60000}}, 60000) in gen_server:call/3 line 223
2019-12-01 15:17:00.066 [error] <0.5715.0>@gen_server:call CRASH REPORT Process 'Elixir.RailwayIpc.Connection' with 0 neighbours exited with reason: no such process or port in call to gen_server:call(<0.5720.0>, {command,{close,{'connection.close',200,<<"Goodbye">>,0,0},60000}}, 60000) in gen_server:call/3 line 223
2019-12-01 15:17:00.066 [error] <0.433.0>@gen_server:call Supervisor 'Elixir.RailwayIpc.Connection.Supervisor' had child 'Elixir.RailwayIpc.Connection' started with 'Elixir.RailwayIpc.Connection':start_link([{name,'Elixir.RailwayIpc.Connection'}]) at <0.5715.0> exit with reason no such process or port in call to gen_server:call(<0.5720.0>, {command,{close,{'connection.close',200,<<"Goodbye">>,0,0},60000}}, 60000) in context child_terminated
2019-12-01 15:17:00.066 [error] <0.5718.0> Supervisor {<0.5718.0>,amqp_connection_sup} had child connection started with amqp_gen_connection:start_link(<0.5719.0>, {amqp_params_network,<<"guest">>,<<"guest">>,<<"/">>,"localhost",5672,2047,0,10,60000,none,[#Fun<am..>,...],...}) at <0.5720.0> exit with reason {socket_error,timeout} in context child_terminated
2019-12-01 15:17:00.067 [error] <0.5718.0> Supervisor {<0.5718.0>,amqp_connection_sup} had child connection started with amqp_gen_connection:start_link(<0.5719.0>, {amqp_params_network,<<"guest">>,<<"guest">>,<<"/">>,"localhost",5672,2047,0,10,60000,none,[#Fun<am..>,...],...}) at <0.5720.0> exit with reason reached_max_restart_intensity in context shutdown
2019-12-01 16:11:02.041 [error] <0.5758.0> gen_server <0.5758.0> terminated with reason: {socket_error,timeout}
2019-12-01 16:11:02.041 [error] <0.5758.0> CRASH REPORT Process <0.5758.0> with 0 neighbours exited with reason: {socket_error,timeout} in gen_server:handle_common_reply/8 line 751
2019-12-01 16:11:02.041 [error] <0.5754.0> gen_server <0.5754.0> terminated with reason: {socket_error,timeout}
2019-12-01 16:11:02.042 [error] <0.5753.0> Supervisor {<0.5753.0>,amqp_connection_type_sup} had child main_reader started with amqp_main_reader:start_link(#Port<0.815>, <0.5754.0>, <0.5756.0>, {method,rabbit_framing_amqp_0_9_1}, <<"client 127.0.0.1:58234 -> 127.0.0.1:5672">>) at <0.5758.0> exit with reason {socket_error,timeout} in context child_terminated
2019-12-01 16:11:02.042 [error] <0.5753.0> Supervisor {<0.5753.0>,amqp_connection_type_sup} had child main_reader started with amqp_main_reader:start_link(#Port<0.815>, <0.5754.0>, <0.5756.0>, {method,rabbit_framing_amqp_0_9_1}, <<"client 127.0.0.1:58234 -> 127.0.0.1:5672">>) at <0.5758.0> exit with reason reached_max_restart_intensity in context shutdown
2019-12-01 16:11:02.042 [error] <0.5754.0> CRASH REPORT Process <0.5754.0> with 0 neighbours exited with reason: {socket_error,timeout} in gen_server:handle_common_reply/8 line 751
2019-12-01 16:11:02.043 [error] <0.5749.0>@gen_server:call gen_server 'Elixir.RailwayIpc.Connection' terminated with reason: no such process or port in call to gen_server:call(<0.5754.0>, {command,{close,{'connection.close',200,<<"Goodbye">>,0,0},60000}}, 60000) in gen_server:call/3 line 223
2019-12-01 16:11:02.043 [error] <0.5749.0>@gen_server:call CRASH REPORT Process 'Elixir.RailwayIpc.Connection' with 0 neighbours exited with reason: no such process or port in call to gen_server:call(<0.5754.0>, {command,{close,{'connection.close',200,<<"Goodbye">>,0,0},60000}}, 60000) in gen_server:call/3 line 223
2019-12-01 16:11:02.062 [error] <0.5752.0> Supervisor {<0.5752.0>,amqp_connection_sup} had child connection started with amqp_gen_connection:start_link(<0.5753.0>, {amqp_params_network,<<"guest">>,<<"guest">>,<<"/">>,"localhost",5672,2047,0,10,60000,none,[#Fun<am..>,...],...}) at <0.5754.0> exit with reason {socket_error,timeout} in context child_terminated
2019-12-01 16:11:02.062 [error] <0.5752.0> Supervisor {<0.5752.0>,amqp_connection_sup} had child connection started with amqp_gen_connection:start_link(<0.5753.0>, {amqp_params_network,<<"guest">>,<<"guest">>,<<"/">>,"localhost",5672,2047,0,10,60000,none,[#Fun<am..>,...],...}) at <0.5754.0> exit with reason reached_max_restart_intensity in context shutdown
2019-12-01 16:11:02.062 [error] <0.5752.0> Supervisor {<0.5752.0>,amqp_connection_sup} had child connection_type_sup started with amqp_connection_type_sup:start_link() at <0.5753.0> exit with reason shutdown in context shutdown_error
2019-12-01 16:11:02.062 [error] <0.433.0>@gen_server:call Supervisor 'Elixir.RailwayIpc.Connection.Supervisor' had child 'Elixir.RailwayIpc.Connection' started with 'Elixir.RailwayIpc.Connection':start_link([{name,'Elixir.RailwayIpc.Connection'}]) at <0.5749.0> exit with reason no such process or port in call to gen_server:call(<0.5754.0>, {command,{close,{'connection.close',200,<<"Goodbye">>,0,0},60000}}, 60000) in context child_terminated
2019-12-01 16:38:50.029 [error] <0.5790.0> gen_server <0.5790.0> terminated with reason: {socket_error,timeout}
2019-12-01 16:38:50.029 [error] <0.5790.0> CRASH REPORT Process <0.5790.0> with 0 neighbours exited with reason: {socket_error,timeout} in gen_server:handle_common_reply/8 line 751
2019-12-01 16:38:50.029 [error] <0.5786.0> gen_server <0.5786.0> terminated with reason: {socket_error,timeout}
2019-12-01 16:38:50.030 [error] <0.5785.0> Supervisor {<0.5785.0>,amqp_connection_type_sup} had child main_reader started with amqp_main_reader:start_link(#Port<0.818>, <0.5786.0>, <0.5788.0>, {method,rabbit_framing_amqp_0_9_1}, <<"client 127.0.0.1:58270 -> 127.0.0.1:5672">>) at <0.5790.0> exit with reason {socket_error,timeout} in context child_terminated
2019-12-01 16:38:50.030 [error] <0.5785.0> Supervisor {<0.5785.0>,amqp_connection_type_sup} had child main_reader started with amqp_main_reader:start_link(#Port<0.818>, <0.5786.0>, <0.5788.0>, {method,rabbit_framing_amqp_0_9_1}, <<"client 127.0.0.1:58270 -> 127.0.0.1:5672">>) at <0.5790.0> exit with reason reached_max_restart_intensity in context shutdown
2019-12-01 16:38:50.030 [error] <0.5786.0> CRASH REPORT Process <0.5786.0> with 0 neighbours exited with reason: {socket_error,timeout} in gen_server:handle_common_reply/8 line 751
2019-12-01 16:38:50.030 [error] <0.5784.0> Supervisor {<0.5784.0>,amqp_connection_sup} had child connection started with amqp_gen_connection:start_link(<0.5785.0>, {amqp_params_network,<<"guest">>,<<"guest">>,<<"/">>,"localhost",5672,2047,0,10,60000,none,[#Fun<am..>,...],...}) at <0.5786.0> exit with reason {socket_error,timeout} in context child_terminated
2019-12-01 16:38:50.030 [error] <0.5784.0> Supervisor {<0.5784.0>,amqp_connection_sup} had child connection started with amqp_gen_connection:start_link(<0.5785.0>, {amqp_params_network,<<"guest">>,<<"guest">>,<<"/">>,"localhost",5672,2047,0,10,60000,none,[#Fun<am..>,...],...}) at <0.5786.0> exit with reason reached_max_restart_intensity in context shutdown
2019-12-01 16:38:50.037 [error] <0.5781.0>@gen_server:call gen_server 'Elixir.RailwayIpc.Connection' terminated with reason: no such process or port in call to gen_server:call(<0.5786.0>, {command,{close,{'connection.close',200,<<"Goodbye">>,0,0},60000}}, 60000) in gen_server:call/3 line 223
2019-12-01 16:38:50.037 [error] <0.5781.0>@gen_server:call CRASH REPORT Process 'Elixir.RailwayIpc.Connection' with 0 neighbours exited with reason: no such process or port in call to gen_server:call(<0.5786.0>, {command,{close,{'connection.close',200,<<"Goodbye">>,0,0},60000}}, 60000) in gen_server:call/3 line 223
2019-12-01 16:38:50.038 [error] <0.433.0>@gen_server:call Supervisor 'Elixir.RailwayIpc.Connection.Supervisor' had child 'Elixir.RailwayIpc.Connection' started with 'Elixir.RailwayIpc.Connection':start_link([{name,'Elixir.RailwayIpc.Connection'}]) at <0.5781.0> exit with reason no such process or port in call to gen_server:call(<0.5786.0>, {command,{close,{'connection.close',200,<<"Goodbye">>,0,0},60000}}, 60000) in context child_terminated
2019-12-01 16:39:48.726 [error] <0.5841.0> gen_server <0.5841.0> terminated with reason: #{'__exception__' => true,'__struct__' => 'Elixir.Ecto.Query.CastError',message => <<"lib/railway_ui/persistence.ex:66: value `\"1234\"` cannot be dumped to type :binary_id in query:\n\nfrom p0 in RailwayIpc.Persistence.PublishedMessage,\n  where: p0.uuid == ^\"1234\",\n  select: count(p0.uuid)\n">>,type => binary_id,value => <<"1234">>} in 'Elixir.Enum':'-reduce/3-lists^foldl/2-0-'/3 line 1948
2019-12-01 16:39:48.728 [error] <0.5841.0> CRASH REPORT Process <0.5841.0> with 0 neighbours crashed with reason: #{'__exception__' => true,'__struct__' => 'Elixir.Ecto.Query.CastError',message => <<"lib/railway_ui/persistence.ex:66: value `\"1234\"` cannot be dumped to type :binary_id in query:\n\nfrom p0 in RailwayIpc.Persistence.PublishedMessage,\n  where: p0.uuid == ^\"1234\",\n  select: count(p0.uuid)\n">>,type => binary_id,value => <<"1234">>} in 'Elixir.Enum':'-reduce/3-lists^foldl/2-0-'/3 line 1948
2019-12-01 16:39:48.728 [error] <0.522.0> Supervisor {<0.522.0>,'Elixir.Phoenix.Socket.PoolSupervisor.WorkerSupervisor'} had child 'Elixir.Phoenix.Channel.Server' started with {'Elixir.Phoenix.Channel.Server',start_link,undefined} at <0.5841.0> exit with reason #{'__exception__' => true,'__struct__' => 'Elixir.Ecto.Query.CastError',message => <<"lib/railway_ui/persistence.ex:66: value `\"1234\"` cannot be dumped to type :binary_id in query:\n\nfrom p0 in RailwayIpc.Persistence.PublishedMessage,\n  where: p0.uuid == ^\"1234\",\n  select: count(p0.uuid)\n">>,type => binary_id,value => <<"1234">>} in 'Elixir.Enum':'-reduce/3-lists^foldl/2-0-'/3 line 1948 in context child_terminated
2019-12-01 16:43:18.030 [error] <0.5904.0> gen_server <0.5904.0> terminated with reason: #{'__exception__' => true,'__struct__' => 'Elixir.Ecto.Query.CastError',message => <<"lib/railway_ui/persistence.ex:66: value `\"1234\"` cannot be dumped to type :binary_id in query:\n\nfrom p0 in RailwayIpc.Persistence.PublishedMessage,\n  where: p0.uuid == ^\"1234\",\n  select: count(p0.uuid)\n">>,type => binary_id,value => <<"1234">>} in 'Elixir.Enum':'-reduce/3-lists^foldl/2-0-'/3 line 1948
2019-12-01 16:43:18.030 [error] <0.5904.0> CRASH REPORT Process <0.5904.0> with 0 neighbours crashed with reason: #{'__exception__' => true,'__struct__' => 'Elixir.Ecto.Query.CastError',message => <<"lib/railway_ui/persistence.ex:66: value `\"1234\"` cannot be dumped to type :binary_id in query:\n\nfrom p0 in RailwayIpc.Persistence.PublishedMessage,\n  where: p0.uuid == ^\"1234\",\n  select: count(p0.uuid)\n">>,type => binary_id,value => <<"1234">>} in 'Elixir.Enum':'-reduce/3-lists^foldl/2-0-'/3 line 1948
2019-12-01 16:43:18.031 [error] <0.520.0> Supervisor {<0.520.0>,'Elixir.Phoenix.Socket.PoolSupervisor.WorkerSupervisor'} had child 'Elixir.Phoenix.Channel.Server' started with {'Elixir.Phoenix.Channel.Server',start_link,undefined} at <0.5904.0> exit with reason #{'__exception__' => true,'__struct__' => 'Elixir.Ecto.Query.CastError',message => <<"lib/railway_ui/persistence.ex:66: value `\"1234\"` cannot be dumped to type :binary_id in query:\n\nfrom p0 in RailwayIpc.Persistence.PublishedMessage,\n  where: p0.uuid == ^\"1234\",\n  select: count(p0.uuid)\n">>,type => binary_id,value => <<"1234">>} in 'Elixir.Enum':'-reduce/3-lists^foldl/2-0-'/3 line 1948 in context child_terminated
2019-12-01 16:43:40.572 [error] <0.5931.0> gen_server <0.5931.0> terminated with reason: #{'__exception__' => true,'__struct__' => 'Elixir.Ecto.Query.CastError',message => <<"lib/railway_ui/persistence.ex:66: value `\"1234\"` cannot be dumped to type :binary_id in query:\n\nfrom p0 in RailwayIpc.Persistence.PublishedMessage,\n  where: p0.uuid == ^\"1234\",\n  select: count(p0.uuid)\n">>,type => binary_id,value => <<"1234">>} in 'Elixir.Enum':'-reduce/3-lists^foldl/2-0-'/3 line 1948
2019-12-01 16:43:40.573 [error] <0.5931.0> CRASH REPORT Process <0.5931.0> with 0 neighbours crashed with reason: #{'__exception__' => true,'__struct__' => 'Elixir.Ecto.Query.CastError',message => <<"lib/railway_ui/persistence.ex:66: value `\"1234\"` cannot be dumped to type :binary_id in query:\n\nfrom p0 in RailwayIpc.Persistence.PublishedMessage,\n  where: p0.uuid == ^\"1234\",\n  select: count(p0.uuid)\n">>,type => binary_id,value => <<"1234">>} in 'Elixir.Enum':'-reduce/3-lists^foldl/2-0-'/3 line 1948
2019-12-01 16:43:40.573 [error] <0.522.0> Supervisor {<0.522.0>,'Elixir.Phoenix.Socket.PoolSupervisor.WorkerSupervisor'} had child 'Elixir.Phoenix.Channel.Server' started with {'Elixir.Phoenix.Channel.Server',start_link,undefined} at <0.5931.0> exit with reason #{'__exception__' => true,'__struct__' => 'Elixir.Ecto.Query.CastError',message => <<"lib/railway_ui/persistence.ex:66: value `\"1234\"` cannot be dumped to type :binary_id in query:\n\nfrom p0 in RailwayIpc.Persistence.PublishedMessage,\n  where: p0.uuid == ^\"1234\",\n  select: count(p0.uuid)\n">>,type => binary_id,value => <<"1234">>} in 'Elixir.Enum':'-reduce/3-lists^foldl/2-0-'/3 line 1948 in context child_terminated
2019-12-01 16:44:42.339 [error] <0.5971.0> gen_server <0.5971.0> terminated with reason: #{'__exception__' => true,'__struct__' => 'Elixir.Ecto.Query.CastError',message => <<"lib/railway_ui/persistence.ex:66: value `\"1234\"` cannot be dumped to type :binary_id in query:\n\nfrom p0 in RailwayIpc.Persistence.PublishedMessage,\n  where: p0.uuid == ^\"1234\",\n  select: count(p0.uuid)\n">>,type => binary_id,value => <<"1234">>} in 'Elixir.Enum':'-reduce/3-lists^foldl/2-0-'/3 line 1948
2019-12-01 16:44:42.341 [error] <0.5971.0> CRASH REPORT Process <0.5971.0> with 0 neighbours crashed with reason: #{'__exception__' => true,'__struct__' => 'Elixir.Ecto.Query.CastError',message => <<"lib/railway_ui/persistence.ex:66: value `\"1234\"` cannot be dumped to type :binary_id in query:\n\nfrom p0 in RailwayIpc.Persistence.PublishedMessage,\n  where: p0.uuid == ^\"1234\",\n  select: count(p0.uuid)\n">>,type => binary_id,value => <<"1234">>} in 'Elixir.Enum':'-reduce/3-lists^foldl/2-0-'/3 line 1948
2019-12-01 16:44:42.342 [error] <0.522.0> Supervisor {<0.522.0>,'Elixir.Phoenix.Socket.PoolSupervisor.WorkerSupervisor'} had child 'Elixir.Phoenix.Channel.Server' started with {'Elixir.Phoenix.Channel.Server',start_link,undefined} at <0.5971.0> exit with reason #{'__exception__' => true,'__struct__' => 'Elixir.Ecto.Query.CastError',message => <<"lib/railway_ui/persistence.ex:66: value `\"1234\"` cannot be dumped to type :binary_id in query:\n\nfrom p0 in RailwayIpc.Persistence.PublishedMessage,\n  where: p0.uuid == ^\"1234\",\n  select: count(p0.uuid)\n">>,type => binary_id,value => <<"1234">>} in 'Elixir.Enum':'-reduce/3-lists^foldl/2-0-'/3 line 1948 in context child_terminated
2019-12-01 16:45:19.280 [error] <0.6027.0> gen_server <0.6027.0> terminated with reason: #{'__exception__' => true,'__struct__' => 'Elixir.Ecto.Query.CastError',message => <<"lib/railway_ui/persistence.ex:66: value `\"1234\"` cannot be dumped to type :binary_id in query:\n\nfrom p0 in RailwayIpc.Persistence.PublishedMessage,\n  where: p0.uuid == ^\"1234\",\n  select: count(p0.uuid)\n">>,type => binary_id,value => <<"1234">>} in 'Elixir.Enum':'-reduce/3-lists^foldl/2-0-'/3 line 1948
2019-12-01 16:45:19.280 [error] <0.6027.0> CRASH REPORT Process <0.6027.0> with 0 neighbours crashed with reason: #{'__exception__' => true,'__struct__' => 'Elixir.Ecto.Query.CastError',message => <<"lib/railway_ui/persistence.ex:66: value `\"1234\"` cannot be dumped to type :binary_id in query:\n\nfrom p0 in RailwayIpc.Persistence.PublishedMessage,\n  where: p0.uuid == ^\"1234\",\n  select: count(p0.uuid)\n">>,type => binary_id,value => <<"1234">>} in 'Elixir.Enum':'-reduce/3-lists^foldl/2-0-'/3 line 1948
2019-12-01 16:45:19.280 [error] <0.522.0> Supervisor {<0.522.0>,'Elixir.Phoenix.Socket.PoolSupervisor.WorkerSupervisor'} had child 'Elixir.Phoenix.Channel.Server' started with {'Elixir.Phoenix.Channel.Server',start_link,undefined} at <0.6027.0> exit with reason #{'__exception__' => true,'__struct__' => 'Elixir.Ecto.Query.CastError',message => <<"lib/railway_ui/persistence.ex:66: value `\"1234\"` cannot be dumped to type :binary_id in query:\n\nfrom p0 in RailwayIpc.Persistence.PublishedMessage,\n  where: p0.uuid == ^\"1234\",\n  select: count(p0.uuid)\n">>,type => binary_id,value => <<"1234">>} in 'Elixir.Enum':'-reduce/3-lists^foldl/2-0-'/3 line 1948 in context child_terminated
2019-12-01 16:50:28.983 [error] <0.6121.0> CRASH REPORT Process <0.6121.0> with 0 neighbours exited with reason: {{#{'__exception__' => true,'__struct__' => 'Elixir.Ecto.Query.CastError',message => <<"lib/railway_ui/persistence.ex:66: value `\"1234\"` cannot be dumped to type :binary_id in query:\n\nfrom p0 in RailwayIpc.Persistence.PublishedMessage,\n  where: p0.uuid == ^\"1234\",\n  limit: ^2,\n  offset: ^0,\n  select: p0\n">>,type => binary_id,value => <<"1234">>},[{'Elixir.Enum','-reduce/3-lists^foldl/2-0-',3,[{file,"lib/enum.ex"},{line,1948}]},{'Elixir.Enum','-map_reduce/3-lists^mapfoldl/2-0-',3,[{file,...},...]},...]},...} in 'Elixir.Phoenix.Endpoint.Cowboy2Handler':init/4 line 59 in 'Elixir.Phoenix.Endpoint.Cowboy2Handler':init/4 line 59
2019-12-01 16:50:28.999 [error] <0.398.0> Lager event handler error_logger_lager_h exited with reason {'EXIT',{{case_clause,['Elixir.RailwayUiWeb.Endpoint.HTTP',<0.6119.0>,1,<0.6121.0>,{{#{'__exception__' => true,'__struct__' => 'Elixir.Ecto.Query.CastError',message => <<"lib/railway_ui/persistence.ex:66: value `\"1234\"` cannot be dumped to type :binary_id in query:\n\nfrom p0 in RailwayIpc.Persistence.PublishedMessage,\n  where: p0.uuid == ^\"1234\",\n  limit: ^2,\n  offset: ^0,\n  select: p0\n">>,type => binary_id,value => <<"1234">>},[{'Elixir.Enum','-reduce/3-lists^foldl/2-0-',3,[{file,"li..."},...]},...]},...},...]},...}}
2019-12-01 16:50:37.734 [error] <0.6172.0> gen_server <0.6172.0> terminated with reason: #{'__exception__' => true,'__struct__' => 'Elixir.Ecto.Query.CastError',message => <<"lib/railway_ui/persistence.ex:66: value `\"1234\"` cannot be dumped to type :binary_id in query:\n\nfrom p0 in RailwayIpc.Persistence.PublishedMessage,\n  where: p0.uuid == ^\"1234\",\n  limit: ^2,\n  offset: ^0,\n  select: p0\n">>,type => binary_id,value => <<"1234">>} in 'Elixir.Enum':'-reduce/3-lists^foldl/2-0-'/3 line 1948
2019-12-01 16:50:37.735 [error] <0.6172.0> CRASH REPORT Process <0.6172.0> with 0 neighbours crashed with reason: #{'__exception__' => true,'__struct__' => 'Elixir.Ecto.Query.CastError',message => <<"lib/railway_ui/persistence.ex:66: value `\"1234\"` cannot be dumped to type :binary_id in query:\n\nfrom p0 in RailwayIpc.Persistence.PublishedMessage,\n  where: p0.uuid == ^\"1234\",\n  limit: ^2,\n  offset: ^0,\n  select: p0\n">>,type => binary_id,value => <<"1234">>} in 'Elixir.Enum':'-reduce/3-lists^foldl/2-0-'/3 line 1948
2019-12-01 16:50:37.735 [error] <0.522.0> Supervisor {<0.522.0>,'Elixir.Phoenix.Socket.PoolSupervisor.WorkerSupervisor'} had child 'Elixir.Phoenix.Channel.Server' started with {'Elixir.Phoenix.Channel.Server',start_link,undefined} at <0.6172.0> exit with reason #{'__exception__' => true,'__struct__' => 'Elixir.Ecto.Query.CastError',message => <<"lib/railway_ui/persistence.ex:66: value `\"1234\"` cannot be dumped to type :binary_id in query:\n\nfrom p0 in RailwayIpc.Persistence.PublishedMessage,\n  where: p0.uuid == ^\"1234\",\n  limit: ^2,\n  offset: ^0,\n  select: p0\n">>,type => binary_id,value => <<"1234">>} in 'Elixir.Enum':'-reduce/3-lists^foldl/2-0-'/3 line 1948 in context child_terminated
2019-12-01 16:52:39.838 [error] <0.6219.0> gen_server <0.6219.0> terminated with reason: #{'__exception__' => true,'__struct__' => 'Elixir.Ecto.Query.CastError',message => <<"lib/railway_ui/persistence.ex:66: value `\"1234\"` cannot be dumped to type :binary_id in query:\n\nfrom p0 in RailwayIpc.Persistence.PublishedMessage,\n  where: p0.uuid == ^\"1234\",\n  select: count(p0.uuid)\n">>,type => binary_id,value => <<"1234">>} in 'Elixir.Enum':'-reduce/3-lists^foldl/2-0-'/3 line 1948
2019-12-01 16:52:39.839 [error] <0.6219.0> CRASH REPORT Process <0.6219.0> with 0 neighbours crashed with reason: #{'__exception__' => true,'__struct__' => 'Elixir.Ecto.Query.CastError',message => <<"lib/railway_ui/persistence.ex:66: value `\"1234\"` cannot be dumped to type :binary_id in query:\n\nfrom p0 in RailwayIpc.Persistence.PublishedMessage,\n  where: p0.uuid == ^\"1234\",\n  select: count(p0.uuid)\n">>,type => binary_id,value => <<"1234">>} in 'Elixir.Enum':'-reduce/3-lists^foldl/2-0-'/3 line 1948
2019-12-01 16:52:39.839 [error] <0.522.0> Supervisor {<0.522.0>,'Elixir.Phoenix.Socket.PoolSupervisor.WorkerSupervisor'} had child 'Elixir.Phoenix.Channel.Server' started with {'Elixir.Phoenix.Channel.Server',start_link,undefined} at <0.6219.0> exit with reason #{'__exception__' => true,'__struct__' => 'Elixir.Ecto.Query.CastError',message => <<"lib/railway_ui/persistence.ex:66: value `\"1234\"` cannot be dumped to type :binary_id in query:\n\nfrom p0 in RailwayIpc.Persistence.PublishedMessage,\n  where: p0.uuid == ^\"1234\",\n  select: count(p0.uuid)\n">>,type => binary_id,value => <<"1234">>} in 'Elixir.Enum':'-reduce/3-lists^foldl/2-0-'/3 line 1948 in context child_terminated
2019-12-01 16:53:54.417 [error] <0.6225.0>@Elixir.RailwayUiWeb.PublishedMessageLive.Index:terminate:3 gen_server <0.6225.0> terminated with reason: no function clause matching 'Elixir.RailwayUiWeb.PublishedMessageLive.Index':terminate({shutdown,closed}, #{'__struct__' => 'Elixir.Phoenix.LiveView.Socket',assigns => #{messages => [],state => #{'__struct__' => ...,...},...},...}) line 3
2019-12-01 16:53:54.418 [error] <0.6225.0>@Elixir.RailwayUiWeb.PublishedMessageLive.Index:terminate:3 CRASH REPORT Process <0.6225.0> with 0 neighbours crashed with reason: no function clause matching 'Elixir.RailwayUiWeb.PublishedMessageLive.Index':terminate({shutdown,closed}, #{'__struct__' => 'Elixir.Phoenix.LiveView.Socket',assigns => #{messages => [],state => #{'__struct__' => ...,...},...},...}) line 3
2019-12-01 16:53:54.418 [error] <0.521.0>@Elixir.RailwayUiWeb.PublishedMessageLive.Index:terminate:3 Supervisor {<0.521.0>,'Elixir.Phoenix.Socket.PoolSupervisor.WorkerSupervisor'} had child 'Elixir.Phoenix.Channel.Server' started with {'Elixir.Phoenix.Channel.Server',start_link,undefined} at <0.6225.0> exit with reason no function clause matching 'Elixir.RailwayUiWeb.PublishedMessageLive.Index':terminate({shutdown,closed}, #{'__struct__' => 'Elixir.Phoenix.LiveView.Socket',assigns => #{messages => [],state => #{'__struct__' => ...,...},...},...}) line 3 in context child_terminated
2019-12-01 16:54:41.229 [error] <0.6358.0> gen_server <0.6358.0> terminated with reason: {#{'__exception__' => true,'__struct__' => 'Elixir.ArgumentError',message => <<"argument error">>},[{erlang,apply,[1,message_type,[]],[]},{'Elixir.RailwayUiWeb.PublishedMessageView','-index.html/1-fun-0-',2,[{file,"lib/railway_ui_web/templates/published_message/index.html.leex"},{line,22}]},{'Elixir.Enum','-reduce/3-lists^foldl/2-0-',3,[{file,"lib/enum.ex"},{line,1948}]},{'Elixir.RailwayUiWeb.PublishedMessageView','index.html',1,[{file,"lib/railway_ui_web/templates/published_message/index.h..."},...]},...]}
2019-12-01 16:54:41.231 [error] <0.6358.0> CRASH REPORT Process <0.6358.0> with 0 neighbours crashed with reason: {#{'__exception__' => true,'__struct__' => 'Elixir.ArgumentError',message => <<"argument error">>},[{erlang,apply,[1,message_type,[]],[]},{'Elixir.RailwayUiWeb.PublishedMessageView','-index.html/1-fun-0-',2,[{file,"lib/railway_ui_web/templates/published_message/index.html.leex"},{line,22}]},{'Elixir.Enum','-reduce/3-lists^foldl/2-0-',3,[{file,"lib/enum.ex"},{line,1948}]},{'Elixir.RailwayUiWeb.PublishedMessageView','index.html',1,[{file,"lib/railway_ui_web/templates/published_message/index.h..."},...]},...]}
2019-12-01 16:54:41.231 [error] <0.523.0> Supervisor {<0.523.0>,'Elixir.Phoenix.Socket.PoolSupervisor.WorkerSupervisor'} had child 'Elixir.Phoenix.Channel.Server' started with {'Elixir.Phoenix.Channel.Server',start_link,undefined} at <0.6358.0> exit with reason {#{'__exception__' => true,'__struct__' => 'Elixir.ArgumentError',message => <<"argument error">>},[{erlang,apply,[1,message_type,[]],[]},{'Elixir.RailwayUiWeb.PublishedMessageView','-index.html/1-fun-0-',2,[{file,"lib/railway_ui_web/templates/published_message/index.html.leex"},{line,22}]},{'Elixir.Enum','-reduce/3-lists^foldl/2-0-',3,[{file,"lib/enum.ex"},{line,1948}]},{'Elixir.RailwayUiWeb.PublishedMessageView','index.html',1,[{file,"lib/railway_ui_web/templates/published_message/index.h..."},...]},...]} in context child_terminated
2019-12-01 16:54:41.360 [error] <0.6344.0> CRASH REPORT Process <0.6344.0> with 0 neighbours exited with reason: {{#{'__exception__' => true,'__struct__' => 'Elixir.ArgumentError',message => <<"argument error">>},[{erlang,apply,[1,message_type,[]],[]},{'Elixir.RailwayUiWeb.PublishedMessageView','-index.html/1-fun-0-',2,[{file,"lib/railway_ui_web/templates/published_message/index.html.leex"},{line,22}]},{'Elixir.Enum','-reduce/3-lists^foldl/2-0-',3,[{file,"lib/enum.ex"},{line,1948}]},{'Elixir.RailwayUiWeb.PublishedMessageView','index.html',1,[{file,"lib/railway_ui_web/templates/published_message/index..."},...]},...]},...} in 'Elixir.Phoenix.Endpoint.Cowboy2Handler':init/4 line 59 in 'Elixir.Phoenix.Endpoint.Cowboy2Handler':init/4 line 59
2019-12-01 16:54:41.374 [error] <0.398.0> Lager event handler error_logger_lager_h exited with reason {'EXIT',{{case_clause,['Elixir.RailwayUiWeb.Endpoint.HTTP',<0.6343.0>,1,<0.6344.0>,{{#{'__exception__' => true,'__struct__' => 'Elixir.ArgumentError',message => <<"argument error">>},[{erlang,apply,[1,message_type,[]],[]},{'Elixir.RailwayUiWeb.PublishedMessageView','-index.html/1-fun-0-',2,[{file,"lib/railway_ui_web/templates/published_message/index.html.leex"},{line,22}]},{'Elixir.Enum','-reduce/3-lists^foldl/2-0-',3,[{file,"lib/enum.ex"},{line,1948}]},{'Elixir.RailwayUiWeb.PublishedMessageView',...},...]},...},...]},...}}
2019-12-01 16:55:15.354 [error] <0.6375.0> CRASH REPORT Process <0.6375.0> with 0 neighbours exited with reason: {{#{'__exception__' => true,'__struct__' => 'Elixir.ArgumentError',message => <<"argument error">>},[{erlang,iolist_to_binary,[nil],[]},{'Elixir.Jason',decode,2,[{file,"lib/jason.ex"},{line,55}]},{'Elixir.Jason','decode!',2,[{file,"lib/jason.ex"},{line,76}]},{'Elixir.RailwayUiWeb.MessageViewHelper',decode_message_body,1,[{file,"lib/railway_ui_web/views/message_view_helper.ex"},{line,3}]},{'Elixir.RailwayUiWeb.PublishedMessageView','-index.html/1-fun-0-',2,[{file,"lib/railway_ui_web/templat..."},...]},...]},...} in 'Elixir.Phoenix.Endpoint.Cowboy2Handler':init/4 line 59 in 'Elixir.Phoenix.Endpoint.Cowboy2Handler':init/4 line 59
2019-12-01 16:55:15.362 [error] <0.398.0> Lager event handler error_logger_lager_h exited with reason {'EXIT',{{case_clause,['Elixir.RailwayUiWeb.Endpoint.HTTP',<0.6373.0>,1,<0.6375.0>,{{#{'__exception__' => true,'__struct__' => 'Elixir.ArgumentError',message => <<"argument error">>},[{erlang,iolist_to_binary,[nil],[]},{'Elixir.Jason',decode,2,[{file,"lib/jason.ex"},{line,55}]},{'Elixir.Jason','decode!',2,[{file,"lib/jason.ex"},{line,76}]},{'Elixir.RailwayUiWeb.MessageViewHelper',decode_message_body,1,[{file,"lib/railway_ui_web/views/message_view_helper.ex"},{line,3}]},{'Elixir.RailwayUiWeb.PublishedMessageView',...},...]},...},...]},...}}
2019-12-01 17:08:51.686 [error] <0.739.0> CRASH REPORT Process <0.739.0> with 0 neighbours exited with reason: {{#{'__exception__' => true,'__struct__' => 'Elixir.ArgumentError',message => <<"assign @uuid not available in eex template.\n\nPlease make sure all proper assigns have been set. If this\nis a child template, ensure assigns are given explicitly by\nthe parent template as they are not automatically forwarded.\n\nAvailable assigns: [:messages, :socket, :state, :view, :view_module, :view_template]\n">>},[{'Elixir.Phoenix.LiveView.Engine','fetch_assign!',2,[{file,"lib/phoenix_live_view/engine.ex"},{line,...}]},...]},...} in 'Elixir.Phoenix.Endpoint.Cowboy2Handler':init/4 line 59 in 'Elixir.Phoenix.Endpoint.Cowboy2Handler':init/4 line 59
2019-12-01 17:08:51.817 [error] <0.389.0> Lager event handler error_logger_lager_h exited with reason {'EXIT',{{case_clause,['Elixir.RailwayUiWeb.Endpoint.HTTP',<0.737.0>,1,<0.739.0>,{{#{'__exception__' => true,'__struct__' => 'Elixir.ArgumentError',message => <<"assign @uuid not available in eex template.\n\nPlease make sure all proper assigns have been set. If this\nis a child template, ensure assigns are given explicitly by\nthe parent template as they are not automatically forwarded.\n\nAvailable assigns: [:messages, :socket, :state, :view, :view_module, :view_template]\n">>},[{'Elixir.Phoenix.LiveView.Engine',...},...]},...},...]},...}}
2019-12-01 17:10:57.657 [error] <0.837.0> CRASH REPORT Process <0.837.0> with 0 neighbours exited with reason: {{#{'__exception__' => true,'__struct__' => 'Elixir.ArgumentError',message => <<"assign @uuid not available in eex template.\n\nPlease make sure all proper assigns have been set. If this\nis a child template, ensure assigns are given explicitly by\nthe parent template as they are not automatically forwarded.\n\nAvailable assigns: [:messages, :socket, :state, :view, :view_module, :view_template]\n">>},[{'Elixir.Phoenix.LiveView.Engine','fetch_assign!',2,[{file,"lib/phoenix_live_view/engine.ex"},{line,...}]},...]},...} in 'Elixir.Phoenix.Endpoint.Cowboy2Handler':init/4 line 59 in 'Elixir.Phoenix.Endpoint.Cowboy2Handler':init/4 line 59
2019-12-01 17:10:57.667 [error] <0.389.0> Lager event handler error_logger_lager_h exited with reason {'EXIT',{{case_clause,['Elixir.RailwayUiWeb.Endpoint.HTTP',<0.836.0>,1,<0.837.0>,{{#{'__exception__' => true,'__struct__' => 'Elixir.ArgumentError',message => <<"assign @uuid not available in eex template.\n\nPlease make sure all proper assigns have been set. If this\nis a child template, ensure assigns are given explicitly by\nthe parent template as they are not automatically forwarded.\n\nAvailable assigns: [:messages, :socket, :state, :view, :view_module, :view_template]\n">>},[{'Elixir.Phoenix.LiveView.Engine',...},...]},...},...]},...}}
2019-12-01 17:17:38.076 [error] <0.873.0> CRASH REPORT Process <0.873.0> with 0 neighbours exited with reason: {{#{'__exception__' => true,'__struct__' => 'Elixir.ArgumentError',message => <<"assign @uuid not available in eex template.\n\nPlease make sure all proper assigns have been set. If this\nis a child template, ensure assigns are given explicitly by\nthe parent template as they are not automatically forwarded.\n\nAvailable assigns: [:messages, :socket, :state, :view, :view_module, :view_template]\n">>},[{'Elixir.Phoenix.LiveView.Engine','fetch_assign!',2,[{file,"lib/phoenix_live_view/engine.ex"},{line,...}]},...]},...} in 'Elixir.Phoenix.Endpoint.Cowboy2Handler':init/4 line 59 in 'Elixir.Phoenix.Endpoint.Cowboy2Handler':init/4 line 59
2019-12-01 17:17:38.081 [error] <0.389.0> Lager event handler error_logger_lager_h exited with reason {'EXIT',{{case_clause,['Elixir.RailwayUiWeb.Endpoint.HTTP',<0.872.0>,1,<0.873.0>,{{#{'__exception__' => true,'__struct__' => 'Elixir.ArgumentError',message => <<"assign @uuid not available in eex template.\n\nPlease make sure all proper assigns have been set. If this\nis a child template, ensure assigns are given explicitly by\nthe parent template as they are not automatically forwarded.\n\nAvailable assigns: [:messages, :socket, :state, :view, :view_module, :view_template]\n">>},[{'Elixir.Phoenix.LiveView.Engine',...},...]},...},...]},...}}
2019-12-01 17:20:06.152 [error] <0.991.0> CRASH REPORT Process <0.991.0> with 0 neighbours exited with reason: {{#{'__exception__' => true,'__struct__' => 'Elixir.ArgumentError',message => <<"assign @uuid not available in eex template.\n\nPlease make sure all proper assigns have been set. If this\nis a child template, ensure assigns are given explicitly by\nthe parent template as they are not automatically forwarded.\n\nAvailable assigns: [:messages, :socket, :state, :view, :view_module, :view_template]\n">>},[{'Elixir.Phoenix.LiveView.Engine','fetch_assign!',2,[{file,"lib/phoenix_live_view/engine.ex"},{line,...}]},...]},...} in 'Elixir.Phoenix.Endpoint.Cowboy2Handler':init/4 line 59 in 'Elixir.Phoenix.Endpoint.Cowboy2Handler':init/4 line 59
2019-12-01 17:20:06.200 [error] <0.389.0> Lager event handler error_logger_lager_h exited with reason {'EXIT',{{case_clause,['Elixir.RailwayUiWeb.Endpoint.HTTP',<0.969.0>,4,<0.991.0>,{{#{'__exception__' => true,'__struct__' => 'Elixir.ArgumentError',message => <<"assign @uuid not available in eex template.\n\nPlease make sure all proper assigns have been set. If this\nis a child template, ensure assigns are given explicitly by\nthe parent template as they are not automatically forwarded.\n\nAvailable assigns: [:messages, :socket, :state, :view, :view_module, :view_template]\n">>},[{'Elixir.Phoenix.LiveView.Engine',...},...]},...},...]},...}}
2019-12-01 17:21:36.140 [error] <0.591.0>@Elixir.RailwayUiWeb.PublishedMessageLive.Index:handle_event:14 gen_server <0.591.0> terminated with reason: call to undefined function 'Elixir.RailwayUiWeb.MessageLive.Index.State':request_data/1 from 'Elixir.RailwayUiWeb.PublishedMessageLive.Index':handle_event/3 line 14
2019-12-01 17:21:36.181 [error] <0.591.0>@Elixir.RailwayUiWeb.MessageLive.Index.State:request_data CRASH REPORT Process <0.591.0> with 0 neighbours crashed with reason: call to undefined function 'Elixir.RailwayUiWeb.MessageLive.Index.State':request_data(#{'__struct__' => 'Elixir.RailwayUiWeb.MessageLive.Index.State',current_user_uuid => <<"67f6c79c-...">>,...})
2019-12-01 17:21:36.182 [error] <0.473.0>@Elixir.RailwayUiWeb.MessageLive.Index.State:request_data Supervisor 'Elixir.Phoenix.LiveView.DynamicSupervisor' had child undefined started with {'Elixir.Phoenix.LiveView.Channel',start_link,undefined} at <0.591.0> exit with reason call to undefined function 'Elixir.RailwayUiWeb.MessageLive.Index.State':request_data(#{'__struct__' => 'Elixir.RailwayUiWeb.MessageLive.Index.State',current_user_uuid => <<"67f6c79c-...">>,...}) in context child_terminated
