2019-12-01 00:43:33.949 [error] <0.3567.0> gen_server <0.3567.0> terminated with reason: {socket_error,timeout}
2019-12-01 00:43:33.950 [error] <0.3567.0> CRASH REPORT Process <0.3567.0> with 0 neighbours exited with reason: {socket_error,timeout} in gen_server:handle_common_reply/8 line 751
2019-12-01 00:43:33.950 [error] <0.3563.0> gen_server <0.3563.0> terminated with reason: {socket_error,timeout}
2019-12-01 00:43:33.950 [error] <0.3562.0> Supervisor {<0.3562.0>,amqp_connection_type_sup} had child main_reader started with amqp_main_reader:start_link(#Port<0.530>, <0.3563.0>, <0.3565.0>, {method,rabbit_framing_amqp_0_9_1}, <<"client 127.0.0.1:63481 -> 127.0.0.1:5672">>) at <0.3567.0> exit with reason {socket_error,timeout} in context child_terminated
2019-12-01 00:43:33.950 [error] <0.3562.0> Supervisor {<0.3562.0>,amqp_connection_type_sup} had child main_reader started with amqp_main_reader:start_link(#Port<0.530>, <0.3563.0>, <0.3565.0>, {method,rabbit_framing_amqp_0_9_1}, <<"client 127.0.0.1:63481 -> 127.0.0.1:5672">>) at <0.3567.0> exit with reason reached_max_restart_intensity in context shutdown
2019-12-01 00:43:33.951 [error] <0.3563.0> CRASH REPORT Process <0.3563.0> with 0 neighbours exited with reason: {socket_error,timeout} in gen_server:handle_common_reply/8 line 751
2019-12-01 00:43:33.952 [error] <0.3561.0> Supervisor {<0.3561.0>,amqp_connection_sup} had child connection started with amqp_gen_connection:start_link(<0.3562.0>, {amqp_params_network,<<"guest">>,<<"guest">>,<<"/">>,"localhost",5672,2047,0,10,60000,none,[#Fun<am..>,...],...}) at <0.3563.0> exit with reason {socket_error,timeout} in context child_terminated
2019-12-01 00:43:33.953 [error] <0.3561.0> Supervisor {<0.3561.0>,amqp_connection_sup} had child connection started with amqp_gen_connection:start_link(<0.3562.0>, {amqp_params_network,<<"guest">>,<<"guest">>,<<"/">>,"localhost",5672,2047,0,10,60000,none,[#Fun<am..>,...],...}) at <0.3563.0> exit with reason reached_max_restart_intensity in context shutdown
2019-12-01 00:43:33.953 [error] <0.3558.0>@gen_server:call gen_server 'Elixir.RailwayIpc.Connection' terminated with reason: no such process or port in call to gen_server:call(<0.3563.0>, {command,{close,{'connection.close',200,<<"Goodbye">>,0,0},60000}}, 60000) in gen_server:call/3 line 223
2019-12-01 00:43:33.953 [error] <0.3558.0>@gen_server:call CRASH REPORT Process 'Elixir.RailwayIpc.Connection' with 0 neighbours exited with reason: no such process or port in call to gen_server:call(<0.3563.0>, {command,{close,{'connection.close',200,<<"Goodbye">>,0,0},60000}}, 60000) in gen_server:call/3 line 223
2019-12-01 00:43:33.953 [error] <0.433.0>@gen_server:call Supervisor 'Elixir.RailwayIpc.Connection.Supervisor' had child 'Elixir.RailwayIpc.Connection' started with 'Elixir.RailwayIpc.Connection':start_link([{name,'Elixir.RailwayIpc.Connection'}]) at <0.3558.0> exit with reason no such process or port in call to gen_server:call(<0.3563.0>, {command,{close,{'connection.close',200,<<"Goodbye">>,0,0},60000}}, 60000) in context child_terminated
2019-12-01 01:37:45.618 [error] <0.3597.0> gen_server <0.3597.0> terminated with reason: {socket_error,timeout}
2019-12-01 01:37:45.619 [error] <0.3593.0> gen_server <0.3593.0> terminated with reason: {socket_error,timeout}
2019-12-01 01:37:45.619 [error] <0.3597.0> CRASH REPORT Process <0.3597.0> with 0 neighbours exited with reason: {socket_error,timeout} in gen_server:handle_common_reply/8 line 751
2019-12-01 01:37:45.619 [error] <0.3592.0> Supervisor {<0.3592.0>,amqp_connection_type_sup} had child main_reader started with amqp_main_reader:start_link(#Port<0.533>, <0.3593.0>, <0.3595.0>, {method,rabbit_framing_amqp_0_9_1}, <<"client 127.0.0.1:63749 -> 127.0.0.1:5672">>) at <0.3597.0> exit with reason {socket_error,timeout} in context child_terminated
2019-12-01 01:37:45.620 [error] <0.3592.0> Supervisor {<0.3592.0>,amqp_connection_type_sup} had child main_reader started with amqp_main_reader:start_link(#Port<0.533>, <0.3593.0>, <0.3595.0>, {method,rabbit_framing_amqp_0_9_1}, <<"client 127.0.0.1:63749 -> 127.0.0.1:5672">>) at <0.3597.0> exit with reason reached_max_restart_intensity in context shutdown
2019-12-01 01:37:45.620 [error] <0.3593.0> CRASH REPORT Process <0.3593.0> with 0 neighbours exited with reason: {socket_error,timeout} in gen_server:handle_common_reply/8 line 751
2019-12-01 01:37:45.620 [error] <0.3591.0> Supervisor {<0.3591.0>,amqp_connection_sup} had child connection started with amqp_gen_connection:start_link(<0.3592.0>, {amqp_params_network,<<"guest">>,<<"guest">>,<<"/">>,"localhost",5672,2047,0,10,60000,none,[#Fun<am..>,...],...}) at <0.3593.0> exit with reason {socket_error,timeout} in context child_terminated
2019-12-01 01:37:45.620 [error] <0.3588.0>@gen_server:call gen_server 'Elixir.RailwayIpc.Connection' terminated with reason: no such process or port in call to gen_server:call(<0.3593.0>, {command,{close,{'connection.close',200,<<"Goodbye">>,0,0},60000}}, 60000) in gen_server:call/3 line 223
2019-12-01 01:37:45.620 [error] <0.3591.0> Supervisor {<0.3591.0>,amqp_connection_sup} had child connection started with amqp_gen_connection:start_link(<0.3592.0>, {amqp_params_network,<<"guest">>,<<"guest">>,<<"/">>,"localhost",5672,2047,0,10,60000,none,[#Fun<am..>,...],...}) at <0.3593.0> exit with reason reached_max_restart_intensity in context shutdown
2019-12-01 01:37:45.621 [error] <0.3588.0>@gen_server:call CRASH REPORT Process 'Elixir.RailwayIpc.Connection' with 0 neighbours exited with reason: no such process or port in call to gen_server:call(<0.3593.0>, {command,{close,{'connection.close',200,<<"Goodbye">>,0,0},60000}}, 60000) in gen_server:call/3 line 223
2019-12-01 01:37:45.621 [error] <0.433.0>@gen_server:call Supervisor 'Elixir.RailwayIpc.Connection.Supervisor' had child 'Elixir.RailwayIpc.Connection' started with 'Elixir.RailwayIpc.Connection':start_link([{name,'Elixir.RailwayIpc.Connection'}]) at <0.3588.0> exit with reason no such process or port in call to gen_server:call(<0.3593.0>, {command,{close,{'connection.close',200,<<"Goodbye">>,0,0},60000}}, 60000) in context child_terminated
2019-12-01 02:31:45.903 [error] <0.3632.0> gen_server <0.3632.0> terminated with reason: {socket_error,timeout}
2019-12-01 02:31:45.903 [error] <0.3632.0> CRASH REPORT Process <0.3632.0> with 0 neighbours exited with reason: {socket_error,timeout} in gen_server:handle_common_reply/8 line 751
2019-12-01 02:31:45.903 [error] <0.3628.0> gen_server <0.3628.0> terminated with reason: {socket_error,timeout}
2019-12-01 02:31:45.904 [error] <0.3627.0> Supervisor {<0.3627.0>,amqp_connection_type_sup} had child main_reader started with amqp_main_reader:start_link(#Port<0.536>, <0.3628.0>, <0.3630.0>, {method,rabbit_framing_amqp_0_9_1}, <<"client 127.0.0.1:64001 -> 127.0.0.1:5672">>) at <0.3632.0> exit with reason {socket_error,timeout} in context child_terminated
2019-12-01 02:31:45.904 [error] <0.3627.0> Supervisor {<0.3627.0>,amqp_connection_type_sup} had child main_reader started with amqp_main_reader:start_link(#Port<0.536>, <0.3628.0>, <0.3630.0>, {method,rabbit_framing_amqp_0_9_1}, <<"client 127.0.0.1:64001 -> 127.0.0.1:5672">>) at <0.3632.0> exit with reason reached_max_restart_intensity in context shutdown
2019-12-01 02:31:45.904 [error] <0.3628.0> CRASH REPORT Process <0.3628.0> with 0 neighbours exited with reason: {socket_error,timeout} in gen_server:handle_common_reply/8 line 751
2019-12-01 02:31:45.905 [error] <0.3623.0>@gen_server:call gen_server 'Elixir.RailwayIpc.Connection' terminated with reason: no such process or port in call to gen_server:call(<0.3628.0>, {command,{close,{'connection.close',200,<<"Goodbye">>,0,0},60000}}, 60000) in gen_server:call/3 line 223
2019-12-01 02:31:45.907 [error] <0.3623.0>@gen_server:call CRASH REPORT Process 'Elixir.RailwayIpc.Connection' with 0 neighbours exited with reason: no such process or port in call to gen_server:call(<0.3628.0>, {command,{close,{'connection.close',200,<<"Goodbye">>,0,0},60000}}, 60000) in gen_server:call/3 line 223
2019-12-01 02:31:45.924 [error] <0.3626.0> Supervisor {<0.3626.0>,amqp_connection_sup} had child connection started with amqp_gen_connection:start_link(<0.3627.0>, {amqp_params_network,<<"guest">>,<<"guest">>,<<"/">>,"localhost",5672,2047,0,10,60000,none,[#Fun<am..>,...],...}) at <0.3628.0> exit with reason {socket_error,timeout} in context child_terminated
2019-12-01 02:31:45.925 [error] <0.3626.0> Supervisor {<0.3626.0>,amqp_connection_sup} had child connection started with amqp_gen_connection:start_link(<0.3627.0>, {amqp_params_network,<<"guest">>,<<"guest">>,<<"/">>,"localhost",5672,2047,0,10,60000,none,[#Fun<am..>,...],...}) at <0.3628.0> exit with reason reached_max_restart_intensity in context shutdown
2019-12-01 02:31:45.925 [error] <0.433.0>@gen_server:call Supervisor 'Elixir.RailwayIpc.Connection.Supervisor' had child 'Elixir.RailwayIpc.Connection' started with 'Elixir.RailwayIpc.Connection':start_link([{name,'Elixir.RailwayIpc.Connection'}]) at <0.3623.0> exit with reason no such process or port in call to gen_server:call(<0.3628.0>, {command,{close,{'connection.close',200,<<"Goodbye">>,0,0},60000}}, 60000) in context child_terminated
2019-12-01 03:25:51.941 [error] <0.3654.0> gen_server <0.3654.0> terminated with reason: {socket_error,timeout}
2019-12-01 03:25:51.941 [error] <0.3654.0> CRASH REPORT Process <0.3654.0> with 0 neighbours exited with reason: {socket_error,timeout} in gen_server:handle_common_reply/8 line 751
2019-12-01 03:25:51.941 [error] <0.3650.0> gen_server <0.3650.0> terminated with reason: {socket_error,timeout}
2019-12-01 03:25:51.942 [error] <0.3649.0> Supervisor {<0.3649.0>,amqp_connection_type_sup} had child main_reader started with amqp_main_reader:start_link(#Port<0.537>, <0.3650.0>, <0.3652.0>, {method,rabbit_framing_amqp_0_9_1}, <<"client 127.0.0.1:64020 -> 127.0.0.1:5672">>) at <0.3654.0> exit with reason {socket_error,timeout} in context child_terminated
2019-12-01 03:25:51.942 [error] <0.3649.0> Supervisor {<0.3649.0>,amqp_connection_type_sup} had child main_reader started with amqp_main_reader:start_link(#Port<0.537>, <0.3650.0>, <0.3652.0>, {method,rabbit_framing_amqp_0_9_1}, <<"client 127.0.0.1:64020 -> 127.0.0.1:5672">>) at <0.3654.0> exit with reason reached_max_restart_intensity in context shutdown
2019-12-01 03:25:51.942 [error] <0.3650.0> CRASH REPORT Process <0.3650.0> with 0 neighbours exited with reason: {socket_error,timeout} in gen_server:handle_common_reply/8 line 751
2019-12-01 03:25:51.942 [error] <0.3648.0> Supervisor {<0.3648.0>,amqp_connection_sup} had child connection started with amqp_gen_connection:start_link(<0.3649.0>, {amqp_params_network,<<"guest">>,<<"guest">>,<<"/">>,"localhost",5672,2047,0,10,60000,none,[#Fun<am..>,...],...}) at <0.3650.0> exit with reason {socket_error,timeout} in context child_terminated
2019-12-01 03:25:51.942 [error] <0.3648.0> Supervisor {<0.3648.0>,amqp_connection_sup} had child connection started with amqp_gen_connection:start_link(<0.3649.0>, {amqp_params_network,<<"guest">>,<<"guest">>,<<"/">>,"localhost",5672,2047,0,10,60000,none,[#Fun<am..>,...],...}) at <0.3650.0> exit with reason reached_max_restart_intensity in context shutdown
2019-12-01 03:25:51.943 [error] <0.3645.0>@gen_server:call gen_server 'Elixir.RailwayIpc.Connection' terminated with reason: no such process or port in call to gen_server:call(<0.3650.0>, {command,{close,{'connection.close',200,<<"Goodbye">>,0,0},60000}}, 60000) in gen_server:call/3 line 223
2019-12-01 03:25:51.944 [error] <0.3645.0>@gen_server:call CRASH REPORT Process 'Elixir.RailwayIpc.Connection' with 0 neighbours exited with reason: no such process or port in call to gen_server:call(<0.3650.0>, {command,{close,{'connection.close',200,<<"Goodbye">>,0,0},60000}}, 60000) in gen_server:call/3 line 223
2019-12-01 03:25:51.944 [error] <0.433.0>@gen_server:call Supervisor 'Elixir.RailwayIpc.Connection.Supervisor' had child 'Elixir.RailwayIpc.Connection' started with 'Elixir.RailwayIpc.Connection':start_link([{name,'Elixir.RailwayIpc.Connection'}]) at <0.3645.0> exit with reason no such process or port in call to gen_server:call(<0.3650.0>, {command,{close,{'connection.close',200,<<"Goodbye">>,0,0},60000}}, 60000) in context child_terminated
2019-12-01 04:19:57.900 [error] <0.3676.0> gen_server <0.3676.0> terminated with reason: {socket_error,timeout}
2019-12-01 04:19:57.900 [error] <0.3676.0> CRASH REPORT Process <0.3676.0> with 0 neighbours exited with reason: {socket_error,timeout} in gen_server:handle_common_reply/8 line 751
2019-12-01 04:19:57.902 [error] <0.3672.0> gen_server <0.3672.0> terminated with reason: {socket_error,timeout}
2019-12-01 04:19:57.903 [error] <0.3671.0> Supervisor {<0.3671.0>,amqp_connection_type_sup} had child main_reader started with amqp_main_reader:start_link(#Port<0.538>, <0.3672.0>, <0.3674.0>, {method,rabbit_framing_amqp_0_9_1}, <<"client 127.0.0.1:64057 -> 127.0.0.1:5672">>) at <0.3676.0> exit with reason {socket_error,timeout} in context child_terminated
2019-12-01 04:19:57.903 [error] <0.3671.0> Supervisor {<0.3671.0>,amqp_connection_type_sup} had child main_reader started with amqp_main_reader:start_link(#Port<0.538>, <0.3672.0>, <0.3674.0>, {method,rabbit_framing_amqp_0_9_1}, <<"client 127.0.0.1:64057 -> 127.0.0.1:5672">>) at <0.3676.0> exit with reason reached_max_restart_intensity in context shutdown
2019-12-01 04:19:57.903 [error] <0.3672.0> CRASH REPORT Process <0.3672.0> with 0 neighbours exited with reason: {socket_error,timeout} in gen_server:handle_common_reply/8 line 751
2019-12-01 04:19:57.904 [error] <0.3670.0> Supervisor {<0.3670.0>,amqp_connection_sup} had child connection started with amqp_gen_connection:start_link(<0.3671.0>, {amqp_params_network,<<"guest">>,<<"guest">>,<<"/">>,"localhost",5672,2047,0,10,60000,none,[#Fun<am..>,...],...}) at <0.3672.0> exit with reason {socket_error,timeout} in context child_terminated
2019-12-01 04:19:57.904 [error] <0.3670.0> Supervisor {<0.3670.0>,amqp_connection_sup} had child connection started with amqp_gen_connection:start_link(<0.3671.0>, {amqp_params_network,<<"guest">>,<<"guest">>,<<"/">>,"localhost",5672,2047,0,10,60000,none,[#Fun<am..>,...],...}) at <0.3672.0> exit with reason reached_max_restart_intensity in context shutdown
2019-12-01 04:19:57.904 [error] <0.3667.0>@gen_server:call gen_server 'Elixir.RailwayIpc.Connection' terminated with reason: no such process or port in call to gen_server:call(<0.3672.0>, {command,{close,{'connection.close',200,<<"Goodbye">>,0,0},60000}}, 60000) in gen_server:call/3 line 223
2019-12-01 04:19:57.905 [error] <0.3667.0>@gen_server:call CRASH REPORT Process 'Elixir.RailwayIpc.Connection' with 0 neighbours exited with reason: no such process or port in call to gen_server:call(<0.3672.0>, {command,{close,{'connection.close',200,<<"Goodbye">>,0,0},60000}}, 60000) in gen_server:call/3 line 223
2019-12-01 04:19:57.905 [error] <0.433.0>@gen_server:call Supervisor 'Elixir.RailwayIpc.Connection.Supervisor' had child 'Elixir.RailwayIpc.Connection' started with 'Elixir.RailwayIpc.Connection':start_link([{name,'Elixir.RailwayIpc.Connection'}]) at <0.3667.0> exit with reason no such process or port in call to gen_server:call(<0.3672.0>, {command,{close,{'connection.close',200,<<"Goodbye">>,0,0},60000}}, 60000) in context child_terminated
2019-12-01 04:46:03.903 [error] <0.3698.0> gen_server <0.3698.0> terminated with reason: {socket_error,timeout}
2019-12-01 04:46:03.903 [error] <0.3698.0> CRASH REPORT Process <0.3698.0> with 0 neighbours exited with reason: {socket_error,timeout} in gen_server:handle_common_reply/8 line 751
2019-12-01 04:46:03.903 [error] <0.3694.0> gen_server <0.3694.0> terminated with reason: {socket_error,timeout}
2019-12-01 04:46:03.904 [error] <0.3694.0> CRASH REPORT Process <0.3694.0> with 0 neighbours exited with reason: {socket_error,timeout} in gen_server:handle_common_reply/8 line 751
2019-12-01 04:46:03.905 [error] <0.3692.0> Supervisor {<0.3692.0>,amqp_connection_sup} had child connection started with amqp_gen_connection:start_link(<0.3693.0>, {amqp_params_network,<<"guest">>,<<"guest">>,<<"/">>,"localhost",5672,2047,0,10,60000,none,[#Fun<am..>,...],...}) at <0.3694.0> exit with reason {socket_error,timeout} in context child_terminated
2019-12-01 04:46:03.905 [error] <0.3692.0> Supervisor {<0.3692.0>,amqp_connection_sup} had child connection started with amqp_gen_connection:start_link(<0.3693.0>, {amqp_params_network,<<"guest">>,<<"guest">>,<<"/">>,"localhost",5672,2047,0,10,60000,none,[#Fun<am..>,...],...}) at <0.3694.0> exit with reason reached_max_restart_intensity in context shutdown
2019-12-01 04:46:03.906 [error] <0.3689.0>@gen_server:call gen_server 'Elixir.RailwayIpc.Connection' terminated with reason: no such process or port in call to gen_server:call(<0.3694.0>, {command,{close,{'connection.close',200,<<"Goodbye">>,0,0},60000}}, 60000) in gen_server:call/3 line 223
2019-12-01 04:46:03.906 [error] <0.3689.0>@gen_server:call CRASH REPORT Process 'Elixir.RailwayIpc.Connection' with 0 neighbours exited with reason: no such process or port in call to gen_server:call(<0.3694.0>, {command,{close,{'connection.close',200,<<"Goodbye">>,0,0},60000}}, 60000) in gen_server:call/3 line 223
2019-12-01 04:46:03.906 [error] <0.433.0>@gen_server:call Supervisor 'Elixir.RailwayIpc.Connection.Supervisor' had child 'Elixir.RailwayIpc.Connection' started with 'Elixir.RailwayIpc.Connection':start_link([{name,'Elixir.RailwayIpc.Connection'}]) at <0.3689.0> exit with reason no such process or port in call to gen_server:call(<0.3694.0>, {command,{close,{'connection.close',200,<<"Goodbye">>,0,0},60000}}, 60000) in context child_terminated
2019-12-01 04:46:03.916 [error] <0.3693.0> Supervisor {<0.3693.0>,amqp_connection_type_sup} had child main_reader started with amqp_main_reader:start_link(#Port<0.539>, <0.3694.0>, <0.3696.0>, {method,rabbit_framing_amqp_0_9_1}, <<"client 127.0.0.1:64093 -> 127.0.0.1:5672">>) at <0.3698.0> exit with reason {socket_error,timeout} in context child_terminated
2019-12-01 04:46:03.916 [error] <0.3693.0> Supervisor {<0.3693.0>,amqp_connection_type_sup} had child main_reader started with amqp_main_reader:start_link(#Port<0.539>, <0.3694.0>, <0.3696.0>, {method,rabbit_framing_amqp_0_9_1}, <<"client 127.0.0.1:64093 -> 127.0.0.1:5672">>) at <0.3698.0> exit with reason reached_max_restart_intensity in context shutdown
2019-12-01 05:16:40.915 [error] <0.3720.0> gen_server <0.3720.0> terminated with reason: {socket_error,timeout}
2019-12-01 05:16:40.915 [error] <0.3720.0> CRASH REPORT Process <0.3720.0> with 0 neighbours exited with reason: {socket_error,timeout} in gen_server:handle_common_reply/8 line 751
2019-12-01 05:16:40.916 [error] <0.3715.0> Supervisor {<0.3715.0>,amqp_connection_type_sup} had child main_reader started with amqp_main_reader:start_link(#Port<0.540>, <0.3716.0>, <0.3718.0>, {method,rabbit_framing_amqp_0_9_1}, <<"client 127.0.0.1:64134 -> 127.0.0.1:5672">>) at <0.3720.0> exit with reason {socket_error,timeout} in context child_terminated
2019-12-01 05:16:40.916 [error] <0.3715.0> Supervisor {<0.3715.0>,amqp_connection_type_sup} had child main_reader started with amqp_main_reader:start_link(#Port<0.540>, <0.3716.0>, <0.3718.0>, {method,rabbit_framing_amqp_0_9_1}, <<"client 127.0.0.1:64134 -> 127.0.0.1:5672">>) at <0.3720.0> exit with reason reached_max_restart_intensity in context shutdown
2019-12-01 05:16:40.916 [error] <0.3716.0> gen_server <0.3716.0> terminated with reason: {socket_error,timeout}
2019-12-01 05:16:40.916 [error] <0.3716.0> CRASH REPORT Process <0.3716.0> with 0 neighbours exited with reason: {socket_error,timeout} in gen_server:handle_common_reply/8 line 751
2019-12-01 05:16:40.916 [error] <0.3711.0>@gen_server:call gen_server 'Elixir.RailwayIpc.Connection' terminated with reason: no such process or port in call to gen_server:call(<0.3716.0>, {command,{close,{'connection.close',200,<<"Goodbye">>,0,0},60000}}, 60000) in gen_server:call/3 line 223
2019-12-01 05:16:40.918 [error] <0.3711.0>@gen_server:call CRASH REPORT Process 'Elixir.RailwayIpc.Connection' with 0 neighbours exited with reason: no such process or port in call to gen_server:call(<0.3716.0>, {command,{close,{'connection.close',200,<<"Goodbye">>,0,0},60000}}, 60000) in gen_server:call/3 line 223
2019-12-01 05:16:40.919 [error] <0.3714.0> Supervisor {<0.3714.0>,amqp_connection_sup} had child connection started with amqp_gen_connection:start_link(<0.3715.0>, {amqp_params_network,<<"guest">>,<<"guest">>,<<"/">>,"localhost",5672,2047,0,10,60000,none,[#Fun<am..>,...],...}) at <0.3716.0> exit with reason {socket_error,timeout} in context child_terminated
2019-12-01 05:16:40.919 [error] <0.3714.0> Supervisor {<0.3714.0>,amqp_connection_sup} had child connection started with amqp_gen_connection:start_link(<0.3715.0>, {amqp_params_network,<<"guest">>,<<"guest">>,<<"/">>,"localhost",5672,2047,0,10,60000,none,[#Fun<am..>,...],...}) at <0.3716.0> exit with reason reached_max_restart_intensity in context shutdown
2019-12-01 05:16:40.919 [error] <0.433.0>@gen_server:call Supervisor 'Elixir.RailwayIpc.Connection.Supervisor' had child 'Elixir.RailwayIpc.Connection' started with 'Elixir.RailwayIpc.Connection':start_link([{name,'Elixir.RailwayIpc.Connection'}]) at <0.3711.0> exit with reason no such process or port in call to gen_server:call(<0.3716.0>, {command,{close,{'connection.close',200,<<"Goodbye">>,0,0},60000}}, 60000) in context child_terminated
2019-12-01 06:10:47.915 [error] <0.3742.0> gen_server <0.3742.0> terminated with reason: {socket_error,timeout}
2019-12-01 06:10:47.915 [error] <0.3742.0> CRASH REPORT Process <0.3742.0> with 0 neighbours exited with reason: {socket_error,timeout} in gen_server:handle_common_reply/8 line 751
2019-12-01 06:10:47.915 [error] <0.3738.0> gen_server <0.3738.0> terminated with reason: {socket_error,timeout}
2019-12-01 06:10:47.915 [error] <0.3737.0> Supervisor {<0.3737.0>,amqp_connection_type_sup} had child main_reader started with amqp_main_reader:start_link(#Port<0.541>, <0.3738.0>, <0.3740.0>, {method,rabbit_framing_amqp_0_9_1}, <<"client 127.0.0.1:64180 -> 127.0.0.1:5672">>) at <0.3742.0> exit with reason {socket_error,timeout} in context child_terminated
2019-12-01 06:10:47.915 [error] <0.3737.0> Supervisor {<0.3737.0>,amqp_connection_type_sup} had child main_reader started with amqp_main_reader:start_link(#Port<0.541>, <0.3738.0>, <0.3740.0>, {method,rabbit_framing_amqp_0_9_1}, <<"client 127.0.0.1:64180 -> 127.0.0.1:5672">>) at <0.3742.0> exit with reason reached_max_restart_intensity in context shutdown
2019-12-01 06:10:47.915 [error] <0.3738.0> CRASH REPORT Process <0.3738.0> with 0 neighbours exited with reason: {socket_error,timeout} in gen_server:handle_common_reply/8 line 751
2019-12-01 06:10:47.915 [error] <0.3732.0>@gen_server:call gen_server 'Elixir.RailwayIpc.Connection' terminated with reason: no such process or port in call to gen_server:call(<0.3738.0>, {command,{close,{'connection.close',200,<<"Goodbye">>,0,0},60000}}, 60000) in gen_server:call/3 line 223
2019-12-01 06:10:47.915 [error] <0.3732.0>@gen_server:call CRASH REPORT Process 'Elixir.RailwayIpc.Connection' with 0 neighbours exited with reason: no such process or port in call to gen_server:call(<0.3738.0>, {command,{close,{'connection.close',200,<<"Goodbye">>,0,0},60000}}, 60000) in gen_server:call/3 line 223
2019-12-01 06:10:47.916 [error] <0.3736.0> Supervisor {<0.3736.0>,amqp_connection_sup} had child connection started with amqp_gen_connection:start_link(<0.3737.0>, {amqp_params_network,<<"guest">>,<<"guest">>,<<"/">>,"localhost",5672,2047,0,10,60000,none,[#Fun<am..>,...],...}) at <0.3738.0> exit with reason {socket_error,timeout} in context child_terminated
2019-12-01 06:10:47.916 [error] <0.3736.0> Supervisor {<0.3736.0>,amqp_connection_sup} had child connection started with amqp_gen_connection:start_link(<0.3737.0>, {amqp_params_network,<<"guest">>,<<"guest">>,<<"/">>,"localhost",5672,2047,0,10,60000,none,[#Fun<am..>,...],...}) at <0.3738.0> exit with reason reached_max_restart_intensity in context shutdown
2019-12-01 06:10:47.916 [error] <0.3736.0> Supervisor {<0.3736.0>,amqp_connection_sup} had child connection_type_sup started with amqp_connection_type_sup:start_link() at <0.3737.0> exit with reason shutdown in context shutdown_error
2019-12-01 06:10:47.916 [error] <0.433.0>@gen_server:call Supervisor 'Elixir.RailwayIpc.Connection.Supervisor' had child 'Elixir.RailwayIpc.Connection' started with 'Elixir.RailwayIpc.Connection':start_link([{name,'Elixir.RailwayIpc.Connection'}]) at <0.3732.0> exit with reason no such process or port in call to gen_server:call(<0.3738.0>, {command,{close,{'connection.close',200,<<"Goodbye">>,0,0},60000}}, 60000) in context child_terminated
2019-12-01 07:04:53.906 [error] <0.3764.0> gen_server <0.3764.0> terminated with reason: {socket_error,timeout}
2019-12-01 07:04:53.906 [error] <0.3764.0> CRASH REPORT Process <0.3764.0> with 0 neighbours exited with reason: {socket_error,timeout} in gen_server:handle_common_reply/8 line 751
2019-12-01 07:04:53.906 [error] <0.3759.0> gen_server <0.3759.0> terminated with reason: {socket_error,timeout}
2019-12-01 07:04:53.907 [error] <0.3758.0> Supervisor {<0.3758.0>,amqp_connection_type_sup} had child main_reader started with amqp_main_reader:start_link(#Port<0.542>, <0.3759.0>, <0.3762.0>, {method,rabbit_framing_amqp_0_9_1}, <<"client 127.0.0.1:64207 -> 127.0.0.1:5672">>) at <0.3764.0> exit with reason {socket_error,timeout} in context child_terminated
2019-12-01 07:04:53.907 [error] <0.3758.0> Supervisor {<0.3758.0>,amqp_connection_type_sup} had child main_reader started with amqp_main_reader:start_link(#Port<0.542>, <0.3759.0>, <0.3762.0>, {method,rabbit_framing_amqp_0_9_1}, <<"client 127.0.0.1:64207 -> 127.0.0.1:5672">>) at <0.3764.0> exit with reason reached_max_restart_intensity in context shutdown
2019-12-01 07:04:53.907 [error] <0.3759.0> CRASH REPORT Process <0.3759.0> with 0 neighbours exited with reason: {socket_error,timeout} in gen_server:handle_common_reply/8 line 751
2019-12-01 07:04:53.908 [error] <0.3754.0>@gen_server:call gen_server 'Elixir.RailwayIpc.Connection' terminated with reason: no such process or port in call to gen_server:call(<0.3759.0>, {command,{close,{'connection.close',200,<<"Goodbye">>,0,0},60000}}, 60000) in gen_server:call/3 line 223
2019-12-01 07:04:53.909 [error] <0.3754.0>@gen_server:call CRASH REPORT Process 'Elixir.RailwayIpc.Connection' with 0 neighbours exited with reason: no such process or port in call to gen_server:call(<0.3759.0>, {command,{close,{'connection.close',200,<<"Goodbye">>,0,0},60000}}, 60000) in gen_server:call/3 line 223
2019-12-01 07:04:53.917 [error] <0.3757.0> Supervisor {<0.3757.0>,amqp_connection_sup} had child connection started with amqp_gen_connection:start_link(<0.3758.0>, {amqp_params_network,<<"guest">>,<<"guest">>,<<"/">>,"localhost",5672,2047,0,10,60000,none,[#Fun<am..>,...],...}) at <0.3759.0> exit with reason {socket_error,timeout} in context child_terminated
2019-12-01 07:04:53.917 [error] <0.3757.0> Supervisor {<0.3757.0>,amqp_connection_sup} had child connection started with amqp_gen_connection:start_link(<0.3758.0>, {amqp_params_network,<<"guest">>,<<"guest">>,<<"/">>,"localhost",5672,2047,0,10,60000,none,[#Fun<am..>,...],...}) at <0.3759.0> exit with reason reached_max_restart_intensity in context shutdown
2019-12-01 07:04:53.917 [error] <0.3757.0> Supervisor {<0.3757.0>,amqp_connection_sup} had child connection_type_sup started with amqp_connection_type_sup:start_link() at <0.3758.0> exit with reason shutdown in context shutdown_error
2019-12-01 07:04:53.918 [error] <0.433.0>@gen_server:call Supervisor 'Elixir.RailwayIpc.Connection.Supervisor' had child 'Elixir.RailwayIpc.Connection' started with 'Elixir.RailwayIpc.Connection':start_link([{name,'Elixir.RailwayIpc.Connection'}]) at <0.3754.0> exit with reason no such process or port in call to gen_server:call(<0.3759.0>, {command,{close,{'connection.close',200,<<"Goodbye">>,0,0},60000}}, 60000) in context child_terminated
2019-12-01 07:15:28.899 [error] <0.3786.0> gen_server <0.3786.0> terminated with reason: {socket_error,timeout}
2019-12-01 07:15:28.899 [error] <0.3786.0> CRASH REPORT Process <0.3786.0> with 0 neighbours exited with reason: {socket_error,timeout} in gen_server:handle_common_reply/8 line 751
2019-12-01 07:15:28.900 [error] <0.3782.0> gen_server <0.3782.0> terminated with reason: {socket_error,timeout}
2019-12-01 07:15:28.902 [error] <0.3781.0> Supervisor {<0.3781.0>,amqp_connection_type_sup} had child main_reader started with amqp_main_reader:start_link(#Port<0.543>, <0.3782.0>, <0.3784.0>, {method,rabbit_framing_amqp_0_9_1}, <<"client 127.0.0.1:64244 -> 127.0.0.1:5672">>) at <0.3786.0> exit with reason {socket_error,timeout} in context child_terminated
2019-12-01 07:15:28.902 [error] <0.3781.0> Supervisor {<0.3781.0>,amqp_connection_type_sup} had child main_reader started with amqp_main_reader:start_link(#Port<0.543>, <0.3782.0>, <0.3784.0>, {method,rabbit_framing_amqp_0_9_1}, <<"client 127.0.0.1:64244 -> 127.0.0.1:5672">>) at <0.3786.0> exit with reason reached_max_restart_intensity in context shutdown
2019-12-01 07:15:28.902 [error] <0.3782.0> CRASH REPORT Process <0.3782.0> with 0 neighbours exited with reason: {socket_error,timeout} in gen_server:handle_common_reply/8 line 751
2019-12-01 07:15:28.903 [error] <0.3777.0>@gen_server:call gen_server 'Elixir.RailwayIpc.Connection' terminated with reason: no such process or port in call to gen_server:call(<0.3782.0>, {command,{close,{'connection.close',200,<<"Goodbye">>,0,0},60000}}, 60000) in gen_server:call/3 line 223
2019-12-01 07:15:28.904 [error] <0.3777.0>@gen_server:call CRASH REPORT Process 'Elixir.RailwayIpc.Connection' with 0 neighbours exited with reason: no such process or port in call to gen_server:call(<0.3782.0>, {command,{close,{'connection.close',200,<<"Goodbye">>,0,0},60000}}, 60000) in gen_server:call/3 line 223
2019-12-01 07:15:28.907 [error] <0.3780.0> Supervisor {<0.3780.0>,amqp_connection_sup} had child connection started with amqp_gen_connection:start_link(<0.3781.0>, {amqp_params_network,<<"guest">>,<<"guest">>,<<"/">>,"localhost",5672,2047,0,10,60000,none,[#Fun<am..>,...],...}) at <0.3782.0> exit with reason {socket_error,timeout} in context child_terminated
2019-12-01 07:15:28.907 [error] <0.3780.0> Supervisor {<0.3780.0>,amqp_connection_sup} had child connection started with amqp_gen_connection:start_link(<0.3781.0>, {amqp_params_network,<<"guest">>,<<"guest">>,<<"/">>,"localhost",5672,2047,0,10,60000,none,[#Fun<am..>,...],...}) at <0.3782.0> exit with reason reached_max_restart_intensity in context shutdown
2019-12-01 07:15:28.907 [error] <0.3780.0> Supervisor {<0.3780.0>,amqp_connection_sup} had child connection_type_sup started with amqp_connection_type_sup:start_link() at <0.3781.0> exit with reason shutdown in context shutdown_error
2019-12-01 07:15:28.907 [error] <0.433.0>@gen_server:call Supervisor 'Elixir.RailwayIpc.Connection.Supervisor' had child 'Elixir.RailwayIpc.Connection' started with 'Elixir.RailwayIpc.Connection':start_link([{name,'Elixir.RailwayIpc.Connection'}]) at <0.3777.0> exit with reason no such process or port in call to gen_server:call(<0.3782.0>, {command,{close,{'connection.close',200,<<"Goodbye">>,0,0},60000}}, 60000) in context child_terminated
2019-12-01 07:21:48.383 [error] <0.3884.0> CRASH REPORT Process <0.3884.0> with 0 neighbours exited with reason: {{#{'__exception__' => true,'__struct__' => 'Elixir.Phoenix.Template.UndefinedError',assigns => #{'__phx_template_not_found__' => 'Elixir.RailwayUiWeb.PublishedMessageView',data => #{'__struct__' => 'Elixir.RailwayUiWeb.PublishedMessageLive.Index.State',current_user_uuid => <<"1f4c4051-fe12-41cf-a39a-49f794f6b333">>,flash => #{},page => 4,page_nums => 8,query_filter => nil,query_value => nil,search => #{'__struct__' => 'Elixir.RailwayUiWeb.PublishedMessageLive.Index.Search',query => nil,...}},...},...},...},...} in 'Elixir.Phoenix.Endpoint.Cowboy2Handler':init/4 line 59 in 'Elixir.Phoenix.Endpoint.Cowboy2Handler':init/4 line 59
2019-12-01 07:21:48.389 [error] <0.398.0> Lager event handler error_logger_lager_h exited with reason {'EXIT',{{case_clause,['Elixir.RailwayUiWeb.Endpoint.HTTP',<0.3882.0>,1,<0.3884.0>,{{#{'__exception__' => true,'__struct__' => 'Elixir.Phoenix.Template.UndefinedError',assigns => #{'__phx_template_not_found__' => 'Elixir.RailwayUiWeb.PublishedMessageView',data => #{'__struct__' => 'Elixir.RailwayUiWeb.PublishedMessageLive.Index.State',current_user_uuid => <<"1f4c4051-fe12-41cf-a39a-49f794f6b333">>,flash => #{},page => 4,page_nums => 8,query_filter => nil,query_value => nil,search => #{...}},...},...},...},...},...]},...}}
2019-12-01 07:21:54.561 [error] <0.3902.0> CRASH REPORT Process <0.3902.0> with 0 neighbours exited with reason: {{#{'__exception__' => true,'__struct__' => 'Elixir.Phoenix.Template.UndefinedError',assigns => #{'__phx_template_not_found__' => 'Elixir.RailwayUiWeb.PublishedMessageView',data => #{'__struct__' => 'Elixir.RailwayUiWeb.PublishedMessageLive.Index.State',current_user_uuid => <<"1f4c4051-fe12-41cf-a39a-49f794f6b333">>,flash => #{},page => 4,page_nums => 8,query_filter => nil,query_value => nil,search => #{'__struct__' => 'Elixir.RailwayUiWeb.PublishedMessageLive.Index.Search',query => nil,...}},...},...},...},...} in 'Elixir.Phoenix.Endpoint.Cowboy2Handler':init/4 line 59 in 'Elixir.Phoenix.Endpoint.Cowboy2Handler':init/4 line 59
2019-12-01 07:21:54.574 [error] <0.398.0> Lager event handler error_logger_lager_h exited with reason {'EXIT',{{case_clause,['Elixir.RailwayUiWeb.Endpoint.HTTP',<0.3901.0>,1,<0.3902.0>,{{#{'__exception__' => true,'__struct__' => 'Elixir.Phoenix.Template.UndefinedError',assigns => #{'__phx_template_not_found__' => 'Elixir.RailwayUiWeb.PublishedMessageView',data => #{'__struct__' => 'Elixir.RailwayUiWeb.PublishedMessageLive.Index.State',current_user_uuid => <<"1f4c4051-fe12-41cf-a39a-49f794f6b333">>,flash => #{},page => 4,page_nums => 8,query_filter => nil,query_value => nil,search => #{...}},...},...},...},...},...]},...}}
2019-12-01 07:22:07.558 [error] <0.3913.0> CRASH REPORT Process <0.3913.0> with 0 neighbours exited with reason: {{#{'__exception__' => true,'__struct__' => 'Elixir.Phoenix.Template.UndefinedError',assigns => #{'__phx_template_not_found__' => 'Elixir.RailwayUiWeb.PublishedMessageView',data => #{'__struct__' => 'Elixir.RailwayUiWeb.PublishedMessageLive.Index.State',current_user_uuid => <<"1f4c4051-fe12-41cf-a39a-49f794f6b333">>,flash => #{},page => 4,page_nums => 8,query_filter => nil,query_value => nil,search => #{'__struct__' => 'Elixir.RailwayUiWeb.PublishedMessageLive.Index.Search',query => nil,...}},...},...},...},...} in 'Elixir.Phoenix.Endpoint.Cowboy2Handler':init/4 line 59 in 'Elixir.Phoenix.Endpoint.Cowboy2Handler':init/4 line 59
2019-12-01 07:22:07.565 [error] <0.398.0> Lager event handler error_logger_lager_h exited with reason {'EXIT',{{case_clause,['Elixir.RailwayUiWeb.Endpoint.HTTP',<0.3911.0>,1,<0.3913.0>,{{#{'__exception__' => true,'__struct__' => 'Elixir.Phoenix.Template.UndefinedError',assigns => #{'__phx_template_not_found__' => 'Elixir.RailwayUiWeb.PublishedMessageView',data => #{'__struct__' => 'Elixir.RailwayUiWeb.PublishedMessageLive.Index.State',current_user_uuid => <<"1f4c4051-fe12-41cf-a39a-49f794f6b333">>,flash => #{},page => 4,page_nums => 8,query_filter => nil,query_value => nil,search => #{...}},...},...},...},...},...]},...}}
2019-12-01 07:22:07.851 [error] <0.3928.0> CRASH REPORT Process <0.3928.0> with 0 neighbours exited with reason: {{#{'__exception__' => true,'__struct__' => 'Elixir.Phoenix.Template.UndefinedError',assigns => #{'__phx_template_not_found__' => 'Elixir.RailwayUiWeb.PublishedMessageView',data => #{'__struct__' => 'Elixir.RailwayUiWeb.PublishedMessageLive.Index.State',current_user_uuid => <<"1f4c4051-fe12-41cf-a39a-49f794f6b333">>,flash => #{},page => 4,page_nums => 8,query_filter => nil,query_value => nil,search => #{'__struct__' => 'Elixir.RailwayUiWeb.PublishedMessageLive.Index.Search',query => nil,...}},...},...},...},...} in 'Elixir.Phoenix.Endpoint.Cowboy2Handler':init/4 line 59 in 'Elixir.Phoenix.Endpoint.Cowboy2Handler':init/4 line 59
2019-12-01 07:22:07.856 [error] <0.398.0> Lager event handler error_logger_lager_h exited with reason {'EXIT',{{case_clause,['Elixir.RailwayUiWeb.Endpoint.HTTP',<0.3911.0>,2,<0.3928.0>,{{#{'__exception__' => true,'__struct__' => 'Elixir.Phoenix.Template.UndefinedError',assigns => #{'__phx_template_not_found__' => 'Elixir.RailwayUiWeb.PublishedMessageView',data => #{'__struct__' => 'Elixir.RailwayUiWeb.PublishedMessageLive.Index.State',current_user_uuid => <<"1f4c4051-fe12-41cf-a39a-49f794f6b333">>,flash => #{},page => 4,page_nums => 8,query_filter => nil,query_value => nil,search => #{...}},...},...},...},...},...]},...}}
2019-12-01 07:22:16.320 [error] <0.3939.0> CRASH REPORT Process <0.3939.0> with 0 neighbours exited with reason: {{#{'__exception__' => true,'__struct__' => 'Elixir.Phoenix.Template.UndefinedError',assigns => #{'__phx_template_not_found__' => 'Elixir.RailwayUiWeb.PublishedMessageView',data => #{'__struct__' => 'Elixir.RailwayUiWeb.PublishedMessageLive.Index.State',current_user_uuid => <<"1f4c4051-fe12-41cf-a39a-49f794f6b333">>,flash => #{},page => 4,page_nums => 8,query_filter => nil,query_value => nil,search => #{'__struct__' => 'Elixir.RailwayUiWeb.PublishedMessageLive.Index.Search',query => nil,...}},...},...},...},...} in 'Elixir.Phoenix.Endpoint.Cowboy2Handler':init/4 line 59 in 'Elixir.Phoenix.Endpoint.Cowboy2Handler':init/4 line 59
2019-12-01 07:22:16.325 [error] <0.398.0> Lager event handler error_logger_lager_h exited with reason {'EXIT',{{case_clause,['Elixir.RailwayUiWeb.Endpoint.HTTP',<0.3938.0>,1,<0.3939.0>,{{#{'__exception__' => true,'__struct__' => 'Elixir.Phoenix.Template.UndefinedError',assigns => #{'__phx_template_not_found__' => 'Elixir.RailwayUiWeb.PublishedMessageView',data => #{'__struct__' => 'Elixir.RailwayUiWeb.PublishedMessageLive.Index.State',current_user_uuid => <<"1f4c4051-fe12-41cf-a39a-49f794f6b333">>,flash => #{},page => 4,page_nums => 8,query_filter => nil,query_value => nil,search => #{...}},...},...},...},...},...]},...}}
2019-12-01 07:22:17.866 [error] <0.3956.0> CRASH REPORT Process <0.3956.0> with 0 neighbours exited with reason: {{#{'__exception__' => true,'__struct__' => 'Elixir.Phoenix.Template.UndefinedError',assigns => #{'__phx_template_not_found__' => 'Elixir.RailwayUiWeb.PublishedMessageView',data => #{'__struct__' => 'Elixir.RailwayUiWeb.PublishedMessageLive.Index.State',current_user_uuid => <<"1f4c4051-fe12-41cf-a39a-49f794f6b333">>,flash => #{},page => 4,page_nums => 8,query_filter => nil,query_value => nil,search => #{'__struct__' => 'Elixir.RailwayUiWeb.PublishedMessageLive.Index.Search',query => nil,...}},...},...},...},...} in 'Elixir.Phoenix.Endpoint.Cowboy2Handler':init/4 line 59 in 'Elixir.Phoenix.Endpoint.Cowboy2Handler':init/4 line 59
2019-12-01 07:22:17.873 [error] <0.398.0> Lager event handler error_logger_lager_h exited with reason {'EXIT',{{case_clause,['Elixir.RailwayUiWeb.Endpoint.HTTP',<0.3938.0>,3,<0.3956.0>,{{#{'__exception__' => true,'__struct__' => 'Elixir.Phoenix.Template.UndefinedError',assigns => #{'__phx_template_not_found__' => 'Elixir.RailwayUiWeb.PublishedMessageView',data => #{'__struct__' => 'Elixir.RailwayUiWeb.PublishedMessageLive.Index.State',current_user_uuid => <<"1f4c4051-fe12-41cf-a39a-49f794f6b333">>,flash => #{},page => 4,page_nums => 8,query_filter => nil,query_value => nil,search => #{...}},...},...},...},...},...]},...}}
2019-12-01 07:23:15.140 [error] <0.3967.0> CRASH REPORT Process <0.3967.0> with 0 neighbours exited with reason: {{#{'__exception__' => true,'__struct__' => 'Elixir.Phoenix.Template.UndefinedError',assigns => #{'__phx_template_not_found__' => 'Elixir.RailwayUiWeb.PublishedMessageView',data => #{'__struct__' => 'Elixir.RailwayUiWeb.PublishedMessageLive.Index.State',current_user_uuid => <<"1f4c4051-fe12-41cf-a39a-49f794f6b333">>,flash => #{},page => 4,page_nums => 8,query_filter => nil,query_value => nil,search => #{'__struct__' => 'Elixir.RailwayUiWeb.PublishedMessageLive.Index.Search',query => nil,...}},...},...},...},...} in 'Elixir.Phoenix.Endpoint.Cowboy2Handler':init/4 line 59 in 'Elixir.Phoenix.Endpoint.Cowboy2Handler':init/4 line 59
2019-12-01 07:23:15.152 [error] <0.398.0> Lager event handler error_logger_lager_h exited with reason {'EXIT',{{case_clause,['Elixir.RailwayUiWeb.Endpoint.HTTP',<0.3966.0>,1,<0.3967.0>,{{#{'__exception__' => true,'__struct__' => 'Elixir.Phoenix.Template.UndefinedError',assigns => #{'__phx_template_not_found__' => 'Elixir.RailwayUiWeb.PublishedMessageView',data => #{'__struct__' => 'Elixir.RailwayUiWeb.PublishedMessageLive.Index.State',current_user_uuid => <<"1f4c4051-fe12-41cf-a39a-49f794f6b333">>,flash => #{},page => 4,page_nums => 8,query_filter => nil,query_value => nil,search => #{...}},...},...},...},...},...]},...}}
2019-12-01 07:23:39.270 [error] <0.3983.0> CRASH REPORT Process <0.3983.0> with 0 neighbours exited with reason: {{#{'__exception__' => true,'__struct__' => 'Elixir.Phoenix.Template.UndefinedError',assigns => #{'__phx_template_not_found__' => 'Elixir.RailwayUiWeb.PublishedMessageView',data => #{'__struct__' => 'Elixir.RailwayUiWeb.PublishedMessageLive.Index.State',current_user_uuid => <<"1f4c4051-fe12-41cf-a39a-49f794f6b333">>,flash => #{},page => 4,page_nums => 8,query_filter => nil,query_value => nil,search => #{'__struct__' => 'Elixir.RailwayUiWeb.PublishedMessageLive.Index.Search',query => nil,...}},...},...},...},...} in 'Elixir.Phoenix.Endpoint.Cowboy2Handler':init/4 line 59 in 'Elixir.Phoenix.Endpoint.Cowboy2Handler':init/4 line 59
2019-12-01 07:23:39.279 [error] <0.398.0> Lager event handler error_logger_lager_h exited with reason {'EXIT',{{case_clause,['Elixir.RailwayUiWeb.Endpoint.HTTP',<0.3981.0>,1,<0.3983.0>,{{#{'__exception__' => true,'__struct__' => 'Elixir.Phoenix.Template.UndefinedError',assigns => #{'__phx_template_not_found__' => 'Elixir.RailwayUiWeb.PublishedMessageView',data => #{'__struct__' => 'Elixir.RailwayUiWeb.PublishedMessageLive.Index.State',current_user_uuid => <<"1f4c4051-fe12-41cf-a39a-49f794f6b333">>,flash => #{},page => 4,page_nums => 8,query_filter => nil,query_value => nil,search => #{...}},...},...},...},...},...]},...}}
2019-12-01 07:23:49.186 [error] <0.4001.0> CRASH REPORT Process <0.4001.0> with 0 neighbours exited with reason: {{#{'__exception__' => true,'__struct__' => 'Elixir.Phoenix.Template.UndefinedError',assigns => #{'__phx_template_not_found__' => 'Elixir.RailwayUiWeb.PublishedMessageView',data => #{'__struct__' => 'Elixir.RailwayUiWeb.PublishedMessageLive.Index.State',current_user_uuid => <<"1f4c4051-fe12-41cf-a39a-49f794f6b333">>,flash => #{},page => 4,page_nums => 8,query_filter => nil,query_value => nil,search => #{'__struct__' => 'Elixir.RailwayUiWeb.PublishedMessageLive.Index.Search',query => nil,...}},...},...},...},...} in 'Elixir.Phoenix.Endpoint.Cowboy2Handler':init/4 line 59 in 'Elixir.Phoenix.Endpoint.Cowboy2Handler':init/4 line 59
2019-12-01 07:23:49.253 [error] <0.398.0> Lager event handler error_logger_lager_h exited with reason {'EXIT',{{case_clause,['Elixir.RailwayUiWeb.Endpoint.HTTP',<0.3999.0>,1,<0.4001.0>,{{#{'__exception__' => true,'__struct__' => 'Elixir.Phoenix.Template.UndefinedError',assigns => #{'__phx_template_not_found__' => 'Elixir.RailwayUiWeb.PublishedMessageView',data => #{'__struct__' => 'Elixir.RailwayUiWeb.PublishedMessageLive.Index.State',current_user_uuid => <<"1f4c4051-fe12-41cf-a39a-49f794f6b333">>,flash => #{},page => 4,page_nums => 8,query_filter => nil,query_value => nil,search => #{...}},...},...},...},...},...]},...}}
2019-12-01 07:24:09.120 [error] <0.433.0> Supervisor 'Elixir.RailwayIpc.Connection.Supervisor' had child 'Elixir.RailwayIpc.Connection' started with 'Elixir.RailwayIpc.Connection':start_link([{name,'Elixir.RailwayIpc.Connection'}]) at <0.3798.0> exit with reason normal in context child_terminated
2019-12-01 07:25:41.270 [error] <0.4087.0> CRASH REPORT Process <0.4087.0> with 0 neighbours exited with reason: {{#{'__exception__' => true,'__struct__' => 'Elixir.Phoenix.Template.UndefinedError',assigns => #{'__phx_template_not_found__' => 'Elixir.RailwayUiWeb.MessageView',data => #{'__struct__' => 'Elixir.RailwayUiWeb.PublishedMessageLive.Index.State',current_user_uuid => <<"1f4c4051-fe12-41cf-a39a-49f794f6b333">>,flash => #{},page => 4,page_nums => 8,query_filter => nil,query_value => nil,search => #{'__struct__' => 'Elixir.RailwayUiWeb.PublishedMessageLive.Index.Search',query => nil,value => nil}},...},...},...},...} in 'Elixir.Phoenix.Endpoint.Cowboy2Handler':init/4 line 59 in 'Elixir.Phoenix.Endpoint.Cowboy2Handler':init/4 line 59
2019-12-01 07:25:41.277 [error] <0.398.0> Lager event handler error_logger_lager_h exited with reason {'EXIT',{{case_clause,['Elixir.RailwayUiWeb.Endpoint.HTTP',<0.4085.0>,1,<0.4087.0>,{{#{'__exception__' => true,'__struct__' => 'Elixir.Phoenix.Template.UndefinedError',assigns => #{'__phx_template_not_found__' => 'Elixir.RailwayUiWeb.MessageView',data => #{'__struct__' => 'Elixir.RailwayUiWeb.PublishedMessageLive.Index.State',current_user_uuid => <<"1f4c4051-fe12-41cf-a39a-49f794f6b333">>,flash => #{},page => 4,page_nums => 8,query_filter => nil,query_value => nil,search => #{'__struct__' => ...,...}},...},...},...},...},...]},...}}
2019-12-01 07:26:55.286 [error] <0.4198.0> CRASH REPORT Process <0.4198.0> with 0 neighbours exited with reason: {{#{'__exception__' => true,'__struct__' => 'Elixir.Phoenix.Template.UndefinedError',assigns => #{'__phx_template_not_found__' => 'Elixir.RailwayUiWeb.MessageView',data => #{'__struct__' => 'Elixir.RailwayUiWeb.PublishedMessageLive.Index.State',current_user_uuid => <<"1f4c4051-fe12-41cf-a39a-49f794f6b333">>,flash => #{},page => 1,page_nums => 5,query_filter => nil,query_value => nil,search => #{'__struct__' => 'Elixir.RailwayUiWeb.PublishedMessageLive.Index.Search',query => <<"message_ty...">>,...}},...},...},...},...} in 'Elixir.Phoenix.Endpoint.Cowboy2Handler':init/4 line 59 in 'Elixir.Phoenix.Endpoint.Cowboy2Handler':init/4 line 59
2019-12-01 07:26:55.346 [error] <0.398.0> Lager event handler error_logger_lager_h exited with reason {'EXIT',{{case_clause,['Elixir.RailwayUiWeb.Endpoint.HTTP',<0.4196.0>,1,<0.4198.0>,{{#{'__exception__' => true,'__struct__' => 'Elixir.Phoenix.Template.UndefinedError',assigns => #{'__phx_template_not_found__' => 'Elixir.RailwayUiWeb.MessageView',data => #{'__struct__' => 'Elixir.RailwayUiWeb.PublishedMessageLive.Index.State',current_user_uuid => <<"1f4c4051-fe12-41cf-a39a-49f794f6b333">>,flash => #{},page => 1,page_nums => 5,query_filter => nil,query_value => nil,search => #{'__struct__' => ...,...}},...},...},...},...},...]},...}}
2019-12-01 07:27:39.272 [error] <0.4283.0> CRASH REPORT Process <0.4283.0> with 0 neighbours exited with reason: {{#{'__exception__' => true,'__struct__' => 'Elixir.Phoenix.Template.UndefinedError',assigns => #{'__phx_template_not_found__' => 'Elixir.RailwayUiWeb.MessageView',data => #{'__struct__' => 'Elixir.RailwayUiWeb.PublishedMessageLive.Index.State',current_user_uuid => <<"1f4c4051-fe12-41cf-a39a-49f794f6b333">>,flash => #{},page => 1,page_nums => 5,query_filter => nil,query_value => nil,search => #{'__struct__' => 'Elixir.RailwayUiWeb.PublishedMessageLive.Index.Search',query => <<"message_ty...">>,...}},...},...},...},...} in 'Elixir.Phoenix.Endpoint.Cowboy2Handler':init/4 line 59 in 'Elixir.Phoenix.Endpoint.Cowboy2Handler':init/4 line 59
2019-12-01 07:27:39.278 [error] <0.398.0> Lager event handler error_logger_lager_h exited with reason {'EXIT',{{case_clause,['Elixir.RailwayUiWeb.Endpoint.HTTP',<0.4280.0>,1,<0.4283.0>,{{#{'__exception__' => true,'__struct__' => 'Elixir.Phoenix.Template.UndefinedError',assigns => #{'__phx_template_not_found__' => 'Elixir.RailwayUiWeb.MessageView',data => #{'__struct__' => 'Elixir.RailwayUiWeb.PublishedMessageLive.Index.State',current_user_uuid => <<"1f4c4051-fe12-41cf-a39a-49f794f6b333">>,flash => #{},page => 1,page_nums => 5,query_filter => nil,query_value => nil,search => #{'__struct__' => ...,...}},...},...},...},...},...]},...}}
2019-12-01 07:31:45.055 [error] <0.4369.0> gen_server <0.4369.0> terminated with reason: {#{'__exception__' => true,'__struct__' => 'Elixir.UndefinedFunctionError',arity => 1,function => render,message => nil,module => 'Elixir.RailwayUiWeb.PublishedMessageLive.Index',reason => nil},[{'Elixir.RailwayUiWeb.PublishedMessageLive.Index',render,[#{socket => #{'__struct__' => 'Elixir.Phoenix.LiveView.Socket',assigns => #{},changed => #{},'connected?' => true,endpoint => 'Elixir.RailwayUiWeb.Endpoint',fingerprints => {nil,#{}},id => <<"phx-lmcGKu2q">>,parent_pid => nil,private => #{...},...}}],...},...]}
2019-12-01 07:31:45.056 [error] <0.4369.0> CRASH REPORT Process <0.4369.0> with 0 neighbours crashed with reason: {#{'__exception__' => true,'__struct__' => 'Elixir.UndefinedFunctionError',arity => 1,function => render,message => nil,module => 'Elixir.RailwayUiWeb.PublishedMessageLive.Index',reason => nil},[{'Elixir.RailwayUiWeb.PublishedMessageLive.Index',render,[#{socket => #{'__struct__' => 'Elixir.Phoenix.LiveView.Socket',assigns => #{},changed => #{},'connected?' => true,endpoint => 'Elixir.RailwayUiWeb.Endpoint',fingerprints => {nil,#{}},id => <<"phx-lmcGKu2q">>,parent_pid => nil,private => #{...},...}}],...},...]}
2019-12-01 07:31:45.057 [error] <0.520.0> Supervisor {<0.520.0>,'Elixir.Phoenix.Socket.PoolSupervisor.WorkerSupervisor'} had child 'Elixir.Phoenix.Channel.Server' started with {'Elixir.Phoenix.Channel.Server',start_link,undefined} at <0.4369.0> exit with reason {#{'__exception__' => true,'__struct__' => 'Elixir.UndefinedFunctionError',arity => 1,function => render,message => nil,module => 'Elixir.RailwayUiWeb.PublishedMessageLive.Index',reason => nil},[{'Elixir.RailwayUiWeb.PublishedMessageLive.Index',render,[#{socket => #{'__struct__' => 'Elixir.Phoenix.LiveView.Socket',assigns => #{},changed => #{},'connected?' => true,endpoint => 'Elixir.RailwayUiWeb.Endpoint',fingerprints => {nil,#{}},id => <<"phx-lmcGKu2q">>,parent_pid => nil,private => #{...},...}}],...},...]} in context child_terminated
2019-12-01 07:31:45.096 [error] <0.4351.0> CRASH REPORT Process <0.4351.0> with 0 neighbours exited with reason: {{#{'__exception__' => true,'__struct__' => 'Elixir.UndefinedFunctionError',arity => 1,function => render,message => nil,module => 'Elixir.RailwayUiWeb.PublishedMessageLive.Index',reason => nil},[{'Elixir.RailwayUiWeb.PublishedMessageLive.Index',render,[#{socket => #{'__struct__' => 'Elixir.Phoenix.LiveView.Socket',assigns => #{},changed => #{},'connected?' => false,endpoint => 'Elixir.RailwayUiWeb.Endpoint',fingerprints => {nil,#{}},id => <<"phx-LB8kZ73p">>,parent_pid => nil,private => #{...},...}}],...},...]},...} in 'Elixir.Phoenix.Endpoint.Cowboy2Handler':init/4 line 59 in 'Elixir.Phoenix.Endpoint.Cowboy2Handler':init/4 line 59
2019-12-01 07:31:45.105 [error] <0.398.0> Lager event handler error_logger_lager_h exited with reason {'EXIT',{{case_clause,['Elixir.RailwayUiWeb.Endpoint.HTTP',<0.4349.0>,1,<0.4351.0>,{{#{'__exception__' => true,'__struct__' => 'Elixir.UndefinedFunctionError',arity => 1,function => render,message => nil,module => 'Elixir.RailwayUiWeb.PublishedMessageLive.Index',reason => nil},[{'Elixir.RailwayUiWeb.PublishedMessageLive.Index',render,[#{socket => #{'__struct__' => 'Elixir.Phoenix.LiveView.Socket',assigns => #{},changed => #{},'connected?' => false,endpoint => 'Elixir.RailwayUiWeb.Endpoint',...}}],...},...]},...},...]},...}}
2019-12-01 07:32:40.767 [error] <0.4382.0> CRASH REPORT Process <0.4382.0> with 0 neighbours exited with reason: {{#{'__exception__' => true,'__struct__' => 'Elixir.UndefinedFunctionError',arity => 1,function => render,message => nil,module => 'Elixir.RailwayUiWeb.PublishedMessageLive.Index',reason => nil},[{'Elixir.RailwayUiWeb.PublishedMessageLive.Index',render,[#{socket => #{'__struct__' => 'Elixir.Phoenix.LiveView.Socket',assigns => #{},changed => #{},'connected?' => false,endpoint => 'Elixir.RailwayUiWeb.Endpoint',fingerprints => {nil,#{}},id => <<"phx-y0Grmm6h">>,parent_pid => nil,private => #{...},...}}],...},...]},...} in 'Elixir.Phoenix.Endpoint.Cowboy2Handler':init/4 line 59 in 'Elixir.Phoenix.Endpoint.Cowboy2Handler':init/4 line 59
2019-12-01 07:32:40.772 [error] <0.398.0> Lager event handler error_logger_lager_h exited with reason {'EXIT',{{case_clause,['Elixir.RailwayUiWeb.Endpoint.HTTP',<0.4380.0>,1,<0.4382.0>,{{#{'__exception__' => true,'__struct__' => 'Elixir.UndefinedFunctionError',arity => 1,function => render,message => nil,module => 'Elixir.RailwayUiWeb.PublishedMessageLive.Index',reason => nil},[{'Elixir.RailwayUiWeb.PublishedMessageLive.Index',render,[#{socket => #{'__struct__' => 'Elixir.Phoenix.LiveView.Socket',assigns => #{},changed => #{},'connected?' => false,endpoint => 'Elixir.RailwayUiWeb.Endpoint',...}}],...},...]},...},...]},...}}
2019-12-01 07:40:46.832 [error] <0.4688.0> gen_server <0.4688.0> terminated with reason: {#{'__exception__' => true,'__struct__' => 'Elixir.UndefinedFunctionError',arity => 1,function => load_messages,message => nil,module => 'Elixir.RailwayUiWeb.PublishedMessageLive.Index.State',reason => nil},[{'Elixir.RailwayUiWeb.PublishedMessageLive.Index.State',load_messages,['Elixir.RailwayUi.PublishedMessage'],[]},{'Elixir.RailwayUiWeb.PublishedMessageLive.Index',mount,2,[{file,"lib/railway_ui_web/live/published_message_live/index.ex"},{line,2}]},{'Elixir.Phoenix.LiveView.Utils','maybe_call_mount!',...},...]}
2019-12-01 07:40:46.833 [error] <0.4688.0> CRASH REPORT Process <0.4688.0> with 0 neighbours crashed with reason: {#{'__exception__' => true,'__struct__' => 'Elixir.UndefinedFunctionError',arity => 1,function => load_messages,message => nil,module => 'Elixir.RailwayUiWeb.PublishedMessageLive.Index.State',reason => nil},[{'Elixir.RailwayUiWeb.PublishedMessageLive.Index.State',load_messages,['Elixir.RailwayUi.PublishedMessage'],[]},{'Elixir.RailwayUiWeb.PublishedMessageLive.Index',mount,2,[{file,"lib/railway_ui_web/live/published_message_live/index.ex"},{line,2}]},{'Elixir.Phoenix.LiveView.Utils','maybe_call_mount!',...},...]}
2019-12-01 07:40:46.833 [error] <0.521.0> Supervisor {<0.521.0>,'Elixir.Phoenix.Socket.PoolSupervisor.WorkerSupervisor'} had child 'Elixir.Phoenix.Channel.Server' started with {'Elixir.Phoenix.Channel.Server',start_link,undefined} at <0.4688.0> exit with reason {#{'__exception__' => true,'__struct__' => 'Elixir.UndefinedFunctionError',arity => 1,function => load_messages,message => nil,module => 'Elixir.RailwayUiWeb.PublishedMessageLive.Index.State',reason => nil},[{'Elixir.RailwayUiWeb.PublishedMessageLive.Index.State',load_messages,['Elixir.RailwayUi.PublishedMessage'],[]},{'Elixir.RailwayUiWeb.PublishedMessageLive.Index',mount,2,[{file,"lib/railway_ui_web/live/published_message_live/index.ex"},{line,2}]},{'Elixir.Phoenix.LiveView.Utils','maybe_call_mount!',...},...]} in context child_terminated
2019-12-01 07:40:46.881 [error] <0.4670.0> CRASH REPORT Process <0.4670.0> with 0 neighbours exited with reason: {{#{'__exception__' => true,'__struct__' => 'Elixir.UndefinedFunctionError',arity => 1,function => load_messages,message => nil,module => 'Elixir.RailwayUiWeb.PublishedMessageLive.Index.State',reason => nil},[{'Elixir.RailwayUiWeb.PublishedMessageLive.Index.State',load_messages,['Elixir.RailwayUi.PublishedMessage'],[]},{'Elixir.RailwayUiWeb.PublishedMessageLive.Index',mount,2,[{file,"lib/railway_ui_web/live/published_message_live/index.ex"},{line,2}]},{'Elixir.Phoenix.LiveView.Utils','maybe_call_mount!',...},...]},...} in 'Elixir.Phoenix.Endpoint.Cowboy2Handler':init/4 line 59 in 'Elixir.Phoenix.Endpoint.Cowboy2Handler':init/4 line 59
2019-12-01 07:40:46.929 [error] <0.398.0> Lager event handler error_logger_lager_h exited with reason {'EXIT',{{case_clause,['Elixir.RailwayUiWeb.Endpoint.HTTP',<0.4668.0>,1,<0.4670.0>,{{#{'__exception__' => true,'__struct__' => 'Elixir.UndefinedFunctionError',arity => 1,function => load_messages,message => nil,module => 'Elixir.RailwayUiWeb.PublishedMessageLive.Index.State',reason => nil},[{'Elixir.RailwayUiWeb.PublishedMessageLive.Index.State',load_messages,['Elixir.RailwayUi.PublishedMessage'],[]},{'Elixir.RailwayUiWeb.PublishedMessageLive.Index',mount,2,[{file,"lib/railway_ui_web/live..."},...]},...]},...},...]},...}}
2019-12-01 07:41:42.388 [error] <0.4727.0>@Elixir.RailwayUiWeb.PublishedMessageLive.Index:handle_params:2 gen_server <0.4727.0> terminated with reason: call to undefined function 'Elixir.RailwayUiWeb.PublishedMessageLive.Index.State':load_messages/0 from 'Elixir.RailwayUiWeb.PublishedMessageLive.Index':handle_params/3 line 2
2019-12-01 07:41:42.389 [error] <0.4727.0>@Elixir.RailwayUiWeb.PublishedMessageLive.Index.State:load_messages CRASH REPORT Process <0.4727.0> with 0 neighbours crashed with reason: call to undefined function 'Elixir.RailwayUiWeb.PublishedMessageLive.Index.State':load_messages()
2019-12-01 07:41:42.389 [error] <0.522.0>@Elixir.RailwayUiWeb.PublishedMessageLive.Index.State:load_messages Supervisor {<0.522.0>,'Elixir.Phoenix.Socket.PoolSupervisor.WorkerSupervisor'} had child 'Elixir.Phoenix.Channel.Server' started with {'Elixir.Phoenix.Channel.Server',start_link,undefined} at <0.4727.0> exit with reason call to undefined function 'Elixir.RailwayUiWeb.PublishedMessageLive.Index.State':load_messages() in context child_terminated
2019-12-01 07:44:17.276 [error] <0.4798.0>@Elixir.RailwayUiWeb.PublishedMessageLive.Index:handle_params:2 gen_server <0.4798.0> terminated with reason: call to undefined function 'Elixir.RailwayUiWeb.PublishedMessageLive.Index.State':for_search/3 from 'Elixir.RailwayUiWeb.PublishedMessageLive.Index':handle_params/3 line 2
2019-12-01 07:44:17.276 [error] <0.4798.0>@Elixir.RailwayUiWeb.PublishedMessageLive.Index.State:for_search CRASH REPORT Process <0.4798.0> with 0 neighbours crashed with reason: call to undefined function 'Elixir.RailwayUiWeb.PublishedMessageLive.Index.State':for_search(#{'__struct__' => 'Elixir.RailwayUiWeb.PublishedMessageLive.Index.State',current_user_uuid => <<"...">>,...}, <<"message_type">>, <<"CreateBatch">>)
2019-12-01 07:44:17.277 [error] <0.520.0>@Elixir.RailwayUiWeb.PublishedMessageLive.Index.State:for_search Supervisor {<0.520.0>,'Elixir.Phoenix.Socket.PoolSupervisor.WorkerSupervisor'} had child 'Elixir.Phoenix.Channel.Server' started with {'Elixir.Phoenix.Channel.Server',start_link,undefined} at <0.4798.0> exit with reason call to undefined function 'Elixir.RailwayUiWeb.PublishedMessageLive.Index.State':for_search(#{'__struct__' => 'Elixir.RailwayUiWeb.PublishedMessageLive.Index.State',current_user_uuid => <<"...">>,...}, <<"message_type">>, <<"CreateBatch">>) in context child_terminated
